Workbook

Sheet Data
A1: Chase Daily 2013 -2025
A2: Last edit 2/04/25 | E2: Average------ | G2: --- | H2: --- | I2: ---] | J2: Maximum ------- | L2: --- | M2: --- | N2: ---] | O2: Minimum------ | Q2: --- | R2: --- | S2: ---] | T2: Ave | U2: Max | V2: Midnight | X2: Ave | Y2: Max | Z2: MidNight
A3: Date | B3: Key1 | C3: ClrSky | D3: Solar | E3: Tair | F3: RH | G3: Ta1.5m | H3: Ta0.2m | I3: Tsoil | J3: Tair | K3: RH | L3: Ta1.5m | M3: Ta0.2m | N3: Tsoil | O3: Tair | P3: RH | Q3: Ta1.5m | R3: Ta0.2m | S3: Tsoil | T3: Wind | U3: Wind | V3: SnowD | W3: PPT | X3: Vapres | Y3: Vpd | Z3: BatV | AA3: Year | AB3: Month | AC3: Day | AD3: Season | AE3: DoY
C4: MJ/m2/d | D4: MJ/m2/d | E4: C | F4: % | G4: C | H4: C | I4: C | J4: C | K4: % | L4: C | M4: C | N4: C | O4: C | P4: % | Q4: C | R4: C | S4: C | T4: m/s | U4: m/s | V4: m | W4: mm | X4: kPa | Y4: kPa | Z4: V
A6: 41275 | B6: =AA6*1000+AE6 -> 2013001 | C6: 4.62 | D6: NA | E6: NA | F6: NA | G6: NA | H6: NA | I6: NA | J6: NA | K6: NA | L6: NA | M6: NA | N6: NA | O6: NA | P6: NA | Q6: NA | R6: NA | S6: NA | T6: NA | U6: NA | V6: NA | W6: NA | X6: NA | Y6: NA | Z6: NA | AA6: 2013 | AB6: 1 | AC6: 1 | AD6: 1 | AE6: 1
A7: 41276 | B7: =AA7*1000+AE7 -> 2013002 | C7: 4.66 | D7: NA | E7: NA | F7: NA | G7: NA | H7: NA | I7: NA | J7: NA | K7: NA | L7: NA | M7: NA | N7: NA | O7: NA | P7: NA | Q7: NA | R7: NA | S7: NA | T7: NA | U7: NA | V7: NA | W7: NA | X7: NA | Y7: NA | Z7: NA | AA7: 2013 | AB7: 1 | AC7: 2 | AD7: 1 | AE7: 2
A8: 41277 | B8: =AA8*1000+AE8 -> 2013003 | C8: 4.7 | D8: NA | E8: NA | F8: NA | G8: NA | H8: NA | I8: NA | J8: NA | K8: NA | L8: NA | M8: NA | N8: NA | O8: NA | P8: NA | Q8: NA | R8: NA | S8: NA | T8: NA | U8: NA | V8: NA | W8: NA | X8: NA | Y8: NA | Z8: NA | AA8: 2013 | AB8: 1 | AC8: 3 | AD8: 1 | AE8: 3
A9: 41278 | B9: =AA9*1000+AE9 -> 2013004 | C9: 4.75 | D9: NA | E9: NA | F9: NA | G9: NA | H9: NA | I9: NA | J9: NA | K9: NA | L9: NA | M9: NA | N9: NA | O9: NA | P9: NA | Q9: NA | R9: NA | S9: NA | T9: NA | U9: NA | V9: NA | W9: NA | X9: NA | Y9: NA | Z9: NA | AA9: 2013 | AB9: 1 | AC9: 4 | AD9: 1 | AE9: 4
A10: 41279 | B10: =AA10*1000+AE10 -> 2013005 | C10: 4.79 | D10: NA | E10: NA | F10: NA | G10: NA | H10: NA | I10: NA | J10: NA | K10: NA | L10: NA | M10: NA | N10: NA | O10: NA | P10: NA | Q10: NA | R10: NA | S10: NA | T10: NA | U10: NA | V10: NA | W10: NA | X10: NA | Y10: NA | Z10: NA | AA10: 2013 | AB10: 1 | AC10: 5 | AD10: 1 | AE10: 5
A11: 41280 | B11: =AA11*1000+AE11 -> 2013006 | C11: 4.85 | D11: NA | E11: NA | F11: NA | G11: NA | H11: NA | I11: NA | J11: NA | K11: NA | L11: NA | M11: NA | N11: NA | O11: NA | P11: NA | Q11: NA | R11: NA | S11: NA | T11: NA | U11: NA | V11: NA | W11: NA | X11: NA | Y11: NA | Z11: NA | AA11: 2013 | AB11: 1 | AC11: 6 | AD11: 1 | AE11: 6
A12: 41281 | B12: =AA12*1000+AE12 -> 2013007 | C12: 4.91 | D12: NA | E12: NA | F12: NA | G12: NA | H12: NA | I12: NA | J12: NA | K12: NA | L12: NA | M12: NA | N12: NA | O12: NA | P12: NA | Q12: NA | R12: NA | S12: NA | T12: NA | U12: NA | V12: NA | W12: NA | X12: NA | Y12: NA | Z12: 12.97 | AA12: 2013 | AB12: 1 | AC12: 7 | AD12: 1 | AE12: 7
A13: 41282 | B13: =AA13*1000+AE13 -> 2013008 | C13: 4.97 | D13: 0.41 | E13: -4.1 | F13: 81 | G13: -4.5 | H13: -1.3 | I13: 1.1 | J13: -0.2 | K13: 91.7 | L13: -1.6 | M13: -1.2 | N13: 1.4 | O13: -6.4 | P13: 58.4 | Q13: -7.3 | R13: -1.6 | S13: 0.7 | T13: 1.64 | U13: 5.43 | V13: 0.713 | W13: 7.7 | X13: 0.35 | Y13: 0.25 | Z13: 12.96 | AA13: 2013 | AB13: 1 | AC13: 8 | AD13: 1 | AE13: 8
A14: 41283 | B14: =AA14*1000+AE14 -> 2013009 | C14: 5.03 | D14: 0.31 | E14: -1.5 | F14: 83.4 | G14: -2 | H14: -1.2 | I14: 1.1 | J14: 0.4 | K14: 94.4 | L14: 0.3 | M14: -1 | N14: 1.2 | O14: -5 | P14: 73.6 | Q14: -5.9 | R14: -1.4 | S14: 0.7 | T14: 1.69 | U14: 4.98 | V14: 0.726 | W14: 1.7 | X14: 0.463 | Y14: 0.166 | Z14: 12.93 | AA14: 2013 | AB14: 1 | AC14: 9 | AD14: 1 | AE14: 9
A15: 41284 | B15: =AA15*1000+AE15 -> 2013010 | C15: 5.09 | D15: 0.6 | E15: -9.1 | F15: 83.4 | G15: -9.6 | H15: -1.3 | I15: 1.1 | J15: -2.6 | K15: 91.6 | L15: -4.8 | M15: -0.8 | N15: 1.6 | O15: -12.8 | P15: 55.2 | Q15: -13.6 | R15: -1.7 | S15: 0.7 | T15: 0.87 | U15: 3.24 | V15: 0.704 | W15: 0 | X15: 0.278 | Y15: 0.226 | Z15: 13.02 | AA15: 2013 | AB15: 1 | AC15: 10 | AD15: 1 | AE15: 10
A16: 41285 | B16: =AA16*1000+AE16 -> 2013011 | C16: 5.16 | D16: 1.24 | E16: -13.3 | F16: 80.8 | G16: -14.4 | H16: -1.9 | I16: 1 | J16: -4.8 | K16: 88.8 | L16: -7.4 | M16: -1.4 | N16: 1.6 | O16: -18 | P16: 51.9 | Q16: -19.6 | R16: -2.5 | S16: 0.3 | T16: 0.49 | U16: 2.03 | V16: 0.67 | W16: 0 | X16: 0.222 | Y16: 0.206 | Z16: 13.17 | AA16: 2013 | AB16: 1 | AC16: 11 | AD16: 1 | AE16: 11
A17: 41286 | B17: =AA17*1000+AE17 -> 2013012 | C17: 5.24 | D17: 0.95 | E17: -13.8 | F17: 80.6 | G17: -14.8 | H17: -2.6 | I17: 1 | J17: -5 | K17: 86.7 | L17: -10.3 | M17: -1.9 | N17: 1.6 | O17: -18.3 | P17: 53.1 | Q17: -19.8 | R17: -3.2 | S17: 0.4 | T17: 0.25 | U17: 1.95 | V17: 0.665 | W17: 0 | X17: 0.224 | Y17: 0.198 | Z17: 13.2 | AA17: 2013 | AB17: 1 | AC17: 12 | AD17: 1 | AE17: 12
A18: 41287 | B18: =AA18*1000+AE18 -> 2013013 | C18: 5.32 | D18: 0.53 | E18: -12.9 | F18: 83.9 | G18: -13.5 | H18: -2.8 | I18: 1.1 | J18: -8.7 | K18: 90.5 | L18: -9.9 | M18: -2.5 | N18: 1.5 | O18: -17.2 | P18: 73.7 | Q18: -18.5 | R18: -3.1 | S18: 0.6 | T18: 0.31 | U18: 1.55 | V18: 0.667 | W18: 0.3 | X18: 0.234 | Y18: 0.084 | Z18: 13.12 | AA18: 2013 | AB18: 1 | AC18: 13 | AD18: 1 | AE18: 13
A19: 41288 | B19: =AA19*1000+AE19 -> 2013014 | C19: 5.39 | D19: 0.28 | E19: -7.3 | F19: 87.2 | G19: -7.9 | H19: -2.5 | I19: 1.1 | J19: -4.3 | K19: 91.5 | L19: -4.4 | M19: -2.3 | N19: 1.4 | O19: -11.1 | P19: 78.5 | Q19: -11.8 | R19: -2.8 | S19: 0.8 | T19: 0.37 | U19: 2.06 | V19: 0.668 | W19: 0.1 | X19: 0.349 | Y19: 0.096 | Z19: 13.03 | AA19: 2013 | AB19: 1 | AC19: 14 | AD19: 1 | AE19: 14
A20: 41289 | B20: =AA20*1000+AE20 -> 2013015 | C20: 5.48 | D20: 1.16 | E20: -3 | F20: 76.7 | G20: -4.3 | H20: -2.1 | I20: 1 | J20: 8.6 | K20: 93 | L20: 3.2 | M20: -1.7 | N20: 1.4 | O20: -7.2 | P20: 34.5 | Q20: -9 | R20: -2.4 | S20: 0.3 | T20: 0.65 | U20: 2.18 | V20: 0.643 | W20: 0 | X20: 0.385 | Y20: 0.73 | Z20: 13.23 | AA20: 2013 | AB20: 1 | AC20: 15 | AD20: 1 | AE20: 15
A21: 41290 | B21: =AA21*1000+AE21 -> 2013016 | C21: 5.57 | D21: 2.77 | E21: 0 | F21: 66.4 | G21: -0.6 | H21: -1.6 | I21: 1.1 | J21: 9.3 | K21: 91.2 | L21: 5.2 | M21: -1.1 | N21: 1.4 | O21: -7.3 | P21: 36 | Q21: -8.7 | R21: -2.4 | S21: 0.1 | T21: 0.55 | U21: 2.11 | V21: 0.645 | W21: 0.3 | X21: 0.422 | Y21: 0.749 | Z21: 13.21 | AA21: 2013 | AB21: 1 | AC21: 16 | AD21: 1 | AE21: 16
A22: 41291 | B22: =AA22*1000+AE22 -> 2013017 | C22: 5.66 | D22: 1.64 | E22: -0.1 | F22: 69.2 | G22: -0.5 | H22: -1.2 | I22: 1 | J22: 2.5 | K22: 92.1 | L22: 2.1 | M22: -1 | N22: 1.3 | O22: -3.7 | P22: 43.6 | Q22: -4.7 | R22: -1.4 | S22: 0.8 | T22: 0.98 | U22: 3.84 | V22: 0.625 | W22: 0 | X22: 0.319 | Y22: 0.412 | Z22: 13.08 | AA22: 2013 | AB22: 1 | AC22: 17 | AD22: 1 | AE22: 17
A23: 41292 | B23: =AA23*1000+AE23 -> 2013018 | C23: 5.75 | D23: 5.48 | E23: 1.2 | F23: 51.4 | G23: 0.1 | H23: -1 | I23: 1 | J23: 10.4 | K23: 75.2 | L23: 5.6 | M23: -0.7 | N23: 1.4 | O23: -3.2 | P23: 27.3 | Q23: -4.2 | R23: -1.7 | S23: 0.1 | T23: 0.64 | U23: 2.48 | V23: 0.614 | W23: 0 | X23: 0.344 | Y23: 0.916 | Z23: 13.21 | AA23: 2013 | AB23: 1 | AC23: 18 | AD23: 1 | AE23: 18
A24: 41293 | B24: =AA24*1000+AE24 -> 2013019 | C24: 5.85 | D24: 5.04 | E24: -1.1 | F24: 64.3 | G24: -1.8 | H24: -1.3 | I24: 1 | J24: 8.3 | K24: 79.8 | L24: 4.3 | M24: -0.8 | N24: 1.6 | O24: -5.4 | P24: 32.1 | Q24: -6.2 | R24: -1.9 | S24: 0.5 | T24: 0.38 | U24: 2.44 | V24: 0.615 | W24: 0.1 | X24: 0.351 | Y24: 0.743 | Z24: 13.21 | AA24: 2013 | AB24: 1 | AC24: 19 | AD24: 1 | AE24: 19
... A643: 41912 | B643: =AA643*1000+AE643 -> 2014273 | C643: 15.22 | D643: 7.74 | E643: 5.5 | F643: 85 | G643: 4.9 | H643: 4.7 | I643: 8.9 | J643: 11.3 | K643: 93.6 | L643: 13.2 | M643: 15.4 | N643: 9.9 | O643: 2.2 | P643: 56.5 | Q643: 1 | R643: -0.7 | S643: 8 | T643: 0.66 | U643: 3.41 | V643: 0 | W643: 4.3 | X643: 0.756 | Y643: 0.582 | Z643: 13.01 | AA643: 2014 | AB643: 9 | AC643: 30 | AD643: 4 | AE643: 273
A644: 41913 | B644: =AA644*1000+AE644 -> 2014274 | C644: 14.97 | D644: 10.75 | E644: 5.8 | F644: 77.4 | G644: NA | H644: 5.1 | I644: 8.3 | J644: 13.3 | K644: 93.8 | L644: NA | M644: 16.9 | N644: 9.6 | O644: -0.6 | P644: 45.2 | Q644: NA | R644: -2.1 | S644: 7.2 | T644: 0.93 | U644: 3.04 | V644: 0 | W644: 4.1 | X644: 0.69 | Y644: 0.838 | Z644: 12.99 | AA644: 2014 | AB644: 10 | AC644: 1 | AD644: 4 | AE644: 274
A645: 41914 | B645: =AA645*1000+AE645 -> 2014275 | C645: 14.74 | D645: 14.68 | E645: 3.2 | F645: 61.6 | G645: NA | H645: 2 | I645: 7.6 | J645: 11.1 | K645: 92.2 | L645: NA | M645: 16.8 | N645: 8.7 | O645: -3.6 | P645: 26.6 | Q645: NA | R645: -5.4 | S645: 6.5 | T645: 0.72 | U645: 2.75 | V645: 0 | W645: 0.1 | X645: 0.352 | Y645: 0.971 | Z645: 13.03 | AA645: 2014 | AB645: 10 | AC645: 2 | AD645: 4 | AE645: 275
A646: 41915 | B646: =AA646*1000+AE646 -> 2014276 | C646: 14.5 | D646: 4.27 | E646: 5.8 | F646: 66.6 | G646: NA | H646: 4.8 | I646: 7.3 | J646: 10.9 | K646: 91 | L646: NA | M646: 12.3 | N646: 7.8 | O646: 1.2 | P646: 36.3 | Q646: NA | R646: -2.2 | S646: 6.7 | T646: 0.54 | U646: 2.68 | V646: 0 | W646: 5 | X646: 0.473 | Y646: 0.83 | Z646: 12.96 | AA646: 2014 | AB646: 10 | AC646: 3 | AD646: 4 | AE646: 276
A647: 41916 | B647: =AA647*1000+AE647 -> 2014277 | C647: 14.26 | D647: 12.29 | E647: 11.2 | F647: 76.5 | G647: NA | H647: 9.8 | I647: 8.5 | J647: 19.2 | K647: 92.9 | L647: NA | M647: 22.1 | N647: 10.4 | O647: 4.6 | P647: 51.9 | Q647: NA | R647: 2.4 | S647: 6.8 | T647: 0.57 | U647: 2.69 | V647: 0 | W647: 0.1 | X647: 1.154 | Y647: 1.068 | Z647: 13.09 | AA647: 2014 | AB647: 10 | AC647: 4 | AD647: 4 | AE647: 277
A648: 41917 | B648: =AA648*1000+AE648 -> 2014278 | C648: 14.02 | D648: 12.76 | E648: 11.8 | F648: 73.8 | G648: NA | H648: 10.2 | I648: 9.5 | J648: 18.8 | K648: 93.6 | L648: NA | M648: 24.6 | N648: 11.1 | O648: 6.5 | P648: 46.4 | Q648: NA | R648: 3 | S648: 8 | T648: 0.46 | U648: 2.49 | V648: 0 | W648: 0.1 | X648: 1.01 | Y648: 1.166 | Z648: 13.05 | AA648: 2014 | AB648: 10 | AC648: 5 | AD648: 4 | AE648: 278
A649: 41918 | B649: =AA649*1000+AE649 -> 2014279 | C649: 13.79 | D649: 5.02 | E649: 11.4 | F649: 81.2 | G649: NA | H649: 10.4 | I649: 9.8 | J649: 15.3 | K649: 92.4 | L649: NA | M649: 16.9 | N649: 10.6 | O649: 8.9 | P649: 65.2 | Q649: NA | R649: 5.9 | S649: 8.9 | T649: 0.22 | U649: 2.08 | V649: 0 | W649: 1.6 | X649: 1.134 | Y649: 0.605 | Z649: 13.02 | AA649: 2014 | AB649: 10 | AC649: 6 | AD649: 4 | AE649: 279
A650: 41919 | B650: =AA650*1000+AE650 -> 2014280 | C650: 13.55 | D650: 8.55 | E650: 12.2 | F650: 76 | G650: NA | H650: 11.2 | I650: 10.4 | J650: 19.5 | K650: 92 | L650: NA | M650: 25.2 | N650: 11.7 | O650: 8.3 | P650: 51.1 | Q650: NA | R650: 5.2 | S650: 9.4 | T650: 0.3 | U650: 2.28 | V650: 0 | W650: 0 | X650: 1.16 | Y650: 1.109 | Z650: 13.03 | AA650: 2014 | AB650: 10 | AC650: 7 | AD650: 4 | AE650: 280
A651: 41920 | B651: =AA651*1000+AE651 -> 2014281 | C651: 13.32 | D651: 9.58 | E651: 11 | F651: 69.3 | G651: NA | H651: 8.7 | I651: 9.8 | J651: 19.7 | K651: 92.8 | L651: NA | M651: 24.9 | N651: 11 | O651: 6.1 | P651: 36.6 | Q651: NA | R651: 2.8 | S651: 9 | T651: 0.25 | U651: 2.09 | V651: 0 | W651: 0 | X651: 0.842 | Y651: 1.457 | Z651: 13.08 | AA651: 2014 | AB651: 10 | AC651: 8 | AD651: 4 | AE651: 281
A652: 41921 | B652: =AA652*1000+AE652 -> 2014282 | C652: 13.09 | D652: 10.97 | E652: 11 | F652: 69.8 | G652: NA | H652: 8.7 | I652: 9.1 | J652: 20.5 | K652: 93.7 | L652: NA | M652: 24.5 | N652: 10.3 | O652: 5.5 | P652: 31 | Q652: NA | R652: 1.4 | S652: 8 | T652: 0.2 | U652: 1.75 | V652: 0 | W652: 0.1 | X652: 0.744 | Y652: 1.658 | Z652: 13.07 | AA652: 2014 | AB652: 10 | AC652: 9 | AD652: 4 | AE652: 282
A653: 41922 | B653: =AA653*1000+AE653 -> 2014283 | C653: 12.87 | D653: 9.84 | E653: 12 | F653: 56.4 | G653: NA | H653: 10 | I653: 9 | J653: 19.4 | K653: 78.3 | L653: NA | M653: 25.3 | N653: 10.2 | O653: 6.6 | P653: 29 | Q653: NA | R653: 1.7 | S653: 7.8 | T653: 1.15 | U653: 4.34 | V653: 0 | W653: 0.1 | X653: 0.653 | Y653: 1.597 | Z653: 13.02 | AA653: 2014 | AB653: 10 | AC653: 10 | AD653: 4 | AE653: 283
A654: 41923 | B654: =AA654*1000+AE654 -> 2014284 | C654: 12.64 | D654: 7.17 | E654: 7.4 | F654: 70.1 | G654: NA | H654: 6.7 | I654: 8.4 | J654: 13 | K654: 91.2 | L654: NA | M654: 17.7 | N654: 9.1 | O654: 3 | P654: 48.8 | Q654: NA | R654: -0.9 | S654: 7.7 | T654: 1.19 | U654: 3.89 | V654: 0 | W654: 1.3 | X654: 0.729 | Y654: 0.765 | Z654: 13.02 | AA654: 2014 | AB654: 10 | AC654: 11 | AD654: 4 | AE654: 284
A655: 41924 | B655: =AA655*1000+AE655 -> 2014285 | C655: 12.42 | D655: 7.9 | E655: 6 | F655: 76.5 | G655: NA | H655: 5.3 | I655: 8 | J655: 11.6 | K655: 92.8 | L655: NA | M655: 15.7 | N655: 8.9 | O655: 2.7 | P655: 48.9 | Q655: NA | R655: -0.1 | S655: 7.1 | T655: 0.78 | U655: 3.55 | V655: 0 | W655: 1.1 | X655: 0.666 | Y655: 0.695 | Z655: 12.98 | AA655: 2014 | AB655: 10 | AC655: 12 | AD655: 4 | AE655: 285
... A1448: 42717 | B1448: =AA1448*1000+AE1448 -> 2016348 | C1448: 4.47 | D1448: 0.3 | E1448: -19 | F1448: 78.3 | G1448: NA | H1448: -7.4 | I1448: 0.5 | J1448: -15 | K1448: 82.6 | L1448: NA | M1448: -6.2 | N1448: 0.8 | O1448: -22.8 | P1448: 72.9 | Q1448: NA | R1448: -9.2 | S1448: 0 | T1448: 0 | U1448: 0.98 | V1448: 0 | W1448: 0 | X1448: 0.139 | Y1448: 0.052 | Z1448: 12.74 | AA1448: 2016 | AB1448: 12 | AC1448: 13 | AD1448: 1 | AE1448: 348
A1449: 42718 | B1449: =AA1449*1000+AE1449 -> 2016349 | C1449: 4.45 | D1449: 0.71 | E1449: -18.6 | F1449: 78.7 | G1449: NA | H1449: -8.9 | I1449: 0.4 | J1449: -12 | K1449: 85.4 | L1449: NA | M1449: -7.3 | N1449: 1.1 | O1449: -22.6 | P1449: 68.1 | Q1449: NA | R1449: -9.8 | S1449: -0.2 | T1449: 0.03 | U1449: 1.18 | V1449: NA | W1449: 0 | X1449: 0.166 | Y1449: 0.078 | Z1449: 13.04 | AA1449: 2016 | AB1449: 12 | AC1449: 14 | AD1449: 1 | AE1449: 349
A1450: 42719 | B1450: =AA1450*1000+AE1450 -> 2016350 | C1450: 4.44 | D1450: 0.73 | E1450: -21 | F1450: 76.6 | G1450: NA | H1450: -9.7 | I1450: 0.2 | J1450: -14.3 | K1450: 83.2 | L1450: NA | M1450: -7.8 | N1450: 0.8 | O1450: -24.7 | P1450: 67.9 | Q1450: NA | R1450: -10.7 | S1450: -0.4 | T1450: 0.03 | U1450: 1.08 | V1450: NA | W1450: 0 | X1450: 0.137 | Y1450: 0.065 | Z1450: 13.05 | AA1450: 2016 | AB1450: 12 | AC1450: 15 | AD1450: 1 | AE1450: 350
A1451: 42720 | B1451: =AA1451*1000+AE1451 -> 2016351 | C1451: 4.43 | D1451: 0.96 | E1451: -21.7 | F1451: 74.4 | G1451: NA | H1451: -9.9 | I1451: 0 | J1451: -16.3 | K1451: 81.2 | L1451: NA | M1451: -8.2 | N1451: 1 | O1451: -24.7 | P1451: 63.6 | Q1451: NA | R1451: -11.6 | S1451: -0.5 | T1451: 0.17 | U1451: 1.7 | V1451: NA | W1451: 0 | X1451: 0.109 | Y1451: 0.062 | Z1451: 13.04 | AA1451: 2016 | AB1451: 12 | AC1451: 16 | AD1451: 1 | AE1451: 351
...

Sheet Graph
A1: Daily time series | C1: 1 | D1: 2 | E1: 3 | F1: 4 | G1: 5 | H1: 6 | I1: 7 | J1: 8 | K1: 9 | L1: 10 | M1: 11 | N1: 12 | O1: 13 | P1: 14 | Q1: 15 | R1: 16 | S1: 17 | T1: 18 | U1: 19 | V1: 20 | W1: 21 | X1: 22 | Y1: 23 | Z1: 24 | AA1: 25
A2: Last edit 31/03/25 | C2: Key1 | D2: ClrSky | E2: Solar | F2: TaAve | G2: RHAve | H2: Ta1.5Ave | I2: Ta0.2Ave | J2: TsoilAve | K2: TaMax | L2: RHMax | M2: Ta1.5Max | N2: Ta0.2Max | O2: TsoilMax | P2: TaMin | Q2: RHMin | R2: Ta1.5Min | S2: Ta0.2Min | T2: TsoilMin | U2: WindAve | V2: WindMax | W2: SnowD | X2: PPT | Y2: Vapres | Z2: Vpd | AA2: BatV
E3: Select col# | F3: 9 | G3: =F3+5 -> 14
A4: Key1 | B4: =F4 -> TaMax | C4: =G4 -> TaMin | F4: =VLOOKUP($A4,Graph!$C2:$AA2,F3) -> TaMax | G4: =VLOOKUP($A4,Graph!$C2:$AA2,G3) -> TaMin
A6: 2013001 | B6: =VLOOKUP($A6,Data!$B$6:$Z$4753,F$3) -> NA | C6: =VLOOKUP($A6,Data!$B$6:$Z$4753,G$3) -> NA
A7: 2013002 | B7: =VLOOKUP($A7,Data!$B$6:$Z$4753,F$3) -> NA | C7: =VLOOKUP($A7,Data!$B$6:$Z$4753,G$3) -> NA
A8: 2013003 | B8: =VLOOKUP($A8,Data!$B$6:$Z$4753,F$3) -> NA | C8: =VLOOKUP($A8,Data!$B$6:$Z$4753,G$3) -> NA
A9: 2013004 | B9: =VLOOKUP($A9,Data!$B$6:$Z$4753,F$3) -> NA | C9: =VLOOKUP($A9,Data!$B$6:$Z$4753,G$3) -> NA
A10: 2013005 | B10: =VLOOKUP($A10,Data!$B$6:$Z$4753,F$3) -> NA | C10: =VLOOKUP($A10,Data!$B$6:$Z$4753,G$3) -> NA
A11: 2013006 | B11: =VLOOKUP($A11,Data!$B$6:$Z$4753,F$3) -> NA | C11: =VLOOKUP($A11,Data!$B$6:$Z$4753,G$3) -> NA
A12: 2013007 | B12: =VLOOKUP($A12,Data!$B$6:$Z$4753,F$3) -> NA | C12: =VLOOKUP($A12,Data!$B$6:$Z$4753,G$3) -> NA
A13: 2013008 | B13: =VLOOKUP($A13,Data!$B$6:$Z$4753,F$3) -> -0.2 | C13: =VLOOKUP($A13,Data!$B$6:$Z$4753,G$3) -> -6.4
A14: 2013009 | B14: =VLOOKUP($A14,Data!$B$6:$Z$4753,F$3) -> 0.4 | C14: =VLOOKUP($A14,Data!$B$6:$Z$4753,G$3) -> -5
A15: 2013010 | B15: =VLOOKUP($A15,Data!$B$6:$Z$4753,F$3) -> -2.6 | C15: =VLOOKUP($A15,Data!$B$6:$Z$4753,G$3) -> -12.8
A16: 2013011 | B16: =VLOOKUP($A16,Data!$B$6:$Z$4753,F$3) -> -4.8 | C16: =VLOOKUP($A16,Data!$B$6:$Z$4753,G$3) -> -18
A17: 2013012 | B17: =VLOOKUP($A17,Data!$B$6:$Z$4753,F$3) -> -5 | C17: =VLOOKUP($A17,Data!$B$6:$Z$4753,G$3) -> -18.3
... A4753: 2025365 | B4753: =VLOOKUP($A4753,Data!$B$6:$Z$4753,F$3) -> NA | C4753: =VLOOKUP($A4753,Data!$B$6:$Z$4753,G$3) -> NA

Sheet Meta
A1: Chase Daily data 2013 -2025
A2: Last edit 31/03/25
A4: Data worksheet
B5: Data source is daily spreadsheets by year.
C6: Data edits are noted in these spreadsheets
B7: NA indicates missing data
B8: Clear sky radiation calculated on 10 min time step for lat, long and elevation of site
A10: Graph worksheet
B11: Select one or a pair of graphs to review using column number of desired variable
