Workbook

Sheet DataHour
A1: HoBo station PL hourly 2024 | F1: Data garrison has 58 as offset | AQ1: 163
A2: Last edit 9/12/25 | F2: 64 | O2: Raw | V2: Edited | W2: Midnight values | AD2: Wind direction summary
E3: cm | F3: cm | G3: m/s | H3: m/s | I3: degree | J3: C | K3: % | L3: m3/m3 | M3: m3/m3 | N3: mm | O3: W/m2 | U3: W/m2 | V3: W/m2 | Y3: m | AA3: vpres | AB3: vpd | AF3: =MAX(AF6:AF13) -> 2366 | AP3: 330
A4: Date | B4: Doy | C4: PST | D4: HoboTime | E4: Depth | F4: AdjSnow | G4: Wind | H4: Gust | I4: WindDir | J4: Temperature | K4: RH | L4: vol10 | M4: vol20 | N4: Rain | O4: Solar | P4: DewPt, °C (LGR S/N: 10688092, SEN S/N: 20367744) | Q4: Backup Batteries_10688092_V | R4: Batt, V (LGR S/N: 20468345) | S4: blnk | T4: DyTime | U4: Kmax | V4: SolAdj | W4: vol10_2400 | X4: vol20_2400 | Y4: Snw2400 | Z4: Comments | AA4: kPa | AB4: kPa | AE4: Octant | AG4: N | AH4: % | AQ4: Time | AR4: ClrSky | AS4: Incident
A5: 45292 | B5: 1 | C5: 100 | D5: 509.04167 | E5: 129.24 | F5: =IF(E5>F$2,E5-F$2,0) -> 65.24 | G5: 0 | H5: 0 | J5: -5.916 | K5: 98.2 | L5: 0.1826 | M5: 0.1884 | N5: 0 | O5: 0.6 | T5: =B5*10000+C5 -> 10100 | U5: 0 | V5: =IF(O5<1,0,ROUND(O5,1)) -> 0 | W5: =IF(C5=2400,ROUND(L5,3),"") | X5: =IF(C5=2400,ROUND(M5,3),"") | Y5: =IF(C5=2400,ROUND(F5/100,3),"") | AA5: =ROUND((0.6105*(EXP((17.273*J5)/(J5+237.3))))*K5/100,3) -> 0.385 | AB5: =ROUND(AA5/K5*(100-K5),3) -> 0.007 | AD5: N | AE5: 0 | AF5: =FREQUENCY(DataHour!I$5:I$8788, AE5) -> 8 | AG5: =AF5 -> 8 | AH5: =AG5/AF$3*100 -> 0.33812342 | AP5: =AP$3*10000+AQ5 -> 3300100 | AQ5: 100 | AR5: =VLOOKUP(AP5,$T$5:$V$8788,2) -> 0 | AS5: =VLOOKUP(AP5,$T$5:$V$8788,3) -> 0
A6: =A$5-1+B6 -> 45292 | B6: 1 | C6: 200 | D6: 509.08333 | E6: 129.13 | F6: =IF(E6>F$2,E6-F$2,0) -> 65.13 | G6: 0 | H6: 0.5 | J6: -6.866 | K6: 98.3 | L6: 0.1826 | M6: 0.1884 | N6: 0 | O6: 0.6 | T6: =B6*10000+C6 -> 10200 | U6: 0 | V6: =IF(O6<1,0,ROUND(O6,1)) -> 0 | W6: =IF(C6=2400,ROUND(L6,3),"") | X6: =IF(C6=2400,ROUND(M6,3),"") | Y6: =IF(C6=2400,ROUND(F6/100,3),"") | AA6: =ROUND((0.6105*(EXP((17.273*J6)/(J6+237.3))))*K6/100,3) -> 0.359 | AB6: =ROUND(AA6/K6*(100-K6),3) -> 0.006 | AD6: NE | AE6: 45 | AF6: =FREQUENCY(DataHour!I$5:I$8788, AE6) -> 667 | AG6: =AF6-AF5 -> 659 | AH6: =AG6/AF$3*100 -> 27.852916 | AP6: =AP$3*10000+AQ6 -> 3300200 | AQ6: 200 | AR6: =VLOOKUP(AP6,$T$5:$V$8788,2) -> 0 | AS6: =VLOOKUP(AP6,$T$5:$V$8788,3) -> 0
A7: =A$5-1+B7 -> 45292 | B7: 1 | C7: 300 | D7: 509.125 | E7: 129.24 | F7: =IF(E7>F$2,E7-F$2,0) -> 65.24 | G7: 0 | H7: 1.51 | J7: -4.834 | K7: 98.5 | L7: 0.1826 | M7: 0.1884 | N7: 0 | O7: 0.6 | T7: =B7*10000+C7 -> 10300 | U7: 0 | V7: =IF(O7<1,0,ROUND(O7,1)) -> 0 | W7: =IF(C7=2400,ROUND(L7,3),"") | X7: =IF(C7=2400,ROUND(M7,3),"") | Y7: =IF(C7=2400,ROUND(F7/100,3),"") | AA7: =ROUND((0.6105*(EXP((17.273*J7)/(J7+237.3))))*K7/100,3) -> 0.42 | AB7: =ROUND(AA7/K7*(100-K7),3) -> 0.006 | AD7: E | AE7: 90 | AF7: =FREQUENCY(DataHour!I$5:I$8788, AE7) -> 947 | AG7: =AF7-AF6 -> 280 | AH7: =AG7/AF$3*100 -> 11.83432 | AP7: =AP$3*10000+AQ7 -> 3300300 | AQ7: 300 | AR7: =VLOOKUP(AP7,$T$5:$V$8788,2) -> 0 | AS7: =VLOOKUP(AP7,$T$5:$V$8788,3) -> 0
A8: =A$5-1+B8 -> 45292 | B8: 1 | C8: 400 | D8: 509.16667 | E8: 129.24 | F8: =IF(E8>F$2,E8-F$2,0) -> 65.24 | G8: 0 | H8: 3.02 | J8: -4.439 | K8: 99 | L8: 0.1826 | M8: 0.1884 | N8: 0 | O8: 0.6 | T8: =B8*10000+C8 -> 10400 | U8: 0 | V8: =IF(O8<1,0,ROUND(O8,1)) -> 0 | W8: =IF(C8=2400,ROUND(L8,3),"") | X8: =IF(C8=2400,ROUND(M8,3),"") | Y8: =IF(C8=2400,ROUND(F8/100,3),"") | AA8: =ROUND((0.6105*(EXP((17.273*J8)/(J8+237.3))))*K8/100,3) -> 0.435 | AB8: =ROUND(AA8/K8*(100-K8),3) -> 0.004 | AD8: SE | AE8: 135 | AF8: =FREQUENCY(DataHour!I$5:I$8788, AE8) -> 1172 | AG8: =AF8-AF7 -> 225 | AH8: =AG8/AF$3*100 -> 9.509721 | AP8: =AP$3*10000+AQ8 -> 3300400 | AQ8: 400 | AR8: =VLOOKUP(AP8,$T$5:$V$8788,2) -> 0 | AS8: =VLOOKUP(AP8,$T$5:$V$8788,3) -> 0
A9: =A$5-1+B9 -> 45292 | B9: 1 | C9: 500 | D9: 509.20833 | E9: 128.77 | F9: =IF(E9>F$2,E9-F$2,0) -> 64.77 | G9: 0 | H9: 3.02 | J9: -4.56 | K9: 99.2 | L9: 0.1833 | M9: 0.1884 | N9: 0 | O9: 0.6 | T9: =B9*10000+C9 -> 10500 | U9: 0 | V9: =IF(O9<1,0,ROUND(O9,1)) -> 0 | W9: =IF(C9=2400,ROUND(L9,3),"") | X9: =IF(C9=2400,ROUND(M9,3),"") | Y9: =IF(C9=2400,ROUND(F9/100,3),"") | AA9: =ROUND((0.6105*(EXP((17.273*J9)/(J9+237.3))))*K9/100,3) -> 0.432 | AB9: =ROUND(AA9/K9*(100-K9),3) -> 0.003 | AD9: SE | AE9: 180 | AF9: =FREQUENCY(DataHour!I$5:I$8788, AE9) -> 1578 | AG9: =AF9-AF8 -> 406 | AH9: =AG9/AF$3*100 -> 17.159763 | AP9: =AP$3*10000+AQ9 -> 3300500 | AQ9: 500 | AR9: =VLOOKUP(AP9,$T$5:$V$8788,2) -> 0 | AS9: =VLOOKUP(AP9,$T$5:$V$8788,3) -> 0
A10: =A$5-1+B10 -> 45292 | B10: 1 | C10: 600 | D10: 509.25 | E10: 128.77 | F10: =IF(E10>F$2,E10-F$2,0) -> 64.77 | G10: 0 | H10: 2.52 | J10: -4.987 | K10: 99 | L10: 0.1833 | M10: 0.1891 | N10: 0 | O10: 0.6 | T10: =B10*10000+C10 -> 10600 | U10: 0 | V10: =IF(O10<1,0,ROUND(O10,1)) -> 0 | W10: =IF(C10=2400,ROUND(L10,3),"") | X10: =IF(C10=2400,ROUND(M10,3),"") | Y10: =IF(C10=2400,ROUND(F10/100,3),"") | AA10: =ROUND((0.6105*(EXP((17.273*J10)/(J10+237.3))))*K10/100,3) -> 0.417 | AB10: =ROUND(AA10/K10*(100-K10),3) -> 0.004 | AD10: SW | AE10: 225 | AF10: =FREQUENCY(DataHour!I$5:I$8788, AE10) -> 1775 | AG10: =AF10-AF9 -> 197 | AH10: =AG10/AF$3*100 -> 8.3262891 | AP10: =AP$3*10000+AQ10 -> 3300600 | AQ10: 600 | AR10: =VLOOKUP(AP10,$T$5:$V$8788,2) -> 0 | AS10: =VLOOKUP(AP10,$T$5:$V$8788,3) -> 0
A11: =A$5-1+B11 -> 45292 | B11: 1 | C11: 700 | D11: 509.29167 | E11: 128.54 | F11: =IF(E11>F$2,E11-F$2,0) -> 64.54 | G11: 0 | H11: 0.5 | J11: -5.76 | K11: 98.7 | L11: 0.1833 | M11: 0.1891 | N11: 0 | O11: 0.6 | T11: =B11*10000+C11 -> 10700 | U11: 0 | V11: =IF(O11<1,0,ROUND(O11,1)) -> 0 | W11: =IF(C11=2400,ROUND(L11,3),"") | X11: =IF(C11=2400,ROUND(M11,3),"") | Y11: =IF(C11=2400,ROUND(F11/100,3),"") | AA11: =ROUND((0.6105*(EXP((17.273*J11)/(J11+237.3))))*K11/100,3) -> 0.392 | AB11: =ROUND(AA11/K11*(100-K11),3) -> 0.005 | AD11: W | AE11: 270 | AF11: =FREQUENCY(DataHour!I$5:I$8788, AE11) -> 1891 | AG11: =AF11-AF10 -> 116 | AH11: =AG11/AF$3*100 -> 4.9027895 | AP11: =AP$3*10000+AQ11 -> 3300700 | AQ11: 700 | AR11: =VLOOKUP(AP11,$T$5:$V$8788,2) -> 0 | AS11: =VLOOKUP(AP11,$T$5:$V$8788,3) -> 0
A12: =A$5-1+B12 -> 45292 | B12: 1 | C12: 800 | D12: 509.33333 | E12: 128.31 | F12: =IF(E12>F$2,E12-F$2,0) -> 64.31 | G12: 0 | H12: 0.5 | J12: -5.636 | K12: 98.4 | L12: 0.1833 | M12: 0.1891 | N12: 0 | O12: 0.6 | T12: =B12*10000+C12 -> 10800 | U12: 0 | V12: =IF(O12<1,0,ROUND(O12,1)) -> 0 | W12: =IF(C12=2400,ROUND(L12,3),"") | X12: =IF(C12=2400,ROUND(M12,3),"") | Y12: =IF(C12=2400,ROUND(F12/100,3),"") | AA12: =ROUND((0.6105*(EXP((17.273*J12)/(J12+237.3))))*K12/100,3) -> 0.395 | AB12: =ROUND(AA12/K12*(100-K12),3) -> 0.006 | AD12: NW | AE12: 315 | AF12: =FREQUENCY(DataHour!I$5:I$8788, AE12) -> 2029 | AG12: =AF12-AF11 -> 138 | AH12: =AG12/AF$3*100 -> 5.8326289 | AP12: =AP$3*10000+AQ12 -> 3300800 | AQ12: 800 | AR12: =VLOOKUP(AP12,$T$5:$V$8788,2) -> 9.5 | AS12: =VLOOKUP(AP12,$T$5:$V$8788,3) -> 0
A13: =A$5-1+B13 -> 45292 | B13: 1 | C13: 900 | D13: 509.375 | E13: 128.31 | F13: =IF(E13>F$2,E13-F$2,0) -> 64.31 | G13: 0 | H13: 0.5 | J13: -5.667 | K13: 98.3 | L13: 0.1833 | M13: 0.1891 | N13: 0 | O13: 5.6 | T13: =B13*10000+C13 -> 10900 | U13: 55 | V13: =IF(O13<1,0,ROUND(O13,1)) -> 5.6 | W13: =IF(C13=2400,ROUND(L13,3),"") | X13: =IF(C13=2400,ROUND(M13,3),"") | Y13: =IF(C13=2400,ROUND(F13/100,3),"") | AA13: =ROUND((0.6105*(EXP((17.273*J13)/(J13+237.3))))*K13/100,3) -> 0.393 | AB13: =ROUND(AA13/K13*(100-K13),3) -> 0.007 | AD13: N | AE13: 360 | AF13: =FREQUENCY(DataHour!I$5:I$8788, AE13) -> 2366 | AG13: =AF13-AF12 -> 337 | AH13: =AG13/AF$3*100 -> 14.243449 | AP13: =AP$3*10000+AQ13 -> 3300900 | AQ13: 900 | AR13: =VLOOKUP(AP13,$T$5:$V$8788,2) -> 107.8 | AS13: =VLOOKUP(AP13,$T$5:$V$8788,3) -> 9.4
A14: =A$5-1+B14 -> 45292 | B14: 1 | C14: 1000 | D14: 509.41667 | E14: 127.96 | F14: =IF(E14>F$2,E14-F$2,0) -> 63.96 | G14: 0 | H14: 0.5 | J14: -4.348 | K14: 98.1 | L14: 0.1833 | M14: 0.1891 | N14: 0 | O14: 78.1 | T14: =B14*10000+C14 -> 11000 | U14: 166.2 | V14: =IF(O14<1,0,ROUND(O14,1)) -> 78.1 | W14: =IF(C14=2400,ROUND(L14,3),"") | X14: =IF(C14=2400,ROUND(M14,3),"") | Y14: =IF(C14=2400,ROUND(F14/100,3),"") | AA14: =ROUND((0.6105*(EXP((17.273*J14)/(J14+237.3))))*K14/100,3) -> 0.434 | AB14: =ROUND(AA14/K14*(100-K14),3) -> 0.008 | AP14: =AP$3*10000+AQ14 -> 3301000 | AQ14: 1000 | AR14: =VLOOKUP(AP14,$T$5:$V$8788,2) -> 218.3 | AS14: =VLOOKUP(AP14,$T$5:$V$8788,3) -> 30.6
A15: =A$5-1+B15 -> 45292 | B15: 1 | C15: 1100 | D15: 509.45833 | E15: 127.14 | F15: =IF(E15>F$2,E15-F$2,0) -> 63.14 | G15: 0 | H15: 0.5 | J15: -4.287 | K15: 98 | L15: 0.1833 | M15: 0.1891 | N15: 0 | O15: 140.6 | T15: =B15*10000+C15 -> 11100 | U15: 251.7 | V15: =IF(O15<1,0,ROUND(O15,1)) -> 140.6 | W15: =IF(C15=2400,ROUND(L15,3),"") | X15: =IF(C15=2400,ROUND(M15,3),"") | Y15: =IF(C15=2400,ROUND(F15/100,3),"") | AA15: =ROUND((0.6105*(EXP((17.273*J15)/(J15+237.3))))*K15/100,3) -> 0.435 | AB15: =ROUND(AA15/K15*(100-K15),3) -> 0.009 | AD15: 360 | AE15: 45 | AF15: 90 | AG15: 135 | AH15: 180 | AI15: 225 | AJ15: 270 | AK15: 315 | AP15: =AP$3*10000+AQ15 -> 3301100 | AQ15: 1100 | AR15: =VLOOKUP(AP15,$T$5:$V$8788,2) -> 295.3 | AS15: =VLOOKUP(AP15,$T$5:$V$8788,3) -> 46.9
A16: =A$5-1+B16 -> 45292 | B16: 1 | C16: 1200 | D16: 509.5 | E16: 126.43 | F16: =IF(E16>F$2,E16-F$2,0) -> 62.43 | G16: 0 | H16: 0.5 | J16: -3.836 | K16: 98.4 | L16: 0.1833 | M16: 0.1891 | N16: 0 | O16: 100.6 | T16: =B16*10000+C16 -> 11200 | U16: 293.3 | V16: =IF(O16<1,0,ROUND(O16,1)) -> 100.6 | W16: =IF(C16=2400,ROUND(L16,3),"") | X16: =IF(C16=2400,ROUND(M16,3),"") | Y16: =IF(C16=2400,ROUND(F16/100,3),"") | AA16: =ROUND((0.6105*(EXP((17.273*J16)/(J16+237.3))))*K16/100,3) -> 0.452 | AB16: =ROUND(AA16/K16*(100-K16),3) -> 0.007 | AD16: =AH13+AH5 -> 14.581572 | AE16: =AH6 -> 27.852916 | AF16: =AH7 -> 11.83432 | AG16: =AH8 -> 9.509721 | AH16: =AH9 -> 17.159763 | AI16: =AH10 -> 8.3262891 | AJ16: =AH11 -> 4.9027895 | AK16: =AH12 -> 5.8326289 | AP16: =AP$3*10000+AQ16 -> 3301200 | AQ16: 1200 | AR16: =VLOOKUP(AP16,$T$5:$V$8788,2) -> 325.5 | AS16: =VLOOKUP(AP16,$T$5:$V$8788,3) -> 55.6
A17: =A$5-1+B17 -> 45292 | B17: 1 | C17: 1300 | D17: 509.54167 | E17: 125.62 | F17: =IF(E17>F$2,E17-F$2,0) -> 61.62 | G17: 0 | H17: 1.01 | J17: -3.301 | K17: 98.2 | L17: 0.1833 | M17: 0.1899 | N17: 0 | O17: 193.1 | T17: =B17*10000+C17 -> 11300 | U17: 285.3 | V17: =IF(O17<1,0,ROUND(O17,1)) -> 193.1 | W17: =IF(C17=2400,ROUND(L17,3),"") | X17: =IF(C17=2400,ROUND(M17,3),"") | Y17: =IF(C17=2400,ROUND(F17/100,3),"") | AA17: =ROUND((0.6105*(EXP((17.273*J17)/(J17+237.3))))*K17/100,3) -> 0.47 | AB17: =ROUND(AA17/K17*(100-K17),3) -> 0.009 | AD17: N-NE | AE17: NE-E | AF17: E-SE | AG17: SE-S | AH17: S-SW | AI17: SW-W | AJ17: W-NW | AK17: NW-N | AP17: =AP$3*10000+AQ17 -> 3301300 | AQ17: 1300 | AR17: =VLOOKUP(AP17,$T$5:$V$8788,2) -> 305.2 | AS17: =VLOOKUP(AP17,$T$5:$V$8788,3) -> 79.4
A18: =A$5-1+B18 -> 45292 | B18: 1 | C18: 1400 | D18: 509.58333 | E18: 127.96 | F18: =IF(E18>F$2,E18-F$2,0) -> 63.96 | G18: 0 | H18: 3.02 | J18: -4.106 | K18: 97.6 | L18: 0.1833 | M18: 0.1899 | N18: 0 | O18: 321.9 | T18: =B18*10000+C18 -> 11400 | U18: 229 | V18: =IF(O18<1,0,ROUND(O18,1)) -> 321.9 | W18: =IF(C18=2400,ROUND(L18,3),"") | X18: =IF(C18=2400,ROUND(M18,3),"") | Y18: =IF(C18=2400,ROUND(F18/100,3),"") | AA18: =ROUND((0.6105*(EXP((17.273*J18)/(J18+237.3))))*K18/100,3) -> 0.44 | AB18: =ROUND(AA18/K18*(100-K18),3) -> 0.011 | AP18: =AP$3*10000+AQ18 -> 3301400 | AQ18: 1400 | AR18: =VLOOKUP(AP18,$T$5:$V$8788,2) -> 237.2 | AS18: =VLOOKUP(AP18,$T$5:$V$8788,3) -> 70.6
A19: =A$5-1+B19 -> 45292 | B19: 1 | C19: 1500 | D19: 509.625 | E19: 128.07 | F19: =IF(E19>F$2,E19-F$2,0) -> 64.07 | G19: 0 | H19: 3.02 | J19: -5.295 | K19: 97.9 | L19: 0.1833 | M19: 0.1899 | N19: 0 | O19: 201.9 | T19: =B19*10000+C19 -> 11500 | U19: 132.8 | V19: =IF(O19<1,0,ROUND(O19,1)) -> 201.9 | W19: =IF(C19=2400,ROUND(L19,3),"") | X19: =IF(C19=2400,ROUND(M19,3),"") | Y19: =IF(C19=2400,ROUND(F19/100,3),"") | AA19: =ROUND((0.6105*(EXP((17.273*J19)/(J19+237.3))))*K19/100,3) -> 0.403 | AB19: =ROUND(AA19/K19*(100-K19),3) -> 0.009 | AP19: =AP$3*10000+AQ19 -> 3301500 | AQ19: 1500 | AR19: =VLOOKUP(AP19,$T$5:$V$8788,2) -> 131.5 | AS19: =VLOOKUP(AP19,$T$5:$V$8788,3) -> 19.4
A20: =A$5-1+B20 -> 45292 | B20: 1 | C20: 1600 | D20: 509.66667 | E20: 127.96 | F20: =IF(E20>F$2,E20-F$2,0) -> 63.96 | G20: 0 | H20: 2.52 | J20: -6.073 | K20: 98.1 | L20: 0.1833 | M20: 0.1899 | N20: 0 | O20: 75.6 | T20: =B20*10000+C20 -> 11600 | U20: 25.3 | V20: =IF(O20<1,0,ROUND(O20,1)) -> 75.6 | W20: =IF(C20=2400,ROUND(L20,3),"") | X20: =IF(C20=2400,ROUND(M20,3),"") | Y20: =IF(C20=2400,ROUND(F20/100,3),"") | AA20: =ROUND((0.6105*(EXP((17.273*J20)/(J20+237.3))))*K20/100,3) -> 0.38 | AB20: =ROUND(AA20/K20*(100-K20),3) -> 0.007 | AP20: =AP$3*10000+AQ20 -> 3301600 | AQ20: 1600 | AR20: =VLOOKUP(AP20,$T$5:$V$8788,2) -> 21.3 | AS20: =VLOOKUP(AP20,$T$5:$V$8788,3) -> 3.1
A21: =A$5-1+B21 -> 45292 | B21: 1 | C21: 1700 | D21: 509.70833 | E21: 127.37 | F21: =IF(E21>F$2,E21-F$2,0) -> 63.37 | G21: 0 | H21: 1.51 | J21: -6.802 | K21: 97.9 | L21: 0.1833 | M21: 0.1899 | N21: 0 | O21: 0.6 | T21: =B21*10000+C21 -> 11700 | U21: 0 | V21: =IF(O21<1,0,ROUND(O21,1)) -> 0 | W21: =IF(C21=2400,ROUND(L21,3),"") | X21: =IF(C21=2400,ROUND(M21,3),"") | Y21: =IF(C21=2400,ROUND(F21/100,3),"") | AA21: =ROUND((0.6105*(EXP((17.273*J21)/(J21+237.3))))*K21/100,3) -> 0.359 | AB21: =ROUND(AA21/K21*(100-K21),3) -> 0.008 | AP21: =AP$3*10000+AQ21 -> 3301700 | AQ21: 1700 | AR21: =VLOOKUP(AP21,$T$5:$V$8788,2) -> 0 | AS21: =VLOOKUP(AP21,$T$5:$V$8788,3) -> 0
A22: =A$5-1+B22 -> 45292 | B22: 1 | C22: 1800 | D22: 509.75 | E22: 126.55 | F22: =IF(E22>F$2,E22-F$2,0) -> 62.55 | G22: 0 | H22: 3.52 | J22: -6.994 | K22: 97.6 | L22: 0.184 | M22: 0.1899 | N22: 0 | O22: 0.6 | T22: =B22*10000+C22 -> 11800 | U22: 0 | V22: =IF(O22<1,0,ROUND(O22,1)) -> 0 | W22: =IF(C22=2400,ROUND(L22,3),"") | X22: =IF(C22=2400,ROUND(M22,3),"") | Y22: =IF(C22=2400,ROUND(F22/100,3),"") | AA22: =ROUND((0.6105*(EXP((17.273*J22)/(J22+237.3))))*K22/100,3) -> 0.353 | AB22: =ROUND(AA22/K22*(100-K22),3) -> 0.009 | AP22: =AP$3*10000+AQ22 -> 3301800 | AQ22: 1800 | AR22: =VLOOKUP(AP22,$T$5:$V$8788,2) -> 0 | AS22: =VLOOKUP(AP22,$T$5:$V$8788,3) -> 0
A23: =A$5-1+B23 -> 45292 | B23: 1 | C23: 1900 | D23: 509.79167 | E23: 126.79 | F23: =IF(E23>F$2,E23-F$2,0) -> 62.79 | G23: 1.01 | H23: 4.53 | J23: -7.187 | K23: 97.4 | L23: 0.184 | M23: 0.1899 | N23: 0 | O23: 0.6 | T23: =B23*10000+C23 -> 11900 | U23: 0 | V23: =IF(O23<1,0,ROUND(O23,1)) -> 0 | W23: =IF(C23=2400,ROUND(L23,3),"") | X23: =IF(C23=2400,ROUND(M23,3),"") | Y23: =IF(C23=2400,ROUND(F23/100,3),"") | AA23: =ROUND((0.6105*(EXP((17.273*J23)/(J23+237.3))))*K23/100,3) -> 0.347 | AB23: =ROUND(AA23/K23*(100-K23),3) -> 0.009 | AP23: =AP$3*10000+AQ23 -> 3301900 | AQ23: 1900 | AR23: =VLOOKUP(AP23,$T$5:$V$8788,2) -> 0 | AS23: =VLOOKUP(AP23,$T$5:$V$8788,3) -> 0
A24: =A$5-1+B24 -> 45292 | B24: 1 | C24: 2000 | D24: 509.83333 | E24: 126.08 | F24: =IF(E24>F$2,E24-F$2,0) -> 62.08 | G24: 2.52 | H24: 6.54 | J24: -7.381 | K24: 97.4 | L24: 0.184 | M24: 0.1899 | N24: 0 | O24: 0.6 | T24: =B24*10000+C24 -> 12000 | U24: 0 | V24: =IF(O24<1,0,ROUND(O24,1)) -> 0 | W24: =IF(C24=2400,ROUND(L24,3),"") | X24: =IF(C24=2400,ROUND(M24,3),"") | Y24: =IF(C24=2400,ROUND(F24/100,3),"") | AA24: =ROUND((0.6105*(EXP((17.273*J24)/(J24+237.3))))*K24/100,3) -> 0.342 | AB24: =ROUND(AA24/K24*(100-K24),3) -> 0.009 | AP24: =AP$3*10000+AQ24 -> 3302000 | AQ24: 2000 | AR24: =VLOOKUP(AP24,$T$5:$V$8788,2) -> 0 | AS24: =VLOOKUP(AP24,$T$5:$V$8788,3) -> 0
A25: =A$5-1+B25 -> 45292 | B25: 1 | C25: 2100 | D25: 509.875 | E25: 125.38 | F25: =IF(E25>F$2,E25-F$2,0) -> 61.38 | G25: 2.52 | H25: 5.54 | J25: -7.673 | K25: 97.1 | L25: 0.184 | M25: 0.1899 | N25: 0 | O25: 0.6 | T25: =B25*10000+C25 -> 12100 | U25: 0 | V25: =IF(O25<1,0,ROUND(O25,1)) -> 0 | W25: =IF(C25=2400,ROUND(L25,3),"") | X25: =IF(C25=2400,ROUND(M25,3),"") | Y25: =IF(C25=2400,ROUND(F25/100,3),"") | AA25: =ROUND((0.6105*(EXP((17.273*J25)/(J25+237.3))))*K25/100,3) -> 0.333 | AB25: =ROUND(AA25/K25*(100-K25),3) -> 0.01 | AP25: =AP$3*10000+AQ25 -> 3302100 | AQ25: 2100 | AR25: =VLOOKUP(AP25,$T$5:$V$8788,2) -> 0 | AS25: =VLOOKUP(AP25,$T$5:$V$8788,3) -> 0
A26: =A$5-1+B26 -> 45292 | B26: 1 | C26: 2200 | D26: 509.91667 | E26: 126.08 | F26: =IF(E26>F$2,E26-F$2,0) -> 62.08 | G26: 2.52 | H26: 5.54 | J26: -7.738 | K26: 97 | L26: 0.184 | M26: 0.1906 | N26: 0 | O26: 0.6 | T26: =B26*10000+C26 -> 12200 | U26: 0 | V26: =IF(O26<1,0,ROUND(O26,1)) -> 0 | W26: =IF(C26=2400,ROUND(L26,3),"") | X26: =IF(C26=2400,ROUND(M26,3),"") | Y26: =IF(C26=2400,ROUND(F26/100,3),"") | AA26: =ROUND((0.6105*(EXP((17.273*J26)/(J26+237.3))))*K26/100,3) -> 0.331 | AB26: =ROUND(AA26/K26*(100-K26),3) -> 0.01 | AP26: =AP$3*10000+AQ26 -> 3302200 | AQ26: 2200 | AR26: =VLOOKUP(AP26,$T$5:$V$8788,2) -> 0 | AS26: =VLOOKUP(AP26,$T$5:$V$8788,3) -> 0
A27: =A$5-1+B27 -> 45292 | B27: 1 | C27: 2300 | D27: 509.95833 | E27: 125.62 | F27: =IF(E27>F$2,E27-F$2,0) -> 61.62 | G27: 1.51 | H27: 5.03 | J27: -7.673 | K27: 97.1 | L27: 0.184 | M27: 0.1906 | N27: 0 | O27: 0.6 | T27: =B27*10000+C27 -> 12300 | U27: 0 | V27: =IF(O27<1,0,ROUND(O27,1)) -> 0 | W27: =IF(C27=2400,ROUND(L27,3),"") | X27: =IF(C27=2400,ROUND(M27,3),"") | Y27: =IF(C27=2400,ROUND(F27/100,3),"") | AA27: =ROUND((0.6105*(EXP((17.273*J27)/(J27+237.3))))*K27/100,3) -> 0.333 | AB27: =ROUND(AA27/K27*(100-K27),3) -> 0.01 | AP27: =AP$3*10000+AQ27 -> 3302300 | AQ27: 2300 | AR27: =VLOOKUP(AP27,$T$5:$V$8788,2) -> 0 | AS27: =VLOOKUP(AP27,$T$5:$V$8788,3) -> 0
A28: =A$5-1+B28 -> 45292 | B28: 1 | C28: 2400 | D28: 510 | E28: 126.2 | F28: =IF(E28>F$2,E28-F$2,0) -> 62.2 | G28: 1.51 | H28: 4.03 | J28: -7.804 | K28: 97 | L28: 0.184 | M28: 0.1906 | N28: 0 | O28: 0.6 | T28: =B28*10000+C28 -> 12400 | U28: 0 | V28: =IF(O28<1,0,ROUND(O28,1)) -> 0 | W28: =IF(C28=2400,ROUND(L28,3),"") -> 0.184 | X28: =IF(C28=2400,ROUND(M28,3),"") -> 0.191 | Y28: =IF(C28=2400,ROUND(F28/100,3),"") -> 0.622 | AA28: =ROUND((0.6105*(EXP((17.273*J28)/(J28+237.3))))*K28/100,3) -> 0.329 | AB28: =ROUND(AA28/K28*(100-K28),3) -> 0.01 | AP28: =AP$3*10000+AQ28 -> 3302400 | AQ28: 2400 | AR28: =VLOOKUP(AP28,$T$5:$V$8788,2) -> 0 | AS28: =VLOOKUP(AP28,$T$5:$V$8788,3) -> 0
A29: =A$5-1+B29 -> 45293 | B29: 2 | C29: 100 | D29: 510.04167 | E29: 126.32 | F29: =IF(E29>F$2,E29-F$2,0) -> 62.32 | G29: 1.01 | H29: 4.03 | J29: -7.64 | K29: 96.9 | L29: 0.184 | M29: 0.1906 | N29: 0 | O29: 0.6 | T29: =B29*10000+C29 -> 20100 | U29: 0 | V29: =IF(O29<1,0,ROUND(O29,1)) -> 0 | W29: =IF(C29=2400,ROUND(L29,3),"") | X29: =IF(C29=2400,ROUND(M29,3),"") | Y29: =IF(C29=2400,ROUND(F29/100,3),"") | AA29: =ROUND((0.6105*(EXP((17.273*J29)/(J29+237.3))))*K29/100,3) -> 0.333 | AB29: =ROUND(AA29/K29*(100-K29),3) -> 0.011 | AP29: =AP5+10000 -> 3310100 | AQ29: 100 | AR29: =VLOOKUP(AP29,$T$5:$V$8788,2) -> 0 | AS29: =VLOOKUP(AP29,$T$5:$V$8788,3) -> 0
A30: =A$5-1+B30 -> 45293 | B30: 2 | C30: 200 | D30: 510.08333 | E30: 125.85 | F30: =IF(E30>F$2,E30-F$2,0) -> 61.85 | G30: 0.5 | H30: 3.52 | J30: -7.478 | K30: 97.1 | L30: 0.184 | M30: 0.1906 | N30: 0 | O30: 0.6 | T30: =B30*10000+C30 -> 20200 | U30: 0 | V30: =IF(O30<1,0,ROUND(O30,1)) -> 0 | W30: =IF(C30=2400,ROUND(L30,3),"") | X30: =IF(C30=2400,ROUND(M30,3),"") | Y30: =IF(C30=2400,ROUND(F30/100,3),"") | AA30: =ROUND((0.6105*(EXP((17.273*J30)/(J30+237.3))))*K30/100,3) -> 0.338 | AB30: =ROUND(AA30/K30*(100-K30),3) -> 0.01 | AP30: =AP6+10000 -> 3310200 | AQ30: 200 | AR30: =VLOOKUP(AP30,$T$5:$V$8788,2) -> 0 | AS30: =VLOOKUP(AP30,$T$5:$V$8788,3) -> 0
A31: =A$5-1+B31 -> 45293 | B31: 2 | C31: 300 | D31: 510.125 | E31: 125.03 | F31: =IF(E31>F$2,E31-F$2,0) -> 61.03 | G31: 0.5 | H31: 3.02 | J31: -7.445 | K31: 97 | L31: 0.184 | M31: 0.1906 | N31: 0 | O31: 0.6 | T31: =B31*10000+C31 -> 20300 | U31: 0 | V31: =IF(O31<1,0,ROUND(O31,1)) -> 0 | W31: =IF(C31=2400,ROUND(L31,3),"") | X31: =IF(C31=2400,ROUND(M31,3),"") | Y31: =IF(C31=2400,ROUND(F31/100,3),"") | AA31: =ROUND((0.6105*(EXP((17.273*J31)/(J31+237.3))))*K31/100,3) -> 0.338 | AB31: =ROUND(AA31/K31*(100-K31),3) -> 0.01 | AP31: =AP7+10000 -> 3310300 | AQ31: 300 | AR31: =VLOOKUP(AP31,$T$5:$V$8788,2) -> 0 | AS31: =VLOOKUP(AP31,$T$5:$V$8788,3) -> 0
A32: =A$5-1+B32 -> 45293 | B32: 2 | C32: 400 | D32: 510.16667 | E32: 125.73 | F32: =IF(E32>F$2,E32-F$2,0) -> 61.73 | G32: 0 | H32: 2.01 | J32: -7.348 | K32: 97.1 | L32: 0.184 | M32: 0.1906 | N32: 0 | O32: 0.6 | T32: =B32*10000+C32 -> 20400 | U32: 0 | V32: =IF(O32<1,0,ROUND(O32,1)) -> 0 | W32: =IF(C32=2400,ROUND(L32,3),"") | X32: =IF(C32=2400,ROUND(M32,3),"") | Y32: =IF(C32=2400,ROUND(F32/100,3),"") | AA32: =ROUND((0.6105*(EXP((17.273*J32)/(J32+237.3))))*K32/100,3) -> 0.341 | AB32: =ROUND(AA32/K32*(100-K32),3) -> 0.01 | AP32: =AP8+10000 -> 3310400 | AQ32: 400 | AR32: =VLOOKUP(AP32,$T$5:$V$8788,2) -> 0 | AS32: =VLOOKUP(AP32,$T$5:$V$8788,3) -> 0
A33: =A$5-1+B33 -> 45293 | B33: 2 | C33: 500 | D33: 510.20833 | E33: 125.15 | F33: =IF(E33>F$2,E33-F$2,0) -> 61.15 | G33: 0 | H33: 2.01 | J33: -7.251 | K33: 97.2 | L33: 0.1848 | M33: 0.1906 | N33: 0 | O33: 0.6 | T33: =B33*10000+C33 -> 20500 | U33: 0 | V33: =IF(O33<1,0,ROUND(O33,1)) -> 0 | W33: =IF(C33=2400,ROUND(L33,3),"") | X33: =IF(C33=2400,ROUND(M33,3),"") | Y33: =IF(C33=2400,ROUND(F33/100,3),"") | AA33: =ROUND((0.6105*(EXP((17.273*J33)/(J33+237.3))))*K33/100,3) -> 0.344 | AB33: =ROUND(AA33/K33*(100-K33),3) -> 0.01 | AP33: =AP9+10000 -> 3310500 | AQ33: 500 | AR33: =VLOOKUP(AP33,$T$5:$V$8788,2) -> 0 | AS33: =VLOOKUP(AP33,$T$5:$V$8788,3) -> 0
A34: =A$5-1+B34 -> 45293 | B34: 2 | C34: 600 | D34: 510.25 | E34: 124.8 | F34: =IF(E34>F$2,E34-F$2,0) -> 60.8 | G34: 0 | H34: 2.01 | J34: -6.93 | K34: 97.3 | L34: 0.184 | M34: 0.1913 | N34: 0 | O34: 0.6 | T34: =B34*10000+C34 -> 20600 | U34: 0 | V34: =IF(O34<1,0,ROUND(O34,1)) -> 0 | W34: =IF(C34=2400,ROUND(L34,3),"") | X34: =IF(C34=2400,ROUND(M34,3),"") | Y34: =IF(C34=2400,ROUND(F34/100,3),"") | AA34: =ROUND((0.6105*(EXP((17.273*J34)/(J34+237.3))))*K34/100,3) -> 0.353 | AB34: =ROUND(AA34/K34*(100-K34),3) -> 0.01 | AP34: =AP10+10000 -> 3310600 | AQ34: 600 | AR34: =VLOOKUP(AP34,$T$5:$V$8788,2) -> 0 | AS34: =VLOOKUP(AP34,$T$5:$V$8788,3) -> 0
A35: =A$5-1+B35 -> 45293 | B35: 2 | C35: 700 | D35: 510.29167 | E35: 124.68 | F35: =IF(E35>F$2,E35-F$2,0) -> 60.68 | G35: 0 | H35: 1.51 | J35: -6.674 | K35: 97.5 | L35: 0.1848 | M35: 0.1913 | N35: 0 | O35: 0.6 | T35: =B35*10000+C35 -> 20700 | U35: 0 | V35: =IF(O35<1,0,ROUND(O35,1)) -> 0 | W35: =IF(C35=2400,ROUND(L35,3),"") | X35: =IF(C35=2400,ROUND(M35,3),"") | Y35: =IF(C35=2400,ROUND(F35/100,3),"") | AA35: =ROUND((0.6105*(EXP((17.273*J35)/(J35+237.3))))*K35/100,3) -> 0.361 | AB35: =ROUND(AA35/K35*(100-K35),3) -> 0.009 | AP35: =AP11+10000 -> 3310700 | AQ35: 700 | AR35: =VLOOKUP(AP35,$T$5:$V$8788,2) -> 0 | AS35: =VLOOKUP(AP35,$T$5:$V$8788,3) -> 0
A36: =A$5-1+B36 -> 45293 | B36: 2 | C36: 800 | D36: 510.33333 | E36: 123.98 | F36: =IF(E36>F$2,E36-F$2,0) -> 59.98 | G36: 0 | H36: 2.01 | J36: -6.452 | K36: 97.6 | L36: 0.1848 | M36: 0.1913 | N36: 0 | O36: 0.6 | T36: =B36*10000+C36 -> 20800 | U36: 0 | V36: =IF(O36<1,0,ROUND(O36,1)) -> 0 | W36: =IF(C36=2400,ROUND(L36,3),"") | X36: =IF(C36=2400,ROUND(M36,3),"") | Y36: =IF(C36=2400,ROUND(F36/100,3),"") | AA36: =ROUND((0.6105*(EXP((17.273*J36)/(J36+237.3))))*K36/100,3) -> 0.368 | AB36: =ROUND(AA36/K36*(100-K36),3) -> 0.009 | AP36: =AP12+10000 -> 3310800 | AQ36: 800 | AR36: =VLOOKUP(AP36,$T$5:$V$8788,2) -> 8.5 | AS36: =VLOOKUP(AP36,$T$5:$V$8788,3) -> 0
A37: =A$5-1+B37 -> 45293 | B37: 2 | C37: 900 | D37: 510.375 | E37: 123.86 | F37: =IF(E37>F$2,E37-F$2,0) -> 59.86 | G37: 0 | H37: 1.51 | J37: -6.042 | K37: 97.7 | L37: 0.1848 | M37: 0.1913 | N37: 0 | O37: 11.9 | T37: =B37*10000+C37 -> 20900 | U37: 55.2 | V37: =IF(O37<1,0,ROUND(O37,1)) -> 11.9 | W37: =IF(C37=2400,ROUND(L37,3),"") | X37: =IF(C37=2400,ROUND(M37,3),"") | Y37: =IF(C37=2400,ROUND(F37/100,3),"") | AA37: =ROUND((0.6105*(EXP((17.273*J37)/(J37+237.3))))*K37/100,3) -> 0.38 | AB37: =ROUND(AA37/K37*(100-K37),3) -> 0.009 | AP37: =AP13+10000 -> 3310900 | AQ37: 900 | AR37: =VLOOKUP(AP37,$T$5:$V$8788,2) -> 104.8 | AS37: =VLOOKUP(AP37,$T$5:$V$8788,3) -> 5.6
A38: =A$5-1+B38 -> 45293 | B38: 2 | C38: 1000 | D38: 510.41667 | E38: 123.63 | F38: =IF(E38>F$2,E38-F$2,0) -> 59.63 | G38: 0 | H38: 1.51 | J38: -5.823 | K38: 97.8 | L38: 0.1848 | M38: 0.1913 | N38: 0 | O38: 34.4 | T38: =B38*10000+C38 -> 21000 | U38: 166.8 | V38: =IF(O38<1,0,ROUND(O38,1)) -> 34.4 | W38: =IF(C38=2400,ROUND(L38,3),"") | X38: =IF(C38=2400,ROUND(M38,3),"") | Y38: =IF(C38=2400,ROUND(F38/100,3),"") | AA38: =ROUND((0.6105*(EXP((17.273*J38)/(J38+237.3))))*K38/100,3) -> 0.387 | AB38: =ROUND(AA38/K38*(100-K38),3) -> 0.009 | AP38: =AP14+10000 -> 3311000 | AQ38: 1000 | AR38: =VLOOKUP(AP38,$T$5:$V$8788,2) -> 215 | AS38: =VLOOKUP(AP38,$T$5:$V$8788,3) -> 23.1
A39: =A$5-1+B39 -> 45293 | B39: 2 | C39: 1100 | D39: 510.45833 | E39: 123.16 | F39: =IF(E39>F$2,E39-F$2,0) -> 59.16 | G39: 0 | H39: 2.52 | J39: -5.172 | K39: 98 | L39: 0.1848 | M39: 0.192 | N39: 0 | O39: 73.1 | T39: =B39*10000+C39 -> 21100 | U39: 252.8 | V39: =IF(O39<1,0,ROUND(O39,1)) -> 73.1 | W39: =IF(C39=2400,ROUND(L39,3),"") | X39: =IF(C39=2400,ROUND(M39,3),"") | Y39: =IF(C39=2400,ROUND(F39/100,3),"") | AA39: =ROUND((0.6105*(EXP((17.273*J39)/(J39+237.3))))*K39/100,3) -> 0.407 | AB39: =ROUND(AA39/K39*(100-K39),3) -> 0.008 | AP39: =AP15+10000 -> 3311100 | AQ39: 1100 | AR39: =VLOOKUP(AP39,$T$5:$V$8788,2) -> 292 | AS39: =VLOOKUP(AP39,$T$5:$V$8788,3) -> 36.9
A40: =A$5-1+B40 -> 45293 | B40: 2 | C40: 1200 | D40: 510.5 | E40: 125.03 | F40: =IF(E40>F$2,E40-F$2,0) -> 61.03 | G40: 0 | H40: 2.52 | J40: -5.202 | K40: 98.2 | L40: 0.1848 | M40: 0.192 | N40: 0 | O40: 64.4 | T40: =B40*10000+C40 -> 21200 | U40: 294.8 | V40: =IF(O40<1,0,ROUND(O40,1)) -> 64.4 | W40: =IF(C40=2400,ROUND(L40,3),"") | X40: =IF(C40=2400,ROUND(M40,3),"") | Y40: =IF(C40=2400,ROUND(F40/100,3),"") | AA40: =ROUND((0.6105*(EXP((17.273*J40)/(J40+237.3))))*K40/100,3) -> 0.407 | AB40: =ROUND(AA40/K40*(100-K40),3) -> 0.007 | AP40: =AP16+10000 -> 3311200 | AQ40: 1200 | AR40: =VLOOKUP(AP40,$T$5:$V$8788,2) -> 322.3 | AS40: =VLOOKUP(AP40,$T$5:$V$8788,3) -> 36.9
...

Sheet DataDay
A1: HoBo station PL daily 2024 calcuated from hourly file | AB1: Estimated from hourly data | AE1: 0.689 | AF1: Calc from snowfall
A2: Last edit 21/12/25 | Q2: Daily PL | AB2: Estimated | AE2: 0 | AG2: Rain | AH2: TXRHn
S3: MJ/m2/d | T3: C | U3: C | V3: C | W3: % | X3: % | Y3: % | Z3: mm | AA3: m/s | AB3: m/s | AE3: m | AF3: mm | AG3: mm | AH3: kPa | AI3: kPa | AK3: MJ/m2/d
A4: Row Labels | B4: Count of Temperature | C4: Average of SolAdj | D4: Average of Temperature | E4: Max of Temperature | F4: Min of Temperature | G4: Average of RH | H4: Max of RH | I4: Min of RH | J4: Sum of Rain | K4: Average of Wind | L4: Max of Gust | M4: Max of vol10_2400 | N4: Max of vol20_2400 | O4: Max of Snw2400 | Q4: DoY | R4: Hours | S4: Solar | T4: Tave | U4: Tmax | V4: Tmin | W4: RHAve | X4: RHMax | Y4: RHMin | Z4: Rain | AA4: Wind | AB4: WindMax | AC4: vol10_2400 | AD4: vol20_2400 | AE4: Snw2400 | AF4: PPT | AG4: PPT | AH4: vpres | AI4: vpdX | AK4: ClearSky
A5: 1 | B5: 24 | C5: 46.558333 | D5: -5.7984583 | E5: -3.301 | F5: -7.804 | G5: 98.016667 | H5: 99.2 | I5: 97 | J5: 0 | K5: 0.48291667 | L5: 6.54 | M5: 0.184 | N5: 0.191 | O5: 0.622 | Q5: =A5 -> 1 | R5: =B5 -> 24 | S5: =ROUND(C5*0.0864,2) -> 4.02 | T5: =ROUND(D5,1) -> -5.8 | U5: =ROUND(E5,1) -> -3.3 | V5: =ROUND(F5,1) -> -7.8 | W5: =ROUND(G5,1) -> 98 | X5: =ROUND(H5,1) -> 99.2 | Y5: =ROUND(I5,1) -> 97 | Z5: =ROUND(J5,2) -> 0 | AA5: =ROUND(K5,2) -> 0.48 | AB5: =ROUND(L5,2) -> 6.54 | AC5: =ROUND(M5,3) -> 0.184 | AD5: =ROUND(N5,3) -> 0.191 | AE5: =ROUND(O5-AE$2,3) -> 0.622 | AF5: =IF(AE5>AE1,ROUND((AE5-AE1)*130,1),0) -> 0 | AG5: =AF5 -> 0 | AH5: =ROUND((0.6105*(EXP((17.273*U5)/(U5+237.3))))*Y5/100,3) -> 0.464 | AI5: =ROUND(AH5/Y5*(100-Y5),3) -> 0.014 | AK5: 5.18
A6: 2 | B6: 24 | C6: 16.354167 | D6: -5.6670417 | E6: -4.106 | F6: -7.64 | G6: 98.05 | H6: 98.8 | I6: 96.9 | J6: 0 | K6: 0.14625 | L6: 4.03 | M6: 0.186 | N6: 0.193 | O6: 0.62 | Q6: =A6 -> 2 | R6: =B6 -> 24 | S6: =ROUND(C6*0.0864,2) -> 1.41 | T6: =ROUND(D6,1) -> -5.7 | U6: =ROUND(E6,1) -> -4.1 | V6: =ROUND(F6,1) -> -7.6 | W6: =ROUND(G6,1) -> 98.1 | X6: =ROUND(H6,1) -> 98.8 | Y6: =ROUND(I6,1) -> 96.9 | Z6: =ROUND(J6,2) -> 0 | AA6: =ROUND(K6,2) -> 0.15 | AB6: =ROUND(L6,2) -> 4.03 | AC6: =ROUND(M6,3) -> 0.186 | AD6: =ROUND(N6,3) -> 0.193 | AE6: =ROUND(O6-AE$2,3) -> 0.62 | AF6: =IF(AE6>AE5,ROUND((AE6-AE5)*130,1),0) -> 0 | AG6: =AF6 -> 0 | AH6: =ROUND((0.6105*(EXP((17.273*U6)/(U6+237.3))))*Y6/100,3) -> 0.437 | AI6: =ROUND(AH6/Y6*(100-Y6),3) -> 0.014 | AK6: 5.22
A7: 3 | B7: 24 | C7: 18.804167 | D7: -2.9628333 | E7: 2.823 | F7: -5.049 | G7: 99.454167 | H7: 100 | I7: 98.7 | J7: 0.2 | K7: 0 | L7: 1.51 | M7: 0.186 | N7: 0.196 | O7: 0.602 | Q7: =A7 -> 3 | R7: =B7 -> 24 | S7: =ROUND(C7*0.0864,2) -> 1.62 | T7: =ROUND(D7,1) -> -3 | U7: =ROUND(E7,1) -> 2.8 | V7: =ROUND(F7,1) -> -5 | W7: =ROUND(G7,1) -> 99.5 | X7: =ROUND(H7,1) -> 100 | Y7: =ROUND(I7,1) -> 98.7 | Z7: =ROUND(J7,2) -> 0.2 | AA7: =ROUND(K7,2) -> 0 | AB7: =ROUND(L7,2) -> 1.51 | AC7: =ROUND(M7,3) -> 0.186 | AD7: =ROUND(N7,3) -> 0.196 | AE7: =ROUND(O7-AE$2,3) -> 0.602 | AF7: =IF(AE7>AE6,ROUND((AE7-AE6)*130,1),0) -> 0 | AG7: =AF7 -> 0 | AH7: =ROUND((0.6105*(EXP((17.273*U7)/(U7+237.3))))*Y7/100,3) -> 0.737 | AI7: =ROUND(AH7/Y7*(100-Y7),3) -> 0.01 | AK7: 5.26
A8: 4 | B8: 24 | C8: 10.670833 | D8: -5.5116667 | E8: -2.363 | F8: -7.413 | G8: 98.333333 | H8: 100 | I8: 97.2 | J8: 0 | K8: 0.2725 | L8: 8.56 | M8: 0.187 | N8: 0.198 | O8: 0.609 | Q8: =A8 -> 4 | R8: =B8 -> 24 | S8: =ROUND(C8*0.0864,2) -> 0.92 | T8: =ROUND(D8,1) -> -5.5 | U8: =ROUND(E8,1) -> -2.4 | V8: =ROUND(F8,1) -> -7.4 | W8: =ROUND(G8,1) -> 98.3 | X8: =ROUND(H8,1) -> 100 | Y8: =ROUND(I8,1) -> 97.2 | Z8: =ROUND(J8,2) -> 0 | AA8: =ROUND(K8,2) -> 0.27 | AB8: =ROUND(L8,2) -> 8.56 | AC8: =ROUND(M8,3) -> 0.187 | AD8: =ROUND(N8,3) -> 0.198 | AE8: =ROUND(O8-AE$2,3) -> 0.609 | AF8: =IF(AE8>AE7,ROUND((AE8-AE7)*130,1),0) -> 0.9 | AG8: =AF8 -> 0.9 | AH8: =ROUND((0.6105*(EXP((17.273*U8)/(U8+237.3))))*Y8/100,3) -> 0.497 | AI8: =ROUND(AH8/Y8*(100-Y8),3) -> 0.014 | AK8: 5.31
A9: 5 | B9: 24 | C9: 16.766667 | D9: -7.174 | E9: -4.712 | F9: -8.73 | G9: 95.5125 | H9: 97.5 | I9: 91.3 | J9: 0 | K9: 0.44 | L9: 6.54 | M9: 0.188 | N9: 0.2 | O9: 0.606 | Q9: =A9 -> 5 | R9: =B9 -> 24 | S9: =ROUND(C9*0.0864,2) -> 1.45 | T9: =ROUND(D9,1) -> -7.2 | U9: =ROUND(E9,1) -> -4.7 | V9: =ROUND(F9,1) -> -8.7 | W9: =ROUND(G9,1) -> 95.5 | X9: =ROUND(H9,1) -> 97.5 | Y9: =ROUND(I9,1) -> 91.3 | Z9: =ROUND(J9,2) -> 0 | AA9: =ROUND(K9,2) -> 0.44 | AB9: =ROUND(L9,2) -> 6.54 | AC9: =ROUND(M9,3) -> 0.188 | AD9: =ROUND(N9,3) -> 0.2 | AE9: =ROUND(O9-AE$2,3) -> 0.606 | AF9: =IF(AE9>AE8,ROUND((AE9-AE8)*130,1),0) -> 0 | AG9: =AF9 -> 0 | AH9: =ROUND((0.6105*(EXP((17.273*U9)/(U9+237.3))))*Y9/100,3) -> 0.393 | AI9: =ROUND(AH9/Y9*(100-Y9),3) -> 0.037 | AK9: 5.36
A10: 6 | B10: 24 | C10: 5.9333333 | D10: -7.3439583 | E10: -5.326 | F10: -9.989 | G10: 97.004167 | H10: 98 | I10: 95.6 | J10: 0 | K10: 0.29375 | L10: 6.04 | M10: 0.188 | N10: 0.202 | O10: 0.819 | Q10: =A10 -> 6 | R10: =B10 -> 24 | S10: =ROUND(C10*0.0864,2) -> 0.51 | T10: =ROUND(D10,1) -> -7.3 | U10: =ROUND(E10,1) -> -5.3 | V10: =ROUND(F10,1) -> -10 | W10: =ROUND(G10,1) -> 97 | X10: =ROUND(H10,1) -> 98 | Y10: =ROUND(I10,1) -> 95.6 | Z10: =ROUND(J10,2) -> 0 | AA10: =ROUND(K10,2) -> 0.29 | AB10: =ROUND(L10,2) -> 6.04 | AC10: =ROUND(M10,3) -> 0.188 | AD10: =ROUND(N10,3) -> 0.202 | AE10: =ROUND(O10-AE$2,3) -> 0.819 | AF10: =IF(AE10>AE9,ROUND((AE10-AE9)*130,1),0) -> 27.7 | AG10: =AF10 -> 27.7 | AH10: =ROUND((0.6105*(EXP((17.273*U10)/(U10+237.3))))*Y10/100,3) -> 0.393 | AI10: =ROUND(AH10/Y10*(100-Y10),3) -> 0.018 | AK10: 5.41
A11: 7 | B11: 24 | C11: 6.6916667 | D11: -11.749083 | E11: -10.162 | F11: -14.004 | G11: 94.425 | H11: 95.5 | I11: 93 | J11: 0 | K11: 0.12625 | L11: 5.54 | M11: 0.189 | N11: 0.204 | O11: 0.769 | Q11: =A11 -> 7 | R11: =B11 -> 24 | S11: =ROUND(C11*0.0864,2) -> 0.58 | T11: =ROUND(D11,1) -> -11.7 | U11: =ROUND(E11,1) -> -10.2 | V11: =ROUND(F11,1) -> -14 | W11: =ROUND(G11,1) -> 94.4 | X11: =ROUND(H11,1) -> 95.5 | Y11: =ROUND(I11,1) -> 93 | Z11: =ROUND(J11,2) -> 0 | AA11: =ROUND(K11,2) -> 0.13 | AB11: =ROUND(L11,2) -> 5.54 | AC11: =ROUND(M11,3) -> 0.189 | AD11: =ROUND(N11,3) -> 0.204 | AE11: =ROUND(O11-AE$2,3) -> 0.769 | AF11: =IF(AE11>AE10,ROUND((AE11-AE10)*130,1),0) -> 0 | AG11: =AF11 -> 0 | AH11: =ROUND((0.6105*(EXP((17.273*U11)/(U11+237.3))))*Y11/100,3) -> 0.261 | AI11: =ROUND(AH11/Y11*(100-Y11),3) -> 0.02 | AK11: 5.47
A12: 8 | B12: 24 | C12: 6.8708333 | D12: -11.6045 | E12: -7.673 | F12: -15.506 | G12: 94.0875 | H12: 95.4 | I12: 92.5 | J12: 0 | K12: 0.67083333 | L12: 7.55 | M12: 0.19 | N12: 0.206 | O12: 0.835 | Q12: =A12 -> 8 | R12: =B12 -> 24 | S12: =ROUND(C12*0.0864,2) -> 0.59 | T12: =ROUND(D12,1) -> -11.6 | U12: =ROUND(E12,1) -> -7.7 | V12: =ROUND(F12,1) -> -15.5 | W12: =ROUND(G12,1) -> 94.1 | X12: =ROUND(H12,1) -> 95.4 | Y12: =ROUND(I12,1) -> 92.5 | Z12: =ROUND(J12,2) -> 0 | AA12: =ROUND(K12,2) -> 0.67 | AB12: =ROUND(L12,2) -> 7.55 | AC12: =ROUND(M12,3) -> 0.19 | AD12: =ROUND(N12,3) -> 0.206 | AE12: =ROUND(O12-AE$2,3) -> 0.835 | AF12: =IF(AE12>AE11,ROUND((AE12-AE11)*130,1),0) -> 8.6 | AG12: =AF12 -> 8.6 | AH12: =ROUND((0.6105*(EXP((17.273*U12)/(U12+237.3))))*Y12/100,3) -> 0.316 | AI12: =ROUND(AH12/Y12*(100-Y12),3) -> 0.026 | AK12: 5.53
A13: 9 | B13: 24 | C13: 24.795833 | D13: -7.0325417 | E13: -5.729 | F13: -8.797 | G13: 97.016667 | H13: 97.7 | I13: 95.4 | J13: 0 | K13: 1.2158333 | L13: 9.06 | M13: 0.191 | N13: 0.208 | O13: 0.862 | Q13: =A13 -> 9 | R13: =B13 -> 24 | S13: =ROUND(C13*0.0864,2) -> 2.14 | T13: =ROUND(D13,1) -> -7 | U13: =ROUND(E13,1) -> -5.7 | V13: =ROUND(F13,1) -> -8.8 | W13: =ROUND(G13,1) -> 97 | X13: =ROUND(H13,1) -> 97.7 | Y13: =ROUND(I13,1) -> 95.4 | Z13: =ROUND(J13,2) -> 0 | AA13: =ROUND(K13,2) -> 1.22 | AB13: =ROUND(L13,2) -> 9.06 | AC13: =ROUND(M13,3) -> 0.191 | AD13: =ROUND(N13,3) -> 0.208 | AE13: =ROUND(O13-AE$2,3) -> 0.862 | AF13: =IF(AE13>AE12,ROUND((AE13-AE12)*130,1),0) -> 3.5 | AG13: =AF13 -> 3.5 | AH13: =ROUND((0.6105*(EXP((17.273*U13)/(U13+237.3))))*Y13/100,3) -> 0.381 | AI13: =ROUND(AH13/Y13*(100-Y13),3) -> 0.018 | AK13: 5.6
A14: 10 | B14: 24 | C14: 46.225 | D14: -12.3045 | E14: -7.64 | F14: -15.345 | G14: 94.133333 | H14: 97.1 | I14: 92.2 | J14: 0 | K14: 0.83833333 | L14: 6.54 | M14: 0.191 | N14: 0.21 | O14: 0.841 | Q14: =A14 -> 10 | R14: =B14 -> 24 | S14: =ROUND(C14*0.0864,2) -> 3.99 | T14: =ROUND(D14,1) -> -12.3 | U14: =ROUND(E14,1) -> -7.6 | V14: =ROUND(F14,1) -> -15.3 | W14: =ROUND(G14,1) -> 94.1 | X14: =ROUND(H14,1) -> 97.1 | Y14: =ROUND(I14,1) -> 92.2 | Z14: =ROUND(J14,2) -> 0 | AA14: =ROUND(K14,2) -> 0.84 | AB14: =ROUND(L14,2) -> 6.54 | AC14: =ROUND(M14,3) -> 0.191 | AD14: =ROUND(N14,3) -> 0.21 | AE14: =ROUND(O14-AE$2,3) -> 0.841 | AF14: =IF(AE14>AE13,ROUND((AE14-AE13)*130,1),0) -> 0 | AG14: =AF14 -> 0 | AH14: =ROUND((0.6105*(EXP((17.273*U14)/(U14+237.3))))*Y14/100,3) -> 0.318 | AI14: =ROUND(AH14/Y14*(100-Y14),3) -> 0.027 | AK14: 5.67
A15: 11 | B15: 24 | C15: 37.370833 | D15: -23.825 | E15: -15.628 | F15: -34.262 | G15: 87.0375 | H15: 92.1 | I15: 80.2 | J15: 0 | K15: 2.51625 | L15: 9.06 | M15: 0.192 | N15: 0.212 | O15: 0.793 | Q15: =A15 -> 11 | R15: =B15 -> 24 | S15: =ROUND(C15*0.0864,2) -> 3.23 | T15: =ROUND(D15,1) -> -23.8 | U15: =ROUND(E15,1) -> -15.6 | V15: =ROUND(F15,1) -> -34.3 | W15: =ROUND(G15,1) -> 87 | X15: =ROUND(H15,1) -> 92.1 | Y15: =ROUND(I15,1) -> 80.2 | Z15: =ROUND(J15,2) -> 0 | AA15: =ROUND(K15,2) -> 2.52 | AB15: =ROUND(L15,2) -> 9.06 | AC15: =ROUND(M15,3) -> 0.192 | AD15: =ROUND(N15,3) -> 0.212 | AE15: =ROUND(O15-AE$2,3) -> 0.793 | AF15: =IF(AE15>AE14,ROUND((AE15-AE14)*130,1),0) -> 0 | AG15: =AF15 -> 0 | AH15: =ROUND((0.6105*(EXP((17.273*U15)/(U15+237.3))))*Y15/100,3) -> 0.145 | AI15: =ROUND(AH15/Y15*(100-Y15),3) -> 0.036 | AK15: 5.74
A16: 12 | B16: 24 | C16: 57.8375 | D16: -32.2655 | E16: -22.833 | F16: -36.059 | G16: 80.679167 | H16: 84.7 | I16: 78.7 | J16: 0 | K16: 1.36375 | L16: 9.06 | M16: 0.193 | N16: 0.213 | O16: 0.795 | Q16: =A16 -> 12 | R16: =B16 -> 24 | S16: =ROUND(C16*0.0864,2) -> 5 | T16: =ROUND(D16,1) -> -32.3 | U16: =ROUND(E16,1) -> -22.8 | V16: =ROUND(F16,1) -> -36.1 | W16: =ROUND(G16,1) -> 80.7 | X16: =ROUND(H16,1) -> 84.7 | Y16: =ROUND(I16,1) -> 78.7 | Z16: =ROUND(J16,2) -> 0 | AA16: =ROUND(K16,2) -> 1.36 | AB16: =ROUND(L16,2) -> 9.06 | AC16: =ROUND(M16,3) -> 0.193 | AD16: =ROUND(N16,3) -> 0.213 | AE16: =ROUND(O16-AE$2,3) -> 0.795 | AF16: =IF(AE16>AE15,ROUND((AE16-AE15)*130,1),0) -> 0.3 | AG16: =AF16 -> 0.3 | AH16: =ROUND((0.6105*(EXP((17.273*U16)/(U16+237.3))))*Y16/100,3) -> 0.077 | AI16: =ROUND(AH16/Y16*(100-Y16),3) -> 0.021 | AK16: 5.82
A17: 13 | B17: 24 | C17: 74.458333 | D17: -25.647208 | E17: -20.451 | F17: -32.445 | G17: 84.45 | H17: 88.4 | I17: 80.3 | J17: 0 | K17: 1.6354167 | L17: 8.05 | M17: 0.194 | N17: 0.214 | O17: 0.779 | Q17: =A17 -> 13 | R17: =B17 -> 24 | S17: =ROUND(C17*0.0864,2) -> 6.43 | T17: =ROUND(D17,1) -> -25.6 | U17: =ROUND(E17,1) -> -20.5 | V17: =ROUND(F17,1) -> -32.4 | W17: =ROUND(G17,1) -> 84.5 | X17: =ROUND(H17,1) -> 88.4 | Y17: =ROUND(I17,1) -> 80.3 | Z17: =ROUND(J17,2) -> 0 | AA17: =ROUND(K17,2) -> 1.64 | AB17: =ROUND(L17,2) -> 8.05 | AC17: =ROUND(M17,3) -> 0.194 | AD17: =ROUND(N17,3) -> 0.214 | AE17: =ROUND(O17-AE$2,3) -> 0.779 | AF17: =IF(AE17>AE16,ROUND((AE17-AE16)*130,1),0) -> 0 | AG17: =AF17 -> 0 | AH17: =ROUND((0.6105*(EXP((17.273*U17)/(U17+237.3))))*Y17/100,3) -> 0.096 | AI17: =ROUND(AH17/Y17*(100-Y17),3) -> 0.024 | AK17: 5.89
... A23: 19 | B23: 24 | C23: 26.954167 | D23: -7.853875 | E23: -1.1 | F23: -12.602 | G23: 95.6625 | H23: 100 | I23: 90.3 | J23: 0 | K23: 2.4116667 | L23: 10.07 | M23: 0.197 | N23: 0.218 | O23: 0.849 | Q23: =A23 -> 19 | R23: =B23 -> 24 | S23: =ROUND(C23*0.0864,2) -> 2.33 | T23: =ROUND(D23,1) -> -7.9 | U23: =ROUND(E23,1) -> -1.1 | V23: =ROUND(F23,1) -> -12.6 | W23: =ROUND(G23,1) -> 95.7 | X23: =ROUND(H23,1) -> 100 | Y23: =ROUND(I23,1) -> 90.3 | Z23: =ROUND(J23,2) -> 0 | AA23: =ROUND(K23,2) -> 2.41 | AB23: =ROUND(L23,2) -> 10.07 | AC23: =ROUND(M23,3) -> 0.197 | AD23: =ROUND(N23,3) -> 0.218 | AE23: =ROUND(O23-AE$2,3) -> 0.849 | AF23: =IF(AE23>AE22,ROUND((AE23-AE22)*130,1),0) -> 0.7 | AG23: =AF23 -> 0.7 | AH23: =ROUND((0.6105*(EXP((17.273*U23)/(U23+237.3))))*Y23/100,3) -> 0.509 | AI23: =ROUND(AH23/Y23*(100-Y23),3) -> 0.055 | AK23: 6.45
A24: 20 | B24: 24 | C24: 31.770833 | D24: -2.0322917 | E24: -1.299 | F24: -3.598 | G24: 99.908333 | H24: 100 | I24: 99.7 | J24: 0.4 | K24: 1.0908333 | L24: 8.05 | M24: 0.197 | N24: 0.218 | O24: 1.629 | Q24: =A24 -> 20 | R24: =B24 -> 24 | S24: =ROUND(C24*0.0864,2) -> 2.75 | T24: =ROUND(D24,1) -> -2 | U24: =ROUND(E24,1) -> -1.3 | V24: =ROUND(F24,1) -> -3.6 | W24: =ROUND(G24,1) -> 99.9 | X24: =ROUND(H24,1) -> 100 | Y24: =ROUND(I24,1) -> 99.7 | Z24: =ROUND(J24,2) -> 0.4 | AA24: =ROUND(K24,2) -> 1.09 | AB24: =ROUND(L24,2) -> 8.05 | AC24: =ROUND(M24,3) -> 0.197 | AD24: =ROUND(N24,3) -> 0.218 | AE24: 0.88 | AF24: =IF(AE24>AE23,ROUND((AE24-AE23)*130,1),0) -> 4 | AG24: =AF24 -> 4 | AH24: =ROUND((0.6105*(EXP((17.273*U24)/(U24+237.3))))*Y24/100,3) -> 0.553 | AI24: =ROUND(AH24/Y24*(100-Y24),3) -> 0.002 | AK24: 6.55
A25: 21 | B25: 24 | C25: 41.358333 | D25: -3.1744583 | E25: -2.131 | F25: -3.777 | G25: 99.591667 | H25: 100 | I25: 98.7 | J25: 0.2 | K25: 0.52375 | L25: 6.04 | M25: 0.197 | N25: 0.218 | O25: 2.355 | Q25: =A25 -> 21 | R25: =B25 -> 24 | S25: =ROUND(C25*0.0864,2) -> 3.57 | T25: =ROUND(D25,1) -> -3.2 | U25: =ROUND(E25,1) -> -2.1 | V25: =ROUND(F25,1) -> -3.8 | W25: =ROUND(G25,1) -> 99.6 | X25: =ROUND(H25,1) -> 100 | Y25: =ROUND(I25,1) -> 98.7 | Z25: =ROUND(J25,2) -> 0.2 | AA25: =ROUND(K25,2) -> 0.52 | AB25: =ROUND(L25,2) -> 6.04 | AC25: =ROUND(M25,3) -> 0.197 | AD25: =ROUND(N25,3) -> 0.218 | AE25: 0.88 | AF25: =IF(AE25>AE24,ROUND((AE25-AE24)*130,1),0) -> 0 | AG25: =AF25 -> 0 | AH25: =ROUND((0.6105*(EXP((17.273*U25)/(U25+237.3))))*Y25/100,3) -> 0.516 | AI25: =ROUND(AH25/Y25*(100-Y25),3) -> 0.007 | AK25: 6.66
A26: 22 | B26: 24 | C26: 22.108333 | D26: -2.3406667 | E26: -1.584 | F26: -3.33 | G26: 99.945833 | H26: 100 | I26: 99.7 | J26: 0 | K26: 0.20833333 | L26: 4.53 | M26: 0.197 | N26: 0.219 | O26: 2.052 | Q26: =A26 -> 22 | R26: =B26 -> 24 | S26: =ROUND(C26*0.0864,2) -> 1.91 | T26: =ROUND(D26,1) -> -2.3 | U26: =ROUND(E26,1) -> -1.6 | V26: =ROUND(F26,1) -> -3.3 | W26: =ROUND(G26,1) -> 99.9 | X26: =ROUND(H26,1) -> 100 | Y26: =ROUND(I26,1) -> 99.7 | Z26: =ROUND(J26,2) -> 0 | AA26: =ROUND(K26,2) -> 0.21 | AB26: =ROUND(L26,2) -> 4.53 | AC26: =ROUND(M26,3) -> 0.197 | AD26: =ROUND(N26,3) -> 0.219 | AE26: 0.88 | AF26: =IF(AE26>AE25,ROUND((AE26-AE25)*130,1),0) -> 0 | AG26: =AF26 -> 0 | AH26: =ROUND((0.6105*(EXP((17.273*U26)/(U26+237.3))))*Y26/100,3) -> 0.541 | AI26: =ROUND(AH26/Y26*(100-Y26),3) -> 0.002 | AK26: 6.77
A27: 23 | B27: 24 | C27: 33.933333 | D27: -2.2461667 | E27: 0.797 | F27: -4.957 | G27: 99.975 | H27: 100 | I27: 99.7 | J27: 1.8 | K27: 0.2725 | L27: 5.54 | M27: 0.197 | N27: 0.22 | O27: 0.889 | Q27: =A27 -> 23 | R27: =B27 -> 24 | S27: =ROUND(C27*0.0864,2) -> 2.93 | T27: =ROUND(D27,1) -> -2.2 | U27: =ROUND(E27,1) -> 0.8 | V27: =ROUND(F27,1) -> -5 | W27: =ROUND(G27,1) -> 100 | X27: =ROUND(H27,1) -> 100 | Y27: =ROUND(I27,1) -> 99.7 | Z27: =ROUND(J27,2) -> 1.8 | AA27: =ROUND(K27,2) -> 0.27 | AB27: =ROUND(L27,2) -> 5.54 | AC27: =ROUND(M27,3) -> 0.197 | AD27: =ROUND(N27,3) -> 0.22 | AE27: =ROUND(O27-AE$2,3) -> 0.889 | AF27: =IF(AE27>AE26,ROUND((AE27-AE26)*130,1),0) -> 1.2 | AG27: =AF27 -> 1.2 | AH27: =ROUND((0.6105*(EXP((17.273*U27)/(U27+237.3))))*Y27/100,3) -> 0.645 | AI27: =ROUND(AH27/Y27*(100-Y27),3) -> 0.002 | AK27: 6.89
A28: 24 | B28: 24 | C28: 16.854167 | D28: -4.1704583 | E28: -2.976 | F28: -6.674 | G28: 99.416667 | H28: 100 | I28: 98 | J28: 0 | K28: 0.042083333 | L28: 4.53 | M28: 0.197 | N28: 0.22 | O28: 2.354 | Q28: =A28 -> 24 | R28: =B28 -> 24 | S28: =ROUND(C28*0.0864,2) -> 1.46 | T28: =ROUND(D28,1) -> -4.2 | U28: =ROUND(E28,1) -> -3 | V28: =ROUND(F28,1) -> -6.7 | W28: =ROUND(G28,1) -> 99.4 | X28: =ROUND(H28,1) -> 100 | Y28: =ROUND(I28,1) -> 98 | Z28: =ROUND(J28,2) -> 0 | AA28: =ROUND(K28,2) -> 0.04 | AB28: =ROUND(L28,2) -> 4.53 | AC28: =ROUND(M28,3) -> 0.197 | AD28: =ROUND(N28,3) -> 0.22 | AE28: 0.91 | AF28: =IF(AE28>AE27,ROUND((AE28-AE27)*130,1),0) -> 2.7 | AG28: =AF28 -> 2.7 | AH28: =ROUND((0.6105*(EXP((17.273*U28)/(U28+237.3))))*Y28/100,3) -> 0.48 | AI28: =ROUND(AH28/Y28*(100-Y28),3) -> 0.01 | AK28: 7.01
A29: 25 | B29: 24 | C29: 24.379167 | D29: -4.8292083 | E29: -0.563 | F29: -8.63 | G29: 98.8125 | H29: 100 | I29: 96.9 | J29: 0.4 | K29: 0 | L29: 0 | M29: 0.197 | N29: 0.222 | O29: 2.354 | Q29: =A29 -> 25 | R29: =B29 -> 24 | S29: =ROUND(C29*0.0864,2) -> 2.11 | T29: =ROUND(D29,1) -> -4.8 | U29: =ROUND(E29,1) -> -0.6 | V29: =ROUND(F29,1) -> -8.6 | W29: =ROUND(G29,1) -> 98.8 | X29: =ROUND(H29,1) -> 100 | Y29: =ROUND(I29,1) -> 96.9 | Z29: =ROUND(J29,2) -> 0.4 | AA29: =ROUND(K29,2) -> 0 | AB29: =ROUND(L29,2) -> 0 | AC29: =ROUND(M29,3) -> 0.197 | AD29: =ROUND(N29,3) -> 0.222 | AE29: 0.91 | AF29: =IF(AE29>AE28,ROUND((AE29-AE28)*130,1),0) -> 0 | AG29: =AF29 -> 0 | AH29: =ROUND((0.6105*(EXP((17.273*U29)/(U29+237.3))))*Y29/100,3) -> 0.566 | AI29: =ROUND(AH29/Y29*(100-Y29),3) -> 0.018 | AK29: 7.13
A30: 26 | B30: 24 | C30: 23.516667 | D30: -4.2649583 | E30: -1.9 | F30: -6.642 | G30: 99.2375 | H30: 100 | I30: 98 | J30: 0.6 | K30: 0 | L30: 0 | M30: 0.2 | N30: 0.223 | O30: 1.006 | Q30: =A30 -> 26 | R30: =B30 -> 24 | S30: =ROUND(C30*0.0864,2) -> 2.03 | T30: =ROUND(D30,1) -> -4.3 | U30: =ROUND(E30,1) -> -1.9 | V30: =ROUND(F30,1) -> -6.6 | W30: =ROUND(G30,1) -> 99.2 | X30: =ROUND(H30,1) -> 100 | Y30: =ROUND(I30,1) -> 98 | Z30: =ROUND(J30,2) -> 0.6 | AA30: =ROUND(K30,2) -> 0 | AB30: =ROUND(L30,2) -> 0 | AC30: =ROUND(M30,3) -> 0.2 | AD30: =ROUND(N30,3) -> 0.223 | AE30: =ROUND(O30-AE$2,3) -> 1.006 | AF30: =IF(AE30>AE29,ROUND((AE30-AE29)*130,1),0) -> 12.5 | AG30: =AF30 -> 12.5 | AH30: =ROUND((0.6105*(EXP((17.273*U30)/(U30+237.3))))*Y30/100,3) -> 0.52 | AI30: =ROUND(AH30/Y30*(100-Y30),3) -> 0.011 | AK30: 7.26
A31: 27 | B31: 24 | C31: 15.3125 | D31: -2.0058333 | E31: 0.163 | F31: -3.717 | G31: 99.954167 | H31: 100 | I31: 99.6 | J31: 0 | K31: 0 | L31: 0 | M31: 0.2 | N31: 0.225 | O31: 0.999 | Q31: =A31 -> 27 | R31: =B31 -> 24 | S31: =ROUND(C31*0.0864,2) -> 1.32 | T31: =ROUND(D31,1) -> -2 | U31: =ROUND(E31,1) -> 0.2 | V31: =ROUND(F31,1) -> -3.7 | W31: =ROUND(G31,1) -> 100 | X31: =ROUND(H31,1) -> 100 | Y31: =ROUND(I31,1) -> 99.6 | Z31: =ROUND(J31,2) -> 0 | AA31: =ROUND(K31,2) -> 0 | AB31: =ROUND(L31,2) -> 0 | AC31: =ROUND(M31,3) -> 0.2 | AD31: =ROUND(N31,3) -> 0.225 | AE31: =ROUND(O31-AE$2,3) -> 0.999 | AF31: =IF(AE31>AE30,ROUND((AE31-AE30)*130,1),0) -> 0 | AG31: =AF31 -> 0 | AH31: =ROUND((0.6105*(EXP((17.273*U31)/(U31+237.3))))*Y31/100,3) -> 0.617 | AI31: =ROUND(AH31/Y31*(100-Y31),3) -> 0.002 | AK31: 7.39
A32: 28 | B32: 24 | C32: 40.9625 | D32: 1.337 | E32: 3.749 | F32: -0.451 | G32: 100 | H32: 100 | I32: 100 | J32: 18 | K32: 1.07 | L32: 9.06 | M32: 0.196 | N32: 0.228 | O32: 0.908 | Q32: =A32 -> 28 | R32: =B32 -> 24 | S32: =ROUND(C32*0.0864,2) -> 3.54 | T32: =ROUND(D32,1) -> 1.3 | U32: =ROUND(E32,1) -> 3.7 | V32: =ROUND(F32,1) -> -0.5 | W32: =ROUND(G32,1) -> 100 | X32: =ROUND(H32,1) -> 100 | Y32: =ROUND(I32,1) -> 100 | Z32: =ROUND(J32,2) -> 18 | AA32: =ROUND(K32,2) -> 1.07 | AB32: =ROUND(L32,2) -> 9.06 | AC32: =ROUND(M32,3) -> 0.196 | AD32: =ROUND(N32,3) -> 0.228 | AE32: =ROUND(O32-AE$2,3) -> 0.908 | AF32: =IF(AE32>AE31,ROUND((AE32-AE31)*130,1),0) -> 0 | AG32: =AF32 -> 0 | AH32: =ROUND((0.6105*(EXP((17.273*U32)/(U32+237.3))))*Y32/100,3) -> 0.796 | AI32: =ROUND(AH32/Y32*(100-Y32),3) -> 0 | AK32: 7.52
A33: 29 | B33: 24 | C33: 40.654167 | D33: 2.1719583 | E33: 3.406 | F33: 0.797 | G33: 100 | H33: 100 | I33: 100 | J33: 0.2 | K33: 3.0004167 | L33: 14.59 | M33: 0.201 | N33: 0.257 | O33: 0.795 | Q33: =A33 -> 29 | R33: =B33 -> 24 | S33: =ROUND(C33*0.0864,2) -> 3.51 | T33: =ROUND(D33,1) -> 2.2 | U33: =ROUND(E33,1) -> 3.4 | V33: =ROUND(F33,1) -> 0.8 | W33: =ROUND(G33,1) -> 100 | X33: =ROUND(H33,1) -> 100 | Y33: =ROUND(I33,1) -> 100 | Z33: =ROUND(J33,2) -> 0.2 | AA33: =ROUND(K33,2) -> 3 | AB33: =ROUND(L33,2) -> 14.59 | AC33: =ROUND(M33,3) -> 0.201 | AD33: =ROUND(N33,3) -> 0.257 | AE33: =ROUND(O33-AE$2,3) -> 0.795 | AF33: =IF(AE33>AE32,ROUND((AE33-AE32)*130,1),0) -> 0 | AG33: =AF33 -> 0 | AH33: =ROUND((0.6105*(EXP((17.273*U33)/(U33+237.3))))*Y33/100,3) -> 0.779 | AI33: =ROUND(AH33/Y33*(100-Y33),3) -> 0 | AK33: 7.66
A34: 30 | B34: 24 | C34: 27.654167 | D34: 1.6382917 | E34: 3.009 | F34: 0.632 | G34: 100 | H34: 100 | I34: 100 | J34: 1.6 | K34: 1.5729167 | L34: 10.57 | M34: 0.206 | N34: 0.273 | O34: 0.775 | Q34: =A34 -> 30 | R34: =B34 -> 24 | S34: =ROUND(C34*0.0864,2) -> 2.39 | T34: =ROUND(D34,1) -> 1.6 | U34: =ROUND(E34,1) -> 3 | V34: =ROUND(F34,1) -> 0.6 | W34: =ROUND(G34,1) -> 100 | X34: =ROUND(H34,1) -> 100 | Y34: =ROUND(I34,1) -> 100 | Z34: =ROUND(J34,2) -> 1.6 | AA34: =ROUND(K34,2) -> 1.57 | AB34: =ROUND(L34,2) -> 10.57 | AC34: =ROUND(M34,3) -> 0.206 | AD34: =ROUND(N34,3) -> 0.273 | AE34: =ROUND(O34-AE$2,3) -> 0.775 | AF34: =IF(AE34>AE33,ROUND((AE34-AE33)*130,1),0) -> 0 | AG34: =AF34 -> 0 | AH34: =ROUND((0.6105*(EXP((17.273*U34)/(U34+237.3))))*Y34/100,3) -> 0.757 | AI34: =ROUND(AH34/Y34*(100-Y34),3) -> 0 | AK34: 7.8
A35: 31 | B35: 24 | C35: 19.579167 | D35: 1.0826667 | E35: 2.209 | F35: 0.687 | G35: 100 | H35: 100 | I35: 100 | J35: 0.2 | K35: 4.4658333 | L35: 16.1 | M35: 0.213 | N35: 0.281 | O35: 0.712 | Q35: =A35 -> 31 | R35: =B35 -> 24 | S35: =ROUND(C35*0.0864,2) -> 1.69 | T35: =ROUND(D35,1) -> 1.1 | U35: =ROUND(E35,1) -> 2.2 | V35: =ROUND(F35,1) -> 0.7 | W35: =ROUND(G35,1) -> 100 | X35: =ROUND(H35,1) -> 100 | Y35: =ROUND(I35,1) -> 100 | Z35: =ROUND(J35,2) -> 0.2 | AA35: =ROUND(K35,2) -> 4.47 | AB35: =ROUND(L35,2) -> 16.1 | AC35: =ROUND(M35,3) -> 0.213 | AD35: =ROUND(N35,3) -> 0.281 | AE35: =ROUND(O35-AE$2,3) -> 0.712 | AF35: =IF(AE35>AE34,ROUND((AE35-AE34)*130,1),0) -> 0 | AG35: =AF35 -> 0 | AH35: =ROUND((0.6105*(EXP((17.273*U35)/(U35+237.3))))*Y35/100,3) -> 0.715 | AI35: =ROUND(AH35/Y35*(100-Y35),3) -> 0 | AK35: 7.95
A36: 32 | B36: 24 | C36: 23.075 | D36: 0.5555 | E36: 1.534 | F36: -0.116 | G36: 100 | H36: 100 | I36: 100 | J36: 1.4 | K36: 2.4116667 | L36: 11.58 | M36: 0.216 | N36: 0.287 | O36: 0.706 | Q36: =A36 -> 32 | R36: =B36 -> 24 | S36: =ROUND(C36*0.0864,2) -> 1.99 | T36: =ROUND(D36,1) -> 0.6 | U36: =ROUND(E36,1) -> 1.5 | V36: =ROUND(F36,1) -> -0.1 | W36: =ROUND(G36,1) -> 100 | X36: =ROUND(H36,1) -> 100 | Y36: =ROUND(I36,1) -> 100 | Z36: =ROUND(J36,2) -> 1.4 | AA36: =ROUND(K36,2) -> 2.41 | AB36: =ROUND(L36,2) -> 11.58 | AC36: =ROUND(M36,3) -> 0.216 | AD36: =ROUND(N36,3) -> 0.287 | AE36: =ROUND(O36-AE$2,3) -> 0.706 | AF36: =IF(AE36>AE35,ROUND((AE36-AE35)*130,1),0) -> 0 | AG36: =AF36 -> 0 | AH36: =ROUND((0.6105*(EXP((17.273*U36)/(U36+237.3))))*Y36/100,3) -> 0.68 | AI36: =ROUND(AH36/Y36*(100-Y36),3) -> 0 | AK36: 8.1
A37: 33 | B37: 24 | C37: 77.183333 | D37: -0.88179167 | E37: 3.67 | F37: -3.657 | G37: 96.929167 | H37: 100 | I37: 87.7 | J37: 0 | K37: 0.35541667 | L37: 6.54 | M37: 0.212 | N37: 0.288 | O37: 0.695 | Q37: =A37 -> 33 | R37: =B37 -> 24 | S37: =ROUND(C37*0.0864,2) -> 6.67 | T37: =ROUND(D37,1) -> -0.9 | U37: =ROUND(E37,1) -> 3.7 | V37: =ROUND(F37,1) -> -3.7 | W37: =ROUND(G37,1) -> 96.9 | X37: =ROUND(H37,1) -> 100 | Y37: =ROUND(I37,1) -> 87.7 | Z37: =ROUND(J37,2) -> 0 | AA37: =ROUND(K37,2) -> 0.36 | AB37: =ROUND(L37,2) -> 6.54 | AC37: =ROUND(M37,3) -> 0.212 | AD37: =ROUND(N37,3) -> 0.288 | AE37: =ROUND(O37-AE$2,3) -> 0.695 | AF37: =IF(AE37>AE36,ROUND((AE37-AE36)*130,1),0) -> 0 | AG37: =AF37 -> 0 | AH37: =ROUND((0.6105*(EXP((17.273*U37)/(U37+237.3))))*Y37/100,3) -> 0.698 | AI37: =ROUND(AH37/Y37*(100-Y37),3) -> 0.098 | AK37: 8.25
A38: 34 | B38: 24 | C38: 30.941667 | D38: -4.2075833 | E38: -2.918 | F38: -5.854 | G38: 97.445833 | H38: 99 | I38: 94.7 | J38: 0.2 | K38: 1.7820833 | L38: 8.56 | M38: 0.213 | N38: 0.283 | O38: 0.677 | Q38: =A38 -> 34 | R38: =B38 -> 24 | S38: =ROUND(C38*0.0864,2) -> 2.67 | T38: =ROUND(D38,1) -> -4.2 | U38: =ROUND(E38,1) -> -2.9 | V38: =ROUND(F38,1) -> -5.9 | W38: =ROUND(G38,1) -> 97.4 | X38: =ROUND(H38,1) -> 99 | Y38: =ROUND(I38,1) -> 94.7 | Z38: =ROUND(J38,2) -> 0.2 | AA38: =ROUND(K38,2) -> 1.78 | AB38: =ROUND(L38,2) -> 8.56 | AC38: =ROUND(M38,3) -> 0.213 | AD38: =ROUND(N38,3) -> 0.283 | AE38: =ROUND(O38-AE$2,3) -> 0.677 | AF38: =IF(AE38>AE37,ROUND((AE38-AE37)*130,1),0) -> 0 | AG38: =AF38 -> 0 | AH38: =ROUND((0.6105*(EXP((17.273*U38)/(U38+237.3))))*Y38/100,3) -> 0.467 | AI38: =ROUND(AH38/Y38*(100-Y38),3) -> 0.026 | AK38: 8.41
A39: 35 | B39: 24 | C39: 44.891667 | D39: -4.3750833 | E39: -2.625 | F39: -5.979 | G39: 98.770833 | H39: 99.3 | I39: 97.9 | J39: 0.8 | K39: 0.56583333 | L39: 8.05 | M39: 0.213 | N39: 0.278 | O39: 0.689 | Q39: =A39 -> 35 | R39: =B39 -> 24 | S39: =ROUND(C39*0.0864,2) -> 3.88 | T39: =ROUND(D39,1) -> -4.4 | U39: =ROUND(E39,1) -> -2.6 | V39: =ROUND(F39,1) -> -6 | W39: =ROUND(G39,1) -> 98.8 | X39: =ROUND(H39,1) -> 99.3 | Y39: =ROUND(I39,1) -> 97.9 | Z39: =ROUND(J39,2) -> 0.8 | AA39: =ROUND(K39,2) -> 0.57 | AB39: =ROUND(L39,2) -> 8.05 | AC39: =ROUND(M39,3) -> 0.213 | AD39: =ROUND(N39,3) -> 0.278 | AE39: =ROUND(O39-AE$2,3) -> 0.689 | AF39: =IF(AE39>AE38,ROUND((AE39-AE38)*130,1),0) -> 1.6 | AG39: =AF39 -> 1.6 | AH39: =ROUND((0.6105*(EXP((17.273*U39)/(U39+237.3))))*Y39/100,3) -> 0.494 | AI39: =ROUND(AH39/Y39*(100-Y39),3) -> 0.011 | AK39: 8.57
A40: 36 | B40: 24 | C40: 40.8875 | D40: -4.2063333 | E40: -2.421 | F40: -5.418 | G40: 99.158333 | H40: 99.8 | I40: 98.7 | J40: 0.2 | K40: 0.25125 | L40: 5.03 | M40: 0.211 | N40: 0.274 | O40: 0.723 | Q40: =A40 -> 36 | R40: =B40 -> 24 | S40: =ROUND(C40*0.0864,2) -> 3.53 | T40: =ROUND(D40,1) -> -4.2 | U40: =ROUND(E40,1) -> -2.4 | V40: =ROUND(F40,1) -> -5.4 | W40: =ROUND(G40,1) -> 99.2 | X40: =ROUND(H40,1) -> 99.8 | Y40: =ROUND(I40,1) -> 98.7 | Z40: =ROUND(J40,2) -> 0.2 | AA40: =ROUND(K40,2) -> 0.25 | AB40: =ROUND(L40,2) -> 5.03 | AC40: =ROUND(M40,3) -> 0.211 | AD40: =ROUND(N40,3) -> 0.274 | AE40: =ROUND(O40-AE$2,3) -> 0.723 | AF40: =IF(AE40>AE39,ROUND((AE40-AE39)*130,1),0) -> 4.4 | AG40: =AF40 -> 4.4 | AH40: =ROUND((0.6105*(EXP((17.273*U40)/(U40+237.3))))*Y40/100,3) -> 0.505 | AI40: =ROUND(AH40/Y40*(100-Y40),3) -> 0.007 | AK40: 8.73
A41: 37 | B41: 24 | C41: 13.645833 | D41: -2.8133333 | E41: -1.242 | F41: -3.747 | G41: 99.95 | H41: 100 | I41: 99.7 | J41: 0.2 | K41: 0.041666667 | L41: 4.03 | M41: 0.21 | N41: 0.271 | O41: 1.331 | Q41: =A41 -> 37 | R41: =B41 -> 24 | S41: =ROUND(C41*0.0864,2) -> 1.18 | T41: =ROUND(D41,1) -> -2.8 | U41: =ROUND(E41,1) -> -1.2 | V41: =ROUND(F41,1) -> -3.7 | W41: =ROUND(G41,1) -> 100 | X41: =ROUND(H41,1) -> 100 | Y41: =ROUND(I41,1) -> 99.7 | Z41: =ROUND(J41,2) -> 0.2 | AA41: =ROUND(K41,2) -> 0.04 | AB41: =ROUND(L41,2) -> 4.03 | AC41: =ROUND(M41,3) -> 0.21 | AD41: =ROUND(N41,3) -> 0.271 | AE41: 0.85 | AF41: =IF(AE41>AE40,ROUND((AE41-AE40)*130,1),0) -> 16.5 | AG41: =AF41 -> 16.5 | AH41: =ROUND((0.6105*(EXP((17.273*U41)/(U41+237.3))))*Y41/100,3) -> 0.558 | AI41: =ROUND(AH41/Y41*(100-Y41),3) -> 0.002 | AK41: 8.9
A42: 38 | B42: 24 | C42: 28.541667 | D42: -3.6167917 | E42: 0.051 | F42: -6.01 | G42: 99.525 | H42: 100 | I42: 98.2 | J42: 0.4 | K42: 0 | L42: 0.5 | M42: 0.21 | N42: 0.27 | O42: 0.861 | Q42: =A42 -> 38 | R42: =B42 -> 24 | S42: =ROUND(C42*0.0864,2) -> 2.47 | T42: =ROUND(D42,1) -> -3.6 | U42: =ROUND(E42,1) -> 0.1 | V42: =ROUND(F42,1) -> -6 | W42: =ROUND(G42,1) -> 99.5 | X42: =ROUND(H42,1) -> 100 | Y42: =ROUND(I42,1) -> 98.2 | Z42: =ROUND(J42,2) -> 0.4 | AA42: =ROUND(K42,2) -> 0 | AB42: =ROUND(L42,2) -> 0.5 | AC42: =ROUND(M42,3) -> 0.21 | AD42: =ROUND(N42,3) -> 0.27 | AE42: =ROUND(O42-AE$2,3) -> 0.861 | AF42: =IF(AE42>AE41,ROUND((AE42-AE41)*130,1),0) -> 1.4 | AG42: =AF42 -> 1.4 | AH42: =ROUND((0.6105*(EXP((17.273*U42)/(U42+237.3))))*Y42/100,3) -> 0.604 | AI42: =ROUND(AH42/Y42*(100-Y42),3) -> 0.011 | AK42: 9.08
A43: 39 | B43: 24 | C43: 57.029167 | D43: -6.7535417 | E43: -4.651 | F43: -8.231 | G43: 96.6 | H43: 97.8 | I43: 92 | J43: 0 | K43: 0.52416667 | L43: 6.04 | M43: 0.212 | N43: 0.268 | O43: 0.856 | Q43: =A43 -> 39 | R43: =B43 -> 24 | S43: =ROUND(C43*0.0864,2) -> 4.93 | T43: =ROUND(D43,1) -> -6.8 | U43: =ROUND(E43,1) -> -4.7 | V43: =ROUND(F43,1) -> -8.2 | W43: =ROUND(G43,1) -> 96.6 | X43: =ROUND(H43,1) -> 97.8 | Y43: =ROUND(I43,1) -> 92 | Z43: =ROUND(J43,2) -> 0 | AA43: =ROUND(K43,2) -> 0.52 | AB43: =ROUND(L43,2) -> 6.04 | AC43: =ROUND(M43,3) -> 0.212 | AD43: =ROUND(N43,3) -> 0.268 | AE43: =ROUND(O43-AE$2,3) -> 0.856 | AF43: =IF(AE43>AE42,ROUND((AE43-AE42)*130,1),0) -> 0 | AG43: =AF43 -> 0 | AH43: =ROUND((0.6105*(EXP((17.273*U43)/(U43+237.3))))*Y43/100,3) -> 0.396 | AI43: =ROUND(AH43/Y43*(100-Y43),3) -> 0.034 | AK43: 9.25
A44: 40 | B44: 24 | C44: 101.55833 | D44: -9.5774167 | E44: -3.777 | F44: -12.454 | G44: 91.575 | H44: 96.8 | I44: 78.7 | J44: 2.6 | K44: 0.56625 | L44: 7.05 | M44: 0.212 | N44: 0.267 | O44: 0.851 | Q44: =A44 -> 40 | R44: =B44 -> 24 | S44: =ROUND(C44*0.0864,2) -> 8.77 | T44: =ROUND(D44,1) -> -9.6 | U44: =ROUND(E44,1) -> -3.8 | V44: =ROUND(F44,1) -> -12.5 | W44: =ROUND(G44,1) -> 91.6 | X44: =ROUND(H44,1) -> 96.8 | Y44: =ROUND(I44,1) -> 78.7 | Z44: =ROUND(J44,2) -> 2.6 | AA44: =ROUND(K44,2) -> 0.57 | AB44: =ROUND(L44,2) -> 7.05 | AC44: =ROUND(M44,3) -> 0.212 | AD44: =ROUND(N44,3) -> 0.267 | AE44: =ROUND(O44-AE$2,3) -> 0.851 | AF44: =IF(AE44>AE43,ROUND((AE44-AE43)*130,1),0) -> 0 | AG44: =AF44 -> 0 | AH44: =ROUND((0.6105*(EXP((17.273*U44)/(U44+237.3))))*Y44/100,3) -> 0.363 | AI44: =ROUND(AH44/Y44*(100-Y44),3) -> 0.098 | AK44: 9.43
A45: 41 | B45: 24 | C45: 59.741667 | D45: -6.1675833 | E45: -3.065 | F45: -11.867 | G45: 90.345833 | H45: 96.9 | I45: 77.8 | J45: 0.2 | K45: 0.08375 | L45: 3.02 | M45: 0.212 | N45: 0.265 | O45: 0.869 | Q45: =A45 -> 41 | R45: =B45 -> 24 | S45: =ROUND(C45*0.0864,2) -> 5.16 | T45: =ROUND(D45,1) -> -6.2 | U45: =ROUND(E45,1) -> -3.1 | V45: =ROUND(F45,1) -> -11.9 | W45: =ROUND(G45,1) -> 90.3 | X45: =ROUND(H45,1) -> 96.9 | Y45: =ROUND(I45,1) -> 77.8 | Z45: =ROUND(J45,2) -> 0.2 | AA45: =ROUND(K45,2) -> 0.08 | AB45: =ROUND(L45,2) -> 3.02 | AC45: =ROUND(M45,3) -> 0.212 | AD45: =ROUND(N45,3) -> 0.265 | AE45: =ROUND(O45-AE$2,3) -> 0.869 | AF45: =IF(AE45>AE44,ROUND((AE45-AE44)*130,1),0) -> 2.3 | AG45: =AF45 -> 2.3 | AH45: =ROUND((0.6105*(EXP((17.273*U45)/(U45+237.3))))*Y45/100,3) -> 0.378 | AI45: =ROUND(AH45/Y45*(100-Y45),3) -> 0.108 | AK45: 9.61
...

Sheet GraphDay

Sheet Meta
A1: Meta data Station PL
A2: Last edit 20/12/25
B3: Hobo Data logger and asssociated sensors with hourly data downloaded from DataGarrison
B4: Hourly values (DataHour worksheet) used to give daily summary (DataDay worksheet)
C5: Daily data graphed in GraphDay
A7: Sola radiation W/m2, MJ/m2/d
B8: Added estimate of maximum clear sky solar radiation
A10: Air temperature C
A12: Relative humidity %
A14: Rainfall mm
A16: Snow Depth cm, m
B17: Data needs filtering
C18: Daily precipitation falling as snow (density of 0.13 to allow for compression to end of day) and rain gauge (discounted snow melt in gauge) for annual estimate of precipitation
A19: Soil moisture m3/m3
B20: TDR probes at 0.1 and 0.2 m
A22: Wind speed m/s
A24: Wind direction degrees
B25: wind rose as % time in octants
A27: Vapour pressure and vapour pressure deficit kPa
B28: Calculated from air temperature and relative humidity
