Workbook

Sheet Data
A1: Penticton Creek Site P1 2019-2025 Daily data
A2: Last edit 2/01/26
A3: Site | B3: Date | C3: Key | D3: Solar | E3: Reflect | F3: Tave | G3: Tmax | H3: Tmin | I3: RHave | J3: RHmin | K3: Wind | L3: WindMax | M3: Precip | N3: SnowD | O3: Tsnow | P3: IRTSurfA | Q3: IRTSurfX | R3: IRTSurfN | S3: Tsoil005 | T3: Tsoil15 | U3: Tsoil50 | V3: SoilH2O | W3: Vapres | X3: vpdX | Y3: Wind Direction (fraction of day) | AG3: ClrSky
D4: MJ/m2/d | E4: MJ/m2/d | F4: C | G4: C | H4: C | I4: % | J4: % | K4: m/s | L4: m/s | M4: mm | N4: m | O4: C | P4: C | Q4: C | R4: C | S4: C | T4: C | U4: C | V4: m3/m3 | W4: kPa | X4: kPa | Y4: N-NE | Z4: NE-E | AA4: E-SE | AB4: SE-S | AC4: S-SW | AD4: SW-W | AE4: W-NW | AF4: NW-N | AG4: MJ/m2/d
A5: P1 | B5: 43466 | C5: 2019001 | D5: 0.64 | E5: NAN | F5: -5.5 | G5: -0.7 | H5: -9.5 | I5: 87.5 | J5: 79.7 | K5: 0 | L5: 0 | M5: 0 | N5: 0.7 | O5: -1 | P5: NAN | Q5: NAN | R5: NAN | S5: -0.1 | T5: 0.5 | U5: 1.1 | V5: NAN | W5: 0.461 | X5: 0.117 | Y5: NAN | Z5: NAN | AA5: NAN | AB5: NAN | AC5: NAN | AD5: NAN | AE5: NAN | AF5: NAN | AG5: 5.14
A6: P1 | B6: 43467 | C6: 2019002 | D6: 0.42 | E6: NAN | F6: -8 | G6: -6.9 | H6: -9.6 | I6: 90.7 | J6: 87.8 | K6: 0 | L6: 0 | M6: 0 | N6: 0.679 | O6: -1 | P6: NAN | Q6: NAN | R6: NAN | S6: -0.1 | T6: 0.4 | U6: 1 | V6: NAN | W6: 0.32 | X6: 0.044 | Y6: NAN | Z6: NAN | AA6: NAN | AB6: NAN | AC6: NAN | AD6: NAN | AE6: NAN | AF6: NAN | AG6: 5.18
A7: P1 | B7: 43468 | C7: 2019003 | D7: 0.43 | E7: NAN | F7: -3.4 | G7: 0.5 | H7: -7.1 | I7: 93.8 | J7: 90.9 | K7: 0.1 | L7: 2.3 | M7: 2 | N7: 0.669 | O7: -0.9 | P7: NAN | Q7: NAN | R7: NAN | S7: 0 | T7: 0.5 | U7: 1.1 | V7: NAN | W7: 0.573 | X7: 0.057 | Y7: NAN | Z7: NAN | AA7: NAN | AB7: NAN | AC7: NAN | AD7: NAN | AE7: NAN | AF7: NAN | AG7: 5.22
A8: P1 | B8: 43469 | C8: 2019004 | D8: 3.19 | E8: NAN | F8: -3 | G8: 0.8 | H8: -9.9 | I8: 89 | J8: 74 | K8: 0.1 | L8: 2.6 | M8: 0 | N8: 0.641 | O8: -0.8 | P8: NAN | Q8: NAN | R8: NAN | S8: -0.1 | T8: 0.5 | U8: 1.1 | V8: NAN | W8: 0.477 | X8: 0.168 | Y8: NAN | Z8: NAN | AA8: NAN | AB8: NAN | AC8: NAN | AD8: NAN | AE8: NAN | AF8: NAN | AG8: 5.27
A9: P1 | B9: 43470 | C9: 2019005 | D9: 2.04 | E9: NAN | F9: -2.3 | G9: 0.6 | H9: -6.9 | I9: 88.6 | J9: 79.1 | K9: 0 | L9: 1 | M9: 0 | N9: 0.642 | O9: -0.9 | P9: NAN | Q9: NAN | R9: NAN | S9: 0 | T9: 0.5 | U9: 1.1 | V9: NAN | W9: 0.503 | X9: 0.133 | Y9: NAN | Z9: NAN | AA9: NAN | AB9: NAN | AC9: NAN | AD9: NAN | AE9: NAN | AF9: NAN | AG9: 5.32
A10: P1 | B10: 43471 | C10: 2019006 | D10: 3.15 | E10: NAN | F10: -5.2 | G10: -1.2 | H10: -14.2 | I10: 83.9 | J10: 63.2 | K10: 0 | L10: 1.6 | M10: 0 | N10: 0.635 | O10: -0.8 | P10: NAN | Q10: NAN | R10: NAN | S10: -0.1 | T10: 0.4 | U10: 1 | V10: NAN | W10: 0.353 | X10: 0.206 | Y10: NAN | Z10: NAN | AA10: NAN | AB10: NAN | AC10: NAN | AD10: NAN | AE10: NAN | AF10: NAN | AG10: 5.37
A11: P1 | B11: 43472 | C11: 2019007 | D11: 3.11 | E11: NAN | F11: -9.6 | G11: -4.8 | H11: -18.2 | I11: 79.4 | J11: 55.5 | K11: 0 | L11: 1.7 | M11: 0.6 | N11: 0.632 | O11: -1.1 | P11: NAN | Q11: NAN | R11: NAN | S11: -0.1 | T11: 0.4 | U11: 1 | V11: NAN | W11: 0.237 | X11: 0.19 | Y11: NAN | Z11: NAN | AA11: NAN | AB11: NAN | AC11: NAN | AD11: NAN | AE11: NAN | AF11: NAN | AG11: 5.43
A12: P1 | B12: 43473 | C12: 2019008 | D12: 1.75 | E12: NAN | F12: -10.6 | G12: -6 | H12: -19.1 | I12: 79.2 | J12: 40.2 | K12: 0.1 | L12: 1.1 | M12: 3.2 | N12: 0.66 | O12: -1.5 | P12: NAN | Q12: NAN | R12: NAN | S12: -0.1 | T12: 0.4 | U12: 1 | V12: NAN | W12: 0.157 | X12: 0.234 | Y12: NAN | Z12: NAN | AA12: NAN | AB12: NAN | AC12: NAN | AD12: NAN | AE12: NAN | AF12: NAN | AG12: 5.49
A13: P1 | B13: 43474 | C13: 2019009 | D13: 0.74 | E13: NAN | F13: -2.1 | G13: 0.6 | H13: -6.1 | I13: 91.9 | J13: 87.5 | K13: 0.2 | L13: 2.3 | M13: 0 | N13: 0.659 | O13: -1.5 | P13: NAN | Q13: NAN | R13: NAN | S13: -0.1 | T13: 0.5 | U13: 1 | V13: NAN | W13: 0.557 | X13: 0.08 | Y13: NAN | Z13: NAN | AA13: NAN | AB13: NAN | AC13: NAN | AD13: NAN | AE13: NAN | AF13: NAN | AG13: 5.56
A14: P1 | B14: 43475 | C14: 2019010 | D14: 3.29 | E14: NAN | F14: -1.4 | G14: 2.1 | H14: -3.7 | I14: 94.4 | J14: 81.8 | K14: 0.3 | L14: 1.5 | M14: 0 | N14: 0.643 | O14: -1.1 | P14: NAN | Q14: NAN | R14: NAN | S14: -0.1 | T14: 0.5 | U14: 1 | V14: NAN | W14: 0.58 | X14: 0.129 | Y14: NAN | Z14: NAN | AA14: NAN | AB14: NAN | AC14: NAN | AD14: NAN | AE14: NAN | AF14: NAN | AG14: 5.63
A15: P1 | B15: 43476 | C15: 2019011 | D15: 2.75 | E15: NAN | F15: -2.3 | G15: 0.5 | H15: -4.1 | I15: 93.2 | J15: 89.6 | K15: 0.5 | L15: 1.8 | M15: 0 | N15: 0.623 | O15: -0.9 | P15: NAN | Q15: NAN | R15: NAN | S15: 0 | T15: 0.4 | U15: 1 | V15: NAN | W15: 0.567 | X15: 0.066 | Y15: NAN | Z15: NAN | AA15: NAN | AB15: NAN | AC15: NAN | AD15: NAN | AE15: NAN | AF15: NAN | AG15: 5.7
A16: P1 | B16: 43477 | C16: 2019012 | D16: 3.83 | E16: NAN | F16: -3.8 | G16: 0.7 | H16: -8.5 | I16: 88.1 | J16: 74.3 | K16: 0.2 | L16: 1.3 | M16: 0 | N16: 0.626 | O16: -0.9 | P16: NAN | Q16: NAN | R16: NAN | S16: 0 | T16: 0.4 | U16: 1 | V16: NAN | W16: 0.476 | X16: 0.165 | Y16: NAN | Z16: NAN | AA16: NAN | AB16: NAN | AC16: NAN | AD16: NAN | AE16: NAN | AF16: NAN | AG16: 5.77
... A24: P1 | B24: 43485 | C24: 2019020 | D24: 2.95 | E24: NAN | F24: -8.2 | G24: -2.8 | H24: -12.7 | I24: 88 | J24: 75.1 | K24: 0 | L24: 0 | M24: 0 | N24: 0.645 | O24: -1.1 | P24: NAN | Q24: NAN | R24: NAN | S24: -0.1 | T24: 0.4 | U24: 0.9 | V24: NAN | W24: 0.374 | X24: 0.124 | Y24: NAN | Z24: NAN | AA24: NAN | AB24: NAN | AC24: NAN | AD24: NAN | AE24: NAN | AF24: NAN | AG24: 6.51
A25: P1 | B25: 43486 | C25: 2019021 | D25: 1.21 | E25: NAN | F25: -9.6 | G25: -4.7 | H25: -15.7 | I25: 84.9 | J25: 76.4 | K25: 0 | L25: 0.5 | M25: 0 | N25: 0.639 | O25: -1.5 | P25: -13.2 | Q25: -6.3 | R25: -19.3 | S25: -0.1 | T25: 0.4 | U25: 0.9 | V25: NAN | W25: 0.328 | X25: 0.101 | Y25: NAN | Z25: NAN | AA25: NAN | AB25: NAN | AC25: NAN | AD25: NAN | AE25: NAN | AF25: NAN | AG25: 6.61
A26: P1 | B26: 43487 | C26: 2019022 | D26: 0.42 | E26: NAN | F26: -7.5 | G26: -5.9 | H26: -12.8 | I26: 90.4 | J26: 85.7 | K26: 0 | L26: 0 | M26: 12.4 | N26: 0.742 | O26: -1.7 | P26: -9.2 | Q26: -6.9 | R26: -15.5 | S26: -0.1 | T26: 0.4 | U26: 0.9 | V26: NAN | W26: 0.337 | X26: 0.056 | Y26: NAN | Z26: NAN | AA26: NAN | AB26: NAN | AC26: NAN | AD26: NAN | AE26: NAN | AF26: NAN | AG26: 6.73
A27: P1 | B27: 43488 | C27: 2019023 | D27: 0.99 | E27: NAN | F27: -5.8 | G27: -1.4 | H27: -10.4 | I27: 89.6 | J27: 80.5 | K27: 0 | L27: 1.4 | M27: 9.2 | N27: 0.815 | O27: -1.6 | P27: NAN | Q27: NAN | R27: NAN | S27: -0.1 | T27: 0.4 | U27: 0.9 | V27: NAN | W27: 0.444 | X27: 0.108 | Y27: NAN | Z27: NAN | AA27: NAN | AB27: NAN | AC27: NAN | AD27: NAN | AE27: NAN | AF27: NAN | AG27: 6.84
A28: P1 | B28: 43489 | C28: 2019024 | D28: 4.65 | E28: NAN | F28: -3.6 | G28: 2.4 | H28: -10.5 | I28: 82 | J28: 50.4 | K28: 0 | L28: 1.7 | M28: 0 | N28: 0.785 | O28: -1.4 | P28: NAN | Q28: NAN | R28: NAN | S28: -0.1 | T28: 0.4 | U28: 0.9 | V28: NAN | W28: 0.367 | X28: 0.361 | Y28: NAN | Z28: NAN | AA28: NAN | AB28: NAN | AC28: NAN | AD28: NAN | AE28: NAN | AF28: NAN | AG28: 6.96
A29: P1 | B29: 43490 | C29: 2019025 | D29: 5.68 | E29: NAN | F29: -2 | G29: 3.5 | H29: -8.9 | I29: 79.9 | J29: 56.1 | K29: 0.1 | L29: 1.8 | M29: 0 | N29: 0.768 | O29: -1.3 | P29: NAN | Q29: NAN | R29: NAN | S29: -0.1 | T29: 0.4 | U29: 0.9 | V29: NAN | W29: 0.441 | X29: 0.345 | Y29: NAN | Z29: NAN | AA29: NAN | AB29: NAN | AC29: NAN | AD29: NAN | AE29: NAN | AF29: NAN | AG29: 7.09
A30: P1 | B30: 43491 | C30: 2019026 | D30: 6.17 | E30: NAN | F30: -0.2 | G30: 10.3 | H30: -6.2 | I30: 84.1 | J30: 45.4 | K30: 0 | L30: 0.8 | M30: 0 | N30: 0.754 | O30: -1.2 | P30: NAN | Q30: NAN | R30: NAN | S30: -0.1 | T30: 0.4 | U30: 0.9 | V30: NAN | W30: 0.569 | X30: 0.684 | Y30: NAN | Z30: NAN | AA30: NAN | AB30: NAN | AC30: NAN | AD30: NAN | AE30: NAN | AF30: NAN | AG30: 7.21
A31: P1 | B31: 43492 | C31: 2019027 | D31: 6.58 | E31: NAN | F31: -0.8 | G31: 4.6 | H31: -12.6 | I31: 62.7 | J31: 43.3 | K31: 0 | L31: 1.1 | M31: 2.5 | N31: 0.764 | O31: -1 | P31: NAN | Q31: NAN | R31: NAN | S31: -0.1 | T31: 0.4 | U31: 0.9 | V31: NAN | W31: 0.367 | X31: 0.481 | Y31: NAN | Z31: NAN | AA31: NAN | AB31: NAN | AC31: NAN | AD31: NAN | AE31: NAN | AF31: NAN | AG31: 7.34
A32: P1 | B32: 43493 | C32: 2019028 | D32: 4.97 | E32: NAN | F32: -10.2 | G32: -0.9 | H32: -15.8 | I32: 76.6 | J32: 38 | K32: 0 | L32: 0.5 | M32: 0 | N32: 0.747 | O32: -1 | P32: NAN | Q32: NAN | R32: NAN | S32: -0.1 | T32: 0.3 | U32: 0.8 | V32: NAN | W32: 0.217 | X32: 0.354 | Y32: NAN | Z32: NAN | AA32: NAN | AB32: NAN | AC32: NAN | AD32: NAN | AE32: NAN | AF32: NAN | AG32: 7.47
A33: P1 | B33: 43494 | C33: 2019029 | D33: 6.85 | E33: NAN | F33: -9.9 | G33: 4.2 | H33: -17.9 | I33: 65.8 | J33: 14 | K33: 0 | L33: 0.5 | M33: 0 | N33: 0.735 | O33: -1.3 | P33: NAN | Q33: NAN | R33: NAN | S33: -0.1 | T33: 0.3 | U33: 0.8 | V33: NAN | W33: 0.115 | X33: 0.706 | Y33: NAN | Z33: NAN | AA33: NAN | AB33: NAN | AC33: NAN | AD33: NAN | AE33: NAN | AF33: NAN | AG33: 7.61
A34: P1 | B34: 43495 | C34: 2019030 | D34: 3.84 | E34: NAN | F34: -4.6 | G34: 4 | H34: -14.4 | I34: 66.1 | J34: 29.8 | K34: 0.1 | L34: 1.9 | M34: 0 | N34: 0.737 | O34: -1.6 | P34: NAN | Q34: NAN | R34: NAN | S34: -0.1 | T34: 0.4 | U34: 0.9 | V34: NAN | W34: 0.242 | X34: 0.57 | Y34: NAN | Z34: NAN | AA34: NAN | AB34: NAN | AC34: NAN | AD34: NAN | AE34: NAN | AF34: NAN | AG34: 7.75
A35: P1 | B35: 43496 | C35: 2019031 | D35: 2.58 | E35: NAN | F35: -2.7 | G35: 1.7 | H35: -5.2 | I35: 74.7 | J35: 56.7 | K35: 0.1 | L35: 1.1 | M35: 0 | N35: 0.721 | O35: -1.5 | P35: NAN | Q35: NAN | R35: NAN | S35: -0.1 | T35: 0.4 | U35: 0.9 | V35: NAN | W35: 0.392 | X35: 0.299 | Y35: NAN | Z35: NAN | AA35: NAN | AB35: NAN | AC35: NAN | AD35: NAN | AE35: NAN | AF35: NAN | AG35: 7.9
A36: P1 | B36: 43497 | C36: 2019032 | D36: 4.09 | E36: NAN | F36: -2.2 | G36: 0.7 | H36: -4.2 | I36: 86 | J36: 69.4 | K36: 0.3 | L36: 2 | M36: 0 | N36: 0.719 | O36: -1.2 | P36: NAN | Q36: NAN | R36: NAN | S36: -0.1 | T36: 0.4 | U36: 0.9 | V36: NAN | W36: 0.444 | X36: 0.196 | Y36: NAN | Z36: NAN | AA36: NAN | AB36: NAN | AC36: NAN | AD36: NAN | AE36: NAN | AF36: NAN | AG36: 8.04
A37: P1 | B37: 43498 | C37: 2019033 | D37: 5.78 | E37: NAN | F37: -3.8 | G37: 0.9 | H37: -11.2 | I37: 78.9 | J37: 52.4 | K37: 0.4 | L37: 2.9 | M37: 2.7 | N37: 0.751 | O37: -1 | P37: NAN | Q37: NAN | R37: NAN | S37: -0.1 | T37: 0.3 | U37: 0.9 | V37: NAN | W37: 0.341 | X37: 0.31 | Y37: NAN | Z37: NAN | AA37: NAN | AB37: NAN | AC37: NAN | AD37: NAN | AE37: NAN | AF37: NAN | AG37: 8.2
A38: P1 | B38: 43499 | C38: 2019034 | D38: 5.26 | E38: NAN | F38: -15.5 | G38: -8.5 | H38: -23.9 | I38: 77.9 | J38: 61 | K38: 0.2 | L38: 2.4 | M38: 0 | N38: 0.74 | O38: -1 | P38: NAN | Q38: NAN | R38: NAN | S38: -0.1 | T38: 0.3 | U38: 0.8 | V38: NAN | W38: 0.196 | X38: 0.125 | Y38: NAN | Z38: NAN | AA38: NAN | AB38: NAN | AC38: NAN | AD38: NAN | AE38: NAN | AF38: NAN | AG38: 8.35
... A133: P1 | B133: 43594 | C133: 2019129 | D133: 28.73 | E133: NAN | F133: 8.1 | G133: 17.9 | H133: -2.4 | I133: 54.2 | J133: 21.7 | K133: 0.5 | L133: 2.6 | M133: 0 | N133: 0.018 | O133: 0 | P133: NAN | Q133: NAN | R133: NAN | S133: 0 | T133: 0.2 | U133: 0.4 | V133: NAN | W133: 0.444 | X133: 1.602 | Y133: NAN | Z133: NAN | AA133: NAN | AB133: NAN | AC133: NAN | AD133: NAN | AE133: NAN | AF133: NAN | AG133: 29.94
A134: P1 | B134: 43595 | C134: 2019130 | D134: 25.52 | E134: NAN | F134: 10.2 | G134: 20 | H134: -0.9 | I134: 59.1 | J134: 30.9 | K134: 0.2 | L134: 2.2 | M134: 0 | N134: 0 | O134: NAN | P134: NAN | Q134: NAN | R134: NAN | S134: 0.5 | T134: 0.6 | U134: 0.5 | V134: NAN | W134: 0.723 | X134: 1.617 | Y134: NAN | Z134: NAN | AA134: NAN | AB134: NAN | AC134: NAN | AD134: NAN | AE134: NAN | AF134: NAN | AG134: 30.1
A135: P1 | B135: 43596 | C135: 2019131 | D135: 23.58 | E135: NAN | F135: 12.6 | G135: 21.5 | H135: 0.4 | I135: 53.4 | J135: 26.9 | K135: 0.7 | L135: 3.2 | M135: 0 | N135: 0 | O135: NAN | P135: NAN | Q135: NAN | R135: NAN | S135: 9.4 | T135: 3.6 | U135: 1.2 | V135: NAN | W135: 0.691 | X135: 1.878 | Y135: NAN | Z135: NAN | AA135: NAN | AB135: NAN | AC135: NAN | AD135: NAN | AE135: NAN | AF135: NAN | AG135: 30.26
A136: P1 | B136: 43597 | C136: 2019132 | D136: 28.92 | E136: NAN | F136: 12.3 | G136: 19.9 | H136: 2 | I136: 39.5 | J136: 19.2 | K136: 1.1 | L136: 3.4 | M136: 0 | N136: 0 | O136: NAN | P136: NAN | Q136: NAN | R136: NAN | S136: 11.5 | T136: 6.5 | U136: 2.5 | V136: NAN | W136: 0.446 | X136: 1.877 | Y136: NAN | Z136: NAN | AA136: NAN | AB136: NAN | AC136: NAN | AD136: NAN | AE136: NAN | AF136: NAN | AG136: 30.41
A137: P1 | B137: 43598 | C137: 2019133 | D137: 23.54 | E137: NAN | F137: 10 | G137: 18.1 | H137: -1.2 | I137: 46.7 | J137: 25.3 | K137: 0.8 | L137: 3.1 | M137: 0 | N137: 0 | O137: NAN | P137: NAN | Q137: NAN | R137: NAN | S137: 11.1 | T137: 7.3 | U137: 3.6 | V137: NAN | W137: 0.524 | X137: 1.547 | Y137: NAN | Z137: NAN | AA137: NAN | AB137: NAN | AC137: NAN | AD137: NAN | AE137: NAN | AF137: NAN | AG137: 30.57
A138: P1 | B138: 43599 | C138: 2019134 | D138: 8.52 | E138: NAN | F138: 5.3 | G138: 12.1 | H138: -1.4 | I138: 78.9 | J138: 41.6 | K138: 0.7 | L138: 3.1 | M138: 9.7 | N138: 0 | O138: NAN | P138: NAN | Q138: NAN | R138: NAN | S138: 6.5 | T138: 6.3 | U138: 4.3 | V138: NAN | W138: 0.586 | X138: 0.823 | Y138: NAN | Z138: NAN | AA138: NAN | AB138: NAN | AC138: NAN | AD138: NAN | AE138: NAN | AF138: NAN | AG138: 30.71
A139: P1 | B139: 43600 | C139: 2019135 | D139: 27.41 | E139: NAN | F139: 7.4 | G139: 15.1 | H139: -1.7 | I139: 68.2 | J139: 35.6 | K139: 0.7 | L139: 2.7 | M139: 0 | N139: 0 | O139: NAN | P139: NAN | Q139: NAN | R139: NAN | S139: 10.4 | T139: 6.4 | U139: 4.2 | V139: NAN | W139: 0.611 | X139: 1.105 | Y139: NAN | Z139: NAN | AA139: NAN | AB139: NAN | AC139: NAN | AD139: NAN | AE139: NAN | AF139: NAN | AG139: 30.86
A140: P1 | B140: 43601 | C140: 2019136 | D140: 11.19 | E140: NAN | F140: 8 | G140: 12.2 | H140: 5.5 | I140: 90.5 | J140: 69 | K140: 0.6 | L140: 2.5 | M140: 5.1 | N140: 0 | O140: NAN | P140: NAN | Q140: NAN | R140: NAN | S140: 10.6 | T140: 7.6 | U140: 4.7 | V140: NAN | W140: 0.979 | X140: 0.44 | Y140: NAN | Z140: NAN | AA140: NAN | AB140: NAN | AC140: NAN | AD140: NAN | AE140: NAN | AF140: NAN | AG140: 31
A141: P1 | B141: 43602 | C141: 2019137 | D141: 10.86 | E141: NAN | F141: 5.3 | G141: 7.6 | H141: 0.5 | I141: 85.7 | J141: 68.4 | K141: 1 | L141: 3.2 | M141: 4.8 | N141: 0 | O141: NAN | P141: NAN | Q141: NAN | R141: NAN | S141: 8.9 | T141: 7.5 | U141: 5.1 | V141: NAN | W141: 0.715 | X141: 0.33 | Y141: NAN | Z141: NAN | AA141: NAN | AB141: NAN | AC141: NAN | AD141: NAN | AE141: NAN | AF141: NAN | AG141: 31.14
...

Sheet Graph
A1: Daily time series | C1: 1 | D1: =C1+1 -> 2 | E1: =D1+1 -> 3 | F1: =E1+1 -> 4 | G1: =F1+1 -> 5 | H1: =G1+1 -> 6 | I1: =H1+1 -> 7 | J1: =I1+1 -> 8 | K1: =J1+1 -> 9 | ... AG1: =AF1+1 -> 31
A2: Last edit 29/12/25 | C2: Key1 | D2: Solar | E2: Reflect | F2: Tave | G2: Tmax | H2: Tmin | I2: RHave | J2: RHmin | K2: Wind | L2: WindMax | M2: Precip | N2: SnowD | O2: Tsnow | P2: IRTSurfA | Q2: IRTSurX | R2: IRTSurmin | S2: Tsoil005 | T2: Tsoil15 | U2: Tsoil50 | V2: SoilH2O | W2: Vapres | X2: vpdX | Y2: Wind Direction (fraction of day) | Z2: Wind Direction (fraction of day) | AA2: Wind Direction (fraction of day) | AB2: Wind Direction (fraction of day) | AC2: Wind Direction (fraction of day) | AD2: Wind Direction (fraction of day) | AE2: Wind Direction (fraction of day) | AF2: Wind Direction (fraction of day) | AG2: ClrSky
C3: Key1 | D3: MJ/m2/d | E3: MJ/m2/d | F3: C | G3: C | H3: C | I3: % | J3: % | K3: m/s | L3: m/s | M3: mm | N3: m | O3: C | P3: C | Q3: C | R3: C | S3: C | T3: C | U3: C | V3: m3/m3 | W3: kPa | X3: kPa | Y3: N-NE | Z3: NE-E | AA3: E-SE | AB3: SE-S | AC3: S-SW | AD3: SW-W | AE3: W-NW | AF3: NW-N | AG3: MJ/m2/d
E4: Select col# | F4: 5 | G4: 6 | H4: Units
A5: Key1 | B5: =F5 -> Tmax | C5: =G5 -> Tmin | F5: =VLOOKUP($A5,Graph!$C2:$AF2,F4) -> Tmax | G5: =VLOOKUP($A5,Graph!$C2:$AG2,G4) -> Tmin | H5: =VLOOKUP($A5,Graph!$C3:$AF3,F4) -> C | I5: =VLOOKUP($A5,Graph!$C3:$AG3,G4) -> C
A7: 2019001 | B7: =VLOOKUP($A7,Data!$C$5:$AG$2561,F$4) -> -0.7 | C7: =VLOOKUP($A7,Data!$C$5:$AG$2561,G$4) -> -9.5
A8: 2019002 | B8: =VLOOKUP($A8,Data!$C$5:$AG$2561,F$4) -> -6.9 | C8: =VLOOKUP($A8,Data!$C$5:$AG$2561,G$4) -> -9.6
A9: 2019003 | B9: =VLOOKUP($A9,Data!$C$5:$AG$2561,F$4) -> 0.5 | C9: =VLOOKUP($A9,Data!$C$5:$AG$2561,G$4) -> -7.1
A10: 2019004 | B10: =VLOOKUP($A10,Data!$C$5:$AG$2561,F$4) -> 0.8 | C10: =VLOOKUP($A10,Data!$C$5:$AG$2561,G$4) -> -9.9
A11: 2019005 | B11: =VLOOKUP($A11,Data!$C$5:$AG$2561,F$4) -> 0.6 | C11: =VLOOKUP($A11,Data!$C$5:$AG$2561,G$4) -> -6.9
A12: 2019006 | B12: =VLOOKUP($A12,Data!$C$5:$AG$2561,F$4) -> -1.2 | C12: =VLOOKUP($A12,Data!$C$5:$AG$2561,G$4) -> -14.2
A13: 2019007 | B13: =VLOOKUP($A13,Data!$C$5:$AG$2561,F$4) -> -4.8 | C13: =VLOOKUP($A13,Data!$C$5:$AG$2561,G$4) -> -18.2
A14: 2019008 | B14: =VLOOKUP($A14,Data!$C$5:$AG$2561,F$4) -> -6 | C14: =VLOOKUP($A14,Data!$C$5:$AG$2561,G$4) -> -19.1
A15: 2019009 | B15: =VLOOKUP($A15,Data!$C$5:$AG$2561,F$4) -> 0.6 | C15: =VLOOKUP($A15,Data!$C$5:$AG$2561,G$4) -> -6.1
A16: 2019010 | B16: =VLOOKUP($A16,Data!$C$5:$AG$2561,F$4) -> 2.1 | C16: =VLOOKUP($A16,Data!$C$5:$AG$2561,G$4) -> -3.7
A17: 2019011 | B17: =VLOOKUP($A17,Data!$C$5:$AG$2561,F$4) -> 0.5 | C17: =VLOOKUP($A17,Data!$C$5:$AG$2561,G$4) -> -4.1
A18: 2019012 | B18: =VLOOKUP($A18,Data!$C$5:$AG$2561,F$4) -> 0.7 | C18: =VLOOKUP($A18,Data!$C$5:$AG$2561,G$4) -> -8.5
... A2563: 2025365 | B2563: =VLOOKUP($A2563,Data!$C$5:$AG$2561,F$4) -> NAN | C2563: =VLOOKUP($A2563,Data!$C$5:$AG$2561,G$4) -> NAN

Sheet Meta
A1: P1 Daily data 2019 -2025
A2: Last edit 17/12/25
A4: Data worksheet
B5: Data source is daily spreadsheets by year.
C6: Data edits are noted in these spreadsheets
B7: NAN indicates missing data
B8: Clear sky radiation calculated on 10 min time step for lat, long and elevation of site
A10: Graph worksheet
B11: Select one or a pair of variables to review using column number of desired variable
B12: Chose 0 for second variable if only showing one.
