Workbook

Sheet Data
A1: Penticton Creek Site PL and Geonor 2019-2025 Daily data
A2: Last edit 30/12/25
A3: Site | B3: Date | C3: Key | D3: Solar | E3: Tave | F3: Tmax | G3: Tmin | H3: RHMax | I3: RHAve | J3: RHMin | K3: Wind | L3: WindMax | M3: PPT_PL | N3: SnwD2400 | O3: vol10_2400 | P3: vol20_2400 | Q3: vpres | R3: vpdX | S3: Geonor | T3: Sum_PL | U3: SumGeonor | V3: ClrSky
D4: MJ/m2/d | E4: C | F4: C | G4: C | H4: % | I4: % | J4: % | K4: m/s | L4: m/s | M4: mm | N4: m | O4: m3/m3 | P4: m3/m3 | Q4: kPa | R4: kPa | S4: mm | T4: mm | U4: mm | V4: MJ/m2/d
A5: PL_Geonor | B5: 43466 | C5: 2019001 | D5: 2.34 | E5: -5.7 | F5: -3.3 | G5: -9.1 | H5: 98.5 | I5: 93.2 | J5: 79.2 | K5: 0.75 | L5: 5.03 | M5: NAN | N5: NAN | O5: 0.19 | P5: 0.201 | Q5: 0.379 | R5: 0.1 | S5: NAN | T5: NAN | U5: NAN | V5: 5.18
A6: PL_Geonor | B6: 43467 | C6: 2019002 | D6: 1.42 | E6: -5.2 | F6: -1.2 | G6: -9.5 | H6: 98.6 | I6: 96.8 | J6: 93.9 | K6: 1.85 | L6: 9.56 | M6: NAN | N6: NAN | O6: 0.191 | P6: 0.201 | Q6: 0.525 | R6: 0.034 | S6: NAN | T6: NAN | U6: NAN | V6: 5.22
A7: PL_Geonor | B7: 43468 | C7: 2019003 | D7: 1.76 | E7: -3.7 | F7: -1.2 | G7: -8.1 | H7: 100 | I7: 99.8 | J7: 98.4 | K7: 1.55 | L7: 6.04 | M7: NAN | N7: NAN | O7: 0.191 | P7: 0.202 | Q7: 0.55 | R7: 0.009 | S7: NAN | T7: NAN | U7: NAN | V7: 5.26
A8: PL_Geonor | B8: 43469 | C8: 2019004 | D8: 4.69 | E8: -3.4 | F8: -1.4 | G8: -5.6 | H8: 100 | I8: 95.7 | J8: 87.6 | K8: 1.36 | L8: 8.56 | M8: NAN | N8: NAN | O8: 0.191 | P8: 0.202 | Q8: 0.483 | R8: 0.068 | S8: NAN | T8: NAN | U8: NAN | V8: 5.31
A9: PL_Geonor | B9: 43470 | C9: 2019005 | D9: 2.25 | E9: -4.3 | F9: -3.1 | G9: -5.4 | H9: 100 | I9: 99.5 | J9: 96.6 | K9: 2.83 | L9: 12.08 | M9: NAN | N9: NAN | O9: 0.191 | P9: 0.203 | Q9: 0.469 | R9: 0.017 | S9: NAN | T9: NAN | U9: NAN | V9: 5.36
A10: PL_Geonor | B10: 43471 | C10: 2019006 | D10: 5.16 | E10: -6.3 | F10: -3.8 | G10: -10.4 | H10: 100 | I10: 96.4 | J10: 82 | K10: 3.02 | L10: 11.58 | M10: NAN | N10: NAN | O10: 0.191 | P10: 0.204 | Q10: 0.378 | R10: 0.083 | S10: NAN | T10: NAN | U10: NAN | V10: 5.41
A11: PL_Geonor | B11: 43472 | C11: 2019007 | D11: 5.99 | E11: -10.1 | F11: -7.6 | G11: -15.1 | H11: 98.6 | I11: 91.5 | J11: 76.2 | K11: 3.06 | L11: 14.09 | M11: NAN | N11: NAN | O11: 0.191 | P11: 0.204 | Q11: 0.263 | R11: 0.082 | S11: NAN | T11: NAN | U11: NAN | V11: 5.47
A12: PL_Geonor | B12: 43473 | C12: 2019008 | D12: 2.07 | E12: -11.4 | F12: -8.5 | G12: -15.4 | H12: 96.8 | I12: 83.8 | J12: 57.8 | K12: 3.9 | L12: 12.08 | M12: NAN | N12: NAN | O12: 0.191 | P12: 0.204 | Q12: 0.186 | R12: 0.136 | S12: NAN | T12: NAN | U12: NAN | V12: 5.53
A13: PL_Geonor | B13: 43474 | C13: 2019009 | D13: 1.58 | E13: -4.1 | F13: -1.4 | G13: -7.6 | H13: 100 | I13: 99.5 | J13: 97.3 | K13: 2.43 | L13: 8.05 | M13: NAN | N13: NAN | O13: 0.191 | P13: 0.204 | Q13: 0.536 | R13: 0.015 | S13: NAN | T13: NAN | U13: NAN | V13: 5.6
A14: PL_Geonor | B14: 43475 | C14: 2019010 | D14: 3.71 | E14: -2.7 | F14: 0.2 | G14: -4.4 | H14: 100 | I14: 100 | J14: 99.8 | K14: 1.34 | L14: 6.54 | M14: NAN | N14: NAN | O14: 0.191 | P14: 0.203 | Q14: 0.618 | R14: 0.001 | S14: NAN | T14: NAN | U14: NAN | V14: 5.67
A15: PL_Geonor | B15: 43476 | C15: 2019011 | D15: 3.01 | E15: -3.6 | F15: -1.2 | G15: -4.9 | H15: 100 | I15: 100 | J15: 100 | K15: 1.49 | L15: 6.04 | M15: NAN | N15: NAN | O15: 0.191 | P15: 0.204 | Q15: 0.559 | R15: 0 | S15: NAN | T15: NAN | U15: NAN | V15: 5.74
A16: PL_Geonor | B16: 43477 | C16: 2019012 | D16: 5.25 | E16: -3.4 | F16: -1.1 | G16: -4.6 | H16: 100 | I16: 97.7 | J16: 84.3 | K16: 2.52 | L16: 7.55 | M16: NAN | N16: NAN | O16: 0.191 | P16: 0.204 | Q16: 0.475 | R16: 0.088 | S16: NAN | T16: NAN | U16: NAN | V16: 5.82
... A73: PL_Geonor | B73: 43534 | C73: 2019069 | D73: 16.45 | E73: -8.2 | F73: -1 | G73: -14.5 | H73: 92.3 | I73: 77.3 | J73: 56.1 | K73: 1.22 | L73: 6.04 | M73: NAN | N73: NAN | O73: 0.19 | P73: 0.199 | Q73: 0.318 | R73: 0.249 | S73: NAN | T73: NAN | U73: NAN | V73: 15.88
A74: PL_Geonor | B74: 43535 | C74: 2019070 | D74: 6.96 | E74: -8.4 | F74: -6.2 | G74: -10.4 | H74: 91 | I74: 79 | J74: 65.2 | K74: 4.07 | L74: 11.58 | M74: NAN | N74: 0.866 | O74: 0.189 | P74: 0.199 | Q74: 0.25 | R74: 0.133 | S74: NAN | T74: NAN | U74: NAN | V74: 16.13
A75: PL_Geonor | B75: 43536 | C75: 2019071 | D75: 7.13 | E75: -7.2 | F75: -5.8 | G75: -9.6 | H75: 96.3 | I75: 95.2 | J75: 91.4 | K75: 1.8 | L75: 10.57 | M75: 1.6 | N75: 0.878 | O75: 0.189 | P75: 0.199 | Q75: 0.362 | R75: 0.034 | S75: NAN | T75: =M75 -> 1.6 | U75: NAN | V75: 16.39
A76: PL_Geonor | B76: 43537 | C76: 2019072 | D76: 13.77 | E76: -7.7 | F76: -2.5 | G76: -11 | H76: 94.8 | I76: 80 | J76: 54.5 | K76: 1.72 | L76: 8.56 | M76: 1.8 | N76: 0.892 | O76: 0.189 | P76: 0.199 | Q76: 0.277 | R76: 0.231 | S76: NAN | T76: =M76+T75 -> 3.4 | U76: NAN | V76: 16.64
A77: PL_Geonor | B77: 43538 | C77: 2019073 | D77: 12.92 | E77: -5.2 | F77: -0.9 | G77: -10.4 | H77: 87.1 | I77: 70.4 | J77: 50.5 | K77: 1.01 | L77: 6.54 | M77: 0 | N77: 0.879 | O77: 0.189 | P77: 0.199 | Q77: 0.289 | R77: 0.283 | S77: NAN | T77: =M77+T76 -> 3.4 | U77: NAN | V77: 16.9
A78: PL_Geonor | B78: 43539 | C78: 2019074 | D78: 12.54 | E78: -3 | F78: 2.3 | G78: -6 | H78: 89.8 | I78: 79.7 | J78: 56.6 | K78: 2.2 | L78: 9.06 | M78: 0 | N78: 0.84 | O78: 0.189 | P78: 0.199 | Q78: 0.408 | R78: 0.313 | S78: NAN | T78: =M78+T77 -> 3.4 | U78: NAN | V78: 17.16
A79: PL_Geonor | B79: 43540 | C79: 2019075 | D79: 16.25 | E79: -1.3 | F79: 4.3 | G79: -6.4 | H79: 89.5 | I79: 74.1 | J79: 49.4 | K79: 1.76 | L79: 5.54 | M79: 0 | N79: 0.838 | O79: 0.189 | P79: 0.199 | Q79: 0.41 | R79: 0.42 | S79: NAN | T79: =M79+T78 -> 3.4 | U79: NAN | V79: 17.42
A80: PL_Geonor | B80: 43541 | C80: 2019076 | D80: 17.96 | E80: 1.4 | F80: 5.9 | G80: -3.6 | H80: 86.4 | I80: 60.4 | J80: 39.6 | K80: 2.43 | L80: 9.06 | M80: 0 | N80: 0.809 | O80: 0.19 | P80: 0.202 | Q80: 0.368 | R80: 0.561 | S80: NAN | T80: =M80+T79 -> 3.4 | U80: NAN | V80: 17.68
A81: PL_Geonor | B81: 43542 | C81: 2019077 | D81: 18.39 | E81: 3.4 | F81: 8.4 | G81: -2.3 | H81: 61 | I81: 43.4 | J81: 24.3 | K81: 2.14 | L81: 9.56 | M81: 0 | N81: 0.771 | O81: 0.191 | P81: 0.21 | Q81: 0.268 | R81: 0.835 | S81: NAN | T81: =M81+T80 -> 3.4 | U81: NAN | V81: 17.94
A82: PL_Geonor | B82: 43543 | C82: 2019078 | D82: 18.55 | E82: 6 | F82: 11.3 | G82: 0.8 | H82: 51.1 | I82: 35.5 | J82: 25.7 | K82: 1.99 | L82: 7.05 | M82: 0 | N82: 0.702 | O82: 0.194 | P82: 0.232 | Q82: 0.344 | R82: 0.995 | S82: NAN | T82: =M82+T81 -> 3.4 | U82: NAN | V82: 18.2
A83: PL_Geonor | B83: 43544 | C83: 2019079 | D83: 18.83 | E83: 8 | F83: 12.4 | G83: 2.9 | H83: 39.8 | I83: 31 | J83: 22.5 | K83: 2.06 | L83: 9.06 | M83: 0 | N83: 0.652 | O83: 0.198 | P83: 0.249 | Q83: 0.324 | R83: 1.116 | S83: NAN | T83: =M83+T82 -> 3.4 | U83: NAN | V83: 18.47
A84: PL_Geonor | B84: 43545 | C84: 2019080 | D84: 18.53 | E84: 6.6 | F84: 11.9 | G84: 2.4 | H84: 50.3 | I84: 34.1 | J84: 24.4 | K84: 1.7 | L84: 6.04 | M84: 0 | N84: 0.629 | O84: 0.201 | P84: 0.263 | Q84: 0.34 | R84: 1.053 | S84: NAN | T84: =M84+T83 -> 3.4 | U84: NAN | V84: 18.73
A85: PL_Geonor | B85: 43546 | C85: 2019081 | D85: 18.58 | E85: 5.3 | F85: 9.8 | G85: 0.6 | H85: 90.2 | I85: 45.1 | J85: 30.5 | K85: 1.97 | L85: 7.55 | M85: 0 | N85: 0.602 | O85: 0.204 | P85: 0.276 | Q85: 0.369 | R85: 0.841 | S85: NAN | T85: =M85+T84 -> 3.4 | U85: NAN | V85: 18.99
A86: PL_Geonor | B86: 43547 | C86: 2019082 | D86: 7.52 | E86: 1.3 | F86: 3.9 | G86: -0.5 | H86: 97.1 | I86: 80.3 | J86: 63.6 | K86: 1.34 | L86: 5.54 | M86: 0 | N86: 0.594 | O86: 0.205 | P86: 0.265 | Q86: 0.513 | R86: 0.294 | S86: NAN | T86: =M86+T85 -> 3.4 | U86: NAN | V86: 19.25
A87: PL_Geonor | B87: 43548 | C87: 2019083 | D87: 8.45 | E87: 1.7 | F87: 5.6 | G87: -0.7 | H87: 99.2 | I87: 80.9 | J87: 62.3 | K87: 1.76 | L87: 7.05 | M87: 0.3 | N87: 0.596 | O87: 0.206 | P87: 0.268 | Q87: 0.566 | R87: 0.343 | S87: NAN | T87: =M87+T86 -> 3.7 | U87: NAN | V87: 19.52
... A369: PL_Geonor | B369: 43830 | C369: 2019365 | D369: 1.21 | E369: -3.7 | F369: -2 | G369: -6.9 | H369: 100 | I369: 99.8 | J369: 98.7 | K369: 0 | L369: 1.01 | M369: 12.4 | N369: 0.67 | O369: 0.198 | P369: 0.207 | Q369: 0.52 | R369: 0.007 | S369: NAN | T369: =M369+T368 -> 452.41 | U369: NAN | V369: 5.13
A370: PL_Geonor | B370: 43831 | C370: 2020001 | D370: 2.3 | E370: -2.4 | F370: -1.2 | G370: -4.3 | H370: 100 | I370: 96.5 | J370: 86.4 | K370: 3.96 | L370: 14.59 | M370: 0 | N370: 0.642 | O370: 0.197 | P370: 0.207 | Q370: 0.483 | R370: 0.076 | S370: NAN | T370: =M370 -> 0 | U370: NAN | V370: 5.18
A371: PL_Geonor | B371: 43832 | C371: 2020002 | D371: 4.25 | E371: -8.1 | F371: -5.2 | G371: -9.2 | H371: 97.8 | I371: 95.9 | J371: 88.3 | K371: 2.41 | L371: 15.1 | M371: 30 | N371: 0.873 | O371: 0.197 | P371: 0.207 | Q371: 0.366 | R371: 0.048 | S371: NAN | T371: =M371+T370 -> 30 | U371: NAN | V371: 5.22
A372: PL_Geonor | B372: 43833 | C372: 2020003 | D372: 2.81 | E372: -3.9 | F372: -1 | G372: -7.3 | H372: 100 | I372: 97.8 | J372: 72.8 | K372: 0 | L372: 5.54 | M372: 0 | N372: 0.778 | O372: 0.199 | P372: 0.208 | Q372: 0.413 | R372: 0.154 | S372: NAN | T372: =M372+T371 -> 30 | U372: NAN | V372: 5.26
A373: PL_Geonor | B373: 43834 | C373: 2020004 | D373: 3.39 | E373: -5.9 | F373: -1.1 | G373: -7.4 | H373: 97.7 | I373: 80.9 | J373: 70.4 | K373: 3.82 | L373: 17.61 | M373: 0 | N373: 0.737 | O373: 0.199 | P373: 0.208 | Q373: 0.397 | R373: 0.167 | S373: NAN | T373: =M373+T372 -> 30 | U373: NAN | V373: 5.31
A374: PL_Geonor | B374: 43835 | C374: 2020005 | D374: 2.11 | E374: -7.5 | F374: -5.9 | G374: -8.9 | H374: 97.7 | I374: 92.6 | J374: 81.3 | K374: 3.96 | L374: 16.1 | M374: 0 | N374: 0.7 | O374: 0.198 | P374: 0.209 | Q374: 0.32 | R374: 0.074 | S374: NAN | T374: =M374+T373 -> 30 | U374: NAN | V374: 5.36
A375: PL_Geonor | B375: 43836 | C375: 2020006 | D375: 0.88 | E375: -6.8 | F375: -3 | G375: -9.4 | H375: 100 | I375: 96.5 | J375: 86 | K375: 1.03 | L375: 7.05 | M375: 12.1 | N375: 0.793 | O375: 0.199 | P375: 0.209 | Q375: 0.421 | R375: 0.069 | S375: NAN | T375: =M375+T374 -> 42.1 | U375: NAN | V375: 5.41
A376: PL_Geonor | B376: 43837 | C376: 2020007 | D376: 0.97 | E376: -2.5 | F376: -1.7 | G376: -3.4 | H376: 100 | I376: 100 | J376: 100 | K376: 1.05 | L376: 8.05 | M376: 1.4 | N376: 0.804 | O376: 0.199 | P376: 0.21 | Q376: 0.539 | R376: 0 | S376: NAN | T376: =M376+T375 -> 43.5 | U376: NAN | V376: 5.47
A377: PL_Geonor | B377: 43838 | C377: 2020008 | D377: 1.64 | E377: -8.7 | F377: -2.9 | G377: -15.9 | H377: 100 | I377: 97.4 | J377: 93.8 | K377: 1.38 | L377: 10.07 | M377: 42.3 | N377: 1.129 | O377: 0.199 | P377: 0.21 | Q377: 0.462 | R377: 0.031 | S377: NAN | T377: =M377+T376 -> 85.8 | U377: NAN | V377: 5.53
...

Sheet Graph
A1: Daily time series | C1: 1 | D1: =C1+1 -> 2 | E1: =D1+1 -> 3 | F1: =E1+1 -> 4 | G1: =F1+1 -> 5 | H1: =G1+1 -> 6 | I1: =H1+1 -> 7 | J1: =I1+1 -> 8 | K1: =J1+1 -> 9 | ... T1: =S1+1 -> 18 | U1: 19 | V1: 20
A2: Last edit 22/12/25 | C2: Key1 | D2: Solar | E2: Tave | F2: Tmax | G2: Tmin | H2: RHMax | I2: RHAve | J2: RHMin | K2: Wind | L2: WindMax | M2: PPT_PL | N2: SnwD2400 | O2: vol10_2400 | P2: vol20_2400 | Q2: vpres | R2: vpdX | S2: Geonor | T2: Sum_PL | U2: SumGeonor | V2: ClrSky
C3: Key1 | D3: MJ/m2/d | E3: C | F3: C | G3: C | H3: % | I3: % | J3: % | K3: m/s | L3: m/s | M3: mm | N3: m | O3: m3/m3 | P3: m3/m3 | Q3: kPa | R3: kPa | S3: mm | T3: mm | U3: mm | V3: MJ/m2/d
E4: Select col# | F4: 4 | G4: 5 | H4: Units
A5: Key1 | B5: =F5 -> Tmax | C5: =G5 -> Tmin | F5: =VLOOKUP($A5,Graph!$C2:$V2,F4) -> Tmax | G5: =VLOOKUP($A5,Graph!$C2:$V2,G4) -> Tmin | H5: =VLOOKUP($A5,Graph!$C3:$V3,F4) -> C | I5: =VLOOKUP($A5,Graph!$C3:$V3,G4) -> C
A7: 2019001 | B7: =VLOOKUP($A7,Data!$C$5:$V$2561,F$4) -> -3.3 | C7: =VLOOKUP($A7,Data!$C$5:$V$2561,G$4) -> -9.1
A8: 2019002 | B8: =VLOOKUP($A8,Data!$C$5:$V$2561,F$4) -> -1.2 | C8: =VLOOKUP($A8,Data!$C$5:$V$2561,G$4) -> -9.5
A9: 2019003 | B9: =VLOOKUP($A9,Data!$C$5:$V$2561,F$4) -> -1.2 | C9: =VLOOKUP($A9,Data!$C$5:$V$2561,G$4) -> -8.1
A10: 2019004 | B10: =VLOOKUP($A10,Data!$C$5:$V$2561,F$4) -> -1.4 | C10: =VLOOKUP($A10,Data!$C$5:$V$2561,G$4) -> -5.6
A11: 2019005 | B11: =VLOOKUP($A11,Data!$C$5:$V$2561,F$4) -> -3.1 | C11: =VLOOKUP($A11,Data!$C$5:$V$2561,G$4) -> -5.4
A12: 2019006 | B12: =VLOOKUP($A12,Data!$C$5:$V$2561,F$4) -> -3.8 | C12: =VLOOKUP($A12,Data!$C$5:$V$2561,G$4) -> -10.4
A13: 2019007 | B13: =VLOOKUP($A13,Data!$C$5:$V$2561,F$4) -> -7.6 | C13: =VLOOKUP($A13,Data!$C$5:$V$2561,G$4) -> -15.1
A14: 2019008 | B14: =VLOOKUP($A14,Data!$C$5:$V$2561,F$4) -> -8.5 | C14: =VLOOKUP($A14,Data!$C$5:$V$2561,G$4) -> -15.4
A15: 2019009 | B15: =VLOOKUP($A15,Data!$C$5:$V$2561,F$4) -> -1.4 | C15: =VLOOKUP($A15,Data!$C$5:$V$2561,G$4) -> -7.6
A16: 2019010 | B16: =VLOOKUP($A16,Data!$C$5:$V$2561,F$4) -> 0.2 | C16: =VLOOKUP($A16,Data!$C$5:$V$2561,G$4) -> -4.4
A17: 2019011 | B17: =VLOOKUP($A17,Data!$C$5:$V$2561,F$4) -> -1.2 | C17: =VLOOKUP($A17,Data!$C$5:$V$2561,G$4) -> -4.9
A18: 2019012 | B18: =VLOOKUP($A18,Data!$C$5:$V$2561,F$4) -> -1.1 | C18: =VLOOKUP($A18,Data!$C$5:$V$2561,G$4) -> -4.6
... A2563: 2025365 | B2563: =VLOOKUP($A2563,Data!$C$5:$V$2561,F$4) -> NAN | C2563: =VLOOKUP($A2563,Data!$C$5:$V$2561,G$4) -> NAN

Sheet Meta
A1: PL and Geonor Daily data 2019 -2025
A2: Last edit 17/12/25
A4: Data worksheet
B5: Data source is daily spreadsheets by year.
C6: Data edits are noted in these spreadsheets
B7: NAN indicates missing data
B8: Clear sky radiation calculated on 10 min time step for lat, long and elevation of site
A10: Graph worksheet
B11: Select one or a pair of variables to review using column number of desired variable
B12: Chose 0 for second variable if only showing one.
B13: Cannot readily show variables with different units
