Workbook

Sheet DataHour
A1: HoBo station PL hourly 2019 | E1: Hourly output matched to PST hourly as best can using match to the solar diurnal patern | AQ1: 62 | AR1: 162 | AS1: 332
A2: Last edit 9/12/25 | F2: 55.5 | O2: Raw | V2: Edited | W2: Midnight values | AD2: Wind direction summary | AR2: 248
E3: cm | F3: cm | G3: m/s | H3: m/s | I3: degree | J3: C | K3: % | L3: m3/m3 | M3: m3/m3 | N3: mm | O3: W/m2 | U3: W/m2 | V3: W/m2 | Y3: m | AA3: vpres | AB3: vpd | AF3: =MAX(AF6:AF13) -> 8726 | AP3: 248
A4: Date | B4: Doy | C4: PST | D4: HoboTime | E4: Depth | F4: AdjSnow | G4: Wind | H4: Gust | I4: WindDir | J4: Temperature | K4: RH | L4: vol10 | M4: vol20 | N4: Rain | O4: Solar | P4: DewPt, °C (LGR S/N: 10688092, SEN S/N: 20367744) | Q4: Backup Batteries_10688092_V | R4: Batt, V (LGR S/N: 20468345) | S4: blnk | T4: DyTime | U4: Kmax | V4: SolAdj | W4: vol10_2400 | X4: vol20_2400 | Y4: Snw2400 | Z4: Comments | AA4: kPa | AB4: kPa | AE4: Octant | AG4: N | AH4: % | AQ4: Time | AR4: ClrSky | AS4: Incident
A5: 43466 | B5: 1 | C5: 100 | D5: 0.0033680556 | G5: 0 | H5: 1.51 | I5: 219.012 | J5: -9.134 | K5: 95.4 | L5: 0.191 | M5: 0.201 | N5: 0 | O5: 0.625 | R5: 12.53 | T5: =B5*10000+C5 -> 10100 | U5: 0 | V5: =IF(O5<1,0,ROUND(O5,1)) -> 0 | W5: =IF(C5=2400,ROUND(L5,3),"") | X5: =IF(C5=2400,ROUND(M5,3),"") | AA5: =ROUND((0.6105*(EXP((17.273*J5)/(J5+237.3))))*K5/100,3) -> 0.292 | AB5: =ROUND(AA5/K5*(100-K5),3) -> 0.014 | AD5: N | AE5: 0 | AF5: =FREQUENCY(DataHour!I$5:I$8764, AE5) -> 64 | AG5: =AF5 -> 64 | AH5: =AG5/AF$3*100 -> 0.73344029 | AP5: =AP$3*10000+AQ5 -> 2480100 | AQ5: 100 | AR5: =VLOOKUP(AP5,$T$5:$V$8764,2) -> 0 | AS5: =VLOOKUP(AP5,$T$5:$V$8764,3) -> 0
A6: 43466 | B6: 1 | C6: 200 | D6: 0.045034722 | G6: 1.007 | H6: 4.529 | I6: 242.878 | J6: -8 | K6: 87.4 | L6: 0.19 | M6: 0.201 | N6: 0 | O6: 0.625 | R6: 12.53 | T6: =B6*10000+C6 -> 10200 | U6: 0 | V6: =IF(O6<1,0,ROUND(O6,1)) -> 0 | W6: =IF(C6=2400,ROUND(L6,3),"") | X6: =IF(C6=2400,ROUND(M6,3),"") | AA6: =ROUND((0.6105*(EXP((17.273*J6)/(J6+237.3))))*K6/100,3) -> 0.292 | AB6: =ROUND(AA6/K6*(100-K6),3) -> 0.042 | AD6: NE | AE6: 45 | AF6: =FREQUENCY(DataHour!I$5:I$8764, AE6) -> 1024 | AG6: =AF6-AF5 -> 960 | AH6: =AG6/AF$3*100 -> 11.001604 | AP6: =AP$3*10000+AQ6 -> 2480200 | AQ6: 200 | AR6: =VLOOKUP(AP6,$T$5:$V$8764,2) -> 0 | AS6: =VLOOKUP(AP6,$T$5:$V$8764,3) -> 0
A7: 43466 | B7: 1 | C7: 300 | D7: 0.086701389 | G7: 1.51 | H7: 4.529 | I7: 242.878 | J7: -7.968 | K7: 79.2 | L7: 0.19 | M7: 0.201 | N7: 0 | O7: 0.625 | R7: 12.43 | T7: =B7*10000+C7 -> 10300 | U7: 0 | V7: =IF(O7<1,0,ROUND(O7,1)) -> 0 | W7: =IF(C7=2400,ROUND(L7,3),"") | X7: =IF(C7=2400,ROUND(M7,3),"") | AA7: =ROUND((0.6105*(EXP((17.273*J7)/(J7+237.3))))*K7/100,3) -> 0.265 | AB7: =ROUND(AA7/K7*(100-K7),3) -> 0.07 | AD7: E | AE7: 90 | AF7: =FREQUENCY(DataHour!I$5:I$8764, AE7) -> 1966 | AG7: =AF7-AF6 -> 942 | AH7: =AG7/AF$3*100 -> 10.795324 | AP7: =AP$3*10000+AQ7 -> 2480300 | AQ7: 300 | AR7: =VLOOKUP(AP7,$T$5:$V$8764,2) -> 0 | AS7: =VLOOKUP(AP7,$T$5:$V$8764,3) -> 0
A8: 43466 | B8: 1 | C8: 400 | D8: 0.12836806 | G8: 1.007 | H8: 2.516 | I8: 244.282 | J8: -7.804 | K8: 79.6 | L8: 0.19 | M8: 0.201 | N8: 0 | O8: 0.625 | R8: 12.43 | T8: =B8*10000+C8 -> 10400 | U8: 0 | V8: =IF(O8<1,0,ROUND(O8,1)) -> 0 | W8: =IF(C8=2400,ROUND(L8,3),"") | X8: =IF(C8=2400,ROUND(M8,3),"") | AA8: =ROUND((0.6105*(EXP((17.273*J8)/(J8+237.3))))*K8/100,3) -> 0.27 | AB8: =ROUND(AA8/K8*(100-K8),3) -> 0.069 | AD8: SE | AE8: 135 | AF8: =FREQUENCY(DataHour!I$5:I$8764, AE8) -> 2462 | AG8: =AF8-AF7 -> 496 | AH8: =AG8/AF$3*100 -> 5.6841623 | AP8: =AP$3*10000+AQ8 -> 2480400 | AQ8: 400 | AR8: =VLOOKUP(AP8,$T$5:$V$8764,2) -> 0 | AS8: =VLOOKUP(AP8,$T$5:$V$8764,3) -> 0
A9: 43466 | B9: 1 | C9: 500 | D9: 0.17003472 | G9: 1.007 | H9: 3.02 | I9: 251.302 | J9: -8.764 | K9: 81.6 | L9: 0.19 | M9: 0.201 | N9: 0 | O9: 0.625 | R9: 12.43 | T9: =B9*10000+C9 -> 10500 | U9: 0 | V9: =IF(O9<1,0,ROUND(O9,1)) -> 0 | W9: =IF(C9=2400,ROUND(L9,3),"") | X9: =IF(C9=2400,ROUND(M9,3),"") | AA9: =ROUND((0.6105*(EXP((17.273*J9)/(J9+237.3))))*K9/100,3) -> 0.257 | AB9: =ROUND(AA9/K9*(100-K9),3) -> 0.058 | AD9: SE | AE9: 180 | AF9: =FREQUENCY(DataHour!I$5:I$8764, AE9) -> 3049 | AG9: =AF9-AF8 -> 587 | AH9: =AG9/AF$3*100 -> 6.7270227 | AP9: =AP$3*10000+AQ9 -> 2480500 | AQ9: 500 | AR9: =VLOOKUP(AP9,$T$5:$V$8764,2) -> 0 | AS9: =VLOOKUP(AP9,$T$5:$V$8764,3) -> 0
A10: 43466 | B10: 1 | C10: 600 | D10: 0.21170139 | G10: 0.503 | H10: 2.516 | I10: 240.071 | J10: -8.297 | K10: 94.3 | L10: 0.19 | M10: 0.201 | N10: 0 | O10: 0.625 | R10: 12.43 | T10: =B10*10000+C10 -> 10600 | U10: 0 | V10: =IF(O10<1,0,ROUND(O10,1)) -> 0 | W10: =IF(C10=2400,ROUND(L10,3),"") | X10: =IF(C10=2400,ROUND(M10,3),"") | AA10: =ROUND((0.6105*(EXP((17.273*J10)/(J10+237.3))))*K10/100,3) -> 0.308 | AB10: =ROUND(AA10/K10*(100-K10),3) -> 0.019 | AD10: SW | AE10: 225 | AF10: =FREQUENCY(DataHour!I$5:I$8764, AE10) -> 4210 | AG10: =AF10-AF9 -> 1161 | AH10: =AG10/AF$3*100 -> 13.305065 | AP10: =AP$3*10000+AQ10 -> 2480600 | AQ10: 600 | AR10: =VLOOKUP(AP10,$T$5:$V$8764,2) -> 10 | AS10: =VLOOKUP(AP10,$T$5:$V$8764,3) -> 13.1
A11: 43466 | B11: 1 | C11: 700 | D11: 0.25336806 | G11: 0.503 | H11: 3.523 | I11: 234.455 | J11: -6.834 | K11: 95.3 | L11: 0.19 | M11: 0.201 | N11: 0 | O11: 0.625 | R11: 12.43 | T11: =B11*10000+C11 -> 10700 | U11: 0 | V11: =IF(O11<1,0,ROUND(O11,1)) -> 0 | W11: =IF(C11=2400,ROUND(L11,3),"") | X11: =IF(C11=2400,ROUND(M11,3),"") | AA11: =ROUND((0.6105*(EXP((17.273*J11)/(J11+237.3))))*K11/100,3) -> 0.349 | AB11: =ROUND(AA11/K11*(100-K11),3) -> 0.017 | AD11: W | AE11: 270 | AF11: =FREQUENCY(DataHour!I$5:I$8764, AE11) -> 5943 | AG11: =AF11-AF10 -> 1733 | AH11: =AG11/AF$3*100 -> 19.860188 | AP11: =AP$3*10000+AQ11 -> 2480700 | AQ11: 700 | AR11: =VLOOKUP(AP11,$T$5:$V$8764,2) -> 137.3 | AS11: =VLOOKUP(AP11,$T$5:$V$8764,3) -> 201.9
A12: 43466 | B12: 1 | C12: 800 | D12: 0.29503472 | G12: 1.51 | H12: 4.026 | I12: 251.302 | J12: -6.547 | K12: 92.2 | L12: 0.19 | M12: 0.201 | N12: 0 | O12: 0.625 | R12: 12.43 | T12: =B12*10000+C12 -> 10800 | U12: 0 | V12: =IF(O12<1,0,ROUND(O12,1)) -> 0 | W12: =IF(C12=2400,ROUND(L12,3),"") | X12: =IF(C12=2400,ROUND(M12,3),"") | AA12: =ROUND((0.6105*(EXP((17.273*J12)/(J12+237.3))))*K12/100,3) -> 0.345 | AB12: =ROUND(AA12/K12*(100-K12),3) -> 0.029 | AD12: NW | AE12: 315 | AF12: =FREQUENCY(DataHour!I$5:I$8764, AE12) -> 7247 | AG12: =AF12-AF11 -> 1304 | AH12: =AG12/AF$3*100 -> 14.943846 | AP12: =AP$3*10000+AQ12 -> 2480800 | AQ12: 800 | AR12: =VLOOKUP(AP12,$T$5:$V$8764,2) -> 318 | AS12: =VLOOKUP(AP12,$T$5:$V$8764,3) -> 370.6
A13: 43466 | B13: 1 | C13: 900 | D13: 0.33670139 | G13: 0.503 | H13: 3.02 | I13: 214.8 | J13: -7.187 | K13: 92 | L13: 0.19 | M13: 0.201 | N13: 0 | O13: 1.875 | R13: 12.43 | T13: =B13*10000+C13 -> 10900 | U13: 55 | V13: =IF(O13<1,0,ROUND(O13,1)) -> 1.9 | W13: =IF(C13=2400,ROUND(L13,3),"") | X13: =IF(C13=2400,ROUND(M13,3),"") | AA13: =ROUND((0.6105*(EXP((17.273*J13)/(J13+237.3))))*K13/100,3) -> 0.327 | AB13: =ROUND(AA13/K13*(100-K13),3) -> 0.028 | AD13: N | AE13: 360 | AF13: =FREQUENCY(DataHour!I$5:I$8764, AE13) -> 8726 | AG13: =AF13-AF12 -> 1479 | AH13: =AG13/AF$3*100 -> 16.949347 | AP13: =AP$3*10000+AQ13 -> 2480900 | AQ13: 900 | AR13: =VLOOKUP(AP13,$T$5:$V$8764,2) -> 490.7 | AS13: =VLOOKUP(AP13,$T$5:$V$8764,3) -> 530.6
A14: 43466 | B14: 1 | C14: 1000 | D14: 0.37836806 | G14: 1.007 | H14: 5.033 | I14: 240.071 | J14: -5.357 | K14: 94.1 | L14: 0.19 | M14: 0.201 | N14: 0 | O14: 56.875 | R14: 13.18 | T14: =B14*10000+C14 -> 11000 | U14: 166.2 | V14: =IF(O14<1,0,ROUND(O14,1)) -> 56.9 | W14: =IF(C14=2400,ROUND(L14,3),"") | X14: =IF(C14=2400,ROUND(M14,3),"") | AA14: =ROUND((0.6105*(EXP((17.273*J14)/(J14+237.3))))*K14/100,3) -> 0.385 | AB14: =ROUND(AA14/K14*(100-K14),3) -> 0.024 | AP14: =AP$3*10000+AQ14 -> 2481000 | AQ14: 1000 | AR14: =VLOOKUP(AP14,$T$5:$V$8764,2) -> 635 | AS14: =VLOOKUP(AP14,$T$5:$V$8764,3) -> 654.4
A15: 43466 | B15: 1 | C15: 1100 | D15: 0.42003472 | G15: 1.007 | H15: 4.026 | I15: 231.647 | J15: -4.56 | K15: 96.2 | L15: 0.191 | M15: 0.201 | N15: 0 | O15: 154.375 | R15: 13.39 | T15: =B15*10000+C15 -> 11100 | U15: 251.7 | V15: =IF(O15<1,0,ROUND(O15,1)) -> 154.4 | W15: =IF(C15=2400,ROUND(L15,3),"") | X15: =IF(C15=2400,ROUND(M15,3),"") | AA15: =ROUND((0.6105*(EXP((17.273*J15)/(J15+237.3))))*K15/100,3) -> 0.419 | AB15: =ROUND(AA15/K15*(100-K15),3) -> 0.017 | AD15: 360 | AE15: 45 | AF15: 90 | AG15: 135 | AH15: 180 | AI15: 225 | AJ15: 270 | AK15: 315 | AP15: =AP$3*10000+AQ15 -> 2481100 | AQ15: 1100 | AR15: =VLOOKUP(AP15,$T$5:$V$8764,2) -> 737.8 | AS15: =VLOOKUP(AP15,$T$5:$V$8764,3) -> 733.1
A16: 43466 | B16: 1 | C16: 1200 | D16: 0.46170139 | G16: 1.51 | H16: 5.033 | I16: 241.475 | J16: -5.202 | K16: 97.5 | L16: 0.191 | M16: 0.201 | N16: 0 | O16: 84.375 | R16: 13.28 | T16: =B16*10000+C16 -> 11200 | U16: 293.3 | V16: =IF(O16<1,0,ROUND(O16,1)) -> 84.4 | W16: =IF(C16=2400,ROUND(L16,3),"") | X16: =IF(C16=2400,ROUND(M16,3),"") | AA16: =ROUND((0.6105*(EXP((17.273*J16)/(J16+237.3))))*K16/100,3) -> 0.404 | AB16: =ROUND(AA16/K16*(100-K16),3) -> 0.01 | AD16: =AH13+AH5 -> 17.682787 | AE16: =AH6 -> 11.001604 | AF16: =AH7 -> 10.795324 | AG16: =AH8 -> 5.6841623 | AH16: =AH9 -> 6.7270227 | AI16: =AH10 -> 13.305065 | AJ16: =AH11 -> 19.860188 | AK16: =AH12 -> 14.943846 | AP16: =AP$3*10000+AQ16 -> 2481200 | AQ16: 1200 | AR16: =VLOOKUP(AP16,$T$5:$V$8764,2) -> 790.3 | AS16: =VLOOKUP(AP16,$T$5:$V$8764,3) -> 751.9
A17: 43466 | B17: 1 | C17: 1300 | D17: 0.50336806 | G17: 0.503 | H17: 2.013 | I17: 204.973 | J17: -4.865 | K17: 98.2 | L17: 0.191 | M17: 0.201 | N17: 0 | O17: 121.875 | R17: 13.5 | T17: =B17*10000+C17 -> 11300 | U17: 285.3 | V17: =IF(O17<1,0,ROUND(O17,1)) -> 121.9 | W17: =IF(C17=2400,ROUND(L17,3),"") | X17: =IF(C17=2400,ROUND(M17,3),"") | AA17: =ROUND((0.6105*(EXP((17.273*J17)/(J17+237.3))))*K17/100,3) -> 0.418 | AB17: =ROUND(AA17/K17*(100-K17),3) -> 0.008 | AD17: N-NE | AE17: NE-E | AF17: E-SE | AG17: SE-S | AH17: S-SW | AI17: SW-W | AJ17: W-NW | AK17: NW-N | AP17: =AP$3*10000+AQ17 -> 2481300 | AQ17: 1300 | AR17: =VLOOKUP(AP17,$T$5:$V$8764,2) -> 789 | AS17: =VLOOKUP(AP17,$T$5:$V$8764,3) -> 774.4
A18: 43466 | B18: 1 | C18: 1400 | D18: 0.54503472 | G18: 0.503 | H18: 4.026 | I18: 197.953 | J18: -4.106 | K18: 98.5 | L18: 0.19 | M18: 0.201 | N18: 0 | O18: 95.625 | R18: 13.28 | T18: =B18*10000+C18 -> 11400 | U18: 229 | V18: =IF(O18<1,0,ROUND(O18,1)) -> 95.6 | W18: =IF(C18=2400,ROUND(L18,3),"") | X18: =IF(C18=2400,ROUND(M18,3),"") | AA18: =ROUND((0.6105*(EXP((17.273*J18)/(J18+237.3))))*K18/100,3) -> 0.444 | AB18: =ROUND(AA18/K18*(100-K18),3) -> 0.007 | AP18: =AP$3*10000+AQ18 -> 2481400 | AQ18: 1400 | AR18: =VLOOKUP(AP18,$T$5:$V$8764,2) -> 733.3 | AS18: =VLOOKUP(AP18,$T$5:$V$8764,3) -> 730.6
A19: 43466 | B19: 1 | C19: 1500 | D19: 0.58670139 | G19: 0 | H19: 1.51 | I19: 207.78 | J19: -3.627 | K19: 96.3 | L19: 0.19 | M19: 0.201 | N19: 0 | O19: 49.375 | R19: 13.61 | T19: =B19*10000+C19 -> 11500 | U19: 132.8 | V19: =IF(O19<1,0,ROUND(O19,1)) -> 49.4 | W19: =IF(C19=2400,ROUND(L19,3),"") | X19: =IF(C19=2400,ROUND(M19,3),"") | AA19: =ROUND((0.6105*(EXP((17.273*J19)/(J19+237.3))))*K19/100,3) -> 0.45 | AB19: =ROUND(AA19/K19*(100-K19),3) -> 0.017 | AP19: =AP$3*10000+AQ19 -> 2481500 | AQ19: 1500 | AR19: =VLOOKUP(AP19,$T$5:$V$8764,2) -> 628.2 | AS19: =VLOOKUP(AP19,$T$5:$V$8764,3) -> 660.6
A20: 43466 | B20: 1 | C20: 1600 | D20: 0.62836806 | G20: 0 | H20: 2.516 | I20: 186.722 | J20: -3.33 | K20: 96.1 | L20: 0.191 | M20: 0.201 | N20: 0 | O20: 84.375 | R20: 14.04 | T20: =B20*10000+C20 -> 11600 | U20: 25.3 | V20: =IF(O20<1,0,ROUND(O20,1)) -> 84.4 | W20: =IF(C20=2400,ROUND(L20,3),"") | X20: =IF(C20=2400,ROUND(M20,3),"") | AA20: =ROUND((0.6105*(EXP((17.273*J20)/(J20+237.3))))*K20/100,3) -> 0.459 | AB20: =ROUND(AA20/K20*(100-K20),3) -> 0.019 | AP20: =AP$3*10000+AQ20 -> 2481600 | AQ20: 1600 | AR20: =VLOOKUP(AP20,$T$5:$V$8764,2) -> 481.8 | AS20: =VLOOKUP(AP20,$T$5:$V$8764,3) -> 438.1
A21: 43466 | B21: 1 | C21: 1700 | D21: 0.67003472 | G21: 1.007 | H21: 3.02 | I21: 200.761 | J21: -4.076 | K21: 97 | L21: 0.19 | M21: 0.201 | N21: 0 | O21: 0.625 | R21: 13.07 | T21: =B21*10000+C21 -> 11700 | U21: 0 | V21: =IF(O21<1,0,ROUND(O21,1)) -> 0 | W21: =IF(C21=2400,ROUND(L21,3),"") | X21: =IF(C21=2400,ROUND(M21,3),"") | AA21: =ROUND((0.6105*(EXP((17.273*J21)/(J21+237.3))))*K21/100,3) -> 0.438 | AB21: =ROUND(AA21/K21*(100-K21),3) -> 0.014 | AP21: =AP$3*10000+AQ21 -> 2481700 | AQ21: 1700 | AR21: =VLOOKUP(AP21,$T$5:$V$8764,2) -> 308 | AS21: =VLOOKUP(AP21,$T$5:$V$8764,3) -> 256.9
A22: 43466 | B22: 1 | C22: 1800 | D22: 0.71170139 | G22: 1.007 | H22: 3.02 | I22: 230.243 | J22: -4.712 | K22: 96.5 | L22: 0.19 | M22: 0.201 | N22: 0 | O22: 0.625 | R22: 12.86 | T22: =B22*10000+C22 -> 11800 | U22: 0 | V22: =IF(O22<1,0,ROUND(O22,1)) -> 0 | W22: =IF(C22=2400,ROUND(L22,3),"") | X22: =IF(C22=2400,ROUND(M22,3),"") | AA22: =ROUND((0.6105*(EXP((17.273*J22)/(J22+237.3))))*K22/100,3) -> 0.415 | AB22: =ROUND(AA22/K22*(100-K22),3) -> 0.015 | AP22: =AP$3*10000+AQ22 -> 2481800 | AQ22: 1800 | AR22: =VLOOKUP(AP22,$T$5:$V$8764,2) -> 128.2 | AS22: =VLOOKUP(AP22,$T$5:$V$8764,3) -> 78.1
A23: 43466 | B23: 1 | C23: 1900 | D23: 0.75336806 | G23: 0.503 | H23: 2.516 | I23: 248.494 | J23: -5.018 | K23: 96.5 | L23: 0.19 | M23: 0.201 | N23: 0 | O23: 0.625 | R23: 12.75 | T23: =B23*10000+C23 -> 11900 | U23: 0 | V23: =IF(O23<1,0,ROUND(O23,1)) -> 0 | W23: =IF(C23=2400,ROUND(L23,3),"") | X23: =IF(C23=2400,ROUND(M23,3),"") | AA23: =ROUND((0.6105*(EXP((17.273*J23)/(J23+237.3))))*K23/100,3) -> 0.406 | AB23: =ROUND(AA23/K23*(100-K23),3) -> 0.015 | AP23: =AP$3*10000+AQ23 -> 2481900 | AQ23: 1900 | AR23: =VLOOKUP(AP23,$T$5:$V$8764,2) -> 6.8 | AS23: =VLOOKUP(AP23,$T$5:$V$8764,3) -> 0
A24: 43466 | B24: 1 | C24: 2000 | D24: 0.79503472 | G24: 1.51 | H24: 3.523 | I24: 238.667 | J24: -5.018 | K24: 95.7 | L24: 0.19 | M24: 0.201 | N24: 0 | O24: 0.625 | R24: 12.75 | T24: =B24*10000+C24 -> 12000 | U24: 0 | V24: =IF(O24<1,0,ROUND(O24,1)) -> 0 | W24: =IF(C24=2400,ROUND(L24,3),"") | X24: =IF(C24=2400,ROUND(M24,3),"") | AA24: =ROUND((0.6105*(EXP((17.273*J24)/(J24+237.3))))*K24/100,3) -> 0.402 | AB24: =ROUND(AA24/K24*(100-K24),3) -> 0.018 | AP24: =AP$3*10000+AQ24 -> 2482000 | AQ24: 2000 | AR24: =VLOOKUP(AP24,$T$5:$V$8764,2) -> 0 | AS24: =VLOOKUP(AP24,$T$5:$V$8764,3) -> 0
A25: 43466 | B25: 1 | C25: 2100 | D25: 0.83670139 | G25: 0.503 | H25: 2.516 | I25: 259.725 | J25: -4.439 | K25: 94.1 | L25: 0.191 | M25: 0.201 | N25: 0 | O25: 0.625 | R25: 12.64 | T25: =B25*10000+C25 -> 12100 | U25: 0 | V25: =IF(O25<1,0,ROUND(O25,1)) -> 0 | W25: =IF(C25=2400,ROUND(L25,3),"") | X25: =IF(C25=2400,ROUND(M25,3),"") | AA25: =ROUND((0.6105*(EXP((17.273*J25)/(J25+237.3))))*K25/100,3) -> 0.413 | AB25: =ROUND(AA25/K25*(100-K25),3) -> 0.026 | AP25: =AP$3*10000+AQ25 -> 2482100 | AQ25: 2100 | AR25: =VLOOKUP(AP25,$T$5:$V$8764,2) -> 0 | AS25: =VLOOKUP(AP25,$T$5:$V$8764,3) -> 0
A26: 43466 | B26: 1 | C26: 2200 | D26: 0.87836806 | G26: 0.503 | H26: 4.026 | I26: 286.4 | J26: -3.777 | K26: 93.9 | L26: 0.191 | M26: 0.201 | N26: 0 | O26: 0.625 | R26: 12.64 | T26: =B26*10000+C26 -> 12200 | U26: 0 | V26: =IF(O26<1,0,ROUND(O26,1)) -> 0 | W26: =IF(C26=2400,ROUND(L26,3),"") | X26: =IF(C26=2400,ROUND(M26,3),"") | AA26: =ROUND((0.6105*(EXP((17.273*J26)/(J26+237.3))))*K26/100,3) -> 0.434 | AB26: =ROUND(AA26/K26*(100-K26),3) -> 0.028 | AP26: =AP$3*10000+AQ26 -> 2482200 | AQ26: 2200 | AR26: =VLOOKUP(AP26,$T$5:$V$8764,2) -> 0 | AS26: =VLOOKUP(AP26,$T$5:$V$8764,3) -> 0
A27: 43466 | B27: 1 | C27: 2300 | D27: 0.92003472 | G27: 0.503 | H27: 2.516 | I27: 301.843 | J27: -3.538 | K27: 95.1 | L27: 0.191 | M27: 0.201 | N27: 0 | O27: 0.625 | R27: 12.53 | T27: =B27*10000+C27 -> 12300 | U27: 0 | V27: =IF(O27<1,0,ROUND(O27,1)) -> 0 | W27: =IF(C27=2400,ROUND(L27,3),"") | X27: =IF(C27=2400,ROUND(M27,3),"") | AA27: =ROUND((0.6105*(EXP((17.273*J27)/(J27+237.3))))*K27/100,3) -> 0.447 | AB27: =ROUND(AA27/K27*(100-K27),3) -> 0.023 | AP27: =AP$3*10000+AQ27 -> 2482300 | AQ27: 2300 | AR27: =VLOOKUP(AP27,$T$5:$V$8764,2) -> 0 | AS27: =VLOOKUP(AP27,$T$5:$V$8764,3) -> 0
A28: 43466 | B28: 1 | C28: 2400 | D28: 0.96170139 | G28: 0.503 | H28: 3.02 | I28: 249.898 | J28: -3.986 | K28: 93.8 | L28: 0.19 | M28: 0.201 | N28: 0 | O28: 0.625 | R28: 12.53 | T28: =B28*10000+C28 -> 12400 | U28: 0 | V28: =IF(O28<1,0,ROUND(O28,1)) -> 0 | W28: =IF(C28=2400,ROUND(L28,3),"") -> 0.19 | X28: =IF(C28=2400,ROUND(M28,3),"") -> 0.201 | AA28: =ROUND((0.6105*(EXP((17.273*J28)/(J28+237.3))))*K28/100,3) -> 0.426 | AB28: =ROUND(AA28/K28*(100-K28),3) -> 0.028 | AP28: =AP$3*10000+AQ28 -> 2482400 | AQ28: 2400 | AR28: =VLOOKUP(AP28,$T$5:$V$8764,2) -> 0 | AS28: =VLOOKUP(AP28,$T$5:$V$8764,3) -> 0
A29: 43467 | B29: 2 | C29: 100 | D29: 0.0033680556 | G29: 0.503 | H29: 4.529 | I29: 261.129 | J29: -3.36 | K29: 94.7 | L29: 0.191 | M29: 0.201 | N29: 0 | O29: 0.625 | R29: 12.53 | T29: =B29*10000+C29 -> 20100 | U29: 0 | V29: =IF(O29<1,0,ROUND(O29,1)) -> 0 | W29: =IF(C29=2400,ROUND(L29,3),"") | X29: =IF(C29=2400,ROUND(M29,3),"") | AA29: =ROUND((0.6105*(EXP((17.273*J29)/(J29+237.3))))*K29/100,3) -> 0.451 | AB29: =ROUND(AA29/K29*(100-K29),3) -> 0.025 | AP29: =AP5+10000 -> 2490100 | AQ29: 100 | AR29: =VLOOKUP(AP29,$T$5:$V$8764,2) -> 0 | AS29: =VLOOKUP(AP29,$T$5:$V$8764,3) -> 0
A30: 43467 | B30: 2 | C30: 200 | D30: 0.045034722 | G30: 1.51 | H30: 4.026 | I30: 238.667 | J30: -2.888 | K30: 94.2 | L30: 0.191 | M30: 0.201 | N30: 0 | O30: 0.625 | R30: 12.53 | T30: =B30*10000+C30 -> 20200 | U30: 0 | V30: =IF(O30<1,0,ROUND(O30,1)) -> 0 | W30: =IF(C30=2400,ROUND(L30,3),"") | X30: =IF(C30=2400,ROUND(M30,3),"") | AA30: =ROUND((0.6105*(EXP((17.273*J30)/(J30+237.3))))*K30/100,3) -> 0.465 | AB30: =ROUND(AA30/K30*(100-K30),3) -> 0.029 | AP30: =AP6+10000 -> 2490200 | AQ30: 200 | AR30: =VLOOKUP(AP30,$T$5:$V$8764,2) -> 0 | AS30: =VLOOKUP(AP30,$T$5:$V$8764,3) -> 0
A31: 43467 | B31: 2 | C31: 300 | D31: 0.086701389 | G31: 1.51 | H31: 4.026 | I31: 228.839 | J31: -3.301 | K31: 94.4 | L31: 0.191 | M31: 0.201 | N31: 0 | O31: 0.625 | R31: 12.53 | T31: =B31*10000+C31 -> 20300 | U31: 0 | V31: =IF(O31<1,0,ROUND(O31,1)) -> 0 | W31: =IF(C31=2400,ROUND(L31,3),"") | X31: =IF(C31=2400,ROUND(M31,3),"") | AA31: =ROUND((0.6105*(EXP((17.273*J31)/(J31+237.3))))*K31/100,3) -> 0.452 | AB31: =ROUND(AA31/K31*(100-K31),3) -> 0.027 | AP31: =AP7+10000 -> 2490300 | AQ31: 300 | AR31: =VLOOKUP(AP31,$T$5:$V$8764,2) -> 0 | AS31: =VLOOKUP(AP31,$T$5:$V$8764,3) -> 0
A32: 43467 | B32: 2 | C32: 400 | D32: 0.12836806 | G32: 0.503 | H32: 3.02 | I32: 219.012 | J32: -2.918 | K32: 96.5 | L32: 0.191 | M32: 0.201 | N32: 0 | O32: 0.625 | R32: 12.53 | T32: =B32*10000+C32 -> 20400 | U32: 0 | V32: =IF(O32<1,0,ROUND(O32,1)) -> 0 | W32: =IF(C32=2400,ROUND(L32,3),"") | X32: =IF(C32=2400,ROUND(M32,3),"") | AA32: =ROUND((0.6105*(EXP((17.273*J32)/(J32+237.3))))*K32/100,3) -> 0.475 | AB32: =ROUND(AA32/K32*(100-K32),3) -> 0.017 | AP32: =AP8+10000 -> 2490400 | AQ32: 400 | AR32: =VLOOKUP(AP32,$T$5:$V$8764,2) -> 0 | AS32: =VLOOKUP(AP32,$T$5:$V$8764,3) -> 0
A33: 43467 | B33: 2 | C33: 500 | D33: 0.17003472 | G33: 0.503 | H33: 3.02 | I33: 224.627 | J33: -1.27 | K33: 97 | L33: 0.191 | M33: 0.201 | N33: 0 | O33: 0.625 | R33: 12.53 | T33: =B33*10000+C33 -> 20500 | U33: 0 | V33: =IF(O33<1,0,ROUND(O33,1)) -> 0 | W33: =IF(C33=2400,ROUND(L33,3),"") | X33: =IF(C33=2400,ROUND(M33,3),"") | AA33: =ROUND((0.6105*(EXP((17.273*J33)/(J33+237.3))))*K33/100,3) -> 0.54 | AB33: =ROUND(AA33/K33*(100-K33),3) -> 0.017 | AP33: =AP9+10000 -> 2490500 | AQ33: 500 | AR33: =VLOOKUP(AP33,$T$5:$V$8764,2) -> 0 | AS33: =VLOOKUP(AP33,$T$5:$V$8764,3) -> 0
A34: 43467 | B34: 2 | C34: 600 | D34: 0.21170139 | G34: 1.51 | H34: 4.026 | I34: 46.329 | J34: -3.598 | K34: 96.7 | L34: 0.191 | M34: 0.201 | N34: 0 | O34: 0.625 | R34: 12.43 | T34: =B34*10000+C34 -> 20600 | U34: 0 | V34: =IF(O34<1,0,ROUND(O34,1)) -> 0 | W34: =IF(C34=2400,ROUND(L34,3),"") | X34: =IF(C34=2400,ROUND(M34,3),"") | AA34: =ROUND((0.6105*(EXP((17.273*J34)/(J34+237.3))))*K34/100,3) -> 0.453 | AB34: =ROUND(AA34/K34*(100-K34),3) -> 0.015 | AP34: =AP10+10000 -> 2490600 | AQ34: 600 | AR34: =VLOOKUP(AP34,$T$5:$V$8764,2) -> 8.2 | AS34: =VLOOKUP(AP34,$T$5:$V$8764,3) -> 5.6
A35: 43467 | B35: 2 | C35: 700 | D35: 0.25336806 | G35: 0.503 | H35: 3.523 | I35: 94.063 | J35: -1.185 | K35: 96.5 | L35: 0.191 | M35: 0.201 | N35: 0 | O35: 0.625 | R35: 12.43 | T35: =B35*10000+C35 -> 20700 | U35: 0 | V35: =IF(O35<1,0,ROUND(O35,1)) -> 0 | W35: =IF(C35=2400,ROUND(L35,3),"") | X35: =IF(C35=2400,ROUND(M35,3),"") | AA35: =ROUND((0.6105*(EXP((17.273*J35)/(J35+237.3))))*K35/100,3) -> 0.54 | AB35: =ROUND(AA35/K35*(100-K35),3) -> 0.02 | AP35: =AP11+10000 -> 2490700 | AQ35: 700 | AR35: =VLOOKUP(AP35,$T$5:$V$8764,2) -> 133.8 | AS35: =VLOOKUP(AP35,$T$5:$V$8764,3) -> 46.9
A36: 43467 | B36: 2 | C36: 800 | D36: 0.29503472 | G36: 0.503 | H36: 2.516 | I36: 164.259 | J36: -1.929 | K36: 93.9 | L36: 0.191 | M36: 0.201 | N36: 0 | O36: 0.625 | R36: 12.53 | T36: =B36*10000+C36 -> 20800 | U36: 0 | V36: =IF(O36<1,0,ROUND(O36,1)) -> 0 | W36: =IF(C36=2400,ROUND(L36,3),"") | X36: =IF(C36=2400,ROUND(M36,3),"") | AA36: =ROUND((0.6105*(EXP((17.273*J36)/(J36+237.3))))*K36/100,3) -> 0.498 | AB36: =ROUND(AA36/K36*(100-K36),3) -> 0.032 | AP36: =AP12+10000 -> 2490800 | AQ36: 800 | AR36: =VLOOKUP(AP36,$T$5:$V$8764,2) -> 314 | AS36: =VLOOKUP(AP36,$T$5:$V$8764,3) -> 81.9
A37: 43467 | B37: 2 | C37: 900 | D37: 0.33670139 | G37: 1.007 | H37: 3.523 | I37: 92.659 | J37: -3.657 | K37: 95.8 | L37: 0.191 | M37: 0.201 | N37: 0 | O37: 0.625 | R37: 12.53 | T37: =B37*10000+C37 -> 20900 | U37: 55.2 | V37: =IF(O37<1,0,ROUND(O37,1)) -> 0 | W37: =IF(C37=2400,ROUND(L37,3),"") | X37: =IF(C37=2400,ROUND(M37,3),"") | AA37: =ROUND((0.6105*(EXP((17.273*J37)/(J37+237.3))))*K37/100,3) -> 0.446 | AB37: =ROUND(AA37/K37*(100-K37),3) -> 0.02 | AP37: =AP13+10000 -> 2490900 | AQ37: 900 | AR37: =VLOOKUP(AP37,$T$5:$V$8764,2) -> 486.7 | AS37: =VLOOKUP(AP37,$T$5:$V$8764,3) -> 95.6
A38: 43467 | B38: 2 | C38: 1000 | D38: 0.37836806 | G38: 0.503 | H38: 4.026 | I38: 153.027 | J38: -4.167 | K38: 97.3 | L38: 0.191 | M38: 0.201 | N38: 0 | O38: 18.125 | R38: 12.64 | T38: =B38*10000+C38 -> 21000 | U38: 166.8 | V38: =IF(O38<1,0,ROUND(O38,1)) -> 18.1 | W38: =IF(C38=2400,ROUND(L38,3),"") | X38: =IF(C38=2400,ROUND(M38,3),"") | AA38: =ROUND((0.6105*(EXP((17.273*J38)/(J38+237.3))))*K38/100,3) -> 0.436 | AB38: =ROUND(AA38/K38*(100-K38),3) -> 0.012 | AP38: =AP14+10000 -> 2491000 | AQ38: 1000 | AR38: =VLOOKUP(AP38,$T$5:$V$8764,2) -> 630.8 | AS38: =VLOOKUP(AP38,$T$5:$V$8764,3) -> 225.6
A39: 43467 | B39: 2 | C39: 1100 | D39: 0.42003472 | G39: 0.503 | H39: 4.026 | I39: 85.639 | J39: -3.836 | K39: 98.1 | L39: 0.191 | M39: 0.201 | N39: 0 | O39: 46.875 | R39: 13.07 | T39: =B39*10000+C39 -> 21100 | U39: 252.8 | V39: =IF(O39<1,0,ROUND(O39,1)) -> 46.9 | W39: =IF(C39=2400,ROUND(L39,3),"") | X39: =IF(C39=2400,ROUND(M39,3),"") | AA39: =ROUND((0.6105*(EXP((17.273*J39)/(J39+237.3))))*K39/100,3) -> 0.451 | AB39: =ROUND(AA39/K39*(100-K39),3) -> 0.009 | AP39: =AP15+10000 -> 2491100 | AQ39: 1100 | AR39: =VLOOKUP(AP39,$T$5:$V$8764,2) -> 733 | AS39: =VLOOKUP(AP39,$T$5:$V$8764,3) -> 581.9
A40: 43467 | B40: 2 | C40: 1200 | D40: 0.46170139 | G40: 1.007 | H40: 4.026 | I40: 92.659 | J40: -3.627 | K40: 97.5 | L40: 0.191 | M40: 0.201 | N40: 0 | O40: 58.125 | R40: 13.93 | T40: =B40*10000+C40 -> 21200 | U40: 294.8 | V40: =IF(O40<1,0,ROUND(O40,1)) -> 58.1 | W40: =IF(C40=2400,ROUND(L40,3),"") | X40: =IF(C40=2400,ROUND(M40,3),"") | AA40: =ROUND((0.6105*(EXP((17.273*J40)/(J40+237.3))))*K40/100,3) -> 0.455 | AB40: =ROUND(AA40/K40*(100-K40),3) -> 0.012 | AP40: =AP16+10000 -> 2491200 | AQ40: 1200 | AR40: =VLOOKUP(AP40,$T$5:$V$8764,2) -> 785.2 | AS40: =VLOOKUP(AP40,$T$5:$V$8764,3) -> 553.1
...

Sheet DataDay
A1: HoBo station PL daily 2019 calcuated from hourly file | AB1: Estimated from hourly data | AF1: Calc from snowfall | AO1: PB | AU1: For PL assessment see worksheet PBvPL for graphs
A2: Last edit 20/12/25 | Q2: Daily PL | AB2: Estimated | AE2: 0 | AG2: Rain | AH2: TXRHn | AO2: Daily
S3: MJ/m2/d | T3: C | U3: C | V3: C | W3: % | X3: % | Y3: % | Z3: mm | AA3: m/s | AB3: m/s | AC3: m3/m3 | AD3: m3/m3 | AE3: m | AF3: PPT | AG3: PPT | AH3: vpres | AI3: vpdX | AK3: MJ/m2/d | AR3: From hourly file | AY3: From hourly file
A4: Row Labels | B4: Count of Temperature | C4: Average of SolAdj | D4: Average of Temperature | E4: Max of Temperature | F4: Min of Temperature | G4: Average of RH | H4: Max of RH | I4: Min of RH | J4: Sum of Rain | K4: Average of Wind | L4: Max of Gust | M4: Max of vol10_2400 | N4: Max of vol20_2400 | O4: Max of Snw2400 | Q4: DoY | R4: Hours | S4: Solar | T4: Tave | U4: Tmax | V4: Tmin | W4: RHAve | X4: RHMax | Y4: RHMin | Z4: Rain | AA4: Wind | AB4: WindMax | AC4: vol10_2400 | AD4: vol20_2400 | AE4: SnwD2400 | AF4: mm | AG4: mm | AH4: kPa | AI4: kPa | AK4: ClearSky | AO4: Solar | AP4: Tave | AQ4: Tmax | AR4: Tmin | AS4: RHAve | AT4: RHMax | AU4: RHMin | AV4: Rain | AW4: Wind | AX4: WindMax | AY4: Snow | AZ4: RHMin | BA4: Rain | BB4: Wind | BC4: WindMax | BD4: Snow
A5: 1 | B5: 24 | C5: 27.0375 | D5: -5.67275 | E5: -3.33 | F5: -9.134 | G5: 93.1875 | H5: 98.5 | I5: 79.2 | J5: 0 | K5: 0.75495833 | L5: 5.033 | M5: 0.19 | N5: 0.201 | Q5: =A5 -> 1 | R5: =B5 -> 24 | S5: =ROUND(C5*0.0864,2) -> 2.34 | T5: =ROUND(D5,1) -> -5.7 | U5: =ROUND(E5,1) -> -3.3 | V5: =ROUND(F5,1) -> -9.1 | W5: =ROUND(G5,1) -> 93.2 | X5: =ROUND(H5,1) -> 98.5 | Y5: =ROUND(I5,1) -> 79.2 | Z5: =ROUND(J5,2) -> 0 | AA5: =ROUND(K5,2) -> 0.75 | AB5: =ROUND(L5,2) -> 5.03 | AC5: =ROUND(M5,3) -> 0.19 | AD5: =ROUND(N5,3) -> 0.201 | AF5: NAN | AG5: =AF5 -> NAN | AH5: =ROUND((0.6105*(EXP((17.273*U5)/(U5+237.3))))*Y5/100,3) -> 0.379 | AI5: =ROUND(AH5/Y5*(100-Y5),3) -> 0.1 | AK5: 5.18 | AO5: 1.7 | AP5: -5.3 | AQ5: -2.8 | AR5: -8.5 | AS5: 92.5 | AT5: 94 | AU5: 90.1 | AV5: 0 | AW5: 0.72 | AX5: 3.07 | AY5: 0.854 | AZ5: 90.1 | BA5: 0 | BB5: 0.72 | BC5: 3.07 | BD5: 0.854
A6: 2 | B6: 24 | C6: 16.379167 | D6: -5.20775 | E6: -1.185 | F6: -9.508 | G6: 96.825 | H6: 98.6 | I6: 93.9 | J6: 0 | K6: 1.8453333 | L6: 9.562 | M6: 0.191 | N6: 0.201 | Q6: =A6 -> 2 | R6: =B6 -> 24 | S6: =ROUND(C6*0.0864,2) -> 1.42 | T6: =ROUND(D6,1) -> -5.2 | U6: =ROUND(E6,1) -> -1.2 | V6: =ROUND(F6,1) -> -9.5 | W6: =ROUND(G6,1) -> 96.8 | X6: =ROUND(H6,1) -> 98.6 | Y6: =ROUND(I6,1) -> 93.9 | Z6: =ROUND(J6,2) -> 0 | AA6: =ROUND(K6,2) -> 1.85 | AB6: =ROUND(L6,2) -> 9.56 | AC6: =ROUND(M6,3) -> 0.191 | AD6: =ROUND(N6,3) -> 0.201 | AF6: NAN | AG6: =AF6 -> NAN | AH6: =ROUND((0.6105*(EXP((17.273*U6)/(U6+237.3))))*Y6/100,3) -> 0.525 | AI6: =ROUND(AH6/Y6*(100-Y6),3) -> 0.034 | AK6: 5.22 | AO6: 1.28 | AP6: -4.1 | AQ6: -1.4 | AR6: -8.6 | AS6: 93.6 | AT6: 95.6 | AU6: 90.5 | AV6: 0 | AW6: 1.1 | AX6: 3.87 | AY6: 0.831 | AZ6: 90.5 | BA6: 0 | BB6: 1.1 | BC6: 3.87 | BD6: 0.831
A7: 3 | B7: 24 | C7: 20.416667 | D7: -3.7495833 | E7: -1.157 | F7: -8.099 | G7: 99.808333 | H7: 100 | I7: 98.4 | J7: 0 | K7: 1.5518333 | L7: 6.039 | M7: 0.191 | N7: 0.202 | Q7: =A7 -> 3 | R7: =B7 -> 24 | S7: =ROUND(C7*0.0864,2) -> 1.76 | T7: =ROUND(D7,1) -> -3.7 | U7: =ROUND(E7,1) -> -1.2 | V7: =ROUND(F7,1) -> -8.1 | W7: =ROUND(G7,1) -> 99.8 | X7: =ROUND(H7,1) -> 100 | Y7: =ROUND(I7,1) -> 98.4 | Z7: =ROUND(J7,2) -> 0 | AA7: =ROUND(K7,2) -> 1.55 | AB7: =ROUND(L7,2) -> 6.04 | AC7: =ROUND(M7,3) -> 0.191 | AD7: =ROUND(N7,3) -> 0.202 | AF7: NAN | AG7: =AF7 -> NAN | AH7: =ROUND((0.6105*(EXP((17.273*U7)/(U7+237.3))))*Y7/100,3) -> 0.55 | AI7: =ROUND(AH7/Y7*(100-Y7),3) -> 0.009 | AK7: 5.26 | AO7: 1.15 | AP7: -2.8 | AQ7: -1.3 | AR7: -4.7 | AS7: 94.7 | AT7: 96.1 | AU7: 93.3 | AV7: 0 | AW7: 1.93 | AX7: 5.09 | AY7: 0.823 | AZ7: 93.3 | BA7: 0 | BB7: 1.93 | BC7: 5.09 | BD7: 0.823
A8: 4 | B8: 24 | C8: 54.245833 | D8: -3.4182083 | E8: -1.356 | F8: -5.636 | G8: 95.666667 | H8: 100 | I8: 87.6 | J8: 0 | K8: 1.3630417 | L8: 8.556 | M8: 0.191 | N8: 0.202 | Q8: =A8 -> 4 | R8: =B8 -> 24 | S8: =ROUND(C8*0.0864,2) -> 4.69 | T8: =ROUND(D8,1) -> -3.4 | U8: =ROUND(E8,1) -> -1.4 | V8: =ROUND(F8,1) -> -5.6 | W8: =ROUND(G8,1) -> 95.7 | X8: =ROUND(H8,1) -> 100 | Y8: =ROUND(I8,1) -> 87.6 | Z8: =ROUND(J8,2) -> 0 | AA8: =ROUND(K8,2) -> 1.36 | AB8: =ROUND(L8,2) -> 8.56 | AC8: =ROUND(M8,3) -> 0.191 | AD8: =ROUND(N8,3) -> 0.202 | AF8: NAN | AG8: =AF8 -> NAN | AH8: =ROUND((0.6105*(EXP((17.273*U8)/(U8+237.3))))*Y8/100,3) -> 0.483 | AI8: =ROUND(AH8/Y8*(100-Y8),3) -> 0.068 | AK8: 5.31 | AO8: 4.38 | AP8: -3.4 | AQ8: -0.4 | AR8: -6.4 | AS8: 93.5 | AT8: 95.3 | AU8: 91.9 | AV8: 0 | AW8: 1.78 | AX8: 5.12 | AY8: 0.801 | AZ8: 91.9 | BA8: 0 | BB8: 1.78 | BC8: 5.12 | BD8: 0.801
A9: 5 | B9: 24 | C9: 26.020833 | D9: -4.2912083 | E9: -3.094 | F9: -5.388 | G9: 99.533333 | H9: 100 | I9: 96.6 | J9: 0 | K9: 2.830875 | L9: 12.078 | M9: 0.191 | N9: 0.203 | Q9: =A9 -> 5 | R9: =B9 -> 24 | S9: =ROUND(C9*0.0864,2) -> 2.25 | T9: =ROUND(D9,1) -> -4.3 | U9: =ROUND(E9,1) -> -3.1 | V9: =ROUND(F9,1) -> -5.4 | W9: =ROUND(G9,1) -> 99.5 | X9: =ROUND(H9,1) -> 100 | Y9: =ROUND(I9,1) -> 96.6 | Z9: =ROUND(J9,2) -> 0 | AA9: =ROUND(K9,2) -> 2.83 | AB9: =ROUND(L9,2) -> 12.08 | AC9: =ROUND(M9,3) -> 0.191 | AD9: =ROUND(N9,3) -> 0.203 | AF9: NAN | AG9: =AF9 -> NAN | AH9: =ROUND((0.6105*(EXP((17.273*U9)/(U9+237.3))))*Y9/100,3) -> 0.469 | AI9: =ROUND(AH9/Y9*(100-Y9),3) -> 0.017 | AK9: 5.36 | AO9: 1.68 | AP9: -4.3 | AQ9: -2.5 | AR9: -5.3 | AS9: 93.6 | AT9: 94 | AU9: 93.2 | AV9: 0 | AW9: 2.24 | AX9: 6.49 | AY9: 0.789 | AZ9: 93.2 | BA9: 0 | BB9: 2.24 | BC9: 6.49 | BD9: 0.789
A10: 6 | B10: 24 | C10: 59.7125 | D10: -6.2687917 | E10: -3.777 | F10: -10.406 | G10: 96.391667 | H10: 100 | I10: 82 | J10: 0 | K10: 3.019625 | L10: 11.575 | M10: 0.191 | N10: 0.204 | Q10: =A10 -> 6 | R10: =B10 -> 24 | S10: =ROUND(C10*0.0864,2) -> 5.16 | T10: =ROUND(D10,1) -> -6.3 | U10: =ROUND(E10,1) -> -3.8 | V10: =ROUND(F10,1) -> -10.4 | W10: =ROUND(G10,1) -> 96.4 | X10: =ROUND(H10,1) -> 100 | Y10: =ROUND(I10,1) -> 82 | Z10: =ROUND(J10,2) -> 0 | AA10: =ROUND(K10,2) -> 3.02 | AB10: =ROUND(L10,2) -> 11.58 | AC10: =ROUND(M10,3) -> 0.191 | AD10: =ROUND(N10,3) -> 0.204 | AF10: NAN | AG10: =AF10 -> NAN | AH10: =ROUND((0.6105*(EXP((17.273*U10)/(U10+237.3))))*Y10/100,3) -> 0.378 | AI10: =ROUND(AH10/Y10*(100-Y10),3) -> 0.083 | AK10: 5.41 | AO10: 4.08 | AP10: -6.3 | AQ10: -3.8 | AR10: -9.9 | AS10: 90.4 | AT10: 94.2 | AU10: 79.2 | AV10: 0 | AW10: 1.91 | AX10: 5.37 | AY10: 0.781 | AZ10: 79.2 | BA10: 0 | BB10: 1.91 | BC10: 5.37 | BD10: 0.781
A11: 7 | B11: 24 | C11: 69.295833 | D11: -10.136208 | E11: -7.575 | F11: -15.144 | G11: 91.520833 | H11: 98.6 | I11: 76.2 | J11: 0 | K11: 3.0615833 | L11: 14.092 | M11: 0.191 | N11: 0.204 | Q11: =A11 -> 7 | R11: =B11 -> 24 | S11: =ROUND(C11*0.0864,2) -> 5.99 | T11: =ROUND(D11,1) -> -10.1 | U11: =ROUND(E11,1) -> -7.6 | V11: =ROUND(F11,1) -> -15.1 | W11: =ROUND(G11,1) -> 91.5 | X11: =ROUND(H11,1) -> 98.6 | Y11: =ROUND(I11,1) -> 76.2 | Z11: =ROUND(J11,2) -> 0 | AA11: =ROUND(K11,2) -> 3.06 | AB11: =ROUND(L11,2) -> 14.09 | AC11: =ROUND(M11,3) -> 0.191 | AD11: =ROUND(N11,3) -> 0.204 | AF11: NAN | AG11: =AF11 -> NAN | AH11: =ROUND((0.6105*(EXP((17.273*U11)/(U11+237.3))))*Y11/100,3) -> 0.263 | AI11: =ROUND(AH11/Y11*(100-Y11),3) -> 0.082 | AK11: 5.47 | AO11: 5.05 | AP11: -10.2 | AQ11: -7.5 | AR11: -15 | AS11: 83.7 | AT11: 91 | AU11: 68.2 | AV11: 0 | AW11: 1.55 | AX11: 5.53 | AY11: 0.783 | AZ11: 68.2 | BA11: 0 | BB11: 1.55 | BC11: 5.53 | BD11: 0.783
A12: 8 | B12: 24 | C12: 23.983333 | D12: -11.399792 | E12: -8.463 | F12: -15.425 | G12: 83.804167 | H12: 96.8 | I12: 57.8 | J12: 0 | K12: 3.9002917 | L12: 12.078 | M12: 0.191 | N12: 0.204 | Q12: =A12 -> 8 | R12: =B12 -> 24 | S12: =ROUND(C12*0.0864,2) -> 2.07 | T12: =ROUND(D12,1) -> -11.4 | U12: =ROUND(E12,1) -> -8.5 | V12: =ROUND(F12,1) -> -15.4 | W12: =ROUND(G12,1) -> 83.8 | X12: =ROUND(H12,1) -> 96.8 | Y12: =ROUND(I12,1) -> 57.8 | Z12: =ROUND(J12,2) -> 0 | AA12: =ROUND(K12,2) -> 3.9 | AB12: =ROUND(L12,2) -> 12.08 | AC12: =ROUND(M12,3) -> 0.191 | AD12: =ROUND(N12,3) -> 0.204 | AF12: NAN | AG12: =AF12 -> NAN | AH12: =ROUND((0.6105*(EXP((17.273*U12)/(U12+237.3))))*Y12/100,3) -> 0.186 | AI12: =ROUND(AH12/Y12*(100-Y12),3) -> 0.136 | AK12: 5.53 | AO12: 1.86 | AP12: -11.4 | AQ12: -7.7 | AR12: -15.3 | AS12: 78.7 | AT12: 91.1 | AU12: 55 | AV12: 0 | AW12: 2.37 | AX12: 6.07 | AY12: 0.816 | AZ12: 55 | BA12: 0 | BB12: 2.37 | BC12: 6.07 | BD12: 0.816
A13: 9 | B13: 24 | C13: 18.254167 | D13: -4.0515833 | E13: -1.384 | F13: -7.64 | G13: 99.479167 | H13: 100 | I13: 97.3 | J13: 0 | K13: 2.4324583 | L13: 8.052 | M13: 0.191 | N13: 0.204 | Q13: =A13 -> 9 | R13: =B13 -> 24 | S13: =ROUND(C13*0.0864,2) -> 1.58 | T13: =ROUND(D13,1) -> -4.1 | U13: =ROUND(E13,1) -> -1.4 | V13: =ROUND(F13,1) -> -7.6 | W13: =ROUND(G13,1) -> 99.5 | X13: =ROUND(H13,1) -> 100 | Y13: =ROUND(I13,1) -> 97.3 | Z13: =ROUND(J13,2) -> 0 | AA13: =ROUND(K13,2) -> 2.43 | AB13: =ROUND(L13,2) -> 8.05 | AC13: =ROUND(M13,3) -> 0.191 | AD13: =ROUND(N13,3) -> 0.204 | AF13: NAN | AG13: =AF13 -> NAN | AH13: =ROUND((0.6105*(EXP((17.273*U13)/(U13+237.3))))*Y13/100,3) -> 0.536 | AI13: =ROUND(AH13/Y13*(100-Y13),3) -> 0.015 | AK13: 5.6 | AO13: 1.3 | AP13: -3.7 | AQ13: -1.7 | AR13: -7.2 | AS13: 94 | AT13: 95.6 | AU13: 91.5 | AV13: 0 | AW13: 2.14 | AX13: 5.25 | AY13: 0.809 | AZ13: 91.5 | BA13: 0 | BB13: 2.14 | BC13: 5.25 | BD13: 0.809
A14: 10 | B14: 24 | C14: 42.941667 | D14: -2.736875 | E14: 0.163 | F14: -4.378 | G14: 99.991667 | H14: 100 | I14: 99.8 | J14: 0 | K14: 1.3420833 | L14: 6.543 | M14: 0.191 | N14: 0.203 | Q14: =A14 -> 10 | R14: =B14 -> 24 | S14: =ROUND(C14*0.0864,2) -> 3.71 | T14: =ROUND(D14,1) -> -2.7 | U14: =ROUND(E14,1) -> 0.2 | V14: =ROUND(F14,1) -> -4.4 | W14: =ROUND(G14,1) -> 100 | X14: =ROUND(H14,1) -> 100 | Y14: =ROUND(I14,1) -> 99.8 | Z14: =ROUND(J14,2) -> 0 | AA14: =ROUND(K14,2) -> 1.34 | AB14: =ROUND(L14,2) -> 6.54 | AC14: =ROUND(M14,3) -> 0.191 | AD14: =ROUND(N14,3) -> 0.203 | AF14: NAN | AG14: =AF14 -> NAN | AH14: =ROUND((0.6105*(EXP((17.273*U14)/(U14+237.3))))*Y14/100,3) -> 0.618 | AI14: =ROUND(AH14/Y14*(100-Y14),3) -> 0.001 | AK14: 5.67 | AO14: 4.67 | AP14: -2.5 | AQ14: 1.3 | AR14: -4.4 | AS14: 94.6 | AT14: 96.3 | AU14: 92.6 | AV14: 0 | AW14: 1.22 | AX14: 3.65 | AY14: 0.804 | AZ14: 92.6 | BA14: 0 | BB14: 1.22 | BC14: 3.65 | BD14: 0.804
A15: 11 | B15: 24 | C15: 34.8125 | D15: -3.6397083 | E15: -1.242 | F15: -4.926 | G15: 100 | H15: 100 | I15: 100 | J15: 0 | K15: 1.4889167 | L15: 6.039 | M15: 0.191 | N15: 0.204 | Q15: =A15 -> 11 | R15: =B15 -> 24 | S15: =ROUND(C15*0.0864,2) -> 3.01 | T15: =ROUND(D15,1) -> -3.6 | U15: =ROUND(E15,1) -> -1.2 | V15: =ROUND(F15,1) -> -4.9 | W15: =ROUND(G15,1) -> 100 | X15: =ROUND(H15,1) -> 100 | Y15: =ROUND(I15,1) -> 100 | Z15: =ROUND(J15,2) -> 0 | AA15: =ROUND(K15,2) -> 1.49 | AB15: =ROUND(L15,2) -> 6.04 | AC15: =ROUND(M15,3) -> 0.191 | AD15: =ROUND(N15,3) -> 0.204 | AF15: NAN | AG15: =AF15 -> NAN | AH15: =ROUND((0.6105*(EXP((17.273*U15)/(U15+237.3))))*Y15/100,3) -> 0.559 | AI15: =ROUND(AH15/Y15*(100-Y15),3) -> 0 | AK15: 5.74 | AO15: 2.44 | AP15: -3.5 | AQ15: -0.7 | AR15: -4.9 | AS15: 94.1 | AT15: 95 | AU15: 93.4 | AV15: 0 | AW15: 1.71 | AX15: 4.37 | AY15: 0.803 | AZ15: 93.4 | BA15: 0 | BB15: 1.71 | BC15: 4.37 | BD15: 0.803
A16: 12 | B16: 24 | C16: 60.758333 | D16: -3.432875 | E16: -1.128 | F16: -4.621 | G16: 97.65 | H16: 100 | I16: 84.3 | J16: 0 | K16: 2.5165417 | L16: 7.549 | M16: 0.191 | N16: 0.204 | Q16: =A16 -> 12 | R16: =B16 -> 24 | S16: =ROUND(C16*0.0864,2) -> 5.25 | T16: =ROUND(D16,1) -> -3.4 | U16: =ROUND(E16,1) -> -1.1 | V16: =ROUND(F16,1) -> -4.6 | W16: =ROUND(G16,1) -> 97.7 | X16: =ROUND(H16,1) -> 100 | Y16: =ROUND(I16,1) -> 84.3 | Z16: =ROUND(J16,2) -> 0 | AA16: =ROUND(K16,2) -> 2.52 | AB16: =ROUND(L16,2) -> 7.55 | AC16: =ROUND(M16,3) -> 0.191 | AD16: =ROUND(N16,3) -> 0.204 | AF16: NAN | AG16: =AF16 -> NAN | AH16: =ROUND((0.6105*(EXP((17.273*U16)/(U16+237.3))))*Y16/100,3) -> 0.475 | AI16: =ROUND(AH16/Y16*(100-Y16),3) -> 0.088 | AK16: 5.82 | AO16: 4.83 | AP16: -3.3 | AQ16: -1.2 | AR16: -4.3 | AS16: 85.4 | AT16: 93.5 | AU16: 71 | AV16: 0 | AW16: 1.67 | AX16: 3.92 | AY16: 0.776 | AZ16: 71 | BA16: 0 | BB16: 1.67 | BC16: 3.92 | BD16: 0.776
... A73: 69 | B73: 24 | C73: 190.39583 | D73: -8.2003333 | E73: -1.015 | F73: -14.471 | G73: 77.329167 | H73: 92.3 | I73: 56.1 | J73: 2.8 | K73: 1.2163333 | L73: 6.039 | M73: 0.19 | N73: 0.199 | Q73: =A73 -> 69 | R73: =B73 -> 24 | S73: =ROUND(C73*0.0864,2) -> 16.45 | T73: =ROUND(D73,1) -> -8.2 | U73: =ROUND(E73,1) -> -1 | V73: =ROUND(F73,1) -> -14.5 | W73: =ROUND(G73,1) -> 77.3 | X73: =ROUND(H73,1) -> 92.3 | Y73: =ROUND(I73,1) -> 56.1 | Z73: =ROUND(J73,2) -> 2.8 | AA73: =ROUND(K73,2) -> 1.22 | AB73: =ROUND(L73,2) -> 6.04 | AC73: =ROUND(M73,3) -> 0.19 | AD73: =ROUND(N73,3) -> 0.199 | AF73: NAN | AG73: =AF73 -> NAN | AH73: =ROUND((0.6105*(EXP((17.273*U73)/(U73+237.3))))*Y73/100,3) -> 0.318 | AI73: =ROUND(AH73/Y73*(100-Y73),3) -> 0.249 | AK73: 15.88 | AO73: 13.8 | AP73: -7.4 | AQ73: 0.2 | AR73: -14 | AS73: 70.7 | AT73: 86 | AU73: 38.9 | AV73: 0 | AW73: 0.94 | AX73: 3.1 | AY73: 1.142 | AZ73: 38.9 | BA73: 0 | BB73: 0.94 | BC73: 3.1 | BD73: 1.142
A74: 70 | B74: 24 | C74: 80.55 | D74: -8.403 | E74: -6.231 | F74: -10.441 | G74: 78.966667 | H74: 91 | I74: 65.2 | J74: 0 | K74: 4.068 | L74: 11.575 | M74: 0.189 | N74: 0.199 | O74: 0.866 | Q74: =A74 -> 70 | R74: =B74 -> 24 | S74: =ROUND(C74*0.0864,2) -> 6.96 | T74: =ROUND(D74,1) -> -8.4 | U74: =ROUND(E74,1) -> -6.2 | V74: =ROUND(F74,1) -> -10.4 | W74: =ROUND(G74,1) -> 79 | X74: =ROUND(H74,1) -> 91 | Y74: =ROUND(I74,1) -> 65.2 | Z74: =ROUND(J74,2) -> 0 | AA74: =ROUND(K74,2) -> 4.07 | AB74: =ROUND(L74,2) -> 11.58 | AC74: =ROUND(M74,3) -> 0.189 | AD74: =ROUND(N74,3) -> 0.199 | AE74: =ROUND(O74-AE$2,3) -> 0.866 | AF74: NAN | AG74: =AF74 -> NAN | AH74: =ROUND((0.6105*(EXP((17.273*U74)/(U74+237.3))))*Y74/100,3) -> 0.25 | AI74: =ROUND(AH74/Y74*(100-Y74),3) -> 0.133 | AK74: 16.13 | AO74: 7.33 | AP74: -7.9 | AQ74: -5.6 | AR74: -10 | AS74: 73.2 | AT74: 87 | AU74: 62.5 | AV74: 0 | AW74: 1.87 | AX74: 4.64 | AY74: 1.126 | AZ74: 62.5 | BA74: 0 | BB74: 1.87 | BC74: 4.64 | BD74: 1.126
A75: 71 | B75: 24 | C75: 82.5 | D75: -7.2385833 | E75: -5.76 | F75: -9.61 | G75: 95.1875 | H75: 96.3 | I75: 91.4 | J75: 0 | K75: 1.8034583 | L75: 10.569 | M75: 0.189 | N75: 0.199 | O75: 0.878 | Q75: =A75 -> 71 | R75: =B75 -> 24 | S75: =ROUND(C75*0.0864,2) -> 7.13 | T75: =ROUND(D75,1) -> -7.2 | U75: =ROUND(E75,1) -> -5.8 | V75: =ROUND(F75,1) -> -9.6 | W75: =ROUND(G75,1) -> 95.2 | X75: =ROUND(H75,1) -> 96.3 | Y75: =ROUND(I75,1) -> 91.4 | Z75: =ROUND(J75,2) -> 0 | AA75: =ROUND(K75,2) -> 1.8 | AB75: =ROUND(L75,2) -> 10.57 | AC75: =ROUND(M75,3) -> 0.189 | AD75: =ROUND(N75,3) -> 0.199 | AE75: =ROUND(O75-AE$2,3) -> 0.878 | AF75: =IF(AE75>AE74,ROUND((AE75-AE74)*130,1),0) -> 1.6 | AG75: =AF75 -> 1.6 | AH75: =ROUND((0.6105*(EXP((17.273*U75)/(U75+237.3))))*Y75/100,3) -> 0.362 | AI75: =ROUND(AH75/Y75*(100-Y75),3) -> 0.034 | AK75: 16.39 | AO75: 4.98 | AP75: -7.2 | AQ75: -5.7 | AR75: -9.9 | AS75: 88.6 | AT75: 91.1 | AU75: 82.9 | AV75: 0 | AW75: 1.13 | AX75: 5.24 | AY75: 1.137 | AZ75: 82.9 | BA75: 0 | BB75: 1.13 | BC75: 5.24 | BD75: 1.137
A76: 72 | B76: 24 | C76: 159.425 | D76: -7.7479583 | E76: -2.537 | F76: -10.969 | G76: 80.041667 | H76: 94.8 | I76: 54.5 | J76: 0.2 | K76: 1.7195833 | L76: 8.556 | M76: 0.189 | N76: 0.199 | O76: 0.892 | Q76: =A76 -> 72 | R76: =B76 -> 24 | S76: =ROUND(C76*0.0864,2) -> 13.77 | T76: =ROUND(D76,1) -> -7.7 | U76: =ROUND(E76,1) -> -2.5 | V76: =ROUND(F76,1) -> -11 | W76: =ROUND(G76,1) -> 80 | X76: =ROUND(H76,1) -> 94.8 | Y76: =ROUND(I76,1) -> 54.5 | Z76: =ROUND(J76,2) -> 0.2 | AA76: =ROUND(K76,2) -> 1.72 | AB76: =ROUND(L76,2) -> 8.56 | AC76: =ROUND(M76,3) -> 0.189 | AD76: =ROUND(N76,3) -> 0.199 | AE76: =ROUND(O76-AE$2,3) -> 0.892 | AF76: =IF(AE76>AE75,ROUND((AE76-AE75)*130,1),0) -> 1.8 | AG76: =AF76 -> 1.8 | AH76: =ROUND((0.6105*(EXP((17.273*U76)/(U76+237.3))))*Y76/100,3) -> 0.277 | AI76: =ROUND(AH76/Y76*(100-Y76),3) -> 0.231 | AK76: 16.64 | AO76: 12.44 | AP76: -7.8 | AQ76: -2.5 | AR76: -11.1 | AS76: 72 | AT76: 85.5 | AU76: 48.5 | AV76: 0 | AW76: 1.09 | AX76: 3.83 | AY76: 1.127 | AZ76: 48.5 | BA76: 0 | BB76: 1.09 | BC76: 3.83 | BD76: 1.127
A77: 73 | B77: 24 | C77: 149.52917 | D77: -5.15475 | E77: -0.93 | F77: -10.371 | G77: 70.4375 | H77: 87.1 | I77: 50.5 | J77: 1.6 | K77: 1.0065 | L77: 6.543 | M77: 0.189 | N77: 0.199 | O77: 0.879 | Q77: =A77 -> 73 | R77: =B77 -> 24 | S77: =ROUND(C77*0.0864,2) -> 12.92 | T77: =ROUND(D77,1) -> -5.2 | U77: =ROUND(E77,1) -> -0.9 | V77: =ROUND(F77,1) -> -10.4 | W77: =ROUND(G77,1) -> 70.4 | X77: =ROUND(H77,1) -> 87.1 | Y77: =ROUND(I77,1) -> 50.5 | Z77: =ROUND(J77,2) -> 1.6 | AA77: =ROUND(K77,2) -> 1.01 | AB77: =ROUND(L77,2) -> 6.54 | AC77: =ROUND(M77,3) -> 0.189 | AD77: =ROUND(N77,3) -> 0.199 | AE77: =ROUND(O77-AE$2,3) -> 0.879 | AF77: =IF(AE77>AE76,ROUND((AE77-AE76)*130,1),0) -> 0 | AG77: =AF77 -> 0 | AH77: =ROUND((0.6105*(EXP((17.273*U77)/(U77+237.3))))*Y77/100,3) -> 0.289 | AI77: =ROUND(AH77/Y77*(100-Y77),3) -> 0.283 | AK77: 16.9 | AO77: 11.92 | AP77: -4.4 | AQ77: 1.6 | AR77: -10.1 | AS77: 62.4 | AT77: 84 | AU77: 38.5 | AV77: 0 | AW77: 0.91 | AX77: 3.57 | AY77: 1.117 | AZ77: 38.5 | BA77: 0 | BB77: 0.91 | BC77: 3.57 | BD77: 1.117
A78: 74 | B78: 24 | C78: 145.10417 | D78: -2.9555 | E78: 2.262 | F78: -6.01 | G78: 79.675 | H78: 89.8 | I78: 56.6 | J78: 0 | K78: 2.2017917 | L78: 9.059 | M78: 0.189 | N78: 0.199 | O78: 0.84 | Q78: =A78 -> 74 | R78: =B78 -> 24 | S78: =ROUND(C78*0.0864,2) -> 12.54 | T78: =ROUND(D78,1) -> -3 | U78: =ROUND(E78,1) -> 2.3 | V78: =ROUND(F78,1) -> -6 | W78: =ROUND(G78,1) -> 79.7 | X78: =ROUND(H78,1) -> 89.8 | Y78: =ROUND(I78,1) -> 56.6 | Z78: =ROUND(J78,2) -> 0 | AA78: =ROUND(K78,2) -> 2.2 | AB78: =ROUND(L78,2) -> 9.06 | AC78: =ROUND(M78,3) -> 0.189 | AD78: =ROUND(N78,3) -> 0.199 | AE78: =ROUND(O78-AE$2,3) -> 0.84 | AF78: =IF(AE78>AE77,ROUND((AE78-AE77)*130,1),0) -> 0 | AG78: =AF78 -> 0 | AH78: =ROUND((0.6105*(EXP((17.273*U78)/(U78+237.3))))*Y78/100,3) -> 0.408 | AI78: =ROUND(AH78/Y78*(100-Y78),3) -> 0.313 | AK78: 17.16 | AO78: 10.98 | AP78: -2.2 | AQ78: 5 | AR78: -6.1 | AS78: 72.7 | AT78: 87.8 | AU78: 42.2 | AV78: 0 | AW78: 1.23 | AX78: 4.09 | AY78: 1.09 | AZ78: 42.2 | BA78: 0 | BB78: 1.23 | BC78: 4.09 | BD78: 1.09
A79: 75 | B79: 24 | C79: 188.125 | D79: -1.2759167 | E79: 4.324 | F79: -6.42 | G79: 74.129167 | H79: 89.5 | I79: 49.4 | J79: 0 | K79: 1.7615 | L79: 5.536 | M79: 0.189 | N79: 0.199 | O79: 0.838 | Q79: =A79 -> 75 | R79: =B79 -> 24 | S79: =ROUND(C79*0.0864,2) -> 16.25 | T79: =ROUND(D79,1) -> -1.3 | U79: =ROUND(E79,1) -> 4.3 | V79: =ROUND(F79,1) -> -6.4 | W79: =ROUND(G79,1) -> 74.1 | X79: =ROUND(H79,1) -> 89.5 | Y79: =ROUND(I79,1) -> 49.4 | Z79: =ROUND(J79,2) -> 0 | AA79: =ROUND(K79,2) -> 1.76 | AB79: =ROUND(L79,2) -> 5.54 | AC79: =ROUND(M79,3) -> 0.189 | AD79: =ROUND(N79,3) -> 0.199 | AE79: =ROUND(O79-AE$2,3) -> 0.838 | AF79: =IF(AE79>AE78,ROUND((AE79-AE78)*130,1),0) -> 0 | AG79: =AF79 -> 0 | AH79: =ROUND((0.6105*(EXP((17.273*U79)/(U79+237.3))))*Y79/100,3) -> 0.41 | AI79: =ROUND(AH79/Y79*(100-Y79),3) -> 0.42 | AK79: 17.42 | AO79: 15.21 | AP79: -0.3 | AQ79: 7.8 | AR79: -5.5 | AS79: 65.8 | AT79: 85 | AU79: 34.9 | AV79: 0 | AW79: 0.99 | AX79: 2.92 | AY79: 1.066 | AZ79: 34.9 | BA79: 0 | BB79: 0.99 | BC79: 2.92 | BD79: 1.066
A80: 76 | B80: 24 | C80: 207.82083 | D80: 1.38725 | E80: 5.898 | F80: -3.568 | G80: 60.4375 | H80: 86.4 | I80: 39.6 | J80: 0 | K80: 2.432625 | L80: 9.059 | M80: 0.19 | N80: 0.202 | O80: 0.809 | Q80: =A80 -> 76 | R80: =B80 -> 24 | S80: =ROUND(C80*0.0864,2) -> 17.96 | T80: =ROUND(D80,1) -> 1.4 | U80: =ROUND(E80,1) -> 5.9 | V80: =ROUND(F80,1) -> -3.6 | W80: =ROUND(G80,1) -> 60.4 | X80: =ROUND(H80,1) -> 86.4 | Y80: =ROUND(I80,1) -> 39.6 | Z80: =ROUND(J80,2) -> 0 | AA80: =ROUND(K80,2) -> 2.43 | AB80: =ROUND(L80,2) -> 9.06 | AC80: =ROUND(M80,3) -> 0.19 | AD80: =ROUND(N80,3) -> 0.202 | AE80: =ROUND(O80-AE$2,3) -> 0.809 | AF80: =IF(AE80>AE79,ROUND((AE80-AE79)*130,1),0) -> 0 | AG80: =AF80 -> 0 | AH80: =ROUND((0.6105*(EXP((17.273*U80)/(U80+237.3))))*Y80/100,3) -> 0.368 | AI80: =ROUND(AH80/Y80*(100-Y80),3) -> 0.561 | AK80: 17.68 | AO80: 16.43 | AP80: 1.5 | AQ80: 6.1 | AR80: -2.9 | AS80: 54.5 | AT80: 78.7 | AU80: 36.2 | AV80: 0 | AW80: 1.76 | AX80: 4.94 | AY80: 1.039 | AZ80: 36.2 | BA80: 0 | BB80: 1.76 | BC80: 4.94 | BD80: 1.039
A81: 77 | B81: 24 | C81: 212.8125 | D81: 3.4444583 | E81: 8.419 | F81: -2.305 | G81: 43.4125 | H81: 61 | I81: 24.3 | J81: 0 | K81: 2.1389167 | L81: 9.562 | M81: 0.191 | N81: 0.21 | O81: 0.771 | Q81: =A81 -> 77 | R81: =B81 -> 24 | S81: =ROUND(C81*0.0864,2) -> 18.39 | T81: =ROUND(D81,1) -> 3.4 | U81: =ROUND(E81,1) -> 8.4 | V81: =ROUND(F81,1) -> -2.3 | W81: =ROUND(G81,1) -> 43.4 | X81: =ROUND(H81,1) -> 61 | Y81: =ROUND(I81,1) -> 24.3 | Z81: =ROUND(J81,2) -> 0 | AA81: =ROUND(K81,2) -> 2.14 | AB81: =ROUND(L81,2) -> 9.56 | AC81: =ROUND(M81,3) -> 0.191 | AD81: =ROUND(N81,3) -> 0.21 | AE81: =ROUND(O81-AE$2,3) -> 0.771 | AF81: =IF(AE81>AE80,ROUND((AE81-AE80)*130,1),0) -> 0 | AG81: =AF81 -> 0 | AH81: =ROUND((0.6105*(EXP((17.273*U81)/(U81+237.3))))*Y81/100,3) -> 0.268 | AI81: =ROUND(AH81/Y81*(100-Y81),3) -> 0.835 | AK81: 17.94 | AO81: 16.94 | AP81: 4.3 | AQ81: 11.2 | AR81: -1.9 | AS81: 38.8 | AT81: 55.1 | AU81: 18.5 | AV81: 0 | AW81: 1.39 | AX81: 4.28 | AY81: 1.008 | AZ81: 18.5 | BA81: 0 | BB81: 1.39 | BC81: 4.28 | BD81: 1.008
A82: 78 | B82: 24 | C82: 214.68333 | D82: 6.0013333 | E82: 11.321 | F82: 0.797 | G82: 35.529167 | H82: 51.1 | I82: 25.7 | J82: 0 | K82: 1.9921667 | L82: 7.046 | M82: 0.194 | N82: 0.232 | O82: 0.702 | Q82: =A82 -> 78 | R82: =B82 -> 24 | S82: =ROUND(C82*0.0864,2) -> 18.55 | T82: =ROUND(D82,1) -> 6 | U82: =ROUND(E82,1) -> 11.3 | V82: =ROUND(F82,1) -> 0.8 | W82: =ROUND(G82,1) -> 35.5 | X82: =ROUND(H82,1) -> 51.1 | Y82: =ROUND(I82,1) -> 25.7 | Z82: =ROUND(J82,2) -> 0 | AA82: =ROUND(K82,2) -> 1.99 | AB82: =ROUND(L82,2) -> 7.05 | AC82: =ROUND(M82,3) -> 0.194 | AD82: =ROUND(N82,3) -> 0.232 | AE82: =ROUND(O82-AE$2,3) -> 0.702 | AF82: =IF(AE82>AE81,ROUND((AE82-AE81)*130,1),0) -> 0 | AG82: =AF82 -> 0 | AH82: =ROUND((0.6105*(EXP((17.273*U82)/(U82+237.3))))*Y82/100,3) -> 0.344 | AI82: =ROUND(AH82/Y82*(100-Y82),3) -> 0.995 | AK82: 18.2 | AO82: 17.18 | AP82: 6.7 | AQ82: 12.9 | AR82: 1.3 | AS82: 31.6 | AT82: 47 | AU82: 20.2 | AV82: 0 | AW82: 1.21 | AX82: 3.53 | AY82: 0.974 | AZ82: 20.2 | BA82: 0 | BB82: 1.21 | BC82: 3.53 | BD82: 0.974
A83: 79 | B83: 24 | C83: 217.92083 | D83: 7.992375 | E83: 12.364 | F83: 2.93 | G83: 31.004167 | H83: 39.8 | I83: 22.5 | J83: 0 | K83: 2.0550417 | L83: 9.059 | M83: 0.198 | N83: 0.249 | O83: 0.652 | Q83: =A83 -> 79 | R83: =B83 -> 24 | S83: =ROUND(C83*0.0864,2) -> 18.83 | T83: =ROUND(D83,1) -> 8 | U83: =ROUND(E83,1) -> 12.4 | V83: =ROUND(F83,1) -> 2.9 | W83: =ROUND(G83,1) -> 31 | X83: =ROUND(H83,1) -> 39.8 | Y83: =ROUND(I83,1) -> 22.5 | Z83: =ROUND(J83,2) -> 0 | AA83: =ROUND(K83,2) -> 2.06 | AB83: =ROUND(L83,2) -> 9.06 | AC83: =ROUND(M83,3) -> 0.198 | AD83: =ROUND(N83,3) -> 0.249 | AE83: =ROUND(O83-AE$2,3) -> 0.652 | AF83: =IF(AE83>AE82,ROUND((AE83-AE82)*130,1),0) -> 0 | AG83: =AF83 -> 0 | AH83: =ROUND((0.6105*(EXP((17.273*U83)/(U83+237.3))))*Y83/100,3) -> 0.324 | AI83: =ROUND(AH83/Y83*(100-Y83),3) -> 1.116 | AK83: 18.47 | AO83: 17.44 | AP83: 8.3 | AQ83: 14.7 | AR83: 3.5 | AS83: 30.1 | AT83: 41.7 | AU83: 18.4 | AV83: 0 | AW83: 1.6 | AX83: 4.09 | AY83: 0.938 | AZ83: 18.4 | BA83: 0 | BB83: 1.6 | BC83: 4.09 | BD83: 0.938
A84: 80 | B84: 24 | C84: 214.425 | D84: 6.613375 | E84: 11.88 | F84: 2.423 | G84: 34.116667 | H84: 50.3 | I84: 24.4 | J84: 0 | K84: 1.6985 | L84: 6.039 | M84: 0.201 | N84: 0.263 | O84: 0.629 | Q84: =A84 -> 80 | R84: =B84 -> 24 | S84: =ROUND(C84*0.0864,2) -> 18.53 | T84: =ROUND(D84,1) -> 6.6 | U84: =ROUND(E84,1) -> 11.9 | V84: =ROUND(F84,1) -> 2.4 | W84: =ROUND(G84,1) -> 34.1 | X84: =ROUND(H84,1) -> 50.3 | Y84: =ROUND(I84,1) -> 24.4 | Z84: =ROUND(J84,2) -> 0 | AA84: =ROUND(K84,2) -> 1.7 | AB84: =ROUND(L84,2) -> 6.04 | AC84: =ROUND(M84,3) -> 0.201 | AD84: =ROUND(N84,3) -> 0.263 | AE84: =ROUND(O84-AE$2,3) -> 0.629 | AF84: =IF(AE84>AE83,ROUND((AE84-AE83)*130,1),0) -> 0 | AG84: =AF84 -> 0 | AH84: =ROUND((0.6105*(EXP((17.273*U84)/(U84+237.3))))*Y84/100,3) -> 0.34 | AI84: =ROUND(AH84/Y84*(100-Y84),3) -> 1.053 | AK84: 18.73 | AO84: 17.2 | AP84: 7.7 | AQ84: 14.7 | AR84: 2.4 | AS84: 29.4 | AT84: 42.2 | AU84: 20.3 | AV84: 0 | AW84: 1.12 | AX84: 3.29 | AY84: 0.917 | AZ84: 20.3 | BA84: 0 | BB84: 1.12 | BC84: 3.29 | BD84: 0.917
A85: 81 | B85: 24 | C85: 215.00417 | D85: 5.2675 | E85: 9.78 | F85: 0.632 | G85: 45.116667 | H85: 90.2 | I85: 30.5 | J85: 0 | K85: 1.9711667 | L85: 7.549 | M85: 0.204 | N85: 0.276 | O85: 0.602 | Q85: =A85 -> 81 | R85: =B85 -> 24 | S85: =ROUND(C85*0.0864,2) -> 18.58 | T85: =ROUND(D85,1) -> 5.3 | U85: =ROUND(E85,1) -> 9.8 | V85: =ROUND(F85,1) -> 0.6 | W85: =ROUND(G85,1) -> 45.1 | X85: =ROUND(H85,1) -> 90.2 | Y85: =ROUND(I85,1) -> 30.5 | Z85: =ROUND(J85,2) -> 0 | AA85: =ROUND(K85,2) -> 1.97 | AB85: =ROUND(L85,2) -> 7.55 | AC85: =ROUND(M85,3) -> 0.204 | AD85: =ROUND(N85,3) -> 0.276 | AE85: =ROUND(O85-AE$2,3) -> 0.602 | AF85: =IF(AE85>AE84,ROUND((AE85-AE84)*130,1),0) -> 0 | AG85: =AF85 -> 0 | AH85: =ROUND((0.6105*(EXP((17.273*U85)/(U85+237.3))))*Y85/100,3) -> 0.369 | AI85: =ROUND(AH85/Y85*(100-Y85),3) -> 0.841 | AK85: 18.99 | AO85: 16.84 | AP85: 6.1 | AQ85: 12.5 | AR85: 0.6 | AS85: 42.8 | AT85: 92.1 | AU85: 23.9 | AV85: 0 | AW85: 1.27 | AX85: 3.94 | AY85: 0.893 | AZ85: 23.9 | BA85: 0 | BB85: 1.27 | BC85: 3.94 | BD85: 0.893
A86: 82 | B86: 24 | C86: 87.0375 | D86: 1.290625 | E86: 3.932 | F86: -0.507 | G86: 80.316667 | H86: 97.1 | I86: 63.6 | J86: 0.2 | K86: 1.3420833 | L86: 5.536 | M86: 0.205 | N86: 0.265 | O86: 0.594 | Q86: =A86 -> 82 | R86: =B86 -> 24 | S86: =ROUND(C86*0.0864,2) -> 7.52 | T86: =ROUND(D86,1) -> 1.3 | U86: =ROUND(E86,1) -> 3.9 | V86: =ROUND(F86,1) -> -0.5 | W86: =ROUND(G86,1) -> 80.3 | X86: =ROUND(H86,1) -> 97.1 | Y86: =ROUND(I86,1) -> 63.6 | Z86: =ROUND(J86,2) -> 0.2 | AA86: =ROUND(K86,2) -> 1.34 | AB86: =ROUND(L86,2) -> 5.54 | AC86: =ROUND(M86,3) -> 0.205 | AD86: =ROUND(N86,3) -> 0.265 | AE86: =ROUND(O86-AE$2,3) -> 0.594 | AF86: =IF(AE86>AE85,ROUND((AE86-AE85)*130,1),0) -> 0 | AG86: =AF86 -> 0 | AH86: =ROUND((0.6105*(EXP((17.273*U86)/(U86+237.3))))*Y86/100,3) -> 0.513 | AI86: =ROUND(AH86/Y86*(100-Y86),3) -> 0.294 | AK86: 19.25 | AO86: 7.48 | AP86: 1.5 | AQ86: 4.8 | AR86: -0.5 | AS86: 76.6 | AT86: 95.2 | AU86: 57 | AV86: 0 | AW86: 1.08 | AX86: 3.41 | AY86: 0.891 | AZ86: 57 | BA86: 0 | BB86: 1.08 | BC86: 3.41 | BD86: 0.891
... A130: 126 | B130: 24 | C130: 302.94583 | D130: 5.7863333 | E130: 11.127 | F130: 1.262 | G130: 54.720833 | H130: 73.8 | I130: 37.8 | J130: 0 | K130: 1.803375 | L130: 10.065 | M130: 0.317 | N130: 0.348 | O130: 0.001 | Q130: =A130 -> 126 | R130: =B130 -> 24 | S130: =ROUND(C130*0.0864,2) -> 26.17 | T130: =ROUND(D130,1) -> 5.8 | U130: =ROUND(E130,1) -> 11.1 | V130: =ROUND(F130,1) -> 1.3 | W130: =ROUND(G130,1) -> 54.7 | X130: =ROUND(H130,1) -> 73.8 | Y130: =ROUND(I130,1) -> 37.8 | Z130: =ROUND(J130,2) -> 0 | AA130: =ROUND(K130,2) -> 1.8 | AB130: =ROUND(L130,2) -> 10.07 | AC130: =ROUND(M130,3) -> 0.317 | AD130: =ROUND(N130,3) -> 0.348 | AE130: =ROUND(O130-AE$2,3) -> 0.001 | AF130: =IF(AE130>AE129,ROUND((AE130-AE129)*130,1),0) -> 0 | AG130: =AF130 -> 0 | AH130: =ROUND((0.6105*(EXP((17.273*U130)/(U130+237.3))))*Y130/100,3) -> 0.499 | AI130: =ROUND(AH130/Y130*(100-Y130),3) -> 0.821 | AK130: 29.55 | AO130: 23.35 | AP130: 5.9 | AQ130: 11 | AR130: 1 | AS130: 51.4 | AT130: 73.4 | AU130: 34.1 | AV130: 0 | AW130: 1.25 | AX130: 4.44 | AY130: 0.444 | AZ130: 34.1 | BA130: 0 | BB130: 1.25 | BC130: 4.44 | BD130: 0.444
A131: 127 | B131: 24 | C131: 315.23333 | D131: 5.9213333 | E131: 10.541 | F131: 1.453 | G131: 58.8625 | H131: 80.4 | I131: 42.3 | J131: 0 | K131: 1.5307917 | L131: 8.556 | M131: 0.322 | N131: 0.349 | O131: 0 | Q131: =A131 -> 127 | R131: =B131 -> 24 | S131: =ROUND(C131*0.0864,2) -> 27.24 | T131: =ROUND(D131,1) -> 5.9 | U131: =ROUND(E131,1) -> 10.5 | V131: =ROUND(F131,1) -> 1.5 | W131: =ROUND(G131,1) -> 58.9 | X131: =ROUND(H131,1) -> 80.4 | Y131: =ROUND(I131,1) -> 42.3 | Z131: =ROUND(J131,2) -> 0 | AA131: =ROUND(K131,2) -> 1.53 | AB131: =ROUND(L131,2) -> 8.56 | AC131: =ROUND(M131,3) -> 0.322 | AD131: =ROUND(N131,3) -> 0.349 | AE131: =ROUND(O131-AE$2,3) -> 0 | AG131: =Z131 -> 0 | AH131: =ROUND((0.6105*(EXP((17.273*U131)/(U131+237.3))))*Y131/100,3) -> 0.537 | AI131: =ROUND(AH131/Y131*(100-Y131),3) -> 0.733 | AK131: 29.72 | AO131: 26.04 | AP131: 5.8 | AQ131: 10.5 | AR131: 1.1 | AS131: 55.9 | AT131: 80.7 | AU131: 39 | AV131: 0 | AW131: 1.12 | AX131: 4.8 | AY131: 0.385 | AZ131: 39 | BA131: 0 | BB131: 1.12 | BC131: 4.8 | BD131: 0.385
A132: 128 | B132: 24 | C132: 262.89583 | D132: 6.4112917 | E132: 11.273 | F132: 2.289 | G132: 57.479167 | H132: 66.6 | I132: 44.6 | J132: 0 | K132: 1.2372083 | L132: 7.549 | M132: 0.319 | N132: 0.352 | O132: 0 | Q132: =A132 -> 128 | R132: =B132 -> 24 | S132: =ROUND(C132*0.0864,2) -> 22.71 | T132: =ROUND(D132,1) -> 6.4 | U132: =ROUND(E132,1) -> 11.3 | V132: =ROUND(F132,1) -> 2.3 | W132: =ROUND(G132,1) -> 57.5 | X132: =ROUND(H132,1) -> 66.6 | Y132: =ROUND(I132,1) -> 44.6 | Z132: =ROUND(J132,2) -> 0 | AA132: =ROUND(K132,2) -> 1.24 | AB132: =ROUND(L132,2) -> 7.55 | AC132: =ROUND(M132,3) -> 0.319 | AD132: =ROUND(N132,3) -> 0.352 | AE132: =ROUND(O132-AE$2,3) -> 0 | AG132: =Z132 -> 0 | AH132: =ROUND((0.6105*(EXP((17.273*U132)/(U132+237.3))))*Y132/100,3) -> 0.597 | AI132: =ROUND(AH132/Y132*(100-Y132),3) -> 0.742 | AK132: 29.89 | AO132: 22.49 | AP132: 6.2 | AQ132: 10.9 | AR132: 2.8 | AS132: 55.4 | AT132: 65.7 | AU132: 41.3 | AV132: 0 | AW132: 0.98 | AX132: 4.44 | AY132: 0.317 | AZ132: 41.3 | BA132: 0 | BB132: 0.98 | BC132: 4.44 | BD132: 0.317
A133: 129 | B133: 24 | C133: 323.45833 | D133: 8.2125417 | E133: 14.697 | F133: 2.423 | G133: 45.570833 | H133: 61.7 | I133: 30.1 | J133: 0 | K133: 1.7824583 | L133: 7.549 | M133: 0.306 | N133: 0.352 | O133: 0 | Q133: =A133 -> 129 | R133: =B133 -> 24 | S133: =ROUND(C133*0.0864,2) -> 27.95 | T133: =ROUND(D133,1) -> 8.2 | U133: =ROUND(E133,1) -> 14.7 | V133: =ROUND(F133,1) -> 2.4 | W133: =ROUND(G133,1) -> 45.6 | X133: =ROUND(H133,1) -> 61.7 | Y133: =ROUND(I133,1) -> 30.1 | Z133: =ROUND(J133,2) -> 0 | AA133: =ROUND(K133,2) -> 1.78 | AB133: =ROUND(L133,2) -> 7.55 | AC133: =ROUND(M133,3) -> 0.306 | AD133: =ROUND(N133,3) -> 0.352 | AE133: =ROUND(O133-AE$2,3) -> 0 | AG133: =Z133 -> 0 | AH133: =ROUND((0.6105*(EXP((17.273*U133)/(U133+237.3))))*Y133/100,3) -> 0.503 | AI133: =ROUND(AH133/Y133*(100-Y133),3) -> 1.168 | AK133: 30.06 | AO133: 26.77 | AP133: 8.4 | AQ133: 14.2 | AR133: 2.8 | AS133: 40.7 | AT133: 55.3 | AU133: 27.1 | AV133: 0 | AW133: 1.28 | AX133: 4.2 | AY133: 0.26 | AZ133: 27.1 | BA133: 0 | BB133: 1.28 | BC133: 4.2 | BD133: 0.26
A134: 130 | B134: 24 | C134: 319.34583 | D134: 10.175 | E134: 16.654 | F134: 3.722 | G134: 51.770833 | H134: 67 | I134: 38 | J134: 0 | K134: 1.6147917 | L134: 7.046 | M134: 0.282 | N134: 0.349 | O134: 0 | Q134: =A134 -> 130 | R134: =B134 -> 24 | S134: =ROUND(C134*0.0864,2) -> 27.59 | T134: =ROUND(D134,1) -> 10.2 | U134: =ROUND(E134,1) -> 16.7 | V134: =ROUND(F134,1) -> 3.7 | W134: =ROUND(G134,1) -> 51.8 | X134: =ROUND(H134,1) -> 67 | Y134: =ROUND(I134,1) -> 38 | Z134: =ROUND(J134,2) -> 0 | AA134: =ROUND(K134,2) -> 1.61 | AB134: =ROUND(L134,2) -> 7.05 | AC134: =ROUND(M134,3) -> 0.282 | AD134: =ROUND(N134,3) -> 0.349 | AE134: =ROUND(O134-AE$2,3) -> 0 | AG134: =Z134 -> 0 | AH134: =ROUND((0.6105*(EXP((17.273*U134)/(U134+237.3))))*Y134/100,3) -> 0.722 | AI134: =ROUND(AH134/Y134*(100-Y134),3) -> 1.178 | AK134: 30.22 | AO134: 24.08 | AP134: 10.8 | AQ134: 15.6 | AR134: 5.8 | AS134: 46.2 | AT134: 58.4 | AU134: 37.2 | AV134: 0 | AW134: 1.03 | AX134: 3.73 | AY134: 0.187 | AZ134: 37.2 | BA134: 0 | BB134: 1.03 | BC134: 3.73 | BD134: 0.187
A135: 131 | B135: 24 | C135: 286.75 | D135: 12.217958 | E135: 18.343 | F135: 5.796 | G135: 49.8625 | H135: 71.4 | I135: 33.3 | J135: 0 | K135: 2.411625 | L135: 11.575 | M135: 0.264 | N135: 0.316 | O135: 0 | Q135: =A135 -> 131 | R135: =B135 -> 24 | S135: =ROUND(C135*0.0864,2) -> 24.78 | T135: =ROUND(D135,1) -> 12.2 | U135: =ROUND(E135,1) -> 18.3 | V135: =ROUND(F135,1) -> 5.8 | W135: =ROUND(G135,1) -> 49.9 | X135: =ROUND(H135,1) -> 71.4 | Y135: =ROUND(I135,1) -> 33.3 | Z135: =ROUND(J135,2) -> 0 | AA135: =ROUND(K135,2) -> 2.41 | AB135: =ROUND(L135,2) -> 11.58 | AC135: =ROUND(M135,3) -> 0.264 | AD135: =ROUND(N135,3) -> 0.316 | AE135: =ROUND(O135-AE$2,3) -> 0 | AG135: =Z135 -> 0 | AH135: =ROUND((0.6105*(EXP((17.273*U135)/(U135+237.3))))*Y135/100,3) -> 0.7 | AI135: =ROUND(AH135/Y135*(100-Y135),3) -> 1.402 | AK135: 30.38 | AO135: 21.64 | AP135: 12.6 | AQ135: 17.8 | AR135: 7.4 | AS135: 45.6 | AT135: 62.5 | AU135: 32.2 | AV135: 0 | AW135: 1.32 | AX135: 4.56 | AY135: 0.099 | AZ135: 32.2 | BA135: 0 | BB135: 1.32 | BC135: 4.56 | BD135: 0.099
A136: 132 | B136: 24 | C136: 309.925 | D136: 10.874333 | E136: 16.701 | F136: 6.585 | G136: 38.920833 | H136: 53.9 | I136: 24.4 | J136: 0 | K136: 2.369625 | L136: 10.065 | M136: 0.255 | N136: 0.296 | O136: 0 | Q136: =A136 -> 132 | R136: =B136 -> 24 | S136: =ROUND(C136*0.0864,2) -> 26.78 | T136: =ROUND(D136,1) -> 10.9 | U136: =ROUND(E136,1) -> 16.7 | V136: =ROUND(F136,1) -> 6.6 | W136: =ROUND(G136,1) -> 38.9 | X136: =ROUND(H136,1) -> 53.9 | Y136: =ROUND(I136,1) -> 24.4 | Z136: =ROUND(J136,2) -> 0 | AA136: =ROUND(K136,2) -> 2.37 | AB136: =ROUND(L136,2) -> 10.07 | AC136: =ROUND(M136,3) -> 0.255 | AD136: =ROUND(N136,3) -> 0.296 | AE136: =ROUND(O136-AE$2,3) -> 0 | AG136: =Z136 -> 0 | AH136: =ROUND((0.6105*(EXP((17.273*U136)/(U136+237.3))))*Y136/100,3) -> 0.464 | AI136: =ROUND(AH136/Y136*(100-Y136),3) -> 1.438 | AK136: 30.54 | AO136: 25.6 | AP136: 10.5 | AQ136: 16.3 | AR136: 6.6 | AS136: 38.1 | AT136: 52.8 | AU136: 24 | AV136: 0 | AW136: 1.39 | AX136: 5.19 | AY136: 0 | AZ136: 24 | BA136: 0 | BB136: 1.39 | BC136: 5.19 | BD136: 0
A137: 133 | B137: 24 | C137: 255.3375 | D137: 8.7995833 | E137: 13.882 | F137: 1.94 | G137: 42.545833 | H137: 56.8 | I137: 33.4 | J137: 0 | K137: 1.7197083 | L137: 8.556 | M137: 0.246 | N137: 0.278 | O137: 0 | Q137: =A137 -> 133 | R137: =B137 -> 24 | S137: =ROUND(C137*0.0864,2) -> 22.06 | T137: =ROUND(D137,1) -> 8.8 | U137: =ROUND(E137,1) -> 13.9 | V137: =ROUND(F137,1) -> 1.9 | W137: =ROUND(G137,1) -> 42.5 | X137: =ROUND(H137,1) -> 56.8 | Y137: =ROUND(I137,1) -> 33.4 | Z137: =ROUND(J137,2) -> 0 | AA137: =ROUND(K137,2) -> 1.72 | AB137: =ROUND(L137,2) -> 8.56 | AC137: =ROUND(M137,3) -> 0.246 | AD137: =ROUND(N137,3) -> 0.278 | AE137: =ROUND(O137-AE$2,3) -> 0 | AG137: =Z137 -> 0 | AH137: =ROUND((0.6105*(EXP((17.273*U137)/(U137+237.3))))*Y137/100,3) -> 0.53 | AI137: =ROUND(AH137/Y137*(100-Y137),3) -> 1.057 | AK137: 30.69 | AO137: 20.64 | AP137: 8.4 | AQ137: 13.4 | AR137: 2.8 | AS137: 42.1 | AT137: 51.7 | AU137: 32.5 | AV137: 0 | AW137: 1.18 | AX137: 4.58 | AY137: 0 | AZ137: 32.5 | BA137: 0 | BB137: 1.18 | BC137: 4.58 | BD137: 0
A138: 134 | B138: 24 | C138: 112.78333 | D138: 4.7712083 | E138: 9.188 | F138: 0.632 | G138: 71.995833 | H138: 97.9 | I138: 46.1 | J138: 6.602 | K138: 2.9567083 | L138: 12.582 | M138: 0.241 | N138: 0.304 | O138: 0 | Q138: =A138 -> 134 | R138: =B138 -> 24 | S138: =ROUND(C138*0.0864,2) -> 9.74 | T138: =ROUND(D138,1) -> 4.8 | U138: =ROUND(E138,1) -> 9.2 | V138: =ROUND(F138,1) -> 0.6 | W138: =ROUND(G138,1) -> 72 | X138: =ROUND(H138,1) -> 97.9 | Y138: =ROUND(I138,1) -> 46.1 | Z138: =ROUND(J138,2) -> 6.6 | AA138: =ROUND(K138,2) -> 2.96 | AB138: =ROUND(L138,2) -> 12.58 | AC138: =ROUND(M138,3) -> 0.241 | AD138: =ROUND(N138,3) -> 0.304 | AE138: =ROUND(O138-AE$2,3) -> 0 | AG138: =Z138 -> 6.6 | AH138: =ROUND((0.6105*(EXP((17.273*U138)/(U138+237.3))))*Y138/100,3) -> 0.536 | AI138: =ROUND(AH138/Y138*(100-Y138),3) -> 0.627 | AK138: 30.84 | AO138: 8.12 | AP138: 4.8 | AQ138: 8.9 | AR138: 0.8 | AS138: 70.5 | AT138: 96.7 | AU138: 45.4 | AV138: 8.13 | AW138: 1.84 | AX138: 6.42 | AY138: 0 | AZ138: 45.4 | BA138: 8.13 | BB138: 1.84 | BC138: 6.42 | BD138: 0
