Workbook

Sheet Meta
A1: Meta data for Sicamous base station
A2: Last edit 17/04/25
B3: 21X data logger and storage module
B4: Gap filling of temperature and humidity using relationships between Sicamous Creek and Sicamous FWS
A5: Solar W/m2 | L5: Based on regressions against Sicamous FWS station and UPC
B6: LiCor silicon Pyranometer at 6 m | N6: See columns BZ to DC
B7: Kmax from 10 min simulation | L7: Temperature
A8: PAR mol/m2/d | M8: Jan 1-March 8, n, 7-13 Nov
B9: LiCor PAR sensor 6 m above surface. Calibration drift adjustment | N9: Tave C = UPC* 1.19 - 0.2, R2=0.922
A10: Tair C | N10: Tmin C = UPC* 0.95 - 0.5, R2=0.752
B11: HMP35C in RMYoung pie plate sheild at 6 m | N11: Tmin C = UPC* 1.1 - 1, R2=0.856
B12: Thermocouples referenced to termistor on panel at 3 m, 1.5 m and 0.25 m | M12: March 9- 11 May and gaps where no FWS to 13 Jun
A13: RH % | N13: Tave C = UPC* 1.02 - 0.4, R2=0.932
B14: HMP35C in RMYoung pie plate sheild at 6 m | N14: Tmin C = UPC* 0.96+ 0.2, R2=0.937
B15: Corrected RH based on Rhmax=100. Calculated vpres (kPa) | N15: Tmin C = UPC* 1.1 - 0.4, R2=0.793
A16: Soil temperature C | M16: 12 May-13 Jun with gaps, 18-29 July
B17: Thermocouples referenced to thermistor on panel at 0.15 m and 0.5 m depths | N17: Tave C = FWS* 0.75 - 0.6, R2=0.941
A18: Precipitation mm | N18: Tmax C = FWS*0.95 - 1.2, R2=0.972
B19: Siera Misco tipping bucket | N19: Tmin C = FWS*0.76 - 3.6, R2=0.579
A20: Snow depth m, mm | M20: 2 Sept - 6 Nov
B21: CSI UDG01 | N21: Tave C = FWS* 0.9 - 1.82
B22: Modelled Jan to May using precipitation and estimate of snow pack density. Not reliable. No depth measurment as anchor | N22: Tmax C = FWS*1 - 0.91
A23: Wind m/s | F23: Need better density change model | N23: Tmin C = FWS*0.77 - 3.4
B24: MetOne anemometer at 6 m | L24: Humidity
A25: Wind direction degrees | M25: 12 May-13 Jun with gaps, 18-29 July
B26: MetOne Wind vane at 6 m | N26: Rhmincor % = FWS*0.85 + 1, R2 0.870
M27: 2 Sept - 6 Nov
A28: PPT= snow+rain | N28: Rhmincor % = FWS*0.9 - 7.7
B29: Snow = Daily increase in pack depth and assumed compacted density of 0.13 Mg/m3
B30: Rain = Rain gauge.
C31: If there is a snow pack then review tiping bucket data to determine if likely snow melt rather than rain, i.e., tipping when above zero and low humidity and sunny.
C32: Also sum tipping bucket over days to see if simialr total to water equivalent of snow fal from depth change.
C33: Sicamous Fire Weather Station rainfall adjusted by *1.05, MoTI Malakwa*1.4*1.05 and UPC*1.0
A34: Vapour pressure kPa
B35: Calculated from the daily maximum temperature and mininimum relative humdity: esat(Tmax)*RHmin/100
B36: If no RHmin vpres = esat(Tmin)
A37: Maximum vapour presure deficit
B38: Calculated from the daily maximum temperature and mininimum relative humdity: esat(Tmax)*(1-RHmin/100)
B39: If no RHmin vpd = esat(Tmax) - esat(Tmin)

Sheet PPTest
A1: Precipitation | I1: 0.13 | K1: Rain | L1: 1 | P1: Max density | Q1: 0.4
A2: Last edit 17/04/25 | K2: SnowDepthChange | P2: Start Density | Q2: 0.22
C3: Total | K3: FWS* | L3: 1.05
C4: Solar | D4: Tmax | E4: Tmin | F4: Rhmin | G4: Rain | H4: SnowD | I4: Precip.from | J4: FWS | M4: FWS | N4: Sicamous | P4: density | R4: SWE | S4: dSWE | T4: Melt | AE4: Enderby Snow 1F04 course 50 39 11.97N, 118 55 37.0 W 1947 m
A5: Date | B5: DoY | C5: MJ/m2/d | I5: snow depth | K5: Precipitation | P5: g/cm3 | R5: mm | S5: mm | T5: mm | AE5: Date | AF5: SWE cm | AG5: Depth cm | AH5: %norm
H6: 858 | Q6: =Q2 -> 0.22 | R6: =H6*Q$2 -> 188.76 | S6: 0 | T6: 0
A7: 35065 | B7: 1 | C7: =ROUND(Data!BJ7,2) -> 0 | D7: =ROUND(Data!R7,1) -> 0.8 | E7: =ROUND(Data!AF7,1) -> -7.5 | F7: =Data!BO7 -> 0 | G7: =Data!Q7 -> 0 | H7: =IF(K7>0,ROUND(H6+K7/0.13,0),H6-22) -> 836 | J7: =Data!BS7 -> 0 | K7: =J7*L$3 -> 0 | M7: =J7 -> 0 | N7: =K7 -> 0 | P7: =(R6+K7)/H7 -> 0.22578947 | Q7: =IF(P7>Q$1,Q$1,P7) -> 0.22578947 | R7: =Q7*H7 -> 188.76 | S7: =R7-R6 -> 0 | T7: =ROUND(K7-S7,1) -> 0 | AE7: 35095 | AF7: 234 | AG7: 820 | AH7: 119
A8: 35066 | B8: 2 | C8: =ROUND(Data!BJ8,2) -> 0 | D8: =ROUND(Data!R8,1) -> 2.6 | E8: =ROUND(Data!AF8,1) -> -6.2 | F8: =Data!BO8 -> 0 | G8: =Data!Q8 -> 0 | H8: =IF(K8>0,ROUND(H7+K8/0.13,0),H7-22) -> 909 | J8: =Data!BS8 -> 9 | K8: =J8*L$3 -> 9.45 | M8: =J8+M7 -> 9 | N8: =K8+N7 -> 9.45 | P8: =(R7+K8)/H8 -> 0.21805281 | Q8: =IF(P8>Q$1,Q$1,P8) -> 0.21805281 | R8: =Q8*H8 -> 198.21 | S8: =R8-R7 -> 9.45 | T8: =ROUND(K8-S8,1) -> 0 | AE8: 35120 | AF8: 287 | AG8: 906 | AH8: 108
A9: 35067 | B9: 3 | C9: =ROUND(Data!BJ9,2) -> 0 | D9: =ROUND(Data!R9,1) -> 0.7 | E9: =ROUND(Data!AF9,1) -> -14.5 | F9: =Data!BO9 -> 0 | G9: =Data!Q9 -> 0 | H9: =IF(K9>0,ROUND(H8+K9/0.13,0),H8-22) -> 887 | J9: =Data!BS9 -> 0 | K9: =J9*L$3 -> 0 | M9: =J9+M8 -> 9 | N9: =K9+N8 -> 9.45 | P9: =(R8+K9)/H9 -> 0.2234611 | Q9: =IF(P9>Q$1,Q$1,P9) -> 0.2234611 | R9: =Q9*H9 -> 198.21 | S9: =R9-R8 -> 0 | T9: =ROUND(K9-S9,1) -> 0 | AE9: 35154 | AF9: 261 | AG9: 1018 | AH9: 102
A10: 35068 | B10: 4 | C10: =ROUND(Data!BJ10,2) -> 0 | D10: =ROUND(Data!R10,1) -> -10.4 | E10: =ROUND(Data!AF10,1) -> -21.2 | F10: =Data!BO10 -> 0 | G10: =Data!Q10 -> 0 | H10: =IF(K10>0,ROUND(H9+K10/0.13,0),H9-22) -> 865 | J10: =Data!BS10 -> 0 | K10: =J10*L$3 -> 0 | M10: =J10+M9 -> 9 | N10: =K10+N9 -> 9.45 | P10: =(R9+K10)/H10 -> 0.22914451 | Q10: =IF(P10>Q$1,Q$1,P10) -> 0.22914451 | R10: =Q10*H10 -> 198.21 | S10: =R10-R9 -> 0 | T10: =ROUND(K10-S10,1) -> 0 | AE10: 35185 | AF10: 238 | AG10: 1120 | AH10: 104
A11: 35069 | B11: 5 | C11: =ROUND(Data!BJ11,2) -> 0 | D11: =ROUND(Data!R11,1) -> -6.1 | E11: =ROUND(Data!AF11,1) -> -22.7 | F11: =Data!BO11 -> 0 | G11: =Data!Q11 -> 0 | H11: =IF(K11>0,ROUND(H10+K11/0.13,0),H10-22) -> 877 | J11: =Data!BS11 -> 1.5 | K11: =J11*L$3 -> 1.575 | M11: =J11+M10 -> 10.5 | N11: =K11+N10 -> 11.025 | P11: =(R10+K11)/H11 -> 0.22780502 | Q11: =IF(P11>Q$1,Q$1,P11) -> 0.22780502 | R11: =Q11*H11 -> 199.785 | S11: =R11-R10 -> 1.575 | T11: =ROUND(K11-S11,1) -> 0 | AE11: 35199 | AF11: 288 | AG11: 1233 | AH11: 115
A12: 35070 | B12: 6 | C12: =ROUND(Data!BJ12,2) -> 0 | D12: =ROUND(Data!R12,1) -> -5.2 | E12: =ROUND(Data!AF12,1) -> -14.6 | F12: =Data!BO12 -> 0 | G12: =Data!Q12 -> 0 | H12: =IF(K12>0,ROUND(H11+K12/0.13,0),H11-22) -> 938 | J12: =Data!BS12 -> 7.5 | K12: =J12*L$3 -> 7.875 | M12: =J12+M11 -> 18 | N12: =K12+N11 -> 18.9 | P12: =(R11+K12)/H12 -> 0.22138593 | Q12: =IF(P12>Q$1,Q$1,P12) -> 0.22138593 | R12: =Q12*H12 -> 207.66 | S12: =R12-R11 -> 7.875 | T12: =ROUND(K12-S12,1) -> 0 | AE12: 35216 | AF12: 294 | AG12: 1280 | AH12: 139
A13: 35071 | B13: 7 | C13: =ROUND(Data!BJ13,2) -> 0 | D13: =ROUND(Data!R13,1) -> 0.6 | E13: =ROUND(Data!AF13,1) -> -6.8 | F13: =Data!BO13 -> 0 | G13: =Data!Q13 -> 0 | H13: =IF(K13>0,ROUND(H12+K13/0.13,0),H12-22) -> 916 | J13: =Data!BS13 -> 0 | K13: =J13*L$3 -> 0 | M13: =J13+M12 -> 18 | N13: =K13+N12 -> 18.9 | P13: =(R12+K13)/H13 -> 0.22670306 | Q13: =IF(P13>Q$1,Q$1,P13) -> 0.22670306 | R13: =Q13*H13 -> 207.66 | S13: =R13-R12 -> 0 | T13: =ROUND(K13-S13,1) -> 0 | AE13: 35230 | AF13: 204 | AG13: 1053 | AH13: 154
A14: 35072 | B14: 8 | C14: =ROUND(Data!BJ14,2) -> 0 | D14: =ROUND(Data!R14,1) -> 2.5 | E14: =ROUND(Data!AF14,1) -> -10.2 | F14: =Data!BO14 -> 0 | G14: =Data!Q14 -> 0 | H14: =IF(K14>0,ROUND(H13+K14/0.13,0),H13-22) -> 894 | J14: =Data!BS14 -> 0 | K14: =J14*L$3 -> 0 | M14: =J14+M13 -> 18 | N14: =K14+N13 -> 18.9 | P14: =(R13+K14)/H14 -> 0.23228188 | Q14: =IF(P14>Q$1,Q$1,P14) -> 0.23228188 | R14: =Q14*H14 -> 207.66 | S14: =R14-R13 -> 0 | T14: =ROUND(K14-S14,1) -> 0
A15: 35073 | B15: 9 | C15: =ROUND(Data!BJ15,2) -> 0 | D15: =ROUND(Data!R15,1) -> 0.9 | E15: =ROUND(Data!AF15,1) -> -7.6 | F15: =Data!BO15 -> 0 | G15: =Data!Q15 -> 0 | H15: =IF(K15>0,ROUND(H14+K15/0.13,0),H14-22) -> 872 | J15: =Data!BS15 -> 0 | K15: =J15*L$3 -> 0 | M15: =J15+M14 -> 18 | N15: =K15+N14 -> 18.9 | P15: =(R14+K15)/H15 -> 0.2381422 | Q15: =IF(P15>Q$1,Q$1,P15) -> 0.2381422 | R15: =Q15*H15 -> 207.66 | S15: =R15-R14 -> 0 | T15: =ROUND(K15-S15,1) -> 0
A16: 35074 | B16: 10 | C16: =ROUND(Data!BJ16,2) -> 0 | D16: =ROUND(Data!R16,1) -> -0.4 | E16: =ROUND(Data!AF16,1) -> -6.1 | F16: =Data!BO16 -> 0 | G16: =Data!Q16 -> 0 | H16: =IF(K16>0,ROUND(H15+K16/0.13,0),H15-22) -> 850 | J16: =Data!BS16 -> 0 | K16: =J16*L$3 -> 0 | M16: =J16+M15 -> 18 | N16: =K16+N15 -> 18.9 | P16: =(R15+K16)/H16 -> 0.24430588 | Q16: =IF(P16>Q$1,Q$1,P16) -> 0.24430588 | R16: =Q16*H16 -> 207.66 | S16: =R16-R15 -> 0 | T16: =ROUND(K16-S16,1) -> 0
A17: 35075 | B17: 11 | C17: =ROUND(Data!BJ17,2) -> 0 | D17: =ROUND(Data!R17,1) -> 1.6 | E17: =ROUND(Data!AF17,1) -> -10.4 | F17: =Data!BO17 -> 0 | G17: =Data!Q17 -> 0 | H17: =IF(K17>0,ROUND(H16+K17/0.13,0),H16-22) -> 828 | J17: =Data!BS17 -> 0 | K17: =J17*L$3 -> 0 | M17: =J17+M16 -> 18 | N17: =K17+N16 -> 18.9 | P17: =(R16+K17)/H17 -> 0.2507971 | Q17: =IF(P17>Q$1,Q$1,P17) -> 0.2507971 | R17: =Q17*H17 -> 207.66 | S17: =R17-R16 -> 0 | T17: =ROUND(K17-S17,1) -> 0
A18: 35076 | B18: 12 | C18: =ROUND(Data!BJ18,2) -> 0 | D18: =ROUND(Data!R18,1) -> 1.5 | E18: =ROUND(Data!AF18,1) -> -12.7 | F18: =Data!BO18 -> 0 | G18: =Data!Q18 -> 0 | H18: =IF(K18>0,ROUND(H17+K18/0.13,0),H17-22) -> 806 | J18: =Data!BS18 -> 0 | K18: =J18*L$3 -> 0 | M18: =J18+M17 -> 18 | N18: =K18+N17 -> 18.9 | P18: =(R17+K18)/H18 -> 0.25764268 | Q18: =IF(P18>Q$1,Q$1,P18) -> 0.25764268 | R18: =Q18*H18 -> 207.66 | S18: =R18-R17 -> 0 | T18: =ROUND(K18-S18,1) -> 0
A19: 35077 | B19: 13 | C19: =ROUND(Data!BJ19,2) -> 0 | D19: =ROUND(Data!R19,1) -> 4 | E19: =ROUND(Data!AF19,1) -> -10.2 | F19: =Data!BO19 -> 0 | G19: =Data!Q19 -> 0 | H19: =IF(K19>0,ROUND(H18+K19/0.13,0),H18-22) -> 784 | J19: =Data!BS19 -> 0 | K19: =J19*L$3 -> 0 | M19: =J19+M18 -> 18 | N19: =K19+N18 -> 18.9 | P19: =(R18+K19)/H19 -> 0.26487245 | Q19: =IF(P19>Q$1,Q$1,P19) -> 0.26487245 | R19: =Q19*H19 -> 207.66 | S19: =R19-R18 -> 0 | T19: =ROUND(K19-S19,1) -> 0
A20: 35078 | B20: 14 | C20: =ROUND(Data!BJ20,2) -> 0 | D20: =ROUND(Data!R20,1) -> 2.2 | E20: =ROUND(Data!AF20,1) -> -2.8 | F20: =Data!BO20 -> 0 | G20: =Data!Q20 -> 0 | H20: =IF(K20>0,ROUND(H19+K20/0.13,0),H19-22) -> 762 | J20: =Data!BS20 -> 0 | K20: =J20*L$3 -> 0 | M20: =J20+M19 -> 18 | N20: =K20+N19 -> 18.9 | P20: =(R19+K20)/H20 -> 0.27251969 | Q20: =IF(P20>Q$1,Q$1,P20) -> 0.27251969 | R20: =Q20*H20 -> 207.66 | S20: =R20-R19 -> 0 | T20: =ROUND(K20-S20,1) -> 0
A21: 35079 | B21: 15 | C21: =ROUND(Data!BJ21,2) -> 0 | D21: =ROUND(Data!R21,1) -> 2.8 | E21: =ROUND(Data!AF21,1) -> -4.3 | F21: =Data!BO21 -> 0 | G21: =Data!Q21 -> 0 | H21: =IF(K21>0,ROUND(H20+K21/0.13,0),H20-22) -> 774 | J21: =Data!BS21 -> 1.5 | K21: =J21*L$3 -> 1.575 | M21: =J21+M20 -> 19.5 | N21: =K21+N20 -> 20.475 | P21: =(R20+K21)/H21 -> 0.27032946 | Q21: =IF(P21>Q$1,Q$1,P21) -> 0.27032946 | R21: =Q21*H21 -> 209.235 | S21: =R21-R20 -> 1.575 | T21: =ROUND(K21-S21,1) -> 0
A22: 35080 | B22: 16 | C22: =ROUND(Data!BJ22,2) -> 0 | D22: =ROUND(Data!R22,1) -> 0.5 | E22: =ROUND(Data!AF22,1) -> -17.8 | F22: =Data!BO22 -> 0 | G22: =Data!Q22 -> 0 | H22: =IF(K22>0,ROUND(H21+K22/0.13,0),H21-22) -> 752 | J22: =Data!BS22 -> 0 | K22: =J22*L$3 -> 0 | M22: =J22+M21 -> 19.5 | N22: =K22+N21 -> 20.475 | P22: =(R21+K22)/H22 -> 0.27823803 | Q22: =IF(P22>Q$1,Q$1,P22) -> 0.27823803 | R22: =Q22*H22 -> 209.235 | S22: =R22-R21 -> 0 | T22: =ROUND(K22-S22,1) -> 0
A23: 35081 | B23: 17 | C23: =ROUND(Data!BJ23,2) -> 0 | D23: =ROUND(Data!R23,1) -> -9.2 | E23: =ROUND(Data!AF23,1) -> -30.9 | F23: =Data!BO23 -> 0 | G23: =Data!Q23 -> 0 | H23: =IF(K23>0,ROUND(H22+K23/0.13,0),H22-22) -> 730 | J23: =Data!BS23 -> 0 | K23: =J23*L$3 -> 0 | M23: =J23+M22 -> 19.5 | N23: =K23+N22 -> 20.475 | P23: =(R22+K23)/H23 -> 0.28662329 | Q23: =IF(P23>Q$1,Q$1,P23) -> 0.28662329 | R23: =Q23*H23 -> 209.235 | S23: =R23-R22 -> 0 | T23: =ROUND(K23-S23,1) -> 0
A24: 35082 | B24: 18 | C24: =ROUND(Data!BJ24,2) -> 0 | D24: =ROUND(Data!R24,1) -> -9.3 | E24: =ROUND(Data!AF24,1) -> -32.4 | F24: =Data!BO24 -> 0 | G24: =Data!Q24 -> 0 | H24: =IF(K24>0,ROUND(H23+K24/0.13,0),H23-22) -> 708 | J24: =Data!BS24 -> 0 | K24: =J24*L$3 -> 0 | M24: =J24+M23 -> 19.5 | N24: =K24+N23 -> 20.475 | P24: =(R23+K24)/H24 -> 0.29552966 | Q24: =IF(P24>Q$1,Q$1,P24) -> 0.29552966 | R24: =Q24*H24 -> 209.235 | S24: =R24-R23 -> 0 | T24: =ROUND(K24-S24,1) -> 0
A25: 35083 | B25: 19 | C25: =ROUND(Data!BJ25,2) -> 0 | D25: =ROUND(Data!R25,1) -> -9.1 | E25: =ROUND(Data!AF25,1) -> -17.7 | F25: =Data!BO25 -> 0 | G25: =Data!Q25 -> 0 | H25: =IF(K25>0,ROUND(H24+K25/0.13,0),H24-22) -> 686 | J25: =Data!BS25 -> 0 | K25: =J25*L$3 -> 0 | M25: =J25+M24 -> 19.5 | N25: =K25+N24 -> 20.475 | P25: =(R24+K25)/H25 -> 0.30500729 | Q25: =IF(P25>Q$1,Q$1,P25) -> 0.30500729 | R25: =Q25*H25 -> 209.235 | S25: =R25-R24 -> 0 | T25: =ROUND(K25-S25,1) -> 0
... A51: 35109 | B51: 45 | C51: =ROUND(Data!BJ51,2) -> 0 | D51: =ROUND(Data!R51,1) -> 6.7 | E51: =ROUND(Data!AF51,1) -> -5.7 | F51: =Data!BO51 -> 0 | G51: =Data!Q51 -> 0 | H51: =IF(K51>0,ROUND(H50+K51/0.13,0),H50-22) -> 741 | J51: =Data!BS51 -> 0 | K51: =J51*L$3 -> 0 | M51: =J51+M50 -> 67.5 | N51: =K51+N50 -> 70.875 | P51: =(R50+K51)/H51 -> 0.35038462 | Q51: =IF(P51>Q$1,Q$1,P51) -> 0.35038462 | R51: =Q51*H51 -> 259.635 | S51: =R51-R50 -> 0 | T51: =ROUND(K51-S51,1) -> 0
A52: 35110 | B52: 46 | C52: =ROUND(Data!BJ52,2) -> 0 | D52: =ROUND(Data!R52,1) -> 10.4 | E52: =ROUND(Data!AF52,1) -> -7.8 | F52: =Data!BO52 -> 0 | G52: =Data!Q52 -> 0 | H52: =IF(K52>0,ROUND(H51+K52/0.13,0),H51-22) -> 719 | J52: =Data!EC52 -> 0 | K52: =J52*L$1 -> 0 | M52: =J52+M51 -> 67.5 | N52: =K52+N51 -> 70.875 | P52: =(R51+K52)/H52 -> 0.3611057 | Q52: =IF(P52>Q$1,Q$1,P52) -> 0.3611057 | R52: =Q52*H52 -> 259.635 | S52: =R52-R51 -> 0 | T52: =ROUND(K52-S52,1) -> 0
A53: 35111 | B53: 47 | C53: =ROUND(Data!BJ53,2) -> 0 | D53: =ROUND(Data!R53,1) -> 10.2 | E53: =ROUND(Data!AF53,1) -> -7.8 | F53: =Data!BO53 -> 0 | G53: =Data!Q53 -> 0 | H53: =IF(K53>0,ROUND(H52+K53/0.13,0),H52-22) -> 697 | J53: =Data!EC53 -> 0 | K53: =J53*L$1 -> 0 | M53: =J53+M52 -> 67.5 | N53: =K53+N52 -> 70.875 | P53: =(R52+K53)/H53 -> 0.37250359 | Q53: =IF(P53>Q$1,Q$1,P53) -> 0.37250359 | R53: =Q53*H53 -> 259.635 | S53: =R53-R52 -> 0 | T53: =ROUND(K53-S53,1) -> 0
A54: 35112 | B54: 48 | C54: =ROUND(Data!BJ54,2) -> 0 | D54: =ROUND(Data!R54,1) -> 1 | E54: =ROUND(Data!AF54,1) -> -4.4 | F54: =Data!BO54 -> 0 | G54: =Data!Q54 -> 0 | H54: =IF(K54>0,ROUND(H53+K54/0.13,0),H53-22) -> 722 | J54: =Data!EC54 -> 3.3 | K54: =J54*L$1 -> 3.3 | M54: =J54+M53 -> 70.8 | N54: =K54+N53 -> 74.175 | P54: =(R53+K54)/H54 -> 0.3641759 | Q54: =IF(P54>Q$1,Q$1,P54) -> 0.3641759 | R54: =Q54*H54 -> 262.935 | S54: =R54-R53 -> 3.3 | T54: =ROUND(K54-S54,1) -> 0
A55: 35113 | B55: 49 | C55: =ROUND(Data!BJ55,2) -> 0 | D55: =ROUND(Data!R55,1) -> 4.1 | E55: =ROUND(Data!AF55,1) -> -2.5 | F55: =Data!BO55 -> 0 | G55: =Data!Q55 -> 0 | H55: =IF(K55>0,ROUND(H54+K55/0.13,0),H54-22) -> 737 | J55: =Data!EC55 -> 1.9 | K55: =J55*L$1 -> 1.9 | M55: =J55+M54 -> 72.7 | N55: =K55+N54 -> 76.075 | P55: =(R54+K55)/H55 -> 0.35934193 | Q55: =IF(P55>Q$1,Q$1,P55) -> 0.35934193 | R55: =Q55*H55 -> 264.835 | S55: =R55-R54 -> 1.9 | T55: =ROUND(K55-S55,1) -> 0
A56: 35114 | B56: 50 | C56: =ROUND(Data!BJ56,2) -> 0 | D56: =ROUND(Data!R56,1) -> 1.7 | E56: =ROUND(Data!AF56,1) -> -3.5 | F56: =Data!BO56 -> 0 | G56: =Data!Q56 -> 0 | H56: =IF(K56>0,ROUND(H55+K56/0.13,0),H55-22) -> 769 | J56: =Data!EC56 -> 4.2 | K56: =J56*L$1 -> 4.2 | M56: =J56+M55 -> 76.9 | N56: =K56+N55 -> 80.275 | P56: =(R55+K56)/H56 -> 0.34985046 | Q56: =IF(P56>Q$1,Q$1,P56) -> 0.34985046 | R56: =Q56*H56 -> 269.035 | S56: =R56-R55 -> 4.2 | T56: =ROUND(K56-S56,1) -> 0
A57: 35115 | B57: 51 | C57: =ROUND(Data!BJ57,2) -> 0 | D57: =ROUND(Data!R57,1) -> 0.1 | E57: =ROUND(Data!AF57,1) -> -4.6 | F57: =Data!BO57 -> 0 | G57: =Data!Q57 -> 0 | H57: =IF(K57>0,ROUND(H56+K57/0.13,0),H56-22) -> 786 | J57: =Data!EC57 -> 2.2 | K57: =J57*L$1 -> 2.2 | M57: =J57+M56 -> 79.1 | N57: =K57+N56 -> 82.475 | P57: =(R56+K57)/H57 -> 0.3450827 | Q57: =IF(P57>Q$1,Q$1,P57) -> 0.3450827 | R57: =Q57*H57 -> 271.235 | S57: =R57-R56 -> 2.2 | T57: =ROUND(K57-S57,1) -> 0
A58: 35116 | B58: 52 | C58: =ROUND(Data!BJ58,2) -> 0 | D58: =ROUND(Data!R58,1) -> -1.8 | E58: =ROUND(Data!AF58,1) -> -9.1 | F58: =Data!BO58 -> 0 | G58: =Data!Q58 -> 0 | H58: =IF(K58>0,ROUND(H57+K58/0.13,0),H57-22) -> 829 | J58: =Data!EC58 -> 5.6 | K58: =J58*L$1 -> 5.6 | M58: =J58+M57 -> 84.7 | N58: =K58+N57 -> 88.075 | P58: =(R57+K58)/H58 -> 0.33393848 | Q58: =IF(P58>Q$1,Q$1,P58) -> 0.33393848 | R58: =Q58*H58 -> 276.835 | S58: =R58-R57 -> 5.6 | T58: =ROUND(K58-S58,1) -> 0
A59: 35117 | B59: 53 | C59: =ROUND(Data!BJ59,2) -> 0 | D59: =ROUND(Data!R59,1) -> -6.1 | E59: =ROUND(Data!AF59,1) -> -11.5 | F59: =Data!BO59 -> 0 | G59: =Data!Q59 -> 0 | H59: =IF(K59>0,ROUND(H58+K59/0.13,0),H58-22) -> 837 | J59: =Data!EC59 -> 1.1 | K59: =J59*L$1 -> 1.1 | M59: =J59+M58 -> 85.8 | N59: =K59+N58 -> 89.175 | P59: =(R58+K59)/H59 -> 0.33206093 | Q59: =IF(P59>Q$1,Q$1,P59) -> 0.33206093 | R59: =Q59*H59 -> 277.935 | S59: =R59-R58 -> 1.1 | T59: =ROUND(K59-S59,1) -> 0
A60: 35118 | B60: 54 | C60: =ROUND(Data!BJ60,2) -> 0 | D60: =ROUND(Data!R60,1) -> -3.9 | E60: =ROUND(Data!AF60,1) -> -18.9 | F60: =Data!BO60 -> 0 | G60: =Data!Q60 -> 0 | H60: =IF(K60>0,ROUND(H59+K60/0.13,0),H59-22) -> 852 | J60: =Data!EC60 -> 1.9 | K60: =J60*L$1 -> 1.9 | M60: =J60+M59 -> 87.7 | N60: =K60+N59 -> 91.075 | P60: =(R59+K60)/H60 -> 0.32844484 | Q60: =IF(P60>Q$1,Q$1,P60) -> 0.32844484 | R60: =Q60*H60 -> 279.835 | S60: =R60-R59 -> 1.9 | T60: =ROUND(K60-S60,1) -> 0
A61: 35119 | B61: 55 | C61: =ROUND(Data!BJ61,2) -> 0 | D61: =ROUND(Data!R61,1) -> -5.7 | E61: =ROUND(Data!AF61,1) -> -20.3 | F61: =Data!BO61 -> 0 | G61: =Data!Q61 -> 0 | H61: =IF(K61>0,ROUND(H60+K61/0.13,0),H60-22) -> 830 | J61: =Data!EC61 -> 0 | K61: =J61*L$1 -> 0 | M61: =J61+M60 -> 87.7 | N61: =K61+N60 -> 91.075 | P61: =(R60+K61)/H61 -> 0.3371506 | Q61: =IF(P61>Q$1,Q$1,P61) -> 0.3371506 | R61: =Q61*H61 -> 279.835 | S61: =R61-R60 -> 0 | T61: =ROUND(K61-S61,1) -> 0
A62: 35120 | B62: 56 | C62: =ROUND(Data!BJ62,2) -> 0 | D62: =ROUND(Data!R62,1) -> -8.7 | E62: =ROUND(Data!AF62,1) -> -16 | F62: =Data!BO62 -> 0 | G62: =Data!Q62 -> 0 | H62: =IF(K62>0,ROUND(H61+K62/0.13,0),H61-22) -> 808 | J62: =Data!EC62 -> 0 | K62: =J62*L$1 -> 0 | M62: =J62+M61 -> 87.7 | N62: =K62+N61 -> 91.075 | P62: =(R61+K62)/H62 -> 0.34633045 | Q62: =IF(P62>Q$1,Q$1,P62) -> 0.34633045 | R62: =Q62*H62 -> 279.835 | S62: =R62-R61 -> 0 | T62: =ROUND(K62-S62,1) -> 0
A63: 35121 | B63: 57 | C63: =ROUND(Data!BJ63,2) -> 0 | D63: =ROUND(Data!R63,1) -> -7.2 | E63: =ROUND(Data!AF63,1) -> -23.8 | F63: =Data!BO63 -> 0 | G63: =Data!Q63 -> 0 | H63: =IF(K63>0,ROUND(H62+K63/0.13,0),H62-22) -> 811 | J63: =Data!EC63 -> 0.4 | K63: =J63*L$1 -> 0.4 | M63: =J63+M62 -> 88.1 | N63: =K63+N62 -> 91.475 | P63: =(R62+K63)/H63 -> 0.34554254 | Q63: =IF(P63>Q$1,Q$1,P63) -> 0.34554254 | R63: =Q63*H63 -> 280.235 | S63: =R63-R62 -> 0.4 | T63: =ROUND(K63-S63,1) -> 0
A64: 35122 | B64: 58 | C64: =ROUND(Data!BJ64,2) -> 0 | D64: =ROUND(Data!R64,1) -> -9.2 | E64: =ROUND(Data!AF64,1) -> -24.3 | F64: =Data!BO64 -> 0 | G64: =Data!Q64 -> 0 | H64: =IF(K64>0,ROUND(H63+K64/0.13,0),H63-22) -> 813 | J64: =Data!EC64 -> 0.3 | K64: =J64*L$1 -> 0.3 | M64: =J64+M63 -> 88.4 | N64: =K64+N63 -> 91.775 | P64: =(R63+K64)/H64 -> 0.3450615 | Q64: =IF(P64>Q$1,Q$1,P64) -> 0.3450615 | R64: =Q64*H64 -> 280.535 | S64: =R64-R63 -> 0.3 | T64: =ROUND(K64-S64,1) -> 0
A65: 35123 | B65: 59 | C65: =ROUND(Data!BJ65,2) -> 0 | D65: =ROUND(Data!R65,1) -> -5.5 | E65: =ROUND(Data!AF65,1) -> -24.1 | F65: =Data!BO65 -> 0 | G65: =Data!Q65 -> 0 | H65: =IF(K65>0,ROUND(H64+K65/0.13,0),H64-22) -> 791 | J65: =Data!EC65 -> 0 | K65: =J65*L$1 -> 0 | M65: =J65+M63 -> 88.1 | N65: =K65+N63 -> 91.475 | P65: =(R64+K65)/H65 -> 0.35465866 | Q65: =IF(P65>Q$1,Q$1,P65) -> 0.35465866 | R65: =Q65*H65 -> 280.535 | S65: =R65-R64 -> 0 | T65: =ROUND(K65-S65,1) -> 0
...

Sheet Data
A1: Sicamous Creek 1996 Daily data | I1: RH, Solar and PAR new calibrations added col BL onwards | N1: Removed -6999 indicating bad data | BF1: 3480 | BI1: =2.02 -> 2.02 | BJ1: Recalibrated 30/07/07 | BM1: Rh_adjustment fro Max=100 and min 20=20 | BQ1: UseRHcor
A2: Last edit 21/04/25 | C2: Rainfall - no data | J2: Empty cell indicates no data | BJ2: 1 | BK2: =274/261.1 -> 1.0494064 | BM2: =MAX(BM7:BM372) -> 100 | BP2: esat(tmin) | BQ2: esat(tx)-esat(Tn) | BT2: 1.5 | BV2: Summary
C3: TOTAL | D3: MEAN | E3: MEAN | F3: MEAN | G3: MEAN | H3: MEAN | I3: MEAN | J3: MEAN | K3: MEAN | L3: MEAN | M3: MEAN | N3: MEAN | O3: MEAN | P3: MEAN | Q3: TOTAL | R3: MAX. | S3: TIME | T3: MAX | U3: TIME | V3: MAX | W3: MAX | X3: MAX | Y3: MAX | Z3: MAX | AA3: MAX | AB3: MAX | AC3: MAX | AD3: MAX | AE3: TIME | AF3: MIN | AG3: TIME | AH3: MIN | AI3: TIME | AJ3: MIN | AK3: MIN | AL3: MIN | AM3: MIN | AN3: MIN | AO3: MIN | AP3: MIN | AQ3: MIN | AR3: Wind Rose: | BJ3: Revised | BM3: 0.924 | BP3: Rhmin*Esat(Tx) | BT3: Snow | CV3: Midnight | DD3: FWS | DZ3: UPC
C4: SOLAR | D4: PAR | E4: Ta 6m | F4: RH | G4: Ta 3m | H4: Ta 1.5m | I4: Ta 0.25m | J4: Tstem | K4: Tstem | L4: Tsoil | M4: Tsoil | N4: Tsoil | O4: SHORT | P4: WIND | Q4: RAIN | R4: Ta 6m | S4: tA 6m | T4: RH | U4: RH | V4: Ta 3m | W4: Ta 1.5m | X4: Ta 0.25m | Y4: Tstem | Z4: Tstem | AA4: Tsoil | AB4: Tsoil | AC4: Tsoil | AD4: WIND SPD | AE4: MAX U | AF4: Ta 6m | AG4: tA 6m | AH4: RH | AI4: RH | AJ4: Ta 3m | AK4: Ta 1.5m | AL4: Ta 0.25m | AM4: Tstem | AN4: Tstem | AO4: Tsoil | AP4: Tsoil | AQ4: Tsoil | AZ4: DAILY AVG | BA4: DISTANCE | BB4: BATT. | BC4: Identity | BD4: Distance | BE4: Distance | BF4: Snow depth | BH4: Solarmax | BI4: PARmax | BJ4: Solar | BK4: PAR | BM4: 1 | BP4: Vpres | BQ4: VPDx | BT4: MoTISicamous | BV4: Solar | BW4: PAR | BX4: Ta6Ave | BY4: Ta3Ave | BZ4: Ta15Ave | CA4: Ta025Ave | CB4: TdufAve | CC4: Ts015Ave | CD4: Ts05Ave | CE4: RH6Ave | CF4: Ta6Max | CG4: Ta3Max | CH4: Ta15Max | CI4: Ta025Max | CJ4: TdufMax | CK4: Ts015Max | CL4: Ts05Max | CM4: RH6Max | CN4: Ta6Min | CO4: Ta3Min | CP4: Ta15Min | CQ4: Ta025Min | CR4: TdufMin | CS4: Ts015Min | CT4: Ts05Min | CU4: RH6Min | CV4: SnowD | CW4: Precipitation | CX4: Wind | CY4: WindX | CZ4: Vapres | DA4: vpdX | DB4: BatV | DD4: C | DE4: C | DF4: C | DG4: % | DH4: % | DZ4: Tave | EA4: Tmax | EB4: Tmin | EC4: ppt
A5: Date | B5: DoY | C5: MJ/m2/d | D5: mol/m2/d | E5: C | F5: % | G5: C | H5: C | I5: C | J5: WEST | K5: EAST | L5: duff | M5: 15cm | N5: 50cm | O5: (mV) | P5: (m/s) | Q5: mm | R5: C | T5: % | V5: C | W5: C | X5: C | Y5: WEST | Z5: EAST | AA5: duff | AB5: 15cm | AC5: 50cm | AD5: m/s | AE5: m/s | AF5: C | AG5: C | AH5: % | AJ5: C | AK5: C | AL5: C | AM5: WEST | AN5: EAST | AO5: duff | AP5: 15cm | AQ5: 50cm | AR5: N--NE | AS5: NE--E | AT5: E--SE | AU5: SE--S | AV5: S--SW | AW5: SW--W | AX5: W--NW | AY5: NW--N | AZ5: PANEL T | BA5: (mm) | BB5: (V) | BD5: Max | BE5: Min | BF5: mm | BH5: MJ/m2/d | BI5: mol/m2/d | BM5: RHMax | BN5: RHAvg | BO5: RHMin | BP5: kPa | BQ5: kPa | BS5: FWS | BV5: MJ/m2/d | BW5: mol/m2/d | BX5: C | BY5: C | BZ5: C | CA5: C | CB5: C | CC5: C | CD5: C | CE5: % | CF5: C | CG5: C | CH5: C | CI5: C | CJ5: C | CK5: C | CL5: C | CM5: % | CN5: C | CO5: C | CP5: C | CQ5: C | CR5: C | CS5: C | CT5: C | CU5: % | CV5: mm | CW5: mm/d | CX5: m/s | CY5: m/s | CZ5: kPa | DA5: kPa | DB5: V | DD5: Tav | DE5: Tmax | DF5: Tmin | DG5: Rhav | DH5: Rhmin | DZ5: C | EA5: C | EB5: C | EC5: mm
A7: 35065 | B7: 1 | E7: =ROUND(1.19*DZ7-0.2,1) -> -4 | R7: =ROUND(0.95*EA7-0.5,1) -> 0.8 | AF7: =ROUND(1.1*EB7-1,1) -> -7.5 | BH7: 4.59 | BI7: =BH7*$BI$1 -> 9.2718 | BP7: =ROUND(0.6105*(EXP((17.273*AF7)/(AF7+237.3))), 3) -> 0.347 | BQ7: =ROUND(0.6105*(EXP((17.273*R7)/(R7+237.3)))-BP7, 3) -> 0.3 | BS7: =BT$2*BT7 -> 0 | BT7: 0 | BV7: NA | BW7: NA | BX7: =ROUND(E7,1) -> -4 | BY7: NA | BZ7: NA | CA7: NA | CB7: NA | CC7: NA | CD7: NA | CE7: NA | CF7: =ROUND(R7,1) -> 0.8 | CG7: NA | CH7: NA | CI7: NA | CJ7: NA | CK7: NA | CL7: NA | CM7: NA | CN7: =ROUND(AF7,1) -> -7.5 | CO7: NA | CP7: NA | CQ7: NA | CR7: NA | CS7: NA | CT7: NA | CU7: NA | CV7: NA | CW7: =ROUND(PPTest!K7,1) -> 0 | CX7: NA | CY7: NA | CZ7: =BP7 -> 0.347 | DA7: =BQ7 -> 0.3 | DB7: NA | DZ7: -3.2 | EA7: 1.4 | EB7: -5.9 | EC7: 10
A8: 35066 | B8: 2 | E8: =ROUND(1.19*DZ8-0.2,1) -> -3.1 | R8: =ROUND(0.95*EA8-0.5,1) -> 2.6 | AF8: =ROUND(1.1*EB8-1,1) -> -6.2 | BH8: 4.63 | BI8: =BH8*$BI$1 -> 9.3526 | BP8: =ROUND(0.6105*(EXP((17.273*AF8)/(AF8+237.3))), 3) -> 0.384 | BQ8: =ROUND(0.6105*(EXP((17.273*R8)/(R8+237.3)))-BP8, 3) -> 0.352 | BS8: =BT$2*BT8 -> 9 | BT8: 6 | BV8: NA | BW8: NA | BX8: =ROUND(E8,1) -> -3.1 | BY8: NA | BZ8: NA | CA8: NA | CB8: NA | CC8: NA | CD8: NA | CE8: NA | CF8: =ROUND(R8,1) -> 2.6 | CG8: NA | CH8: NA | CI8: NA | CJ8: NA | CK8: NA | CL8: NA | CM8: NA | CN8: =ROUND(AF8,1) -> -6.2 | CO8: NA | CP8: NA | CQ8: NA | CR8: NA | CS8: NA | CT8: NA | CU8: NA | CV8: NA | CW8: =ROUND(PPTest!K8,1) -> 9.5 | CX8: NA | CY8: NA | CZ8: =BP8 -> 0.384 | DA8: =BQ8 -> 0.352 | DB8: NA | DZ8: -2.4 | EA8: 3.3 | EB8: -4.7 | EC8: 5.6
A9: 35067 | B9: 3 | E9: =ROUND(1.19*DZ9-0.2,1) -> -7.1 | R9: =ROUND(0.95*EA9-0.5,1) -> 0.7 | AF9: =ROUND(1.1*EB9-1,1) -> -14.5 | BH9: 4.67 | BI9: =BH9*$BI$1 -> 9.4334 | BP9: =ROUND(0.6105*(EXP((17.273*AF9)/(AF9+237.3))), 3) -> 0.198 | BQ9: =ROUND(0.6105*(EXP((17.273*R9)/(R9+237.3)))-BP9, 3) -> 0.444 | BS9: =BT$2*BT9 -> 0 | BT9: 0 | BV9: NA | BW9: NA | BX9: =ROUND(E9,1) -> -7.1 | BY9: NA | BZ9: NA | CA9: NA | CB9: NA | CC9: NA | CD9: NA | CE9: NA | CF9: =ROUND(R9,1) -> 0.7 | CG9: NA | CH9: NA | CI9: NA | CJ9: NA | CK9: NA | CL9: NA | CM9: NA | CN9: =ROUND(AF9,1) -> -14.5 | CO9: NA | CP9: NA | CQ9: NA | CR9: NA | CS9: NA | CT9: NA | CU9: NA | CV9: NA | CW9: =ROUND(PPTest!K9,1) -> 0 | CX9: NA | CY9: NA | CZ9: =BP9 -> 0.198 | DA9: =BQ9 -> 0.444 | DB9: NA | DZ9: -5.8 | EA9: 1.3 | EB9: -12.3 | EC9: 5
A10: 35068 | B10: 4 | E10: =ROUND(1.19*DZ10-0.2,1) -> -16.5 | R10: =ROUND(0.95*EA10-0.5,1) -> -10.4 | AF10: =ROUND(1.1*EB10-1,1) -> -21.2 | BH10: 4.72 | BI10: =BH10*$BI$1 -> 9.5344 | BP10: =ROUND(0.6105*(EXP((17.273*AF10)/(AF10+237.3))), 3) -> 0.112 | BQ10: =ROUND(0.6105*(EXP((17.273*R10)/(R10+237.3)))-BP10, 3) -> 0.165 | BS10: =BT$2*BT10 -> 0 | BT10: 0 | BV10: NA | BW10: NA | BX10: =ROUND(E10,1) -> -16.5 | BY10: NA | BZ10: NA | CA10: NA | CB10: NA | CC10: NA | CD10: NA | CE10: NA | CF10: =ROUND(R10,1) -> -10.4 | CG10: NA | CH10: NA | CI10: NA | CJ10: NA | CK10: NA | CL10: NA | CM10: NA | CN10: =ROUND(AF10,1) -> -21.2 | CO10: NA | CP10: NA | CQ10: NA | CR10: NA | CS10: NA | CT10: NA | CU10: NA | CV10: NA | CW10: =ROUND(PPTest!K10,1) -> 0 | CX10: NA | CY10: NA | CZ10: =BP10 -> 0.112 | DA10: =BQ10 -> 0.165 | DB10: NA | DZ10: -13.7 | EA10: -10.4 | EB10: -18.4 | EC10: 2.2
A11: 35069 | B11: 5 | E11: =ROUND(1.19*DZ11-0.2,1) -> -17.2 | R11: =ROUND(0.95*EA11-0.5,1) -> -6.1 | AF11: =ROUND(1.1*EB11-1,1) -> -22.7 | BH11: 4.76 | BI11: =BH11*$BI$1 -> 9.6152 | BP11: =ROUND(0.6105*(EXP((17.273*AF11)/(AF11+237.3))), 3) -> 0.098 | BQ11: =ROUND(0.6105*(EXP((17.273*R11)/(R11+237.3)))-BP11, 3) -> 0.289 | BS11: =BT$2*BT11 -> 1.5 | BT11: 1 | BV11: NA | BW11: NA | BX11: =ROUND(E11,1) -> -17.2 | BY11: NA | BZ11: NA | CA11: NA | CB11: NA | CC11: NA | CD11: NA | CE11: NA | CF11: =ROUND(R11,1) -> -6.1 | CG11: NA | CH11: NA | CI11: NA | CJ11: NA | CK11: NA | CL11: NA | CM11: NA | CN11: =ROUND(AF11,1) -> -22.7 | CO11: NA | CP11: NA | CQ11: NA | CR11: NA | CS11: NA | CT11: NA | CU11: NA | CV11: NA | CW11: =ROUND(PPTest!K11,1) -> 1.6 | CX11: NA | CY11: NA | CZ11: =BP11 -> 0.098 | DA11: =BQ11 -> 0.289 | DB11: NA | DZ11: -14.3 | EA11: -5.9 | EB11: -19.7 | EC11: 2.6
A12: 35070 | B12: 6 | E12: =ROUND(1.19*DZ12-0.2,1) -> -10.3 | R12: =ROUND(0.95*EA12-0.5,1) -> -5.2 | AF12: =ROUND(1.1*EB12-1,1) -> -14.6 | BH12: 4.82 | BI12: =BH12*$BI$1 -> 9.7364 | BP12: =ROUND(0.6105*(EXP((17.273*AF12)/(AF12+237.3))), 3) -> 0.197 | BQ12: =ROUND(0.6105*(EXP((17.273*R12)/(R12+237.3)))-BP12, 3) -> 0.218 | BS12: =BT$2*BT12 -> 7.5 | BT12: 5 | BV12: NA | BW12: NA | BX12: =ROUND(E12,1) -> -10.3 | BY12: NA | BZ12: NA | CA12: NA | CB12: NA | CC12: NA | CD12: NA | CE12: NA | CF12: =ROUND(R12,1) -> -5.2 | CG12: NA | CH12: NA | CI12: NA | CJ12: NA | CK12: NA | CL12: NA | CM12: NA | CN12: =ROUND(AF12,1) -> -14.6 | CO12: NA | CP12: NA | CQ12: NA | CR12: NA | CS12: NA | CT12: NA | CU12: NA | CV12: NA | CW12: =ROUND(PPTest!K12,1) -> 7.9 | CX12: NA | CY12: NA | CZ12: =BP12 -> 0.197 | DA12: =BQ12 -> 0.218 | DB12: NA | DZ12: -8.5 | EA12: -4.9 | EB12: -12.4 | EC12: 0.6
A13: 35071 | B13: 7 | E13: =ROUND(1.19*DZ13-0.2,1) -> -4 | R13: =ROUND(0.95*EA13-0.5,1) -> 0.6 | AF13: =ROUND(1.1*EB13-1,1) -> -6.8 | BH13: 4.87 | BI13: =BH13*$BI$1 -> 9.8374 | BP13: =ROUND(0.6105*(EXP((17.273*AF13)/(AF13+237.3))), 3) -> 0.367 | BQ13: =ROUND(0.6105*(EXP((17.273*R13)/(R13+237.3)))-BP13, 3) -> 0.271 | BS13: =BT$2*BT13 -> 0 | BT13: 0 | BV13: NA | BW13: NA | BX13: =ROUND(E13,1) -> -4 | BY13: NA | BZ13: NA | CA13: NA | CB13: NA | CC13: NA | CD13: NA | CE13: NA | CF13: =ROUND(R13,1) -> 0.6 | CG13: NA | CH13: NA | CI13: NA | CJ13: NA | CK13: NA | CL13: NA | CM13: NA | CN13: =ROUND(AF13,1) -> -6.8 | CO13: NA | CP13: NA | CQ13: NA | CR13: NA | CS13: NA | CT13: NA | CU13: NA | CV13: NA | CW13: =ROUND(PPTest!K13,1) -> 0 | CX13: NA | CY13: NA | CZ13: =BP13 -> 0.367 | DA13: =BQ13 -> 0.271 | DB13: NA | DZ13: -3.2 | EA13: 1.2 | EB13: -5.3 | EC13: 1.8
A14: 35072 | B14: 8 | E14: =ROUND(1.19*DZ14-0.2,1) -> -5.6 | R14: =ROUND(0.95*EA14-0.5,1) -> 2.5 | AF14: =ROUND(1.1*EB14-1,1) -> -10.2 | BH14: 4.93 | BI14: =BH14*$BI$1 -> 9.9586 | BP14: =ROUND(0.6105*(EXP((17.273*AF14)/(AF14+237.3))), 3) -> 0.281 | BQ14: =ROUND(0.6105*(EXP((17.273*R14)/(R14+237.3)))-BP14, 3) -> 0.45 | BS14: =BT$2*BT14 -> 0 | BT14: 0 | BV14: NA | BW14: NA | BX14: =ROUND(E14,1) -> -5.6 | BY14: NA | BZ14: NA | CA14: NA | CB14: NA | CC14: NA | CD14: NA | CE14: NA | CF14: =ROUND(R14,1) -> 2.5 | CG14: NA | CH14: NA | CI14: NA | CJ14: NA | CK14: NA | CL14: NA | CM14: NA | CN14: =ROUND(AF14,1) -> -10.2 | CO14: NA | CP14: NA | CQ14: NA | CR14: NA | CS14: NA | CT14: NA | CU14: NA | CV14: NA | CW14: =ROUND(PPTest!K14,1) -> 0 | CX14: NA | CY14: NA | CZ14: =BP14 -> 0.281 | DA14: =BQ14 -> 0.45 | DB14: NA | DZ14: -4.5 | EA14: 3.2 | EB14: -8.4 | EC14: 0
A15: 35073 | B15: 9 | E15: =ROUND(1.19*DZ15-0.2,1) -> -4 | R15: =ROUND(0.95*EA15-0.5,1) -> 0.9 | AF15: =ROUND(1.1*EB15-1,1) -> -7.6 | BH15: 4.99 | BI15: =BH15*$BI$1 -> 10.0798 | BP15: =ROUND(0.6105*(EXP((17.273*AF15)/(AF15+237.3))), 3) -> 0.345 | BQ15: =ROUND(0.6105*(EXP((17.273*R15)/(R15+237.3)))-BP15, 3) -> 0.307 | BS15: =BT$2*BT15 -> 0 | BT15: 0 | BV15: NA | BW15: NA | BX15: =ROUND(E15,1) -> -4 | BY15: NA | BZ15: NA | CA15: NA | CB15: NA | CC15: NA | CD15: NA | CE15: NA | CF15: =ROUND(R15,1) -> 0.9 | CG15: NA | CH15: NA | CI15: NA | CJ15: NA | CK15: NA | CL15: NA | CM15: NA | CN15: =ROUND(AF15,1) -> -7.6 | CO15: NA | CP15: NA | CQ15: NA | CR15: NA | CS15: NA | CT15: NA | CU15: NA | CV15: NA | CW15: =ROUND(PPTest!K15,1) -> 0 | CX15: NA | CY15: NA | CZ15: =BP15 -> 0.345 | DA15: =BQ15 -> 0.307 | DB15: NA | DZ15: -3.2 | EA15: 1.5 | EB15: -6 | EC15: 0
A16: 35074 | B16: 10 | E16: =ROUND(1.19*DZ16-0.2,1) -> -3.8 | R16: =ROUND(0.95*EA16-0.5,1) -> -0.4 | AF16: =ROUND(1.1*EB16-1,1) -> -6.1 | BH16: 5.06 | BI16: =BH16*$BI$1 -> 10.2212 | BP16: =ROUND(0.6105*(EXP((17.273*AF16)/(AF16+237.3))), 3) -> 0.387 | BQ16: =ROUND(0.6105*(EXP((17.273*R16)/(R16+237.3)))-BP16, 3) -> 0.206 | BS16: =BT$2*BT16 -> 0 | BT16: 0 | BV16: NA | BW16: NA | BX16: =ROUND(E16,1) -> -3.8 | BY16: NA | BZ16: NA | CA16: NA | CB16: NA | CC16: NA | CD16: NA | CE16: NA | CF16: =ROUND(R16,1) -> -0.4 | CG16: NA | CH16: NA | CI16: NA | CJ16: NA | CK16: NA | CL16: NA | CM16: NA | CN16: =ROUND(AF16,1) -> -6.1 | CO16: NA | CP16: NA | CQ16: NA | CR16: NA | CS16: NA | CT16: NA | CU16: NA | CV16: NA | CW16: =ROUND(PPTest!K16,1) -> 0 | CX16: NA | CY16: NA | CZ16: =BP16 -> 0.387 | DA16: =BQ16 -> 0.206 | DB16: NA | DZ16: -3 | EA16: 0.1 | EB16: -4.6 | EC16: 0
A17: 35075 | B17: 11 | E17: =ROUND(1.19*DZ17-0.2,1) -> -3.9 | R17: =ROUND(0.95*EA17-0.5,1) -> 1.6 | AF17: =ROUND(1.1*EB17-1,1) -> -10.4 | BH17: 5.13 | BI17: =BH17*$BI$1 -> 10.3626 | BP17: =ROUND(0.6105*(EXP((17.273*AF17)/(AF17+237.3))), 3) -> 0.277 | BQ17: =ROUND(0.6105*(EXP((17.273*R17)/(R17+237.3)))-BP17, 3) -> 0.408 | BS17: =BT$2*BT17 -> 0 | BT17: 0 | BV17: NA | BW17: NA | BX17: =ROUND(E17,1) -> -3.9 | BY17: NA | BZ17: NA | CA17: NA | CB17: NA | CC17: NA | CD17: NA | CE17: NA | CF17: =ROUND(R17,1) -> 1.6 | CG17: NA | CH17: NA | CI17: NA | CJ17: NA | CK17: NA | CL17: NA | CM17: NA | CN17: =ROUND(AF17,1) -> -10.4 | CO17: NA | CP17: NA | CQ17: NA | CR17: NA | CS17: NA | CT17: NA | CU17: NA | CV17: NA | CW17: =ROUND(PPTest!K17,1) -> 0 | CX17: NA | CY17: NA | CZ17: =BP17 -> 0.277 | DA17: =BQ17 -> 0.408 | DB17: NA | DZ17: -3.1 | EA17: 2.2 | EB17: -8.5 | EC17: 0
A18: 35076 | B18: 12 | E18: =ROUND(1.19*DZ18-0.2,1) -> -6.7 | R18: =ROUND(0.95*EA18-0.5,1) -> 1.5 | AF18: =ROUND(1.1*EB18-1,1) -> -12.7 | BH18: 5.2 | BI18: =BH18*$BI$1 -> 10.504 | BP18: =ROUND(0.6105*(EXP((17.273*AF18)/(AF18+237.3))), 3) -> 0.23 | BQ18: =ROUND(0.6105*(EXP((17.273*R18)/(R18+237.3)))-BP18, 3) -> 0.45 | BS18: =BT$2*BT18 -> 0 | BT18: 0 | BV18: NA | BW18: NA | BX18: =ROUND(E18,1) -> -6.7 | BY18: NA | BZ18: NA | CA18: NA | CB18: NA | CC18: NA | CD18: NA | CE18: NA | CF18: =ROUND(R18,1) -> 1.5 | CG18: NA | CH18: NA | CI18: NA | CJ18: NA | CK18: NA | CL18: NA | CM18: NA | CN18: =ROUND(AF18,1) -> -12.7 | CO18: NA | CP18: NA | CQ18: NA | CR18: NA | CS18: NA | CT18: NA | CU18: NA | CV18: NA | CW18: =ROUND(PPTest!K18,1) -> 0 | CX18: NA | CY18: NA | CZ18: =BP18 -> 0.23 | DA18: =BQ18 -> 0.45 | DB18: NA | DZ18: -5.5 | EA18: 2.1 | EB18: -10.6 | EC18: 0
... A67: 35125 | B67: 61 | E67: =ROUND(1.19*DZ67-0.2,1) -> -5.3 | R67: =ROUND(0.95*EA67-0.5,1) -> 6.7 | AF67: =ROUND(1.1*EB67-1,1) -> -16.3 | BH67: 13.23 | BI67: =BH67*$BI$1 -> 26.7246 | BP67: =ROUND(0.6105*(EXP((17.273*AF67)/(AF67+237.3))), 3) -> 0.171 | BQ67: =ROUND(0.6105*(EXP((17.273*R67)/(R67+237.3)))-BP67, 3) -> 0.81 | BS67: =BT$2*BT67 -> 0 | BT67: 0 | BV67: NA | BW67: NA | BX67: =ROUND(E67,1) -> -5.3 | BY67: NA | BZ67: NA | CA67: NA | CB67: NA | CC67: NA | CD67: NA | CE67: NA | CF67: =ROUND(R67,1) -> 6.7 | CG67: NA | CH67: NA | CI67: NA | CJ67: NA | CK67: NA | CL67: NA | CM67: NA | CN67: =ROUND(AF67,1) -> -16.3 | CO67: NA | CP67: NA | CQ67: NA | CR67: NA | CS67: NA | CT67: NA | CU67: NA | CV67: NA | CW67: =ROUND(PPTest!K67,1) -> 0 | CX67: NA | CY67: NA | CZ67: =BP67 -> 0.171 | DA67: =BQ67 -> 0.81 | DB67: NA | DZ67: -4.3 | EA67: 7.6 | EB67: -13.9 | EC67: 0
A68: 35126 | B68: 62 | E68: =ROUND(1.19*DZ68-0.2,1) -> -2.8 | R68: =ROUND(0.95*EA68-0.5,1) -> 5.1 | AF68: =ROUND(1.1*EB68-1,1) -> -12.6 | BH68: 13.47 | BI68: =BH68*$BI$1 -> 27.2094 | BP68: =ROUND(0.6105*(EXP((17.273*AF68)/(AF68+237.3))), 3) -> 0.232 | BQ68: =ROUND(0.6105*(EXP((17.273*R68)/(R68+237.3)))-BP68, 3) -> 0.646 | BV68: NA | BW68: NA | BX68: =ROUND(E68,1) -> -2.8 | BY68: NA | BZ68: NA | CA68: NA | CB68: NA | CC68: NA | CD68: NA | CE68: NA | CF68: =ROUND(R68,1) -> 5.1 | CG68: NA | CH68: NA | CI68: NA | CJ68: NA | CK68: NA | CL68: NA | CM68: NA | CN68: =ROUND(AF68,1) -> -12.6 | CO68: NA | CP68: NA | CQ68: NA | CR68: NA | CS68: NA | CT68: NA | CU68: NA | CV68: NA | CW68: =ROUND(PPTest!K68,1) -> 0 | CX68: NA | CY68: NA | CZ68: =BP68 -> 0.232 | DA68: =BQ68 -> 0.646 | DB68: NA | DZ68: -2.2 | EA68: 5.9 | EB68: -10.5 | EC68: 0
A69: 35127 | B69: 63 | E69: =ROUND(1.19*DZ69-0.2,1) -> -7.7 | R69: =ROUND(0.95*EA69-0.5,1) -> -3.2 | AF69: =ROUND(1.1*EB69-1,1) -> -12.4 | BH69: 13.71 | BI69: =BH69*$BI$1 -> 27.6942 | BP69: =ROUND(0.6105*(EXP((17.273*AF69)/(AF69+237.3))), 3) -> 0.236 | BQ69: =ROUND(0.6105*(EXP((17.273*R69)/(R69+237.3)))-BP69, 3) -> 0.246 | BV69: NA | BW69: NA | BX69: =ROUND(E69,1) -> -7.7 | BY69: NA | BZ69: NA | CA69: NA | CB69: NA | CC69: NA | CD69: NA | CE69: NA | CF69: =ROUND(R69,1) -> -3.2 | CG69: NA | CH69: NA | CI69: NA | CJ69: NA | CK69: NA | CL69: NA | CM69: NA | CN69: =ROUND(AF69,1) -> -12.4 | CO69: NA | CP69: NA | CQ69: NA | CR69: NA | CS69: NA | CT69: NA | CU69: NA | CV69: NA | CW69: =ROUND(PPTest!K69,1) -> 3.6 | CX69: NA | CY69: NA | CZ69: =BP69 -> 0.236 | DA69: =BQ69 -> 0.246 | DB69: NA | DZ69: -6.3 | EA69: -2.8 | EB69: -10.4 | EC69: 3.6
A70: 35128 | B70: 64 | E70: =ROUND(1.19*DZ70-0.2,1) -> -13.9 | R70: =ROUND(0.95*EA70-0.5,1) -> -9.5 | AF70: =ROUND(1.1*EB70-1,1) -> -15.2 | BH70: 13.95 | BI70: =BH70*$BI$1 -> 28.179 | BP70: =ROUND(0.6105*(EXP((17.273*AF70)/(AF70+237.3))), 3) -> 0.187 | BQ70: =ROUND(0.6105*(EXP((17.273*R70)/(R70+237.3)))-BP70, 3) -> 0.11 | BV70: NA | BW70: NA | BX70: =ROUND(E70,1) -> -13.9 | BY70: NA | BZ70: NA | CA70: NA | CB70: NA | CC70: NA | CD70: NA | CE70: NA | CF70: =ROUND(R70,1) -> -9.5 | CG70: NA | CH70: NA | CI70: NA | CJ70: NA | CK70: NA | CL70: NA | CM70: NA | CN70: =ROUND(AF70,1) -> -15.2 | CO70: NA | CP70: NA | CQ70: NA | CR70: NA | CS70: NA | CT70: NA | CU70: NA | CV70: NA | CW70: =ROUND(PPTest!K70,1) -> 0 | CX70: NA | CY70: NA | CZ70: =BP70 -> 0.187 | DA70: =BQ70 -> 0.11 | DB70: NA | DZ70: -11.5 | EA70: -9.5 | EB70: -12.9 | EC70: 0
A71: 35129 | B71: 65 | E71: =ROUND(1.19*DZ71-0.2,1) -> -13.6 | R71: =ROUND(0.95*EA71-0.5,1) -> -4.6 | AF71: =ROUND(1.1*EB71-1,1) -> -18.5 | BH71: 14.21 | BI71: =BH71*$BI$1 -> 28.7042 | BP71: =ROUND(0.6105*(EXP((17.273*AF71)/(AF71+237.3))), 3) -> 0.142 | BQ71: =ROUND(0.6105*(EXP((17.273*R71)/(R71+237.3)))-BP71, 3) -> 0.292 | BV71: NA | BW71: NA | BX71: =ROUND(E71,1) -> -13.6 | BY71: NA | BZ71: NA | CA71: NA | CB71: NA | CC71: NA | CD71: NA | CE71: NA | CF71: =ROUND(R71,1) -> -4.6 | CG71: NA | CH71: NA | CI71: NA | CJ71: NA | CK71: NA | CL71: NA | CM71: NA | CN71: =ROUND(AF71,1) -> -18.5 | CO71: NA | CP71: NA | CQ71: NA | CR71: NA | CS71: NA | CT71: NA | CU71: NA | CV71: NA | CW71: =ROUND(PPTest!K71,1) -> 1.2 | CX71: NA | CY71: NA | CZ71: =BP71 -> 0.142 | DA71: =BQ71 -> 0.292 | DB71: NA | DZ71: -11.3 | EA71: -4.3 | EB71: -15.9 | EC71: 1.2
A72: 35130 | B72: 66 | E72: =ROUND(1.19*DZ72-0.2,1) -> -9 | R72: =ROUND(0.95*EA72-0.5,1) -> -2.8 | AF72: =ROUND(1.1*EB72-1,1) -> -18.7 | BH72: 14.45 | BI72: =BH72*$BI$1 -> 29.189 | BP72: =ROUND(0.6105*(EXP((17.273*AF72)/(AF72+237.3))), 3) -> 0.139 | BQ72: =ROUND(0.6105*(EXP((17.273*R72)/(R72+237.3)))-BP72, 3) -> 0.358 | BV72: NA | BW72: NA | BX72: =ROUND(E72,1) -> -9 | BY72: NA | BZ72: NA | CA72: NA | CB72: NA | CC72: NA | CD72: NA | CE72: NA | CF72: =ROUND(R72,1) -> -2.8 | CG72: NA | CH72: NA | CI72: NA | CJ72: NA | CK72: NA | CL72: NA | CM72: NA | CN72: =ROUND(AF72,1) -> -18.7 | CO72: NA | CP72: NA | CQ72: NA | CR72: NA | CS72: NA | CT72: NA | CU72: NA | CV72: NA | CW72: =ROUND(PPTest!K72,1) -> 0.3 | CX72: NA | CY72: NA | CZ72: =BP72 -> 0.139 | DA72: =BQ72 -> 0.358 | DB72: NA | DZ72: -7.4 | EA72: -2.4 | EB72: -16.1 | EC72: 0.3
A73: 35131 | B73: 67 | E73: =ROUND(1.19*DZ73-0.2,1) -> -6.5 | R73: =ROUND(0.95*EA73-0.5,1) -> -3.4 | AF73: =ROUND(1.1*EB73-1,1) -> -12.2 | BH73: 14.7 | BI73: =BH73*$BI$1 -> 29.694 | BP73: =ROUND(0.6105*(EXP((17.273*AF73)/(AF73+237.3))), 3) -> 0.239 | BQ73: =ROUND(0.6105*(EXP((17.273*R73)/(R73+237.3)))-BP73, 3) -> 0.236 | BV73: NA | BW73: NA | BX73: =ROUND(E73,1) -> -6.5 | BY73: NA | BZ73: NA | CA73: NA | CB73: NA | CC73: NA | CD73: NA | CE73: NA | CF73: =ROUND(R73,1) -> -3.4 | CG73: NA | CH73: NA | CI73: NA | CJ73: NA | CK73: NA | CL73: NA | CM73: NA | CN73: =ROUND(AF73,1) -> -12.2 | CO73: NA | CP73: NA | CQ73: NA | CR73: NA | CS73: NA | CT73: NA | CU73: NA | CV73: NA | CW73: =ROUND(PPTest!K73,1) -> 2.3 | CX73: NA | CY73: NA | CZ73: =BP73 -> 0.239 | DA73: =BQ73 -> 0.236 | DB73: NA | DZ73: -5.3 | EA73: -3 | EB73: -10.2 | EC73: 2.3
A74: 35132 | B74: 68 | E74: =ROUND(1.19*DZ74-0.2,1) -> -2.8 | R74: =ROUND(0.95*EA74-0.5,1) -> 0 | AF74: =ROUND(1.1*EB74-1,1) -> -7.1 | BH74: 14.96 | BI74: =BH74*$BI$1 -> 30.2192 | BP74: =ROUND(0.6105*(EXP((17.273*AF74)/(AF74+237.3))), 3) -> 0.358 | BQ74: =ROUND(0.6105*(EXP((17.273*R74)/(R74+237.3)))-BP74, 3) -> 0.253 | BV74: NA | BW74: NA | BX74: =ROUND(E74,1) -> -2.8 | BY74: NA | BZ74: NA | CA74: NA | CB74: NA | CC74: NA | CD74: NA | CE74: NA | CF74: =ROUND(R74,1) -> 0 | CG74: NA | CH74: NA | CI74: NA | CJ74: NA | CK74: NA | CL74: NA | CM74: NA | CN74: =ROUND(AF74,1) -> -7.1 | CO74: NA | CP74: NA | CQ74: NA | CR74: NA | CS74: NA | CT74: NA | CU74: NA | CV74: NA | CW74: =ROUND(PPTest!K74,1) -> 1.6 | CX74: NA | CY74: NA | CZ74: =BP74 -> 0.358 | DA74: =BQ74 -> 0.253 | DB74: NA | DZ74: -2.2 | EA74: 0.5 | EB74: -5.5 | EC74: 1.6
A75: 35133 | B75: 69 | E75: =ROUND(1.02*DZ75-0.4,1) -> 0.7 | R75: =ROUND(0.96*EA75+0.2,1) -> 3.8 | AF75: =ROUND(1.1*EB75-0.4,1) -> -1.2 | BH75: 15.22 | BI75: =BH75*$BI$1 -> 30.7444 | BP75: =ROUND(0.6105*(EXP((17.273*AF75)/(AF75+237.3))), 3) -> 0.559 | BQ75: =ROUND(0.6105*(EXP((17.273*R75)/(R75+237.3)))-BP75, 3) -> 0.243 | BV75: NA | BW75: NA | BX75: =ROUND(E75,1) -> 0.7 | BY75: NA | BZ75: NA | CA75: NA | CB75: NA | CC75: NA | CD75: NA | CE75: NA | CF75: =ROUND(R75,1) -> 3.8 | CG75: NA | CH75: NA | CI75: NA | CJ75: NA | CK75: NA | CL75: NA | CM75: NA | CN75: =ROUND(AF75,1) -> -1.2 | CO75: NA | CP75: NA | CQ75: NA | CR75: NA | CS75: NA | CT75: NA | CU75: NA | CV75: NA | CW75: =ROUND(PPTest!K75,1) -> 4.8 | CX75: NA | CY75: NA | CZ75: =BP75 -> 0.559 | DA75: =BQ75 -> 0.243 | DB75: NA | DZ75: 1.1 | EA75: 3.7 | EB75: -0.7 | EC75: 4.8
A76: 35134 | B76: 70 | E76: =ROUND(1.02*DZ76-0.4,1) -> 1.5 | R76: =ROUND(0.96*EA76+0.2,1) -> 4.7 | AF76: =ROUND(1.1*EB76-0.4,1) -> -0.7 | BH76: 15.48 | BI76: =BH76*$BI$1 -> 31.2696 | BP76: =ROUND(0.6105*(EXP((17.273*AF76)/(AF76+237.3))), 3) -> 0.58 | BQ76: =ROUND(0.6105*(EXP((17.273*R76)/(R76+237.3)))-BP76, 3) -> 0.274 | BV76: NA | BW76: NA | BX76: =ROUND(E76,1) -> 1.5 | BY76: NA | BZ76: NA | CA76: NA | CB76: NA | CC76: NA | CD76: NA | CE76: NA | CF76: =ROUND(R76,1) -> 4.7 | CG76: NA | CH76: NA | CI76: NA | CJ76: NA | CK76: NA | CL76: NA | CM76: NA | CN76: =ROUND(AF76,1) -> -0.7 | CO76: NA | CP76: NA | CQ76: NA | CR76: NA | CS76: NA | CT76: NA | CU76: NA | CV76: NA | CW76: =ROUND(PPTest!K76,1) -> 2.2 | CX76: NA | CY76: NA | CZ76: =BP76 -> 0.58 | DA76: =BQ76 -> 0.274 | DB76: NA | DZ76: 1.9 | EA76: 4.7 | EB76: -0.3 | EC76: 2.2
A77: 35135 | B77: 71 | E77: =ROUND(1.02*DZ77-0.4,1) -> 1 | R77: =ROUND(0.96*EA77+0.2,1) -> 4.6 | AF77: =ROUND(1.1*EB77-0.4,1) -> -2.8 | BH77: 15.73 | BI77: =BH77*$BI$1 -> 31.7746 | BP77: =ROUND(0.6105*(EXP((17.273*AF77)/(AF77+237.3))), 3) -> 0.497 | BQ77: =ROUND(0.6105*(EXP((17.273*R77)/(R77+237.3)))-BP77, 3) -> 0.351 | BV77: NA | BW77: NA | BX77: =ROUND(E77,1) -> 1 | BY77: NA | BZ77: NA | CA77: NA | CB77: NA | CC77: NA | CD77: NA | CE77: NA | CF77: =ROUND(R77,1) -> 4.6 | CG77: NA | CH77: NA | CI77: NA | CJ77: NA | CK77: NA | CL77: NA | CM77: NA | CN77: =ROUND(AF77,1) -> -2.8 | CO77: NA | CP77: NA | CQ77: NA | CR77: NA | CS77: NA | CT77: NA | CU77: NA | CV77: NA | CW77: =ROUND(PPTest!K77,1) -> 1 | CX77: NA | CY77: NA | CZ77: =BP77 -> 0.497 | DA77: =BQ77 -> 0.351 | DB77: NA | DZ77: 1.4 | EA77: 4.6 | EB77: -2.2 | EC77: 1
A78: 35136 | B78: 72 | E78: =ROUND(1.02*DZ78-0.4,1) -> -1.9 | R78: =ROUND(0.96*EA78+0.2,1) -> 1.7 | AF78: =ROUND(1.1*EB78-0.4,1) -> -5.6 | BH78: 15.98 | BI78: =BH78*$BI$1 -> 32.2796 | BP78: =ROUND(0.6105*(EXP((17.273*AF78)/(AF78+237.3))), 3) -> 0.402 | BQ78: =ROUND(0.6105*(EXP((17.273*R78)/(R78+237.3)))-BP78, 3) -> 0.288 | BV78: NA | BW78: NA | BX78: =ROUND(E78,1) -> -1.9 | BY78: NA | BZ78: NA | CA78: NA | CB78: NA | CC78: NA | CD78: NA | CE78: NA | CF78: =ROUND(R78,1) -> 1.7 | CG78: NA | CH78: NA | CI78: NA | CJ78: NA | CK78: NA | CL78: NA | CM78: NA | CN78: =ROUND(AF78,1) -> -5.6 | CO78: NA | CP78: NA | CQ78: NA | CR78: NA | CS78: NA | CT78: NA | CU78: NA | CV78: NA | CW78: =ROUND(PPTest!K78,1) -> 0.7 | CX78: NA | CY78: NA | CZ78: =BP78 -> 0.402 | DA78: =BQ78 -> 0.288 | DB78: NA | DZ78: -1.5 | EA78: 1.6 | EB78: -4.7 | EC78: 0.7
A79: 35137 | B79: 73 | E79: =ROUND(1.02*DZ79-0.4,1) -> -0.9 | R79: =ROUND(0.96*EA79+0.2,1) -> 5.3 | AF79: =ROUND(1.1*EB79-0.4,1) -> -5.2 | BH79: 16.25 | BI79: =BH79*$BI$1 -> 32.825 | BP79: =ROUND(0.6105*(EXP((17.273*AF79)/(AF79+237.3))), 3) -> 0.415 | BQ79: =ROUND(0.6105*(EXP((17.273*R79)/(R79+237.3)))-BP79, 3) -> 0.475 | BV79: NA | BW79: NA | BX79: =ROUND(E79,1) -> -0.9 | BY79: NA | BZ79: NA | CA79: NA | CB79: NA | CC79: NA | CD79: NA | CE79: NA | CF79: =ROUND(R79,1) -> 5.3 | CG79: NA | CH79: NA | CI79: NA | CJ79: NA | CK79: NA | CL79: NA | CM79: NA | CN79: =ROUND(AF79,1) -> -5.2 | CO79: NA | CP79: NA | CQ79: NA | CR79: NA | CS79: NA | CT79: NA | CU79: NA | CV79: NA | CW79: =ROUND(PPTest!K79,1) -> 0 | CX79: NA | CY79: NA | CZ79: =BP79 -> 0.415 | DA79: =BQ79 -> 0.475 | DB79: NA | DZ79: -0.5 | EA79: 5.3 | EB79: -4.4 | EC79: 0
A80: 35138 | B80: 74 | E80: =ROUND(1.02*DZ80-0.4,1) -> 3.7 | R80: =ROUND(0.96*EA80+0.2,1) -> 12.3 | AF80: =ROUND(1.1*EB80-0.4,1) -> -4.1 | BH80: 16.51 | BI80: =BH80*$BI$1 -> 33.3502 | BP80: =ROUND(0.6105*(EXP((17.273*AF80)/(AF80+237.3))), 3) -> 0.451 | BQ80: =ROUND(0.6105*(EXP((17.273*R80)/(R80+237.3)))-BP80, 3) -> 0.979 | BV80: NA | BW80: NA | BX80: =ROUND(E80,1) -> 3.7 | BY80: NA | BZ80: NA | CA80: NA | CB80: NA | CC80: NA | CD80: NA | CE80: NA | CF80: =ROUND(R80,1) -> 12.3 | CG80: NA | CH80: NA | CI80: NA | CJ80: NA | CK80: NA | CL80: NA | CM80: NA | CN80: =ROUND(AF80,1) -> -4.1 | CO80: NA | CP80: NA | CQ80: NA | CR80: NA | CS80: NA | CT80: NA | CU80: NA | CV80: NA | CW80: =ROUND(PPTest!K80,1) -> 0 | CX80: NA | CY80: NA | CZ80: =BP80 -> 0.451 | DA80: =BQ80 -> 0.979 | DB80: NA | DZ80: 4 | EA80: 12.6 | EB80: -3.4 | EC80: 0
A81: 35139 | B81: 75 | E81: =ROUND(1.02*DZ81-0.4,1) -> -1.2 | R81: =ROUND(0.96*EA81+0.2,1) -> 3.4 | AF81: =ROUND(1.1*EB81-0.4,1) -> -2.8 | BH81: 16.77 | BI81: =BH81*$BI$1 -> 33.8754 | BP81: =ROUND(0.6105*(EXP((17.273*AF81)/(AF81+237.3))), 3) -> 0.497 | BQ81: =ROUND(0.6105*(EXP((17.273*R81)/(R81+237.3)))-BP81, 3) -> 0.282 | BV81: NA | BW81: NA | BX81: =ROUND(E81,1) -> -1.2 | BY81: NA | BZ81: NA | CA81: NA | CB81: NA | CC81: NA | CD81: NA | CE81: NA | CF81: =ROUND(R81,1) -> 3.4 | CG81: NA | CH81: NA | CI81: NA | CJ81: NA | CK81: NA | CL81: NA | CM81: NA | CN81: =ROUND(AF81,1) -> -2.8 | CO81: NA | CP81: NA | CQ81: NA | CR81: NA | CS81: NA | CT81: NA | CU81: NA | CV81: NA | CW81: =ROUND(PPTest!K81,1) -> 4.4 | CX81: NA | CY81: NA | CZ81: =BP81 -> 0.497 | DA81: =BQ81 -> 0.282 | DB81: NA | DZ81: -0.8 | EA81: 3.3 | EB81: -2.2 | EC81: 4.4
A82: 35140 | B82: 76 | E82: =ROUND(1.02*DZ82-0.4,1) -> -3.2 | R82: =ROUND(0.96*EA82+0.2,1) -> -1 | AF82: =ROUND(1.1*EB82-0.4,1) -> -5.1 | BH82: 17.03 | BI82: =BH82*$BI$1 -> 34.4006 | BP82: =ROUND(0.6105*(EXP((17.273*AF82)/(AF82+237.3))), 3) -> 0.418 | BQ82: =ROUND(0.6105*(EXP((17.273*R82)/(R82+237.3)))-BP82, 3) -> 0.149 | BV82: NA | BW82: NA | BX82: =ROUND(E82,1) -> -3.2 | BY82: NA | BZ82: NA | CA82: NA | CB82: NA | CC82: NA | CD82: NA | CE82: NA | CF82: =ROUND(R82,1) -> -1 | CG82: NA | CH82: NA | CI82: NA | CJ82: NA | CK82: NA | CL82: NA | CM82: NA | CN82: =ROUND(AF82,1) -> -5.1 | CO82: NA | CP82: NA | CQ82: NA | CR82: NA | CS82: NA | CT82: NA | CU82: NA | CV82: NA | CW82: =ROUND(PPTest!K82,1) -> 3.6 | CX82: NA | CY82: NA | CZ82: =BP82 -> 0.418 | DA82: =BQ82 -> 0.149 | DB82: NA | DZ82: -2.7 | EA82: -1.3 | EB82: -4.3 | EC82: 3.6
A83: 35141 | B83: 77 | E83: =ROUND(1.02*DZ83-0.4,1) -> -2.5 | R83: =ROUND(0.96*EA83+0.2,1) -> 4.3 | AF83: =ROUND(1.1*EB83-0.4,1) -> -8.7 | BH83: 17.3 | BI83: =BH83*$BI$1 -> 34.946 | BP83: =ROUND(0.6105*(EXP((17.273*AF83)/(AF83+237.3))), 3) -> 0.316 | BQ83: =ROUND(0.6105*(EXP((17.273*R83)/(R83+237.3)))-BP83, 3) -> 0.514 | BV83: NA | BW83: NA | BX83: =ROUND(E83,1) -> -2.5 | BY83: NA | BZ83: NA | CA83: NA | CB83: NA | CC83: NA | CD83: NA | CE83: NA | CF83: =ROUND(R83,1) -> 4.3 | CG83: NA | CH83: NA | CI83: NA | CJ83: NA | CK83: NA | CL83: NA | CM83: NA | CN83: =ROUND(AF83,1) -> -8.7 | CO83: NA | CP83: NA | CQ83: NA | CR83: NA | CS83: NA | CT83: NA | CU83: NA | CV83: NA | CW83: =ROUND(PPTest!K83,1) -> 1 | CX83: NA | CY83: NA | CZ83: =BP83 -> 0.316 | DA83: =BQ83 -> 0.514 | DB83: NA | DZ83: -2.1 | EA83: 4.3 | EB83: -7.5 | EC83: 1
A84: 35142 | B84: 78 | E84: =ROUND(1.02*DZ84-0.4,1) -> -1.6 | R84: =ROUND(0.96*EA84+0.2,1) -> 4.7 | AF84: =ROUND(1.1*EB84-0.4,1) -> -11 | BH84: 17.56 | BI84: =BH84*$BI$1 -> 35.4712 | BP84: =ROUND(0.6105*(EXP((17.273*AF84)/(AF84+237.3))), 3) -> 0.264 | BQ84: =ROUND(0.6105*(EXP((17.273*R84)/(R84+237.3)))-BP84, 3) -> 0.59 | BV84: NA | BW84: NA | BX84: =ROUND(E84,1) -> -1.6 | BY84: NA | BZ84: NA | CA84: NA | CB84: NA | CC84: NA | CD84: NA | CE84: NA | CF84: =ROUND(R84,1) -> 4.7 | CG84: NA | CH84: NA | CI84: NA | CJ84: NA | CK84: NA | CL84: NA | CM84: NA | CN84: =ROUND(AF84,1) -> -11 | CO84: NA | CP84: NA | CQ84: NA | CR84: NA | CS84: NA | CT84: NA | CU84: NA | CV84: NA | CW84: =ROUND(PPTest!K84,1) -> 0 | CX84: NA | CY84: NA | CZ84: =BP84 -> 0.264 | DA84: =BQ84 -> 0.59 | DB84: NA | DZ84: -1.2 | EA84: 4.7 | EB84: -9.6 | EC84: 0
A85: 35143 | B85: 79 | E85: =ROUND(1.02*DZ85-0.4,1) -> 0.6 | R85: =ROUND(0.96*EA85+0.2,1) -> 5.5 | AF85: =ROUND(1.1*EB85-0.4,1) -> -4.1 | BH85: 17.83 | BI85: =BH85*$BI$1 -> 36.0166 | BP85: =ROUND(0.6105*(EXP((17.273*AF85)/(AF85+237.3))), 3) -> 0.451 | BQ85: =ROUND(0.6105*(EXP((17.273*R85)/(R85+237.3)))-BP85, 3) -> 0.452 | BV85: NA | BW85: NA | BX85: =ROUND(E85,1) -> 0.6 | BY85: NA | BZ85: NA | CA85: NA | CB85: NA | CC85: NA | CD85: NA | CE85: NA | CF85: =ROUND(R85,1) -> 5.5 | CG85: NA | CH85: NA | CI85: NA | CJ85: NA | CK85: NA | CL85: NA | CM85: NA | CN85: =ROUND(AF85,1) -> -4.1 | CO85: NA | CP85: NA | CQ85: NA | CR85: NA | CS85: NA | CT85: NA | CU85: NA | CV85: NA | CW85: =ROUND(PPTest!K85,1) -> 0 | CX85: NA | CY85: NA | CZ85: =BP85 -> 0.451 | DA85: =BQ85 -> 0.452 | DB85: NA | DZ85: 1 | EA85: 5.5 | EB85: -3.4 | EC85: 0
A86: 35144 | B86: 80 | E86: =ROUND(1.02*DZ86-0.4,1) -> -2.4 | R86: =ROUND(0.96*EA86+0.2,1) -> 4.9 | AF86: =ROUND(1.1*EB86-0.4,1) -> -8 | BH86: 18.1 | BI86: =BH86*$BI$1 -> 36.562 | BP86: =ROUND(0.6105*(EXP((17.273*AF86)/(AF86+237.3))), 3) -> 0.334 | BQ86: =ROUND(0.6105*(EXP((17.273*R86)/(R86+237.3)))-BP86, 3) -> 0.532 | BV86: NA | BW86: NA | BX86: =ROUND(E86,1) -> -2.4 | BY86: NA | BZ86: NA | CA86: NA | CB86: NA | CC86: NA | CD86: NA | CE86: NA | CF86: =ROUND(R86,1) -> 4.9 | CG86: NA | CH86: NA | CI86: NA | CJ86: NA | CK86: NA | CL86: NA | CM86: NA | CN86: =ROUND(AF86,1) -> -8 | CO86: NA | CP86: NA | CQ86: NA | CR86: NA | CS86: NA | CT86: NA | CU86: NA | CV86: NA | CW86: =ROUND(PPTest!K86,1) -> 0 | CX86: NA | CY86: NA | CZ86: =BP86 -> 0.334 | DA86: =BQ86 -> 0.532 | DB86: NA | DZ86: -2 | EA86: 4.9 | EB86: -6.9 | EC86: 0
... A136: 35194 | B136: 130 | E136: =ROUND(1.02*DZ136-0.4,1) -> -2.4 | R136: =ROUND(0.96*EA136+0.2,1) -> 5.5 | AF136: =ROUND(1.1*EB136-0.4,1) -> -9.6 | BH136: 29.87 | BI136: =BH136*$BI$1 -> 60.3374 | BP136: =ROUND(0.6105*(EXP((17.273*AF136)/(AF136+237.3))), 3) -> 0.295 | BQ136: =ROUND(0.6105*(EXP((17.273*R136)/(R136+237.3)))-BP136, 3) -> 0.608 | BV136: NA | BW136: NA | BX136: =ROUND(E136,1) -> -2.4 | BY136: NA | BZ136: NA | CA136: NA | CB136: NA | CC136: NA | CD136: NA | CE136: NA | CF136: =ROUND(R136,1) -> 5.5 | CG136: NA | CH136: NA | CI136: NA | CJ136: NA | CK136: NA | CL136: NA | CM136: NA | CN136: =ROUND(AF136,1) -> -9.6 | CO136: NA | CP136: NA | CQ136: NA | CR136: NA | CS136: NA | CT136: NA | CU136: NA | CV136: NA | CW136: =ROUND(PPTest!K136,1) -> 0 | CX136: NA | CY136: NA | CZ136: =BP136 -> 0.295 | DA136: =BQ136 -> 0.608 | DB136: NA | DZ136: -2 | EA136: 5.5 | EB136: -8.4 | EC136: 0
A137: 35195 | B137: 131 | E137: =ROUND(1.02*DZ137-0.4,1) -> -0.9 | R137: =ROUND(0.96*EA137+0.2,1) -> 4.3 | AF137: =ROUND(1.1*EB137-0.4,1) -> -4.9 | BH137: 30.03 | BI137: =BH137*$BI$1 -> 60.6606 | BP137: =ROUND(0.6105*(EXP((17.273*AF137)/(AF137+237.3))), 3) -> 0.424 | BQ137: =ROUND(0.6105*(EXP((17.273*R137)/(R137+237.3)))-BP137, 3) -> 0.406 | BS137: 0.5 | BV137: NA | BW137: NA | BX137: =ROUND(E137,1) -> -0.9 | BY137: NA | BZ137: NA | CA137: NA | CB137: NA | CC137: NA | CD137: NA | CE137: NA | CF137: =ROUND(R137,1) -> 4.3 | CG137: NA | CH137: NA | CI137: NA | CJ137: NA | CK137: NA | CL137: NA | CM137: NA | CN137: =ROUND(AF137,1) -> -4.9 | CO137: NA | CP137: NA | CQ137: NA | CR137: NA | CS137: NA | CT137: NA | CU137: NA | CV137: NA | CW137: =ROUND(PPTest!K137,1) -> 0.5 | CX137: NA | CY137: NA | CZ137: =BP137 -> 0.424 | DA137: =BQ137 -> 0.406 | DB137: NA | DZ137: -0.5 | EA137: 4.3 | EB137: -4.1 | EC137: 0
A138: 35196 | B138: 132 | E138: =ROUND(DD138*0.75-0.6,1) -> 1.3 | R138: =ROUND(DE138*0.95-1.2,1) -> 5 | AF138: =ROUND(DF138*0.76-3.6,1) -> -4.4 | BH138: 30.19 | BI138: =BH138*$BI$1 -> 60.9838 | BO138: =ROUND(DH138*0.85+1,0) -> 57 | BP138: =ROUND(0.6105*(EXP((17.273*R138)/(R138+237.3)))*BO138/100, 3) -> 0.497 | BQ138: =ROUND((100-BO138)*BP138/BO138,3) -> 0.375 | BS138: 1.8 | BV138: NA | BW138: NA | BX138: =ROUND(E138,1) -> 1.3 | BY138: NA | BZ138: NA | CA138: NA | CB138: NA | CC138: NA | CD138: NA | CE138: NA | CF138: =ROUND(R138,1) -> 5 | CG138: NA | CH138: NA | CI138: NA | CJ138: NA | CK138: NA | CL138: NA | CM138: NA | CN138: =ROUND(AF138,1) -> -4.4 | CO138: NA | CP138: NA | CQ138: NA | CR138: NA | CS138: NA | CT138: NA | CU138: =ROUND(BO138,1) -> 57 | CV138: NA | CW138: =ROUND(PPTest!K138,1) -> 1.9 | CX138: NA | CY138: NA | CZ138: =BP138 -> 0.497 | DA138: =BQ138 -> 0.375 | DB138: NA | DD138: 2.5291667 | DE138: 6.5 | DF138: -1 | DG138: 86.791667 | DH138: 66 | DZ138: 0.1 | EA138: 3.8 | EB138: -4.9 | EC138: 1.3
...

Sheet DerVar
A1: Derived variables
A2: Last edit 26/09/17
O5: Sum
A6: Date | B6: DoY | C6: YrMn | D6: DD<0 | E6: DD>5 | H6: Row Labels | I6: Sum of DD<0 | J6: Sum of DD>5 | L6: YrMn | M6: DD<0 | N6: DD>5 | O6: DD<0 | P6: DD>5
A7: 35065 | B7: 1 | C7: 199601 | D7: =ROUND(IF(Data!E7<0,0-Data!E7,0),1) -> 4 | E7: =ROUND(IF(Data!E7>5,Data!E7-5,0),1) -> 0 | H7: 199601 | I7: 387.7 | J7: 0 | L7: =H7 -> 199601 | M7: =I7 -> 387.7 | N7: =J7 -> 0 | O7: =M7 -> 387.7 | P7: =N7 -> 0
A8: 35066 | B8: 2 | C8: 199601 | D8: =ROUND(IF(Data!E8<0,0-Data!E8,0),1) -> 3.1 | E8: =ROUND(IF(Data!E8>5,Data!E8-5,0),1) -> 0 | H8: 199602 | I8: 231.8 | J8: 0 | L8: =H8 -> 199602 | M8: =I8 -> 231.8 | N8: =J8 -> 0 | O8: =M8+O7 -> 619.5 | P8: =N8+P7 -> 0
A9: 35067 | B9: 3 | C9: 199601 | D9: =ROUND(IF(Data!E9<0,0-Data!E9,0),1) -> 7.1 | E9: =ROUND(IF(Data!E9>5,Data!E9-5,0),1) -> 0 | H9: 199603 | I9: 150.3 | J9: 0 | L9: =H9 -> 199603 | M9: =I9 -> 150.3 | N9: =J9 -> 0 | O9: =M9+O8 -> 769.8 | P9: =N9+P8 -> 0
A10: 35068 | B10: 4 | C10: 199601 | D10: =ROUND(IF(Data!E10<0,0-Data!E10,0),1) -> 16.5 | E10: =ROUND(IF(Data!E10>5,Data!E10-5,0),1) -> 0 | H10: 199604 | I10: 23.1 | J10: 2.4 | L10: =H10 -> 199604 | M10: =I10 -> 23.1 | N10: =J10 -> 2.4 | O10: =M10+O9 -> 792.9 | P10: =N10+P9 -> 2.4
A11: 35069 | B11: 5 | C11: 199601 | D11: =ROUND(IF(Data!E11<0,0-Data!E11,0),1) -> 17.2 | E11: =ROUND(IF(Data!E11>5,Data!E11-5,0),1) -> 0 | H11: 199605 | I11: 17.7 | J11: 11.6 | L11: =H11 -> 199605 | M11: =I11 -> 17.7 | N11: =J11 -> 11.6 | O11: =M11+O10 -> 810.6 | P11: =N11+P10 -> 14
A12: 35070 | B12: 6 | C12: 199601 | D12: =ROUND(IF(Data!E12<0,0-Data!E12,0),1) -> 10.3 | E12: =ROUND(IF(Data!E12>5,Data!E12-5,0),1) -> 0 | H12: 199606 | I12: 0 | J12: 79.2 | L12: =H12 -> 199606 | M12: =I12 -> 0 | N12: =J12 -> 79.2 | O12: =M12+O11 -> 810.6 | P12: =N12+P11 -> 93.2
A13: 35071 | B13: 7 | C13: 199601 | D13: =ROUND(IF(Data!E13<0,0-Data!E13,0),1) -> 4 | E13: =ROUND(IF(Data!E13>5,Data!E13-5,0),1) -> 0 | H13: 199607 | I13: 0 | J13: 222.1 | L13: =H13 -> 199607 | M13: =I13 -> 0 | N13: =J13 -> 222.1 | O13: =M13+O12 -> 810.6 | P13: =N13+P12 -> 315.3
A14: 35072 | B14: 8 | C14: 199601 | D14: =ROUND(IF(Data!E14<0,0-Data!E14,0),1) -> 5.6 | E14: =ROUND(IF(Data!E14>5,Data!E14-5,0),1) -> 0 | H14: 199608 | I14: 0 | J14: 183.9 | L14: =H14 -> 199608 | M14: =I14 -> 0 | N14: =J14 -> 183.9 | O14: =M14+O13 -> 810.6 | P14: =N14+P13 -> 499.2
A15: 35073 | B15: 9 | C15: 199601 | D15: =ROUND(IF(Data!E15<0,0-Data!E15,0),1) -> 4 | E15: =ROUND(IF(Data!E15>5,Data!E15-5,0),1) -> 0 | H15: 199609 | I15: 0.5 | J15: 46 | L15: =H15 -> 199609 | M15: =I15 -> 0.5 | N15: =J15 -> 46 | O15: =M15+O14 -> 811.1 | P15: =N15+P14 -> 545.2
A16: 35074 | B16: 10 | C16: 199601 | D16: =ROUND(IF(Data!E16<0,0-Data!E16,0),1) -> 3.8 | E16: =ROUND(IF(Data!E16>5,Data!E16-5,0),1) -> 0 | H16: 199610 | I16: 51.4 | J16: 8.9 | L16: =H16 -> 199610 | M16: =I16 -> 51.4 | N16: =J16 -> 8.9 | O16: =M16+O15 -> 862.5 | P16: =N16+P15 -> 554.1
A17: 35075 | B17: 11 | C17: 199601 | D17: =ROUND(IF(Data!E17<0,0-Data!E17,0),1) -> 3.9 | E17: =ROUND(IF(Data!E17>5,Data!E17-5,0),1) -> 0 | H17: 199611 | I17: 186.2 | J17: 0 | L17: =H17 -> 199611 | M17: =I17 -> 186.2 | N17: =J17 -> 0 | O17: =M17+O16 -> 1048.7 | P17: =N17+P16 -> 554.1
A18: 35076 | B18: 12 | C18: 199601 | D18: =ROUND(IF(Data!E18<0,0-Data!E18,0),1) -> 6.7 | E18: =ROUND(IF(Data!E18>5,Data!E18-5,0),1) -> 0 | H18: 199612 | I18: 344.9 | J18: 0 | L18: =H18 -> 199612 | M18: =I18 -> 344.9 | N18: =J18 -> 0 | O18: =M18+O17 -> 1393.6 | P18: =N18+P17 -> 554.1
A19: 35077 | B19: 13 | C19: 199601 | D19: =ROUND(IF(Data!E19<0,0-Data!E19,0),1) -> 2.3 | E19: =ROUND(IF(Data!E19>5,Data!E19-5,0),1) -> 0 | H19: Grand Total | I19: 1393.6 | J19: 554.1
A20: 35078 | B20: 14 | C20: 199601 | D20: =ROUND(IF(Data!E20<0,0-Data!E20,0),1) -> 0 | E20: =ROUND(IF(Data!E20>5,Data!E20-5,0),1) -> 0
A21: 35079 | B21: 15 | C21: 199601 | D21: =ROUND(IF(Data!E21<0,0-Data!E21,0),1) -> 0.4 | E21: =ROUND(IF(Data!E21>5,Data!E21-5,0),1) -> 0
A22: 35080 | B22: 16 | C22: 199601 | D22: =ROUND(IF(Data!E22<0,0-Data!E22,0),1) -> 9.4 | E22: =ROUND(IF(Data!E22>5,Data!E22-5,0),1) -> 0
A23: 35081 | B23: 17 | C23: 199601 | D23: =ROUND(IF(Data!E23<0,0-Data!E23,0),1) -> 22.8 | E23: =ROUND(IF(Data!E23>5,Data!E23-5,0),1) -> 0
A24: 35082 | B24: 18 | C24: 199601 | D24: =ROUND(IF(Data!E24<0,0-Data!E24,0),1) -> 18.9 | E24: =ROUND(IF(Data!E24>5,Data!E24-5,0),1) -> 0
A25: 35083 | B25: 19 | C25: 199601 | D25: =ROUND(IF(Data!E25<0,0-Data!E25,0),1) -> 14.2 | E25: =ROUND(IF(Data!E25>5,Data!E25-5,0),1) -> 0
A26: 35084 | B26: 20 | C26: 199601 | D26: =ROUND(IF(Data!E26<0,0-Data!E26,0),1) -> 13.3 | E26: =ROUND(IF(Data!E26>5,Data!E26-5,0),1) -> 0
A27: 35085 | B27: 21 | C27: 199601 | D27: =ROUND(IF(Data!E27<0,0-Data!E27,0),1) -> 17.8 | E27: =ROUND(IF(Data!E27>5,Data!E27-5,0),1) -> 0
A28: 35086 | B28: 22 | C28: 199601 | D28: =ROUND(IF(Data!E28<0,0-Data!E28,0),1) -> 14.8 | E28: =ROUND(IF(Data!E28>5,Data!E28-5,0),1) -> 0
A29: 35087 | B29: 23 | C29: 199601 | D29: =ROUND(IF(Data!E29<0,0-Data!E29,0),1) -> 12.6 | E29: =ROUND(IF(Data!E29>5,Data!E29-5,0),1) -> 0
A30: 35088 | B30: 24 | C30: 199601 | D30: =ROUND(IF(Data!E30<0,0-Data!E30,0),1) -> 14.8 | E30: =ROUND(IF(Data!E30>5,Data!E30-5,0),1) -> 0
A31: 35089 | B31: 25 | C31: 199601 | D31: =ROUND(IF(Data!E31<0,0-Data!E31,0),1) -> 18.1 | E31: =ROUND(IF(Data!E31>5,Data!E31-5,0),1) -> 0
... A372: 35430 | B372: 366 | C372: 199612 | D372: =ROUND(IF(Data!E372<0,0-Data!E372,0),1) -> 0 | E372: =ROUND(IF(Data!E372>5,Data!E372-5,0),1) -> 0
