Workbook

Sheet Meta
A1: Meta data for Sicamous base station
A2: Last edit 17/04/25
B3: 21X data logger and storage module
B4: Gap filling of temperature and humidity using relationships between Sicamous Creek and Sicamous FWS
A5: Solar W/m2 | F5: Incomplete
B6: LiCor silicon Pyranometer at 6 m
B7: Kmax from 10 min simulation
A8: PAR mol/m2/d
B9: LiCor PAR sensor 6 m above surface. Calibration drift adjustment
A10: Tair C | J10: Temperature | L10: Based on regressions against UPC station
B11: HMP35C in RMYoung pie plate sheild at 6 m | K11: Dec 8 - 31 | N11: See columns BZ to DC
B12: Thermocouples referenced to termistor on panel at 3 m, 1.5 m and 0.25 m | L12: Tave C = UPC* 1.19 - 0.2, R2=0.922
A13: RH % | L13: Tmin C = UPC* 0.95 - 0.5, R2=0.752
B14: HMP35C in RMYoung pie plate sheild at 6 m | L14: Tmin C = UPC* 1.1 - 1, R2=0.856
B15: Corrected RH based on Rhmax=100. Calculated vpres (kPa)
A16: Soil temperature C
B17: Thermocouples referenced to thermistor on panel at 0.15 m and 0.5 m depths
A18: Precipitation mm
B19: Siera Misco tipping bucket
A20: Snow depth m, mm
B21: CSI UDG01
C22: Modelled Nov-Dec using precipitation and estimate of snow pack density
A23: Wind m/s | E23: Need better density change model
B24: MetOne anemometer at 6 m
A25: Wind direction degrees
B26: MetOne Wind vane at 6 m
A28: PPT= snow+rain
B29: Snow = Daily increase in pack depth and assumed compacted density of 0.13 Mg/m3
B30: Rain = Rain gauge.
C31: If there is a snow pack then review tiping bucket data to determine if likely snow melt rather than rain, i.e., tipping when above zero and low humidity and sunny.
C32: Also sum tipping bucket over days to see if simialr total to water equivalent of snow fal from depth change.
C33: Sicamous Fire Weather Station rainfall adjusted by *1.05 and MoTI Malakwa*1.4*1.05 and UPC*1.4
A34: Vapour pressure kPa
B35: Calculated from the daily maximum temperature and mininimum relative humdity: esat(Tmax)*RHmin/100
B36: If no RHmin vpres = esat(Tmin)
A37: Maximum vapour presure deficit
B38: Calculated from the daily maximum temperature and mininimum relative humdity: esat(Tmax)*(1-RHmin/100)
B39: If no RHmin vpd = esat(Tmax) - esat(Tmin)

Sheet PPTest
A1: Precipitation | I1: 0.13 | K1: Rain | L1: UPC*1.4*1.05 | P1: Max density | Q1: 0.4
A2: Last edit 16/04/25 | K2: SnowDepthChange | M2: MoTISicamous*1.5 | P2: Start Density | Q2: 0.241
C3: Total | K3: FWS* | L3: 1.05
C4: Solar | D4: Tmax | E4: Tmin | F4: Rhmin | G4: Rain | H4: SnowD | I4: Precip.from | J4: FWS | M4: FWS | N4: Sicamous | P4: density | R4: SWE | S4: dSWE | T4: Melt | AE4: Enderby Snow 1F04 course 50 39 11.97N, 118 55 37.0 W 1947 m
A5: Date | B5: DoY | C5: MJ/m2/d | I5: snow depth | K5: Precipitation | P5: g/cm3 | R5: mm | S5: mm | T5: mm | AE5: Date | AF5: SWE cm | AG5: Depth cm | AH5: %norm
H6: =Data!BF6 -> 842 | Q6: =Q2 -> 0.241 | R6: =H6*Q$2 -> 202.922 | S6: 0 | T6: 0
A7: 34700 | B7: 1 | C7: =ROUND(Data!BJ7,2) -> 4.29 | D7: =ROUND(Data!R7,1) -> -4.5 | E7: =ROUND(Data!AF7,1) -> -20.4 | F7: =Data!BO7 -> 74.2 | G7: =Data!Q7 -> 0 | H7: =Data!BF7 -> 842 | I7: =IF(H7>H6,ROUND((H7-H6)*I$1,1),0) -> 0 | J7: =Data!BS7 -> 0 | K7: =I7 -> 0 | M7: =J7 -> 0 | N7: =K7 -> 0 | P7: =(R6+K7)/H7 -> 0.241 | Q7: =IF(P7>Q$1,Q$1,P7) -> 0.241 | R7: =Q7*H7 -> 202.922 | S7: =R7-R6 -> 0 | T7: =K7-S7 -> 0 | AE7: 34730 | AF7: 212 | AG7: 704 | AH7: 102
A8: 34701 | B8: 2 | C8: =ROUND(Data!BJ8,2) -> 4.37 | D8: =ROUND(Data!R8,1) -> -5.7 | E8: =ROUND(Data!AF8,1) -> -21.3 | F8: =Data!BO8 -> 71.5 | G8: =Data!Q8 -> 0 | H8: =Data!BF8 -> 841 | I8: =IF(H8>H7,ROUND((H8-H7)*I$1,1),0) -> 0 | J8: =Data!BS8 -> 0 | K8: =I8 -> 0 | M8: =J8+M7 -> 0 | N8: =K8+N7 -> 0 | P8: =(R7+K8)/H8 -> 0.24128656 | Q8: =IF(P8>Q$1,Q$1,P8) -> 0.24128656 | R8: =Q8*H8 -> 202.922 | S8: =R8-R7 -> 0 | T8: =K8-S8 -> 0 | AE8: 34758 | AF8: 215 | AG8: 775 | AH8: 92
A9: 34702 | B9: 3 | C9: =ROUND(Data!BJ9,2) -> 4.56 | D9: =ROUND(Data!R9,1) -> -5.7 | E9: =ROUND(Data!AF9,1) -> -21.8 | F9: =Data!BO9 -> 70.9 | G9: =Data!Q9 -> 0 | H9: =Data!BF9 -> 832 | I9: =IF(H9>H8,ROUND((H9-H8)*I$1,1),0) -> 0 | J9: =Data!BS9 -> 0 | K9: =I9 -> 0 | M9: =J9+M8 -> 0 | N9: =K9+N8 -> 0 | P9: =(R8+K9)/H9 -> 0.24389663 | Q9: =IF(P9>Q$1,Q$1,P9) -> 0.24389663 | R9: =Q9*H9 -> 202.922 | S9: =R9-R8 -> 0 | T9: =K9-S9 -> 0 | AE9: 34789 | AF9: 242 | AG9: 906 | AH9: 90
A10: 34703 | B10: 4 | C10: =ROUND(Data!BJ10,2) -> 4.89 | D10: =ROUND(Data!R10,1) -> -4.9 | E10: =ROUND(Data!AF10,1) -> -20.2 | F10: =Data!BO10 -> 69.9 | G10: =Data!Q10 -> 0 | H10: =Data!BF10 -> 823 | I10: =IF(H10>H9,ROUND((H10-H9)*I$1,1),0) -> 0 | J10: =Data!BS10 -> 0 | K10: =I10 -> 0 | M10: =J10+M9 -> 0 | N10: =K10+N9 -> 0 | P10: =(R9+K10)/H10 -> 0.24656379 | Q10: =IF(P10>Q$1,Q$1,P10) -> 0.24656379 | R10: =Q10*H10 -> 202.922 | S10: =R10-R9 -> 0 | T10: =K10-S10 -> 0 | AE10: 34818 | AF10: 231 | AG10: 918 | AH10: 85
A11: 34704 | B11: 5 | C11: =ROUND(Data!BJ11,2) -> 5.37 | D11: =ROUND(Data!R11,1) -> -5.7 | E11: =ROUND(Data!AF11,1) -> -22 | F11: =Data!BO11 -> 57.2 | G11: =Data!Q11 -> 0 | H11: =Data!BF11 -> 819 | I11: =IF(H11>H10,ROUND((H11-H10)*I$1,1),0) -> 0 | J11: =Data!BS11 -> 0 | K11: =I11 -> 0 | M11: =J11+M10 -> 0 | N11: =K11+N10 -> 0 | P11: =(R10+K11)/H11 -> 0.24776801 | Q11: =IF(P11>Q$1,Q$1,P11) -> 0.24776801 | R11: =Q11*H11 -> 202.922 | S11: =R11-R10 -> 0 | T11: =K11-S11 -> 0 | AE11: 34834 | AF11: 213 | AG11: 960 | AH11: 90
A12: 34705 | B12: 6 | C12: =ROUND(Data!BJ12,2) -> 3.73 | D12: =ROUND(Data!R12,1) -> -5.8 | E12: =ROUND(Data!AF12,1) -> -21.4 | F12: =Data!BO12 -> 59.3 | G12: =Data!Q12 -> 0 | H12: =Data!BF12 -> 806 | I12: =IF(H12>H11,ROUND((H12-H11)*I$1,1),0) -> 0 | J12: =Data!BS12 -> 0 | K12: =I12 -> 0 | M12: =J12+M11 -> 0 | N12: =K12+N11 -> 0 | P12: =(R11+K12)/H12 -> 0.25176427 | Q12: =IF(P12>Q$1,Q$1,P12) -> 0.25176427 | R12: =Q12*H12 -> 202.922 | S12: =R12-R11 -> 0 | T12: =K12-S12 -> 0 | AE12: 34850 | AF12: 138 | AG12: 681 | AH12: 74
A13: 34706 | B13: 7 | C13: =ROUND(Data!BJ13,2) -> 6.05 | D13: =ROUND(Data!R13,1) -> -5.3 | E13: =ROUND(Data!AF13,1) -> -24.2 | F13: =Data!BO13 -> 63.2 | G13: =Data!Q13 -> 0 | H13: =Data!BF13 -> 809 | I13: =IF(H13>H12,ROUND((H13-H12)*I$1,1),0) -> 0.4 | J13: =Data!BS13 -> 0 | K13: =I13 -> 0.4 | M13: =J13+M12 -> 0 | N13: =K13+N12 -> 0.4 | P13: =(R12+K13)/H13 -> 0.25132509 | Q13: =IF(P13>Q$1,Q$1,P13) -> 0.25132509 | R13: =Q13*H13 -> 203.322 | S13: =R13-R12 -> 0.4 | T13: =K13-S13 -> -5.6621374e-15 | AE13: 34865 | AF13: 74 | AG13: 411 | AH13: 60
A14: 34707 | B14: 8 | C14: =ROUND(Data!BJ14,2) -> 0.63 | D14: =ROUND(Data!R14,1) -> 0 | E14: =ROUND(Data!AF14,1) -> -7.7 | F14: =Data!BO14 -> 76.1 | G14: =Data!Q14 -> 0 | H14: =Data!BF14 -> 859 | I14: =IF(H14>H13,ROUND((H14-H13)*I$1,1),0) -> 6.5 | J14: =Data!BS14 -> 0 | K14: =I14 -> 6.5 | M14: =J14+M13 -> 0 | N14: =K14+N13 -> 6.9 | P14: =(R13+K14)/H14 -> 0.2442631 | Q14: =IF(P14>Q$1,Q$1,P14) -> 0.2442631 | R14: =Q14*H14 -> 209.822 | S14: =R14-R13 -> 6.5 | T14: =K14-S14 -> 0
A15: 34708 | B15: 9 | C15: =ROUND(Data!BJ15,2) -> 0.54 | D15: =ROUND(Data!R15,1) -> 1.2 | E15: =ROUND(Data!AF15,1) -> -5.8 | F15: =Data!BO15 -> 75.8 | G15: =Data!Q15 -> 0 | H15: =Data!BF15 -> 900 | I15: =IF(H15>H14,ROUND((H15-H14)*I$1,1),0) -> 5.3 | J15: =Data!BS15 -> 0 | K15: =I15 -> 5.3 | M15: =J15+M14 -> 0 | N15: =K15+N14 -> 12.2 | P15: =(R14+K15)/H15 -> 0.23902444 | Q15: =IF(P15>Q$1,Q$1,P15) -> 0.23902444 | R15: =Q15*H15 -> 215.122 | S15: =R15-R14 -> 5.3 | T15: =K15-S15 -> -1.1546319e-14 | AE15: 35064 | AF15: 223 | AG15: 684 | AH15: 140
A16: 34709 | B16: 10 | C16: =ROUND(Data!BJ16,2) -> 0.57 | D16: =ROUND(Data!R16,1) -> 2.2 | E16: =ROUND(Data!AF16,1) -> -3.8 | F16: =Data!BO16 -> 78.7 | G16: =Data!Q16 -> 0 | H16: =Data!BF16 -> 968 | I16: =IF(H16>H15,ROUND((H16-H15)*I$1,1),0) -> 8.8 | J16: =Data!BS16 -> 0 | K16: =I16 -> 8.8 | M16: =J16+M15 -> 0 | N16: =K16+N15 -> 21 | P16: =(R15+K16)/H16 -> 0.23132438 | Q16: =IF(P16>Q$1,Q$1,P16) -> 0.23132438 | R16: =Q16*H16 -> 223.922 | S16: =R16-R15 -> 8.8 | T16: =K16-S16 -> 0
A17: 34710 | B17: 11 | C17: =ROUND(Data!BJ17,2) -> 0.25 | D17: =ROUND(Data!R17,1) -> -0.4 | E17: =ROUND(Data!AF17,1) -> -6.8 | F17: =Data!BO17 -> 92 | G17: =Data!Q17 -> 0 | H17: =Data!BF17 -> 1007 | I17: =IF(H17>H16,ROUND((H17-H16)*I$1,1),0) -> 5.1 | J17: =Data!BS17 -> 0 | K17: =I17 -> 5.1 | M17: =J17+M16 -> 0 | N17: =K17+N16 -> 26.1 | P17: =(R16+K17)/H17 -> 0.22742999 | Q17: =IF(P17>Q$1,Q$1,P17) -> 0.22742999 | R17: =Q17*H17 -> 229.022 | S17: =R17-R16 -> 5.1 | T17: =K17-S17 -> 0
A18: 34711 | B18: 12 | C18: =ROUND(Data!BJ18,2) -> 0.74 | D18: =ROUND(Data!R18,1) -> 1.1 | E18: =ROUND(Data!AF18,1) -> -7.8 | F18: =Data!BO18 -> 69.8 | G18: =Data!Q18 -> 0 | H18: =Data!BF18 -> 997 | I18: =IF(H18>H17,ROUND((H18-H17)*I$1,1),0) -> 0 | J18: =Data!BS18 -> 0 | K18: =I18 -> 0 | M18: =J18+M17 -> 0 | N18: =K18+N17 -> 26.1 | P18: =(R17+K18)/H18 -> 0.22971113 | Q18: =IF(P18>Q$1,Q$1,P18) -> 0.22971113 | R18: =Q18*H18 -> 229.022 | S18: =R18-R17 -> 0 | T18: =K18-S18 -> 0
A19: 34712 | B19: 13 | C19: =ROUND(Data!BJ19,2) -> 0.4 | D19: =ROUND(Data!R19,1) -> -0.3 | E19: =ROUND(Data!AF19,1) -> -2.9 | F19: =Data!BO19 -> 74.1 | G19: =Data!Q19 -> 0 | H19: =Data!BF19 -> 1019 | I19: =IF(H19>H18,ROUND((H19-H18)*I$1,1),0) -> 2.9 | J19: =Data!BS19 -> 0 | K19: =I19 -> 2.9 | M19: =J19+M18 -> 0 | N19: =K19+N18 -> 29 | P19: =(R18+K19)/H19 -> 0.22759764 | Q19: =IF(P19>Q$1,Q$1,P19) -> 0.22759764 | R19: =Q19*H19 -> 231.922 | S19: =R19-R18 -> 2.9 | T19: =K19-S19 -> -5.7731597e-15
A20: 34713 | B20: 14 | C20: =ROUND(Data!BJ20,2) -> 0.38 | D20: =ROUND(Data!R20,1) -> -0.3 | E20: =ROUND(Data!AF20,1) -> -6.6 | F20: =Data!BO20 -> 79.4 | G20: =Data!Q20 -> 0 | H20: =Data!BF20 -> 1044 | I20: =IF(H20>H19,ROUND((H20-H19)*I$1,1),0) -> 3.3 | J20: =Data!BS20 -> 0 | K20: =I20 -> 3.3 | M20: =J20+M19 -> 0 | N20: =K20+N19 -> 32.3 | P20: =(R19+K20)/H20 -> 0.22530843 | Q20: =IF(P20>Q$1,Q$1,P20) -> 0.22530843 | R20: =Q20*H20 -> 235.222 | S20: =R20-R19 -> 3.3 | T20: =K20-S20 -> -1.1546319e-14
A21: 34714 | B21: 15 | C21: =ROUND(Data!BJ21,2) -> 0.45 | D21: =ROUND(Data!R21,1) -> 0.5 | E21: =ROUND(Data!AF21,1) -> -5.9 | F21: =Data!BO21 -> 75.3 | G21: =Data!Q21 -> 0 | H21: =Data!BF21 -> 1051 | I21: =IF(H21>H20,ROUND((H21-H20)*I$1,1),0) -> 0.9 | J21: =Data!BS21 -> 0 | K21: =I21 -> 0.9 | M21: =J21+M20 -> 0 | N21: =K21+N20 -> 33.2 | P21: =(R20+K21)/H21 -> 0.22466413 | Q21: =IF(P21>Q$1,Q$1,P21) -> 0.22466413 | R21: =Q21*H21 -> 236.122 | S21: =R21-R20 -> 0.9 | T21: =K21-S21 -> -5.6621374e-15
A22: 34715 | B22: 16 | C22: =ROUND(Data!BJ22,2) -> 0.35 | D22: =ROUND(Data!R22,1) -> -3.3 | E22: =ROUND(Data!AF22,1) -> -6 | F22: =Data!BO22 -> 92.4 | G22: =Data!Q22 -> 0 | H22: =Data!BF22 -> 1053 | I22: =IF(H22>H21,ROUND((H22-H21)*I$1,1),0) -> 0.3 | J22: =Data!BS22 -> 0 | K22: =I22 -> 0.3 | M22: =J22+M21 -> 0 | N22: =K22+N21 -> 33.5 | P22: =(R21+K22)/H22 -> 0.22452232 | Q22: =IF(P22>Q$1,Q$1,P22) -> 0.22452232 | R22: =Q22*H22 -> 236.422 | S22: =R22-R21 -> 0.3 | T22: =K22-S22 -> -1.1379786e-14
A23: 34716 | B23: 17 | C23: =ROUND(Data!BJ23,2) -> 0.34 | D23: =ROUND(Data!R23,1) -> -5 | E23: =ROUND(Data!AF23,1) -> -7.3 | F23: =Data!BO23 -> 79.3 | G23: =Data!Q23 -> 0 | H23: =Data!BF23 -> 1042 | I23: =IF(H23>H22,ROUND((H23-H22)*I$1,1),0) -> 0 | J23: =Data!BS23 -> 0 | K23: =I23 -> 0 | M23: =J23+M22 -> 0 | N23: =K23+N22 -> 33.5 | P23: =(R22+K23)/H23 -> 0.22689251 | Q23: =IF(P23>Q$1,Q$1,P23) -> 0.22689251 | R23: =Q23*H23 -> 236.422 | S23: =R23-R22 -> 0 | T23: =K23-S23 -> 0
A24: 34717 | B24: 18 | C24: =ROUND(Data!BJ24,2) -> 0.27 | D24: =ROUND(Data!R24,1) -> -1.4 | E24: =ROUND(Data!AF24,1) -> -6.2 | F24: =Data!BO24 -> 80.3 | G24: =Data!Q24 -> 0 | H24: =Data!BF24 -> 1093 | I24: =IF(H24>H23,ROUND((H24-H23)*I$1,1),0) -> 6.6 | J24: =Data!BS24 -> 0 | K24: =I24 -> 6.6 | M24: =J24+M23 -> 0 | N24: =K24+N23 -> 40.1 | P24: =(R23+K24)/H24 -> 0.22234401 | Q24: =IF(P24>Q$1,Q$1,P24) -> 0.22234401 | R24: =Q24*H24 -> 243.022 | S24: =R24-R23 -> 6.6 | T24: =K24-S24 -> 0
A25: 34718 | B25: 19 | C25: =ROUND(Data!BJ25,2) -> 1.65 | D25: =ROUND(Data!R25,1) -> 3.1 | E25: =ROUND(Data!AF25,1) -> -12.8 | F25: =Data!BO25 -> 51.4 | G25: =Data!Q25 -> 0 | H25: =Data!BF25 -> 1063 | I25: =IF(H25>H24,ROUND((H25-H24)*I$1,1),0) -> 0 | J25: =Data!BS25 -> 0 | K25: =I25 -> 0 | M25: =J25+M24 -> 0 | N25: =K25+N24 -> 40.1 | P25: =(R24+K25)/H25 -> 0.228619 | Q25: =IF(P25>Q$1,Q$1,P25) -> 0.228619 | R25: =Q25*H25 -> 243.022 | S25: =R25-R24 -> 0 | T25: =K25-S25 -> 0
A26: 34719 | B26: 20 | C26: =ROUND(Data!BJ26,2) -> 0.85 | D26: =ROUND(Data!R26,1) -> 3.5 | E26: =ROUND(Data!AF26,1) -> -13.7 | F26: =Data!BO26 -> 39.7 | G26: =Data!Q26 -> 0 | H26: =Data!BF26 -> 1041 | I26: =IF(H26>H25,ROUND((H26-H25)*I$1,1),0) -> 0 | J26: =Data!BS26 -> 0 | K26: =I26 -> 0 | M26: =J26+M25 -> 0 | N26: =K26+N25 -> 40.1 | P26: =(R25+K26)/H26 -> 0.23345053 | Q26: =IF(P26>Q$1,Q$1,P26) -> 0.23345053 | R26: =Q26*H26 -> 243.022 | S26: =R26-R25 -> 0 | T26: =K26-S26 -> 0
A27: 34720 | B27: 21 | C27: =ROUND(Data!BJ27,2) -> 1.51 | D27: =ROUND(Data!R27,1) -> 1.2 | E27: =ROUND(Data!AF27,1) -> -16 | F27: =Data!BO27 -> 62.2 | G27: =Data!Q27 -> 0 | H27: =Data!BF27 -> 1022 | I27: =IF(H27>H26,ROUND((H27-H26)*I$1,1),0) -> 0 | J27: =Data!BS27 -> 0 | K27: =I27 -> 0 | M27: =J27+M26 -> 0 | N27: =K27+N26 -> 40.1 | P27: =(R26+K27)/H27 -> 0.23779061 | Q27: =IF(P27>Q$1,Q$1,P27) -> 0.23779061 | R27: =Q27*H27 -> 243.022 | S27: =R27-R26 -> 0 | T27: =K27-S27 -> 0
... A135: 34828 | B135: 129 | C135: =ROUND(Data!BJ135,2) -> 18.76 | D135: =ROUND(Data!R135,1) -> 13.8 | E135: =ROUND(Data!AF135,1) -> -0.4 | F135: =Data!BO135 -> 34.9 | G135: =Data!Q135 -> 0 | H135: =Data!BF135 -> 630 | I135: =IF(H135>H134,ROUND((H135-H134)*I$1,1),0) -> 0 | J135: =Data!BS135 -> 0 | K135: =I135 -> 0 | M135: =J135+M134 -> 197.6 | N135: =K135+N134 -> 182.5 | P135: =(R134+K135)/H135 -> 0.42412698 | Q135: =IF(P135>Q$1,Q$1,P135) -> 0.4 | R135: =Q135*H135 -> 252 | S135: =R135-R134 -> -15.2 | T135: =K135-S135 -> 15.2
A136: 34829 | B136: 130 | C136: =ROUND(Data!BJ136,2) -> 11.69 | D136: =ROUND(Data!R136,1) -> 10.2 | E136: =ROUND(Data!AF136,1) -> 0.1 | F136: =Data!BO136 -> 61.1 | G136: =Data!Q136 -> 0 | H136: =Data!BF136 -> 593 | I136: =IF(H136>H135,ROUND((H136-H135)*I$1,1),0) -> 0 | J136: =Data!BS136 -> 5.6 | K136: =J136*L$3 -> 5.88 | M136: =J136+M135 -> 203.2 | N136: =K136+N135 -> 188.38 | P136: =(R135+K136)/H136 -> 0.43487352 | Q136: =IF(P136>Q$1,Q$1,P136) -> 0.4 | R136: =Q136*H136 -> 237.2 | S136: =R136-R135 -> -14.8 | T136: =K136-S136 -> 20.68
A137: 34830 | B137: 131 | C137: =ROUND(Data!BJ137,2) -> 6.71 | D137: =ROUND(Data!R137,1) -> 4.2 | E137: =ROUND(Data!AF137,1) -> 0.6 | F137: =Data!BO137 -> 90.3 | G137: =Data!Q137 -> 0 | H137: =Data!BF137 -> 550 | I137: =IF(H137>H136,ROUND((H137-H136)*I$1,1),0) -> 0 | J137: =Data!BS137 -> 15.4 | K137: =J137*L$3 -> 16.17 | M137: =J137+M136 -> 218.6 | N137: =K137+N136 -> 204.55 | P137: =(R136+K137)/H137 -> 0.46067273 | Q137: =IF(P137>Q$1,Q$1,P137) -> 0.4 | R137: =Q137*H137 -> 220 | S137: =R137-R136 -> -17.2 | T137: =K137-S137 -> 33.37
A138: 34831 | B138: 132 | C138: =ROUND(Data!BJ138,2) -> 10.35 | D138: =ROUND(Data!R138,1) -> 5.4 | E138: =ROUND(Data!AF138,1) -> -0.8 | F138: =Data!BO138 -> 81.9 | G138: =Data!Q138 -> 0 | H138: =Data!BF138 -> 500 | I138: =IF(H138>H137,ROUND((H138-H137)*I$1,1),0) -> 0 | J138: =Data!BS138 -> 5.6 | K138: =J138*L$3 -> 5.88 | M138: =J138+M137 -> 224.2 | N138: =K138+N137 -> 210.43 | P138: =(R137+K138)/H138 -> 0.45176 | Q138: =IF(P138>Q$1,Q$1,P138) -> 0.4 | R138: =Q138*H138 -> 200 | S138: =R138-R137 -> -20 | T138: =K138-S138 -> 25.88
A139: 34832 | B139: 133 | C139: =ROUND(Data!BJ139,2) -> 29.8 | D139: =ROUND(Data!R139,1) -> 14.5 | E139: =ROUND(Data!AF139,1) -> -3.6 | F139: =Data!BO139 -> 28.3 | G139: =Data!Q139 -> 0 | H139: =Data!BF139 -> 450 | I139: =IF(H139>H138,ROUND((H139-H138)*I$1,1),0) -> 0 | J139: =Data!BS139 -> 0 | K139: =I139 -> 0 | M139: =J139+M138 -> 224.2 | N139: =K139+N138 -> 210.43 | P139: =(R138+K139)/H139 -> 0.44444444 | Q139: =IF(P139>Q$1,Q$1,P139) -> 0.4 | R139: =Q139*H139 -> 180 | S139: =R139-R138 -> -20 | T139: =K139-S139 -> 20
A140: 34833 | B140: 134 | C140: =ROUND(Data!BJ140,2) -> 17.19 | D140: =ROUND(Data!R140,1) -> 13.6 | E140: =ROUND(Data!AF140,1) -> -2.1 | F140: =Data!BO140 -> 36.3 | G140: =Data!Q140 -> 0 | H140: =Data!BF140 -> 400 | I140: =IF(H140>H139,ROUND((H140-H139)*I$1,1),0) -> 0 | J140: =Data!BS140 -> 0 | K140: =I140 -> 0 | M140: =J140+M139 -> 224.2 | N140: =K140+N139 -> 210.43 | P140: =(R139+K140)/H140 -> 0.45 | Q140: =IF(P140>Q$1,Q$1,P140) -> 0.4 | R140: =Q140*H140 -> 160 | S140: =R140-R139 -> -20 | T140: =K140-S140 -> 20
A141: 34834 | B141: 135 | C141: =ROUND(Data!BJ141,2) -> 22.81 | D141: =ROUND(Data!R141,1) -> 14.7 | E141: =ROUND(Data!AF141,1) -> -1 | F141: =Data!BO141 -> 37.7 | G141: =Data!Q141 -> 0 | H141: =Data!BF141 -> 350 | I141: =IF(H141>H140,ROUND((H141-H140)*I$1,1),0) -> 0 | J141: =Data!BS141 -> 0 | K141: =I141 -> 0 | M141: =J141+M140 -> 224.2 | N141: =K141+N140 -> 210.43 | P141: =(R140+K141)/H141 -> 0.45714286 | Q141: =IF(P141>Q$1,Q$1,P141) -> 0.4 | R141: =Q141*H141 -> 140 | S141: =R141-R140 -> -20 | T141: =K141-S141 -> 20
A142: 34835 | B142: 136 | C142: =ROUND(Data!BJ142,2) -> 25.21 | D142: =ROUND(Data!R142,1) -> 16.6 | E142: =ROUND(Data!AF142,1) -> -1.8 | F142: =Data!BO142 -> 36.5 | G142: =Data!Q142 -> 0 | H142: =Data!BF142 -> 300 | I142: =IF(H142>H141,ROUND((H142-H141)*I$1,1),0) -> 0 | J142: =Data!BS142 -> 0 | K142: =I142 -> 0 | M142: =J142+M141 -> 224.2 | N142: =K142+N141 -> 210.43 | P142: =(R141+K142)/H142 -> 0.46666667 | Q142: =IF(P142>Q$1,Q$1,P142) -> 0.4 | R142: =Q142*H142 -> 120 | S142: =R142-R141 -> -20 | T142: =K142-S142 -> 20
A143: 34836 | B143: 137 | C143: =ROUND(Data!BJ143,2) -> 11.95 | D143: =ROUND(Data!R143,1) -> 10.5 | E143: =ROUND(Data!AF143,1) -> 1 | F143: =Data!BO143 -> 53.9 | G143: =Data!Q143 -> 0 | H143: =Data!BF143 -> 250 | I143: =IF(H143>H142,ROUND((H143-H142)*I$1,1),0) -> 0 | J143: =Data!BS143 -> 0 | K143: =I143 -> 0 | M143: =J143+M142 -> 224.2 | N143: =K143+N142 -> 210.43 | P143: =(R142+K143)/H143 -> 0.48 | Q143: =IF(P143>Q$1,Q$1,P143) -> 0.4 | R143: =Q143*H143 -> 100 | S143: =R143-R142 -> -20 | T143: =K143-S143 -> 20
A144: 34837 | B144: 138 | C144: =ROUND(Data!BJ144,2) -> 27.66 | D144: =ROUND(Data!R144,1) -> 7.3 | E144: =ROUND(Data!AF144,1) -> -2.5 | F144: =Data!BO144 -> 32.5 | G144: =Data!Q144 -> 0 | H144: =Data!BF144 -> 200 | I144: =IF(H144>H143,ROUND((H144-H143)*I$1,1),0) -> 0 | J144: =Data!BS144 -> 0 | K144: =I144 -> 0 | M144: =J144+M143 -> 224.2 | N144: =K144+N143 -> 210.43 | P144: =(R143+K144)/H144 -> 0.5 | Q144: =IF(P144>Q$1,Q$1,P144) -> 0.4 | R144: =Q144*H144 -> 80 | S144: =R144-R143 -> -20 | T144: =K144-S144 -> 20
A145: 34838 | B145: 139 | C145: =ROUND(Data!BJ145,2) -> 30.23 | D145: =ROUND(Data!R145,1) -> 9.9 | E145: =ROUND(Data!AF145,1) -> -5.5 | F145: =Data!BO145 -> 17.8 | G145: =Data!Q145 -> 0 | H145: =Data!BF145 -> 130 | I145: =IF(H145>H144,ROUND((H145-H144)*I$1,1),0) -> 0 | J145: =Data!BS145 -> 0 | K145: =G145 -> 0 | M145: =J145+M144 -> 224.2 | N145: =K145+N144 -> 210.43 | P145: =(R144+K145)/H145 -> 0.61538462 | Q145: =IF(P145>Q$1,Q$1,P145) -> 0.4 | R145: =Q145*H145 -> 52 | S145: =R145-R144 -> -28 | T145: =K145-S145 -> 28
A146: 34839 | B146: 140 | C146: =ROUND(Data!BJ146,2) -> 20.58 | D146: =ROUND(Data!R146,1) -> 7 | E146: =ROUND(Data!AF146,1) -> -3.4 | F146: =Data!BO146 -> 42.5 | G146: =Data!Q146 -> 1 | H146: =Data!BF146 -> 70 | I146: =IF(H146>H145,ROUND((H146-H145)*I$1,1),0) -> 0 | J146: =Data!BS146 -> 1.4 | K146: =G146 -> 1 | M146: =J146+M145 -> 225.6 | N146: =K146+N145 -> 211.43 | P146: =(R145+K146)/H146 -> 0.75714286 | Q146: =IF(P146>Q$1,Q$1,P146) -> 0.4 | R146: =Q146*H146 -> 28 | S146: =R146-R145 -> -24 | T146: =K146-S146 -> 25
A147: 34840 | B147: 141 | C147: =ROUND(Data!BJ147,2) -> 31.34 | D147: =ROUND(Data!R147,1) -> 11.2 | E147: =ROUND(Data!AF147,1) -> -5.3 | F147: =Data!BO147 -> 23.8 | G147: =Data!Q147 -> 0 | H147: =Data!BF147 -> 0 | I147: =IF(H147>H146,ROUND((H147-H146)*I$1,1),0) -> 0 | J147: =Data!BS147 -> 0 | K147: =G147 -> 0 | M147: =J147+M146 -> 225.6 | N147: =K147+N146 -> 211.43 | P147: 1 | Q147: =IF(P147>Q$1,Q$1,P147) -> 0.4 | R147: =Q147*H147 -> 0 | S147: =R147-R146 -> -28 | T147: =K147-S147 -> 28
...

Sheet Data
A1: Sicamous Creek 1995 Daily data | D1: No data Dec 7 onwards | J1: Empty cell indicates no data | BF1: 3485 | BI1: =2.02 -> 2.02 | BJ1: Recalibrated 30/07/07 | BM1: Rh_adjustment for Max=100 and min 20=20 | BQ1: UseRHcor
A2: Last edit 21/04/25 | BJ2: 1 | BK2: 1.08 | BM2: =MAX(BM7:BM347) -> 100 | BP2: esat(tmin) | BQ2: esat(tx)-esat(Tn) | BS2: 1.4 | BW2: Summary
C3: TOTAL | D3: MEAN | E3: MEAN | F3: MEAN | G3: MEAN | H3: MEAN | I3: MEAN | J3: MEAN | K3: MEAN | L3: MEAN | M3: MEAN | N3: MEAN | O3: MEAN | P3: MEAN | Q3: TOTAL | R3: MAX. | S3: TIME | T3: MAX | U3: TIME | V3: MAX | W3: MAX | X3: MAX | Y3: MAX | Z3: MAX | AA3: MAX | AB3: MAX | AC3: MAX | AD3: MAX | AE3: TIME | AF3: MIN | AG3: TIME | AH3: MIN | AI3: TIME | AJ3: MIN | AK3: MIN | AL3: MIN | AM3: MIN | AN3: MIN | AO3: MIN | AP3: MIN | AQ3: MIN | AR3: Wind Rose: | BJ3: Revised | BM3: 0.924 | BU3: 1.5 | CW3: Midnight | DF3: FWS | DW3: UPC
C4: SOLAR | D4: PAR | E4: Ta 6m | F4: RH | G4: Ta 3m | H4: Ta 1.5m | I4: Ta 0.25m | J4: Tstem | K4: Tstem | L4: Tsoil | M4: Tsoil | N4: Tsoil | O4: SHORT | P4: WIND | Q4: RAIN | R4: Ta 6m | S4: tA 6m | T4: RH | U4: RH | V4: Ta 3m | W4: Ta 1.5m | X4: Ta 0.25m | Y4: Tstem | Z4: Tstem | AA4: Tsoil | AB4: Tsoil | AC4: Tsoil | AD4: WIND SPD | AE4: MAX U | AF4: Ta 6m | AG4: tA 6m | AH4: RH | AI4: RH | AJ4: Ta 3m | AK4: Ta 1.5m | AL4: Ta 0.25m | AM4: Tstem | AN4: Tstem | AO4: Tsoil | AP4: Tsoil | AQ4: Tsoil | AZ4: DAILY AVG | BA4: DISTANCE | BB4: BATT. | BC4: Identity | BD4: Distance | BE4: Distance | BF4: Snow depth | BH4: Solarmax | BI4: PARmax | BJ4: Solar | BK4: PAR | BL4: =MAX(BM7:BM371) -> 100 | BM4: 1 | BP4: Vpres | BQ4: VPDx | BS4: UPC to FWS | BU4: MoTISicamous | BW4: Solar | BX4: PAR | BY4: Ta6Ave | BZ4: Ta3Ave | CA4: Ta15Ave | CB4: Ta025Ave | CC4: TdufAve | CD4: Ts015Ave | CE4: Ts05Ave | CF4: RH6Ave | CG4: Ta6Max | CH4: Ta3Max | CI4: Ta15Max | CJ4: Ta025Max | CK4: TdufMax | CL4: Ts015Max | CM4: Ts05Max | CN4: RH6Max | CO4: Ta6Min | CP4: Ta3Min | CQ4: Ta15Min | CR4: Ta025Min | CS4: TdufMin | CT4: Ts015Min | CU4: Ts05Min | CV4: RH6Min | CW4: SnowD | CX4: Precipitation | CY4: Wind | CZ4: WindX | DA4: Vapres | DB4: vpdX | DC4: BatV | DF4: C | DG4: C | DH4: C | DI4: % | DJ4: % | DW4: Tave | DX4: Tmax | DY4: Tmin
A5: Date | B5: DoY | C5: MJ/m2/d | D5: mol/m2/d | E5: C | F5: % | G5: C | H5: C | I5: C | J5: WEST | K5: EAST | L5: duff | M5: 15cm | N5: 50cm | O5: (mV) | P5: (m/s) | Q5: mm | R5: C | T5: % | V5: C | W5: C | X5: C | Y5: WEST | Z5: EAST | AA5: duff | AB5: 15cm | AC5: 50cm | AD5: m/s | AE5: m/s | AF5: C | AG5: C | AH5: % | AJ5: C | AK5: C | AL5: C | AM5: WEST | AN5: EAST | AO5: duff | AP5: 15cm | AQ5: 50cm | AR5: N--NE | AS5: NE--E | AT5: E--SE | AU5: SE--S | AV5: S--SW | AW5: SW--W | AX5: W--NW | AY5: NW--N | AZ5: PANEL T | BA5: (mm) | BB5: (V) | BD5: Max | BE5: Min | BF5: mm | BH5: MJ/m2/d | BI5: mol/m2/d | BM5: RHMax | BN5: RHAvg | BO5: RHMin | BP5: kPa | BQ5: kPa | BS5: FWS | BT5: UPC | BW5: MJ/m2/d | BX5: mol/m2/d | BY5: C | BZ5: C | CA5: C | CB5: C | CC5: C | CD5: C | CE5: C | CF5: % | CG5: C | CH5: C | CI5: C | CJ5: C | CK5: C | CL5: C | CM5: C | CN5: % | CO5: C | CP5: C | CQ5: C | CR5: C | CS5: C | CT5: C | CU5: C | CV5: % | CW5: mm | CX5: mm/d | CY5: m/s | CZ5: m/s | DA5: kPa | DB5: kPa | DC5: V | DF5: Tav | DG5: Tmax | DH5: Tmin | DI5: Rhav | DJ5: Rhmin | DW5: C | DX5: C | DY5: C
BF6: 842 | EA6: Jan-Feb
A7: 34700 | B7: 1 | C7: 4.29 | D7: 7.65 | E7: -15.64 | F7: 90.6 | G7: -16.52 | H7: -18.14 | I7: 0.058 | J7: -17.71 | K7: -16.73 | L7: 0.526 | M7: 1.286 | N7: 1.956 | O7: 0 | P7: 1.476 | R7: -4.454 | S7: 1423 | T7: 98 | U7: 1632 | V7: -4.747 | W7: -9.19 | X7: 0.164 | Y7: -4.35 | Z7: -5.793 | AA7: 0.621 | AB7: 1.382 | AC7: 2.057 | AD7: 2.9941667 | AE7: 2231 | AF7: -20.36 | AG7: 25 | AH7: 79.2 | AI7: 1423 | AJ7: -21.16 | AK7: -22.66 | AL7: -0.034 | AM7: -22.47 | AN7: -21.48 | AO7: 0.457 | AP7: 1.211 | AQ7: 1.868 | AR7: 0.003 | AS7: 0.271 | AT7: 0.644 | AU7: 0.035 | AV7: 0.046 | AW7: 0 | AX7: 0 | AY7: 0 | AZ7: -17.82 | BA7: 2643 | BB7: 12.31 | BC7: 2876 | BF7: =BF$1-BA7 -> 842 | BH7: 4.59 | BI7: =BH7*$BI$1 -> 9.2718 | BJ7: =ROUND(C7*BJ$2,2) -> 4.29 | BK7: =ROUND(D7*BK$2,2) -> 8.26 | BM7: =ROUND(T7*BM$3+BM$4,1) -> 91.6 | BN7: =ROUND(F7*BM$3+BM$4,1) -> 84.7 | BO7: =ROUND(AH7*BM$3+BM$4,1) -> 74.2 | BP7: =ROUND(0.6105*(EXP((17.273*R7)/(R7+237.3)))*BO7/100, 3) -> 0.326 | BQ7: =ROUND((100-BO7)*BP7/BO7,3) -> 0.113 | BW7: =BJ7 -> 4.29 | BX7: =BK7 -> 8.26 | BY7: =ROUND(E7,1) -> -15.6 | BZ7: =ROUND(G7,1) -> -16.5 | CA7: =ROUND(H7,1) -> -18.1 | CB7: =ROUND(I7,1) -> 0.1 | CC7: =ROUND(L7,1) -> 0.5 | CD7: =ROUND(M7,1) -> 1.3 | CE7: =ROUND(N7,1) -> 2 | CF7: =ROUND(BN7,1) -> 84.7 | CG7: =ROUND(R7,1) -> -4.5 | CH7: =ROUND(V7,1) -> -4.7 | CI7: =ROUND(W7,1) -> -9.2 | CJ7: =ROUND(X7,1) -> 0.2 | CK7: =ROUND(AA7,1) -> 0.6 | CL7: =ROUND(AB7,1) -> 1.4 | CM7: =ROUND(AC7,1) -> 2.1 | CN7: =ROUND(BM7,1) -> 91.6 | CO7: =ROUND(AF7,1) -> -20.4 | CP7: =ROUND(AJ7,1) -> -21.2 | CQ7: =ROUND(AK7,1) -> -22.7 | CR7: =ROUND(AL7,1) -> 0 | CS7: =ROUND(AO7,1) -> 0.5 | CT7: =ROUND(AP7,1) -> 1.2 | CU7: =ROUND(AQ7,1) -> 1.9 | CV7: =ROUND(BO7,1) -> 74.2 | CW7: =BF7 -> 842 | CX7: =ROUND(PPTest!K7,1) -> 0 | CY7: =ROUND(P7,2) -> 1.48 | CZ7: =ROUND(AD7,2) -> 2.99 | DA7: =BP7 -> 0.326 | DB7: =BQ7 -> 0.113 | DC7: =BB7 -> 12.31 | DW7: -13.6 | DX7: -2.5 | DY7: -18.5
A8: 34701 | B8: 2 | C8: 4.367 | D8: 7.75 | E8: -16.37 | F8: 89.8 | G8: -17.3 | H8: -18.88 | I8: -0.168 | J8: -18.55 | K8: -17.53 | L8: 0.509 | M8: 1.267 | N8: 1.936 | O8: 0 | P8: 1.6275 | R8: -5.716 | S8: 1305 | T8: 98.1 | U8: 1626 | V8: -6.915 | W8: -10.23 | X8: -0.012 | Y8: -4.976 | Z8: -7.11 | AA8: 0.615 | AB8: 1.381 | AC8: 2.055 | AD8: 2.9675 | AE8: 856 | AF8: -21.33 | AG8: 821 | AH8: 76.3 | AI8: 1305 | AJ8: -22.16 | AK8: -23.52 | AL8: -0.383 | AM8: -23.22 | AN8: -22.37 | AO8: 0.421 | AP8: 1.171 | AQ8: 1.84 | AR8: 0.001 | AS8: 0.3 | AT8: 0.669 | AU8: 0.019 | AV8: 0.009 | AW8: 0 | AX8: 0 | AY8: 0 | AZ8: -18.29 | BA8: 2644 | BB8: 12.3 | BC8: 2876 | BF8: =BF$1-BA8 -> 841 | BH8: 4.63 | BI8: =BH8*$BI$1 -> 9.3526 | BJ8: =ROUND(C8*BJ$2,2) -> 4.37 | BK8: =ROUND(D8*BK$2,2) -> 8.37 | BM8: =ROUND(T8*BM$3+BM$4,1) -> 91.6 | BN8: =ROUND(F8*BM$3+BM$4,1) -> 84 | BO8: =ROUND(AH8*BM$3+BM$4,1) -> 71.5 | BP8: =ROUND(0.6105*(EXP((17.273*R8)/(R8+237.3)))*BO8/100, 3) -> 0.285 | BQ8: =ROUND((100-BO8)*BP8/BO8,3) -> 0.114 | BW8: =BJ8 -> 4.37 | BX8: =BK8 -> 8.37 | BY8: =ROUND(E8,1) -> -16.4 | BZ8: =ROUND(G8,1) -> -17.3 | CA8: =ROUND(H8,1) -> -18.9 | CB8: =ROUND(I8,1) -> -0.2 | CC8: =ROUND(L8,1) -> 0.5 | CD8: =ROUND(M8,1) -> 1.3 | CE8: =ROUND(N8,1) -> 1.9 | CF8: =ROUND(BN8,1) -> 84 | CG8: =ROUND(R8,1) -> -5.7 | CH8: =ROUND(V8,1) -> -6.9 | CI8: =ROUND(W8,1) -> -10.2 | CJ8: =ROUND(X8,1) -> 0 | CK8: =ROUND(AA8,1) -> 0.6 | CL8: =ROUND(AB8,1) -> 1.4 | CM8: =ROUND(AC8,1) -> 2.1 | CN8: =ROUND(BM8,1) -> 91.6 | CO8: =ROUND(AF8,1) -> -21.3 | CP8: =ROUND(AJ8,1) -> -22.2 | CQ8: =ROUND(AK8,1) -> -23.5 | CR8: =ROUND(AL8,1) -> -0.4 | CS8: =ROUND(AO8,1) -> 0.4 | CT8: =ROUND(AP8,1) -> 1.2 | CU8: =ROUND(AQ8,1) -> 1.8 | CV8: =ROUND(BO8,1) -> 71.5 | CW8: =BF8 -> 841 | CX8: =ROUND(PPTest!K8,1) -> 0 | CY8: =ROUND(P8,2) -> 1.63 | CZ8: =ROUND(AD8,2) -> 2.97 | DA8: =BP8 -> 0.285 | DB8: =BQ8 -> 0.114 | DC8: =BB8 -> 12.3 | DW8: -12.5 | DX8: -1.8 | DY8: -19.4
A9: 34702 | B9: 3 | C9: 4.559 | D9: 8.2 | E9: -16.09 | F9: 90 | G9: -17.01 | H9: -18.41 | I9: -0.439 | J9: -18.08 | K9: -17.21 | L9: 0.471 | M9: 1.234 | N9: 1.904 | O9: 0 | P9: 1.7758333 | R9: -5.706 | S9: 1333 | T9: 101.7 | U9: 2134 | V9: -5.705 | W9: -8.86 | X9: -0.327 | Y9: -3.327 | Z9: -5.852 | AA9: 0.585 | AB9: 1.352 | AC9: 2.037 | AD9: 3.1141667 | AE9: 2134 | AF9: -21.81 | AG9: 417 | AH9: 75.7 | AI9: 1213 | AJ9: -22.65 | AK9: -23.91 | AL9: -0.542 | AM9: -23.49 | AN9: -22.86 | AO9: 0.355 | AP9: 1.106 | AQ9: 1.775 | AR9: 0 | AS9: 0.272 | AT9: 0.711 | AU9: 0.016 | AV9: 0.001 | AW9: 0 | AX9: 0 | AY9: 0 | AZ9: -18.2 | BA9: 2653 | BB9: 12.3 | BC9: 2876 | BF9: =BF$1-BA9 -> 832 | BH9: 4.67 | BI9: =BH9*$BI$1 -> 9.4334 | BJ9: =ROUND(C9*BJ$2,2) -> 4.56 | BK9: =ROUND(D9*BK$2,2) -> 8.86 | BM9: =ROUND(T9*BM$3+BM$4,1) -> 95 | BN9: =ROUND(F9*BM$3+BM$4,1) -> 84.2 | BO9: =ROUND(AH9*BM$3+BM$4,1) -> 70.9 | BP9: =ROUND(0.6105*(EXP((17.273*R9)/(R9+237.3)))*BO9/100, 3) -> 0.283 | BQ9: =ROUND((100-BO9)*BP9/BO9,3) -> 0.116 | BW9: =BJ9 -> 4.56 | BX9: =BK9 -> 8.86 | BY9: =ROUND(E9,1) -> -16.1 | BZ9: =ROUND(G9,1) -> -17 | CA9: =ROUND(H9,1) -> -18.4 | CB9: =ROUND(I9,1) -> -0.4 | CC9: =ROUND(L9,1) -> 0.5 | CD9: =ROUND(M9,1) -> 1.2 | CE9: =ROUND(N9,1) -> 1.9 | CF9: =ROUND(BN9,1) -> 84.2 | CG9: =ROUND(R9,1) -> -5.7 | CH9: =ROUND(V9,1) -> -5.7 | CI9: =ROUND(W9,1) -> -8.9 | CJ9: =ROUND(X9,1) -> -0.3 | CK9: =ROUND(AA9,1) -> 0.6 | CL9: =ROUND(AB9,1) -> 1.4 | CM9: =ROUND(AC9,1) -> 2 | CN9: =ROUND(BM9,1) -> 95 | CO9: =ROUND(AF9,1) -> -21.8 | CP9: =ROUND(AJ9,1) -> -22.7 | CQ9: =ROUND(AK9,1) -> -23.9 | CR9: =ROUND(AL9,1) -> -0.5 | CS9: =ROUND(AO9,1) -> 0.4 | CT9: =ROUND(AP9,1) -> 1.1 | CU9: =ROUND(AQ9,1) -> 1.8 | CV9: =ROUND(BO9,1) -> 70.9 | CW9: =BF9 -> 832 | CX9: =ROUND(PPTest!K9,1) -> 0 | CY9: =ROUND(P9,2) -> 1.78 | CZ9: =ROUND(AD9,2) -> 3.11 | DA9: =BP9 -> 0.283 | DB9: =BQ9 -> 0.116 | DC9: =BB9 -> 12.3 | DW9: -12.6 | DX9: -0.6 | DY9: -19.2
A10: 34703 | B10: 4 | C10: 4.89 | D10: 8.47 | E10: -15.33 | F10: 90.4 | G10: -16.3 | H10: -17.75 | I10: -0.556 | J10: -17.59 | K10: -16.58 | L10: 0.457 | M10: 1.233 | N10: 1.906 | O10: 0 | P10: 1.7925 | R10: -4.87 | S10: 1329 | T10: 102.8 | U10: 541 | V10: -5.557 | W10: -7.06 | X10: -0.463 | Y10: -2.564 | Z10: -5.584 | AA10: 0.551 | AB10: 1.334 | AC10: 2.025 | AD10: 2.7408333 | AE10: 527 | AF10: -20.18 | AG10: 2340 | AH10: 74.6 | AI10: 1217 | AJ10: -21.15 | AK10: -22.62 | AL10: -0.683 | AM10: -22.72 | AN10: -21.51 | AO10: 0.381 | AP10: 1.154 | AQ10: 1.822 | AR10: 0 | AS10: 0.265 | AT10: 0.722 | AU10: 0.01 | AV10: 0.002 | AW10: 0 | AX10: 0 | AY10: 0 | AZ10: -17.55 | BA10: 2662 | BB10: 12.29 | BC10: 2876 | BF10: =BF$1-BA10 -> 823 | BH10: 4.72 | BI10: =BH10*$BI$1 -> 9.5344 | BJ10: =ROUND(C10*BJ$2,2) -> 4.89 | BK10: =ROUND(D10*BK$2,2) -> 9.15 | BM10: =ROUND(T10*BM$3+BM$4,1) -> 96 | BN10: =ROUND(F10*BM$3+BM$4,1) -> 84.5 | BO10: =ROUND(AH10*BM$3+BM$4,1) -> 69.9 | BP10: =ROUND(0.6105*(EXP((17.273*R10)/(R10+237.3)))*BO10/100, 3) -> 0.297 | BQ10: =ROUND((100-BO10)*BP10/BO10,3) -> 0.128 | BW10: =BJ10 -> 4.89 | BX10: =BK10 -> 9.15 | BY10: =ROUND(E10,1) -> -15.3 | BZ10: =ROUND(G10,1) -> -16.3 | CA10: =ROUND(H10,1) -> -17.8 | CB10: =ROUND(I10,1) -> -0.6 | CC10: =ROUND(L10,1) -> 0.5 | CD10: =ROUND(M10,1) -> 1.2 | CE10: =ROUND(N10,1) -> 1.9 | CF10: =ROUND(BN10,1) -> 84.5 | CG10: =ROUND(R10,1) -> -4.9 | CH10: =ROUND(V10,1) -> -5.6 | CI10: =ROUND(W10,1) -> -7.1 | CJ10: =ROUND(X10,1) -> -0.5 | CK10: =ROUND(AA10,1) -> 0.6 | CL10: =ROUND(AB10,1) -> 1.3 | CM10: =ROUND(AC10,1) -> 2 | CN10: =ROUND(BM10,1) -> 96 | CO10: =ROUND(AF10,1) -> -20.2 | CP10: =ROUND(AJ10,1) -> -21.2 | CQ10: =ROUND(AK10,1) -> -22.6 | CR10: =ROUND(AL10,1) -> -0.7 | CS10: =ROUND(AO10,1) -> 0.4 | CT10: =ROUND(AP10,1) -> 1.2 | CU10: =ROUND(AQ10,1) -> 1.8 | CV10: =ROUND(BO10,1) -> 69.9 | CW10: =BF10 -> 823 | CX10: =ROUND(PPTest!K10,1) -> 0 | CY10: =ROUND(P10,2) -> 1.79 | CZ10: =ROUND(AD10,2) -> 2.74 | DA10: =BP10 -> 0.297 | DB10: =BQ10 -> 0.128 | DC10: =BB10 -> 12.29 | DW10: -12 | DX10: -2.3 | DY10: -16.9
A11: 34704 | B11: 5 | C11: 5.365 | D11: 8.94 | E11: -17.11 | F11: 87.4 | G11: -17.99 | H11: -19.34 | I11: -0.699 | J11: -19.01 | K11: -18.19 | L11: 0.375 | M11: 1.164 | N11: 1.849 | O11: 0 | P11: 1.6541667 | R11: -5.734 | S11: 1345 | T11: 95 | U11: 1624 | V11: -4.958 | W11: -7.43 | X11: -0.552 | Y11: -2.306 | Z11: -5.806 | AA11: 0.499 | AB11: 1.306 | AC11: 2.001 | AD11: 2.6875 | AE11: 251 | AF11: -22.01 | AG11: 710 | AH11: 60.85 | AI11: 1342 | AJ11: -22.99 | AK11: -24.51 | AL11: -0.836 | AM11: -24.47 | AN11: -23.26 | AO11: 0.251 | AP11: 1.037 | AQ11: 1.717 | AR11: 0.001 | AS11: 0.203 | AT11: 0.73 | AU11: 0.037 | AV11: 0.027 | AW11: 0.002 | AX11: 0 | AY11: 0 | AZ11: -19.01 | BA11: 2666 | BB11: 12.29 | BC11: 2876 | BF11: =BF$1-BA11 -> 819 | BH11: 4.76 | BI11: =BH11*$BI$1 -> 9.6152 | BJ11: =ROUND(C11*BJ$2,2) -> 5.37 | BK11: =ROUND(D11*BK$2,2) -> 9.66 | BM11: =ROUND(T11*BM$3+BM$4,1) -> 88.8 | BN11: =ROUND(F11*BM$3+BM$4,1) -> 81.8 | BO11: =ROUND(AH11*BM$3+BM$4,1) -> 57.2 | BP11: =ROUND(0.6105*(EXP((17.273*R11)/(R11+237.3)))*BO11/100, 3) -> 0.228 | BQ11: =ROUND((100-BO11)*BP11/BO11,3) -> 0.171 | BW11: =BJ11 -> 5.37 | BX11: =BK11 -> 9.66 | BY11: =ROUND(E11,1) -> -17.1 | BZ11: =ROUND(G11,1) -> -18 | CA11: =ROUND(H11,1) -> -19.3 | CB11: =ROUND(I11,1) -> -0.7 | CC11: =ROUND(L11,1) -> 0.4 | CD11: =ROUND(M11,1) -> 1.2 | CE11: =ROUND(N11,1) -> 1.8 | CF11: =ROUND(BN11,1) -> 81.8 | CG11: =ROUND(R11,1) -> -5.7 | CH11: =ROUND(V11,1) -> -5 | CI11: =ROUND(W11,1) -> -7.4 | CJ11: =ROUND(X11,1) -> -0.6 | CK11: =ROUND(AA11,1) -> 0.5 | CL11: =ROUND(AB11,1) -> 1.3 | CM11: =ROUND(AC11,1) -> 2 | CN11: =ROUND(BM11,1) -> 88.8 | CO11: =ROUND(AF11,1) -> -22 | CP11: =ROUND(AJ11,1) -> -23 | CQ11: =ROUND(AK11,1) -> -24.5 | CR11: =ROUND(AL11,1) -> -0.8 | CS11: =ROUND(AO11,1) -> 0.3 | CT11: =ROUND(AP11,1) -> 1 | CU11: =ROUND(AQ11,1) -> 1.7 | CV11: =ROUND(BO11,1) -> 57.2 | CW11: =BF11 -> 819 | CX11: =ROUND(PPTest!K11,1) -> 0 | CY11: =ROUND(P11,2) -> 1.65 | CZ11: =ROUND(AD11,2) -> 2.69 | DA11: =BP11 -> 0.228 | DB11: =BQ11 -> 0.171 | DC11: =BB11 -> 12.29 | DW11: -11.5 | DX11: 3.2 | DY11: -17
A12: 34705 | B12: 6 | C12: 3.726 | D12: 5.865 | E12: -16.65 | F12: 86.7 | G12: -17.1 | H12: -18.25 | I12: -0.768 | J12: -17.78 | K12: -17.3 | L12: 0.331 | M12: 1.142 | N12: 1.848 | O12: 0 | P12: 1.4668333 | R12: -5.772 | S12: 1416 | T12: 97.1 | U12: 1625 | V12: -4.03 | W12: -6.756 | X12: -0.635 | Y12: -1.788 | Z12: -4.553 | AA12: 0.45 | AB12: 1.265 | AC12: 1.99 | AD12: 2.6475 | AE12: 2359 | AF12: -21.43 | AG12: 625 | AH12: 63.05 | AI12: 1418 | AJ12: -22.23 | AK12: -23.33 | AL12: -0.874 | AM12: -23.26 | AN12: -22.54 | AO12: 0.242 | AP12: 1.045 | AQ12: 1.742 | AR12: 0.006 | AS12: 0.281 | AT12: 0.553 | AU12: 0.017 | AV12: 0.092 | AW12: 0.04 | AX12: 0.003 | AY12: 0.009 | AZ12: -17.76 | BA12: 2679 | BB12: 12.29 | BC12: 2876 | BF12: =BF$1-BA12 -> 806 | BH12: 4.82 | BI12: =BH12*$BI$1 -> 9.7364 | BJ12: =ROUND(C12*BJ$2,2) -> 3.73 | BK12: =ROUND(D12*BK$2,2) -> 6.33 | BM12: =ROUND(T12*BM$3+BM$4,1) -> 90.7 | BN12: =ROUND(F12*BM$3+BM$4,1) -> 81.1 | BO12: =ROUND(AH12*BM$3+BM$4,1) -> 59.3 | BP12: =ROUND(0.6105*(EXP((17.273*R12)/(R12+237.3)))*BO12/100, 3) -> 0.235 | BQ12: =ROUND((100-BO12)*BP12/BO12,3) -> 0.161 | BW12: =BJ12 -> 3.73 | BX12: =BK12 -> 6.33 | BY12: =ROUND(E12,1) -> -16.7 | BZ12: =ROUND(G12,1) -> -17.1 | CA12: =ROUND(H12,1) -> -18.3 | CB12: =ROUND(I12,1) -> -0.8 | CC12: =ROUND(L12,1) -> 0.3 | CD12: =ROUND(M12,1) -> 1.1 | CE12: =ROUND(N12,1) -> 1.8 | CF12: =ROUND(BN12,1) -> 81.1 | CG12: =ROUND(R12,1) -> -5.8 | CH12: =ROUND(V12,1) -> -4 | CI12: =ROUND(W12,1) -> -6.8 | CJ12: =ROUND(X12,1) -> -0.6 | CK12: =ROUND(AA12,1) -> 0.5 | CL12: =ROUND(AB12,1) -> 1.3 | CM12: =ROUND(AC12,1) -> 2 | CN12: =ROUND(BM12,1) -> 90.7 | CO12: =ROUND(AF12,1) -> -21.4 | CP12: =ROUND(AJ12,1) -> -22.2 | CQ12: =ROUND(AK12,1) -> -23.3 | CR12: =ROUND(AL12,1) -> -0.9 | CS12: =ROUND(AO12,1) -> 0.2 | CT12: =ROUND(AP12,1) -> 1 | CU12: =ROUND(AQ12,1) -> 1.7 | CV12: =ROUND(BO12,1) -> 59.3 | CW12: =BF12 -> 806 | CX12: =ROUND(PPTest!K12,1) -> 0 | CY12: =ROUND(P12,2) -> 1.47 | CZ12: =ROUND(AD12,2) -> 2.65 | DA12: =BP12 -> 0.235 | DB12: =BQ12 -> 0.161 | DC12: =BB12 -> 12.29 | DW12: -12.9 | DX12: -4 | DY12: -16.8
A13: 34706 | B13: 7 | C13: 6.047 | D13: 11.05 | E13: -15.76 | F13: 85.7 | G13: -16.61 | H13: -17.6 | I13: -0.908 | J13: -17.35 | K13: -16.86 | L13: 0.226 | M13: 1.063 | N13: 1.789 | O13: 0 | P13: 1.8091667 | R13: -5.267 | S13: 2238 | T13: 98.9 | U13: 1616 | V13: -5.365 | W13: -6.155 | X13: -0.758 | Y13: -3.458 | Z13: -6.656 | AA13: 0.361 | AB13: 1.214 | AC13: 1.954 | AD13: 4.0208333 | AE13: 2224 | AF13: -24.24 | AG13: 814 | AH13: 67.36 | AI13: 1416 | AJ13: -25.12 | AK13: -26.44 | AL13: -1.124 | AM13: -26.43 | AN13: -25.63 | AO13: 0.057 | AP13: 0.894 | AQ13: 1.612 | AR13: 0.019 | AS13: 0.382 | AT13: 0.571 | AU13: 0.014 | AV13: 0.006 | AW13: 0.005 | AX13: 0.001 | AY13: 0.001 | AZ13: -18.19 | BA13: 2676 | BB13: 12.29 | BC13: 2876 | BF13: =BF$1-BA13 -> 809 | BH13: 4.87 | BI13: =BH13*$BI$1 -> 9.8374 | BJ13: =ROUND(C13*BJ$2,2) -> 6.05 | BK13: =ROUND(D13*BK$2,2) -> 11.93 | BM13: =ROUND(T13*BM$3+BM$4,1) -> 92.4 | BN13: =ROUND(F13*BM$3+BM$4,1) -> 80.2 | BO13: =ROUND(AH13*BM$3+BM$4,1) -> 63.2 | BP13: =ROUND(0.6105*(EXP((17.273*R13)/(R13+237.3)))*BO13/100, 3) -> 0.261 | BQ13: =ROUND((100-BO13)*BP13/BO13,3) -> 0.152 | BW13: =BJ13 -> 6.05 | BX13: =BK13 -> 11.93 | BY13: =ROUND(E13,1) -> -15.8 | BZ13: =ROUND(G13,1) -> -16.6 | CA13: =ROUND(H13,1) -> -17.6 | CB13: =ROUND(I13,1) -> -0.9 | CC13: =ROUND(L13,1) -> 0.2 | CD13: =ROUND(M13,1) -> 1.1 | CE13: =ROUND(N13,1) -> 1.8 | CF13: =ROUND(BN13,1) -> 80.2 | CG13: =ROUND(R13,1) -> -5.3 | CH13: =ROUND(V13,1) -> -5.4 | CI13: =ROUND(W13,1) -> -6.2 | CJ13: =ROUND(X13,1) -> -0.8 | CK13: =ROUND(AA13,1) -> 0.4 | CL13: =ROUND(AB13,1) -> 1.2 | CM13: =ROUND(AC13,1) -> 2 | CN13: =ROUND(BM13,1) -> 92.4 | CO13: =ROUND(AF13,1) -> -24.2 | CP13: =ROUND(AJ13,1) -> -25.1 | CQ13: =ROUND(AK13,1) -> -26.4 | CR13: =ROUND(AL13,1) -> -1.1 | CS13: =ROUND(AO13,1) -> 0.1 | CT13: =ROUND(AP13,1) -> 0.9 | CU13: =ROUND(AQ13,1) -> 1.6 | CV13: =ROUND(BO13,1) -> 63.2 | CW13: =BF13 -> 809 | CX13: =ROUND(PPTest!K13,1) -> 0.4 | CY13: =ROUND(P13,2) -> 1.81 | CZ13: =ROUND(AD13,2) -> 4.02 | DA13: =BP13 -> 0.261 | DB13: =BQ13 -> 0.152 | DC13: =BB13 -> 12.29 | DW13: -9.6 | DX13: -3.1 | DY13: -17.7
A14: 34707 | B14: 8 | C14: 0.631 | D14: 1.459 | E14: -3.872 | F14: 97.2 | G14: -4.284 | H14: -4.828 | I14: -0.879 | J14: -4.862 | K14: -4.474 | L14: 0.217 | M14: 1.092 | N14: 1.848 | O14: 0 | P14: 1.3216667 | R14: -0.005 | S14: 1146 | T14: 105.2 | U14: 2332 | V14: -0.165 | W14: -1.431 | X14: -0.838 | Y14: -1.238 | Z14: -0.758 | AA14: 0.268 | AB14: 1.14 | AC14: 1.909 | AD14: 4.1008333 | AE14: 1528 | AF14: -7.66 | AG14: 645 | AH14: 81.3 | AI14: 1040 | AJ14: -8.42 | AK14: -9.72 | AL14: -0.927 | AM14: -9.65 | AN14: -8.37 | AO14: 0.154 | AP14: 1.006 | AQ14: 1.754 | AR14: 0.148 | AS14: 0.188 | AT14: 0.115 | AU14: 0.088 | AV14: 0.093 | AW14: 0.172 | AX14: 0.126 | AY14: 0.07 | AZ14: -5.32 | BA14: 2626 | BB14: 12.29 | BC14: 2876 | BF14: =BF$1-BA14 -> 859 | BH14: 4.93 | BI14: =BH14*$BI$1 -> 9.9586 | BJ14: =ROUND(C14*BJ$2,2) -> 0.63 | BK14: =ROUND(D14*BK$2,2) -> 1.58 | BM14: =ROUND(T14*BM$3+BM$4,1) -> 98.2 | BN14: =ROUND(F14*BM$3+BM$4,1) -> 90.8 | BO14: =ROUND(AH14*BM$3+BM$4,1) -> 76.1 | BP14: =ROUND(0.6105*(EXP((17.273*R14)/(R14+237.3)))*BO14/100, 3) -> 0.464 | BQ14: =ROUND((100-BO14)*BP14/BO14,3) -> 0.146 | BW14: =BJ14 -> 0.63 | BX14: =BK14 -> 1.58 | BY14: =ROUND(E14,1) -> -3.9 | BZ14: =ROUND(G14,1) -> -4.3 | CA14: =ROUND(H14,1) -> -4.8 | CB14: =ROUND(I14,1) -> -0.9 | CC14: =ROUND(L14,1) -> 0.2 | CD14: =ROUND(M14,1) -> 1.1 | CE14: =ROUND(N14,1) -> 1.8 | CF14: =ROUND(BN14,1) -> 90.8 | CG14: =ROUND(R14,1) -> 0 | CH14: =ROUND(V14,1) -> -0.2 | CI14: =ROUND(W14,1) -> -1.4 | CJ14: =ROUND(X14,1) -> -0.8 | CK14: =ROUND(AA14,1) -> 0.3 | CL14: =ROUND(AB14,1) -> 1.1 | CM14: =ROUND(AC14,1) -> 1.9 | CN14: =ROUND(BM14,1) -> 98.2 | CO14: =ROUND(AF14,1) -> -7.7 | CP14: =ROUND(AJ14,1) -> -8.4 | CQ14: =ROUND(AK14,1) -> -9.7 | CR14: =ROUND(AL14,1) -> -0.9 | CS14: =ROUND(AO14,1) -> 0.2 | CT14: =ROUND(AP14,1) -> 1 | CU14: =ROUND(AQ14,1) -> 1.8 | CV14: =ROUND(BO14,1) -> 76.1 | CW14: =BF14 -> 859 | CX14: =ROUND(PPTest!K14,1) -> 6.5 | CY14: =ROUND(P14,2) -> 1.32 | CZ14: =ROUND(AD14,2) -> 4.1 | DA14: =BP14 -> 0.464 | DB14: =BQ14 -> 0.146 | DC14: =BB14 -> 12.29 | DW14: -4.5 | DX14: -1.2 | DY14: -7.6
A15: 34708 | B15: 9 | C15: 0.541 | D15: 1.138 | E15: -1.153 | F15: 94.9 | G15: -1.517 | H15: -1.861 | I15: -0.86 | J15: -2.284 | K15: -1.951 | L15: 0.163 | M15: 1.058 | N15: 1.836 | O15: 0 | P15: 1.6575 | R15: 1.192 | S15: 2315 | T15: 103.2 | U15: 339 | V15: 1.583 | W15: 1.062 | X15: -0.781 | Y15: 0.313 | Z15: -0.187 | AA15: 0.207 | AB15: 1.105 | AC15: 1.876 | AD15: 4.3008333 | AE15: 2339 | AF15: -5.813 | AG15: 404 | AH15: 81 | AI15: 614 | AJ15: -6.859 | AK15: -7.82 | AL15: -0.919 | AM15: -7.49 | AN15: -6.788 | AO15: 0.131 | AP15: 1.02 | AQ15: 1.791 | AR15: 0.244 | AS15: 0.278 | AT15: 0.099 | AU15: 0.061 | AV15: 0.056 | AW15: 0.087 | AX15: 0.101 | AY15: 0.073 | AZ15: -3.182 | BA15: 3474 | BB15: 12.29 | BC15: 2876 | BF15: 900 | BH15: 4.99 | BI15: =BH15*$BI$1 -> 10.0798 | BJ15: =ROUND(C15*BJ$2,2) -> 0.54 | BK15: =ROUND(D15*BK$2,2) -> 1.23 | BM15: =ROUND(T15*BM$3+BM$4,1) -> 96.4 | BN15: =ROUND(F15*BM$3+BM$4,1) -> 88.7 | BO15: =ROUND(AH15*BM$3+BM$4,1) -> 75.8 | BP15: =ROUND(0.6105*(EXP((17.273*R15)/(R15+237.3)))*BO15/100, 3) -> 0.504 | BQ15: =ROUND((100-BO15)*BP15/BO15,3) -> 0.161 | BW15: =BJ15 -> 0.54 | BX15: =BK15 -> 1.23 | BY15: =ROUND(E15,1) -> -1.2 | BZ15: =ROUND(G15,1) -> -1.5 | CA15: =ROUND(H15,1) -> -1.9 | CB15: =ROUND(I15,1) -> -0.9 | CC15: =ROUND(L15,1) -> 0.2 | CD15: =ROUND(M15,1) -> 1.1 | CE15: =ROUND(N15,1) -> 1.8 | CF15: =ROUND(BN15,1) -> 88.7 | CG15: =ROUND(R15,1) -> 1.2 | CH15: =ROUND(V15,1) -> 1.6 | CI15: =ROUND(W15,1) -> 1.1 | CJ15: =ROUND(X15,1) -> -0.8 | CK15: =ROUND(AA15,1) -> 0.2 | CL15: =ROUND(AB15,1) -> 1.1 | CM15: =ROUND(AC15,1) -> 1.9 | CN15: =ROUND(BM15,1) -> 96.4 | CO15: =ROUND(AF15,1) -> -5.8 | CP15: =ROUND(AJ15,1) -> -6.9 | CQ15: =ROUND(AK15,1) -> -7.8 | CR15: =ROUND(AL15,1) -> -0.9 | CS15: =ROUND(AO15,1) -> 0.1 | CT15: =ROUND(AP15,1) -> 1 | CU15: =ROUND(AQ15,1) -> 1.8 | CV15: =ROUND(BO15,1) -> 75.8 | CW15: =BF15 -> 900 | CX15: =ROUND(PPTest!K15,1) -> 5.3 | CY15: =ROUND(P15,2) -> 1.66 | CZ15: =ROUND(AD15,2) -> 4.3 | DA15: =BP15 -> 0.504 | DB15: =BQ15 -> 0.161 | DC15: =BB15 -> 12.29 | DW15: -1.6 | DX15: 1.8 | DY15: -4.5
A16: 34709 | B16: 10 | C16: 0.572 | D16: 0.926 | E16: -0.354 | F16: 99.6 | G16: -0.938 | H16: -1.355 | I16: -0.746 | J16: -1.453 | K16: -1.049 | L16: 0.151 | M16: 1.046 | N16: 1.838 | O16: 0 | P16: 0.87916667 | R16: 2.208 | S16: 1128 | T16: 104.6 | U16: 440 | V16: 2.215 | W16: 1.848 | X16: -0.685 | Y16: 1.019 | Z16: 0.28 | AA16: 0.18 | AB16: 1.087 | AC16: 1.871 | AD16: 3.9675 | AE16: 44 | AF16: -3.791 | AG16: 0 | AH16: 84.1 | AI16: 1124 | AJ16: -4.905 | AK16: -6.412 | AL16: -0.815 | AM16: -5.349 | AN16: -4.465 | AO16: 0.119 | AP16: 1.012 | AQ16: 1.808 | AR16: 0.09 | AS16: 0.303 | AT16: 0.217 | AU16: 0.083 | AV16: 0.055 | AW16: 0.14 | AX16: 0.06 | AY16: 0.052 | AZ16: -1.434 | BA16: 2517 | BB16: 12.3 | BC16: 2876 | BF16: =BF$1-BA16 -> 968 | BH16: 5.06 | BI16: =BH16*$BI$1 -> 10.2212 | BJ16: =ROUND(C16*BJ$2,2) -> 0.57 | BK16: =ROUND(D16*BK$2,2) -> 1 | BM16: =ROUND(T16*BM$3+BM$4,1) -> 97.7 | BN16: =ROUND(F16*BM$3+BM$4,1) -> 93 | BO16: =ROUND(AH16*BM$3+BM$4,1) -> 78.7 | BP16: =ROUND(0.6105*(EXP((17.273*R16)/(R16+237.3)))*BO16/100, 3) -> 0.563 | BQ16: =ROUND((100-BO16)*BP16/BO16,3) -> 0.152 | BW16: =BJ16 -> 0.57 | BX16: =BK16 -> 1 | BY16: =ROUND(E16,1) -> -0.4 | BZ16: =ROUND(G16,1) -> -0.9 | CA16: =ROUND(H16,1) -> -1.4 | CB16: =ROUND(I16,1) -> -0.7 | CC16: =ROUND(L16,1) -> 0.2 | CD16: =ROUND(M16,1) -> 1 | CE16: =ROUND(N16,1) -> 1.8 | CF16: =ROUND(BN16,1) -> 93 | CG16: =ROUND(R16,1) -> 2.2 | CH16: =ROUND(V16,1) -> 2.2 | CI16: =ROUND(W16,1) -> 1.8 | CJ16: =ROUND(X16,1) -> -0.7 | CK16: =ROUND(AA16,1) -> 0.2 | CL16: =ROUND(AB16,1) -> 1.1 | CM16: =ROUND(AC16,1) -> 1.9 | CN16: =ROUND(BM16,1) -> 97.7 | CO16: =ROUND(AF16,1) -> -3.8 | CP16: =ROUND(AJ16,1) -> -4.9 | CQ16: =ROUND(AK16,1) -> -6.4 | CR16: =ROUND(AL16,1) -> -0.8 | CS16: =ROUND(AO16,1) -> 0.1 | CT16: =ROUND(AP16,1) -> 1 | CU16: =ROUND(AQ16,1) -> 1.8 | CV16: =ROUND(BO16,1) -> 78.7 | CW16: =BF16 -> 968 | CX16: =ROUND(PPTest!K16,1) -> 8.8 | CY16: =ROUND(P16,2) -> 0.88 | CZ16: =ROUND(AD16,2) -> 3.97 | DA16: =BP16 -> 0.563 | DB16: =BQ16 -> 0.152 | DC16: =BB16 -> 12.3 | DW16: -0.7 | DX16: 1.1 | DY16: -3.7
A17: 34710 | B17: 11 | C17: 0.246 | D17: 0.626 | E17: -3.724 | F17: 101.2 | G17: -4.345 | H17: -5.053 | I17: -0.648 | J17: -5.423 | K17: -4.603 | L17: 0.133 | M17: 1.011 | N17: 1.805 | O17: 0 | P17: 0.80366667 | R17: -0.377 | S17: 1545 | T17: 102.9 | U17: 423 | V17: 0.287 | W17: -1.396 | X17: -0.577 | Y17: -1.948 | Z17: -0.983 | AA17: 0.157 | AB17: 1.044 | AC17: 1.844 | AD17: 4.1408333 | AE17: 1337 | AF17: -6.796 | AG17: 351 | AH17: 98.5 | AI17: 1531 | AJ17: -7.89 | AK17: -9.82 | AL17: -0.72 | AM17: -9.33 | AN17: -8.23 | AO17: 0.106 | AP17: 0.981 | AQ17: 1.775 | AR17: 0.467 | AS17: 0.21 | AT17: 0.194 | AU17: 0.024 | AV17: 0.028 | AW17: 0.06 | AX17: 0.015 | AY17: 0.002 | AZ17: -3.683 | BA17: 2478 | BB17: 12.3 | BC17: 2876 | BF17: =BF$1-BA17 -> 1007 | BH17: 5.13 | BI17: =BH17*$BI$1 -> 10.3626 | BJ17: =ROUND(C17*BJ$2,2) -> 0.25 | BK17: =ROUND(D17*BK$2,2) -> 0.68 | BM17: =ROUND(T17*BM$3+BM$4,1) -> 96.1 | BN17: =ROUND(F17*BM$3+BM$4,1) -> 94.5 | BO17: =ROUND(AH17*BM$3+BM$4,1) -> 92 | BP17: =ROUND(0.6105*(EXP((17.273*R17)/(R17+237.3)))*BO17/100, 3) -> 0.546 | BQ17: =ROUND((100-BO17)*BP17/BO17,3) -> 0.047 | BW17: =BJ17 -> 0.25 | BX17: =BK17 -> 0.68 | BY17: =ROUND(E17,1) -> -3.7 | BZ17: =ROUND(G17,1) -> -4.3 | CA17: =ROUND(H17,1) -> -5.1 | CB17: =ROUND(I17,1) -> -0.6 | CC17: =ROUND(L17,1) -> 0.1 | CD17: =ROUND(M17,1) -> 1 | CE17: =ROUND(N17,1) -> 1.8 | CF17: =ROUND(BN17,1) -> 94.5 | CG17: =ROUND(R17,1) -> -0.4 | CH17: =ROUND(V17,1) -> 0.3 | CI17: =ROUND(W17,1) -> -1.4 | CJ17: =ROUND(X17,1) -> -0.6 | CK17: =ROUND(AA17,1) -> 0.2 | CL17: =ROUND(AB17,1) -> 1 | CM17: =ROUND(AC17,1) -> 1.8 | CN17: =ROUND(BM17,1) -> 96.1 | CO17: =ROUND(AF17,1) -> -6.8 | CP17: =ROUND(AJ17,1) -> -7.9 | CQ17: =ROUND(AK17,1) -> -9.8 | CR17: =ROUND(AL17,1) -> -0.7 | CS17: =ROUND(AO17,1) -> 0.1 | CT17: =ROUND(AP17,1) -> 1 | CU17: =ROUND(AQ17,1) -> 1.8 | CV17: =ROUND(BO17,1) -> 92 | CW17: =BF17 -> 1007 | CX17: =ROUND(PPTest!K17,1) -> 5.1 | CY17: =ROUND(P17,2) -> 0.8 | CZ17: =ROUND(AD17,2) -> 4.14 | DA17: =BP17 -> 0.546 | DB17: =BQ17 -> 0.047 | DC17: =BB17 -> 12.3 | DW17: -2.3 | DX17: 1.9 | DY17: -4
A18: 34711 | B18: 12 | C18: 0.737 | D18: 1.471 | E18: -3.776 | F18: 95.4 | G18: -4.435 | H18: -5.312 | I18: -0.543 | J18: -6.013 | K18: -4.9 | L18: 0.146 | M18: 1 | N18: 1.785 | O18: 0 | P18: 0.72283333 | R18: 1.062 | S18: 1109 | T18: 103 | U18: 737 | V18: 0.647 | W18: -1.118 | X18: -0.489 | Y18: -2.747 | Z18: -1.151 | AA18: 0.188 | AB18: 1.04 | AC18: 1.822 | AD18: 3.3275 | AE18: 1208 | AF18: -7.77 | AG18: 444 | AH18: 74.5 | AI18: 1110 | AJ18: -9.59 | AK18: -11.81 | AL18: -0.608 | AM18: -11.73 | AN18: -9.34 | AO18: 0.111 | AP18: 0.964 | AQ18: 1.743 | AR18: 0.535 | AS18: 0.214 | AT18: 0.143 | AU18: 0.039 | AV18: 0.006 | AW18: 0.021 | AX18: 0.015 | AY18: 0.028 | AZ18: -4.006 | BA18: 2488 | BB18: 12.29 | BC18: 2876 | BF18: =BF$1-BA18 -> 997 | BH18: 5.2 | BI18: =BH18*$BI$1 -> 10.504 | BJ18: =ROUND(C18*BJ$2,2) -> 0.74 | BK18: =ROUND(D18*BK$2,2) -> 1.59 | BM18: =ROUND(T18*BM$3+BM$4,1) -> 96.2 | BN18: =ROUND(F18*BM$3+BM$4,1) -> 89.1 | BO18: =ROUND(AH18*BM$3+BM$4,1) -> 69.8 | BP18: =ROUND(0.6105*(EXP((17.273*R18)/(R18+237.3)))*BO18/100, 3) -> 0.46 | BQ18: =ROUND((100-BO18)*BP18/BO18,3) -> 0.199 | BW18: =BJ18 -> 0.74 | BX18: =BK18 -> 1.59 | BY18: =ROUND(E18,1) -> -3.8 | BZ18: =ROUND(G18,1) -> -4.4 | CA18: =ROUND(H18,1) -> -5.3 | CB18: =ROUND(I18,1) -> -0.5 | CC18: =ROUND(L18,1) -> 0.1 | CD18: =ROUND(M18,1) -> 1 | CE18: =ROUND(N18,1) -> 1.8 | CF18: =ROUND(BN18,1) -> 89.1 | CG18: =ROUND(R18,1) -> 1.1 | CH18: =ROUND(V18,1) -> 0.6 | CI18: =ROUND(W18,1) -> -1.1 | CJ18: =ROUND(X18,1) -> -0.5 | CK18: =ROUND(AA18,1) -> 0.2 | CL18: =ROUND(AB18,1) -> 1 | CM18: =ROUND(AC18,1) -> 1.8 | CN18: =ROUND(BM18,1) -> 96.2 | CO18: =ROUND(AF18,1) -> -7.8 | CP18: =ROUND(AJ18,1) -> -9.6 | CQ18: =ROUND(AK18,1) -> -11.8 | CR18: =ROUND(AL18,1) -> -0.6 | CS18: =ROUND(AO18,1) -> 0.1 | CT18: =ROUND(AP18,1) -> 1 | CU18: =ROUND(AQ18,1) -> 1.7 | CV18: =ROUND(BO18,1) -> 69.8 | CW18: =BF18 -> 997 | CX18: =ROUND(PPTest!K18,1) -> 0 | CY18: =ROUND(P18,2) -> 0.72 | CZ18: =ROUND(AD18,2) -> 3.33 | DA18: =BP18 -> 0.46 | DB18: =BQ18 -> 0.199 | DC18: =BB18 -> 12.29 | DW18: -3 | DX18: -0.2 | DY18: -6.1
A19: 34712 | B19: 13 | C19: 0.402 | D19: 0.879 | E19: -1.742 | F19: 97.9 | G19: -2.045 | H19: -2.158 | I19: -0.463 | J19: -2.77 | K19: -2.286 | L19: 0.169 | M19: 0.998 | N19: 1.771 | O19: 0 | P19: 1.3923333 | R19: -0.263 | S19: 1046 | T19: 103.1 | U19: 655 | V19: -0.327 | W19: -0.491 | X19: -0.416 | Y19: -2.044 | Z19: -1.036 | AA19: 0.198 | AB19: 1.016 | AC19: 1.792 | AD19: 5.3541667 | AE19: 1854 | AF19: -2.854 | AG19: 614 | AH19: 79.1 | AI19: 1209 | AJ19: -3.555 | AK19: -4.123 | AL19: -0.513 | AM19: -3.566 | AN19: -3.331 | AO19: 0.14 | AP19: 0.973 | AQ19: 1.752 | AR19: 0.195 | AS19: 0.263 | AT19: 0.099 | AU19: 0.068 | AV19: 0.087 | AW19: 0.121 | AX19: 0.093 | AY19: 0.073 | AZ19: -2.598 | BA19: 2466 | BB19: 12.29 | BC19: 2876 | BF19: =BF$1-BA19 -> 1019 | BH19: 5.27 | BI19: =BH19*$BI$1 -> 10.6454 | BJ19: =ROUND(C19*BJ$2,2) -> 0.4 | BK19: =ROUND(D19*BK$2,2) -> 0.95 | BM19: =ROUND(T19*BM$3+BM$4,1) -> 96.3 | BN19: =ROUND(F19*BM$3+BM$4,1) -> 91.5 | BO19: =ROUND(AH19*BM$3+BM$4,1) -> 74.1 | BP19: =ROUND(0.6105*(EXP((17.273*R19)/(R19+237.3)))*BO19/100, 3) -> 0.444 | BQ19: =ROUND((100-BO19)*BP19/BO19,3) -> 0.155 | BW19: =BJ19 -> 0.4 | BX19: =BK19 -> 0.95 | BY19: =ROUND(E19,1) -> -1.7 | BZ19: =ROUND(G19,1) -> -2 | CA19: =ROUND(H19,1) -> -2.2 | CB19: =ROUND(I19,1) -> -0.5 | CC19: =ROUND(L19,1) -> 0.2 | CD19: =ROUND(M19,1) -> 1 | CE19: =ROUND(N19,1) -> 1.8 | CF19: =ROUND(BN19,1) -> 91.5 | CG19: =ROUND(R19,1) -> -0.3 | CH19: =ROUND(V19,1) -> -0.3 | CI19: =ROUND(W19,1) -> -0.5 | CJ19: =ROUND(X19,1) -> -0.4 | CK19: =ROUND(AA19,1) -> 0.2 | CL19: =ROUND(AB19,1) -> 1 | CM19: =ROUND(AC19,1) -> 1.8 | CN19: =ROUND(BM19,1) -> 96.3 | CO19: =ROUND(AF19,1) -> -2.9 | CP19: =ROUND(AJ19,1) -> -3.6 | CQ19: =ROUND(AK19,1) -> -4.1 | CR19: =ROUND(AL19,1) -> -0.5 | CS19: =ROUND(AO19,1) -> 0.1 | CT19: =ROUND(AP19,1) -> 1 | CU19: =ROUND(AQ19,1) -> 1.8 | CV19: =ROUND(BO19,1) -> 74.1 | CW19: =BF19 -> 1019 | CX19: =ROUND(PPTest!K19,1) -> 2.9 | CY19: =ROUND(P19,2) -> 1.39 | CZ19: =ROUND(AD19,2) -> 5.35 | DA19: =BP19 -> 0.444 | DB19: =BQ19 -> 0.155 | DC19: =BB19 -> 12.29 | DW19: -2.8 | DX19: -1.4 | DY19: -5.2
A20: 34713 | B20: 14 | C20: 0.384 | D20: 0.899 | E20: -2.723 | F20: 98.9 | G20: -3.301 | H20: -3.691 | I20: -0.413 | J20: -4.268 | K20: -3.472 | L20: 0.187 | M20: 1 | N20: 1.761 | O20: 0 | P20: 1.1083333 | R20: -0.329 | S20: 1318 | T20: 103.3 | U20: 436 | V20: 0.065 | W20: -0.708 | X20: -0.372 | Y20: -2.168 | Z20: -0.488 | AA20: 0.215 | AB20: 1.023 | AC20: 1.789 | AD20: 3.5941667 | AE20: 724 | AF20: -6.553 | AG20: 546 | AH20: 84.8 | AI20: 1240 | AJ20: -8.15 | AK20: -9.6 | AL20: -0.448 | AM20: -8.61 | AN20: -8.46 | AO20: 0.162 | AP20: 0.979 | AQ20: 1.737 | AR20: 0.095 | AS20: 0.457 | AT20: 0.262 | AU20: 0.035 | AV20: 0.042 | AW20: 0.082 | AX20: 0.015 | AY20: 0.012 | AZ20: -2.884 | BA20: 2441 | BB20: 12.29 | BC20: 2876 | BF20: =BF$1-BA20 -> 1044 | BH20: 5.36 | BI20: =BH20*$BI$1 -> 10.8272 | BJ20: =ROUND(C20*BJ$2,2) -> 0.38 | BK20: =ROUND(D20*BK$2,2) -> 0.97 | BM20: =ROUND(T20*BM$3+BM$4,1) -> 96.4 | BN20: =ROUND(F20*BM$3+BM$4,1) -> 92.4 | BO20: =ROUND(AH20*BM$3+BM$4,1) -> 79.4 | BP20: =ROUND(0.6105*(EXP((17.273*R20)/(R20+237.3)))*BO20/100, 3) -> 0.473 | BQ20: =ROUND((100-BO20)*BP20/BO20,3) -> 0.123 | BW20: =BJ20 -> 0.38 | BX20: =BK20 -> 0.97 | BY20: =ROUND(E20,1) -> -2.7 | BZ20: =ROUND(G20,1) -> -3.3 | CA20: =ROUND(H20,1) -> -3.7 | CB20: =ROUND(I20,1) -> -0.4 | CC20: =ROUND(L20,1) -> 0.2 | CD20: =ROUND(M20,1) -> 1 | CE20: =ROUND(N20,1) -> 1.8 | CF20: =ROUND(BN20,1) -> 92.4 | CG20: =ROUND(R20,1) -> -0.3 | CH20: =ROUND(V20,1) -> 0.1 | CI20: =ROUND(W20,1) -> -0.7 | CJ20: =ROUND(X20,1) -> -0.4 | CK20: =ROUND(AA20,1) -> 0.2 | CL20: =ROUND(AB20,1) -> 1 | CM20: =ROUND(AC20,1) -> 1.8 | CN20: =ROUND(BM20,1) -> 96.4 | CO20: =ROUND(AF20,1) -> -6.6 | CP20: =ROUND(AJ20,1) -> -8.2 | CQ20: =ROUND(AK20,1) -> -9.6 | CR20: =ROUND(AL20,1) -> -0.4 | CS20: =ROUND(AO20,1) -> 0.2 | CT20: =ROUND(AP20,1) -> 1 | CU20: =ROUND(AQ20,1) -> 1.7 | CV20: =ROUND(BO20,1) -> 79.4 | CW20: =BF20 -> 1044 | CX20: =ROUND(PPTest!K20,1) -> 3.3 | CY20: =ROUND(P20,2) -> 1.11 | CZ20: =ROUND(AD20,2) -> 3.59 | DA20: =BP20 -> 0.473 | DB20: =BQ20 -> 0.123 | DC20: =BB20 -> 12.29 | DW20: -1.9 | DX20: 0.3 | DY20: -3.9
A21: 34714 | B21: 15 | C21: 0.447 | D21: 1.179 | E21: -2.833 | F21: 99.1 | G21: -3.265 | H21: -3.731 | I21: -0.356 | J21: -2.916 | K21: -3.308 | L21: 0.216 | M21: 1.009 | N21: 1.757 | O21: 0 | P21: 0.6075 | R21: 0.501 | S21: 1316 | T21: 103.8 | U21: 1947 | V21: 1.563 | W21: -0.404 | X21: -0.315 | Y21: -2.252 | Z21: -0.323 | AA21: 0.249 | AB21: 1.036 | AC21: 1.781 | AD21: 2.3008333 | AE21: 1352 | AF21: -5.895 | AG21: 2208 | AH21: 80.4 | AI21: 1317 | AJ21: -6.829 | AK21: -8.6 | AL21: -0.399 | AM21: -3.579 | AN21: -6.851 | AO21: 0.193 | AP21: 0.988 | AQ21: 1.738 | AR21: 0.231 | AS21: 0.167 | AT21: 0.126 | AU21: 0.043 | AV21: 0.133 | AW21: 0.187 | AX21: 0.051 | AY21: 0.063 | AZ21: -2.231 | BA21: 2434 | BB21: 12.29 | BC21: 2876 | BF21: =BF$1-BA21 -> 1051 | BH21: 5.44 | BI21: =BH21*$BI$1 -> 10.9888 | BJ21: =ROUND(C21*BJ$2,2) -> 0.45 | BK21: =ROUND(D21*BK$2,2) -> 1.27 | BM21: =ROUND(T21*BM$3+BM$4,1) -> 96.9 | BN21: =ROUND(F21*BM$3+BM$4,1) -> 92.6 | BO21: =ROUND(AH21*BM$3+BM$4,1) -> 75.3 | BP21: =ROUND(0.6105*(EXP((17.273*R21)/(R21+237.3)))*BO21/100, 3) -> 0.477 | BQ21: =ROUND((100-BO21)*BP21/BO21,3) -> 0.156 | BW21: =BJ21 -> 0.45 | BX21: =BK21 -> 1.27 | BY21: =ROUND(E21,1) -> -2.8 | BZ21: =ROUND(G21,1) -> -3.3 | CA21: =ROUND(H21,1) -> -3.7 | CB21: =ROUND(I21,1) -> -0.4 | CC21: =ROUND(L21,1) -> 0.2 | CD21: =ROUND(M21,1) -> 1 | CE21: =ROUND(N21,1) -> 1.8 | CF21: =ROUND(BN21,1) -> 92.6 | CG21: =ROUND(R21,1) -> 0.5 | CH21: =ROUND(V21,1) -> 1.6 | CI21: =ROUND(W21,1) -> -0.4 | CJ21: =ROUND(X21,1) -> -0.3 | CK21: =ROUND(AA21,1) -> 0.2 | CL21: =ROUND(AB21,1) -> 1 | CM21: =ROUND(AC21,1) -> 1.8 | CN21: =ROUND(BM21,1) -> 96.9 | CO21: =ROUND(AF21,1) -> -5.9 | CP21: =ROUND(AJ21,1) -> -6.8 | CQ21: =ROUND(AK21,1) -> -8.6 | CR21: =ROUND(AL21,1) -> -0.4 | CS21: =ROUND(AO21,1) -> 0.2 | CT21: =ROUND(AP21,1) -> 1 | CU21: =ROUND(AQ21,1) -> 1.7 | CV21: =ROUND(BO21,1) -> 75.3 | CW21: =BF21 -> 1051 | CX21: =ROUND(PPTest!K21,1) -> 0.9 | CY21: =ROUND(P21,2) -> 0.61 | CZ21: =ROUND(AD21,2) -> 2.3 | DA21: =BP21 -> 0.477 | DB21: =BQ21 -> 0.156 | DC21: =BB21 -> 12.29 | DW21: -4.2 | DX21: -0.3 | DY21: -6.4
A22: 34715 | B22: 16 | C22: 0.345 | D22: 0.932 | E22: -4.235 | F22: 101 | G22: -4.677 | H22: -4.885 | I22: -0.318 | J22: -3.366 | K22: -4.639 | L22: 0.236 | M22: 1.008 | N22: 1.743 | O22: 0 | P22: 0.98616667 | R22: -3.26 | S22: 1306 | T22: 103 | U22: 159 | V22: -2.912 | W22: -3.421 | X22: -0.268 | Y22: -3.08 | Z22: -2.842 | AA22: 0.262 | AB22: 1.029 | AC22: 1.767 | AD22: 3.1408333 | AE22: 1536 | AF22: -6.001 | AG22: 2300 | AH22: 98.9 | AI22: 2254 | AJ22: -7.02 | AK22: -8.58 | AL22: -0.354 | AM22: -3.71 | AN22: -7.23 | AO22: 0.212 | AP22: 0.991 | AQ22: 1.72 | AR22: 0.025 | AS22: 0.192 | AT22: 0.179 | AU22: 0.04 | AV22: 0.151 | AW22: 0.366 | AX22: 0.039 | AY22: 0.008 | AZ22: -2.922 | BA22: 2432 | BB22: 12.28 | BC22: 2876 | BF22: =BF$1-BA22 -> 1053 | BH22: 5.53 | BI22: =BH22*$BI$1 -> 11.1706 | BJ22: =ROUND(C22*BJ$2,2) -> 0.35 | BK22: =ROUND(D22*BK$2,2) -> 1.01 | BM22: =ROUND(T22*BM$3+BM$4,1) -> 96.2 | BN22: =ROUND(F22*BM$3+BM$4,1) -> 94.3 | BO22: =ROUND(AH22*BM$3+BM$4,1) -> 92.4 | BP22: =ROUND(0.6105*(EXP((17.273*R22)/(R22+237.3)))*BO22/100, 3) -> 0.443 | BQ22: =ROUND((100-BO22)*BP22/BO22,3) -> 0.036 | BW22: =BJ22 -> 0.35 | BX22: =BK22 -> 1.01 | BY22: =ROUND(E22,1) -> -4.2 | BZ22: =ROUND(G22,1) -> -4.7 | CA22: =ROUND(H22,1) -> -4.9 | CB22: =ROUND(I22,1) -> -0.3 | CC22: =ROUND(L22,1) -> 0.2 | CD22: =ROUND(M22,1) -> 1 | CE22: =ROUND(N22,1) -> 1.7 | CF22: =ROUND(BN22,1) -> 94.3 | CG22: =ROUND(R22,1) -> -3.3 | CH22: =ROUND(V22,1) -> -2.9 | CI22: =ROUND(W22,1) -> -3.4 | CJ22: =ROUND(X22,1) -> -0.3 | CK22: =ROUND(AA22,1) -> 0.3 | CL22: =ROUND(AB22,1) -> 1 | CM22: =ROUND(AC22,1) -> 1.8 | CN22: =ROUND(BM22,1) -> 96.2 | CO22: =ROUND(AF22,1) -> -6 | CP22: =ROUND(AJ22,1) -> -7 | CQ22: =ROUND(AK22,1) -> -8.6 | CR22: =ROUND(AL22,1) -> -0.4 | CS22: =ROUND(AO22,1) -> 0.2 | CT22: =ROUND(AP22,1) -> 1 | CU22: =ROUND(AQ22,1) -> 1.7 | CV22: =ROUND(BO22,1) -> 92.4 | CW22: =BF22 -> 1053 | CX22: =ROUND(PPTest!K22,1) -> 0.3 | CY22: =ROUND(P22,2) -> 0.99 | CZ22: =ROUND(AD22,2) -> 3.14 | DA22: =BP22 -> 0.443 | DB22: =BQ22 -> 0.036 | DC22: =BB22 -> 12.28 | DF22: -2 | DG22: -1.1 | DH22: -2.8 | DI22: 93 | DJ22: 93 | DW22: -4.9 | DX22: -1.2 | DY22: -7.9
A23: 34716 | B23: 17 | C23: 0.336 | D23: 0.906 | E23: -5.776 | F23: 95 | G23: -6.187 | H23: -6.409 | I23: -0.166 | J23: -3.828 | K23: -6.316 | L23: 0.258 | M23: 1.013 | N23: 1.734 | O23: 0 | P23: 1.0371667 | R23: -4.964 | S23: 1433 | T23: 101.9 | U23: 446 | V23: -4.907 | W23: -4.953 | X23: -0.097 | Y23: -3.278 | Z23: -4.756 | AA23: 0.283 | AB23: 1.043 | AC23: 1.768 | AD23: 3.8341667 | AE23: 1228 | AF23: -7.27 | AG23: 414 | AH23: 84.7 | AI23: 854 | AJ23: -8.39 | AK23: -10.45 | AL23: -0.293 | AM23: -4.296 | AN23: -8.55 | AO23: 0.23 | AP23: 0.991 | AQ23: 1.715 | AR23: 0.058 | AS23: 0.17 | AT23: 0.115 | AU23: 0.063 | AV23: 0.159 | AW23: 0.33 | AX23: 0.076 | AY23: 0.03 | AZ23: -4.041 | BA23: 2443 | BB23: 12.28 | BC23: 2876 | BF23: =BF$1-BA23 -> 1042 | BH23: 5.63 | BI23: =BH23*$BI$1 -> 11.3726 | BJ23: =ROUND(C23*BJ$2,2) -> 0.34 | BK23: =ROUND(D23*BK$2,2) -> 0.98 | BM23: =ROUND(T23*BM$3+BM$4,1) -> 95.2 | BN23: =ROUND(F23*BM$3+BM$4,1) -> 88.8 | BO23: =ROUND(AH23*BM$3+BM$4,1) -> 79.3 | BP23: =ROUND(0.6105*(EXP((17.273*R23)/(R23+237.3)))*BO23/100, 3) -> 0.335 | BQ23: =ROUND((100-BO23)*BP23/BO23,3) -> 0.087 | BW23: =BJ23 -> 0.34 | BX23: =BK23 -> 0.98 | BY23: =ROUND(E23,1) -> -5.8 | BZ23: =ROUND(G23,1) -> -6.2 | CA23: =ROUND(H23,1) -> -6.4 | CB23: =ROUND(I23,1) -> -0.2 | CC23: =ROUND(L23,1) -> 0.3 | CD23: =ROUND(M23,1) -> 1 | CE23: =ROUND(N23,1) -> 1.7 | CF23: =ROUND(BN23,1) -> 88.8 | CG23: =ROUND(R23,1) -> -5 | CH23: =ROUND(V23,1) -> -4.9 | CI23: =ROUND(W23,1) -> -5 | CJ23: =ROUND(X23,1) -> -0.1 | CK23: =ROUND(AA23,1) -> 0.3 | CL23: =ROUND(AB23,1) -> 1 | CM23: =ROUND(AC23,1) -> 1.8 | CN23: =ROUND(BM23,1) -> 95.2 | CO23: =ROUND(AF23,1) -> -7.3 | CP23: =ROUND(AJ23,1) -> -8.4 | CQ23: =ROUND(AK23,1) -> -10.5 | CR23: =ROUND(AL23,1) -> -0.3 | CS23: =ROUND(AO23,1) -> 0.2 | CT23: =ROUND(AP23,1) -> 1 | CU23: =ROUND(AQ23,1) -> 1.7 | CV23: =ROUND(BO23,1) -> 79.3 | CW23: =BF23 -> 1042 | CX23: =ROUND(PPTest!K23,1) -> 0 | CY23: =ROUND(P23,2) -> 1.04 | CZ23: =ROUND(AD23,2) -> 3.83 | DA23: =BP23 -> 0.335 | DB23: =BQ23 -> 0.087 | DC23: =BB23 -> 12.28 | DF23: -3.7 | DG23: -2.7 | DH23: -4.5 | DI23: 93.2 | DJ23: 92 | DW23: -6.2 | DX23: -3.1 | DY23: -8.2
