Workbook

Sheet Meta
A1: Meta data for Sicamous base station
A2: Last edit 30/04/25
B3: CR1000 data logger
A5: Solar MJ/m2/d
B6: Kipp and Zonen silicon Pyranometer at 6 m
B7: Adjusted to zero at night in hourly file.
B8: Adjusting for snow on sensor using reflected and max albedo of 0.92
B9: Summed to daily
B10: Kmax from 10 min simulation
B11: Jan 26-29 have solar radiation substantailly above the clear sky value. May be due to snow focus radiation onto sensor.
C12: Adjusted by assuming a fixed albedo and the measured reflected radiation
A14: Reflected MJ/m2/d
B15: LiCor silicon pyranometer at 6 m above surface.
B16: Adjusting for spectral response of pyranometer =0.93*Measured
A17: Tair C
B18: HMP45C in RMYoung pie plate sheild at 6 m
B20: Chromel constantan thermocouples referenced to thermistor on panel at 3 m, 1.5 m and 0.25 m
B21: Referenced to logger panel
A23: RH %
B24: HMP45C in RMYoung pie plate sheild at 6 m
B25: Corrected RH based on Rhmax=100. Calculated vpres (kPa)
A27: Soil temperature C
B28: Chromel constantan thermocouples referenced tologger panel at Duff, 0.15 m and 0.5 m
A30: Precip mm
B31: TexasElectronic tipping bucketmm/tip
A33: Snow depth m, mm
B34: CSI SR50A
A36: Wind m/s
B37: MetOne anemometer at 6 m
A39: Wind direction degrees - number of occurances in 8 bins
B40: MetOne Wind vane at 6 m
A42: PPT= snow+rain
B43: Snow = Daily increase in pack depth and assumed compacted density of 0.13 Mg/m3
B44: Rain = Rain gauge.
C45: If there is a snow pack then review tiping bucket data to determine if likely snow melt rather than rain, i.e., tipping when above zero and low humidity and sunny.
C46: Also sum tipping bucket over days to see if simialr total to water equivalent of snow fal from depth change.
C47: Sicamous Fire Weather Station rainfall not included
A48: Vapour pressure kPa
B49: Calculated from the daily maximum temperature and mininimum relative humdity: esat(Tmax)*RHmin/100
A50: Maximum vapour presure deficit
...

Sheet PPTest
A1: Precipitation | I1: 0.13 | K1: Rain | P1: Max density | Q1: 0.4
A2: =Data!A2 -> Last edit 19/04/25 | C2: Total | K2: SnowDepthChange | P2: Start Density | Q2: 0.23
C3: Solar | D3: Tmax | E3: Tmin | F3: Rhmin | G3: Rain | H3: SnowD | I3: Precip.from | J3: FWS | K3: FWS* | L3: 1.05 | M3: FWS | N3: Sicamous | P3: Scrtchdensity | Q3: density | R3: SWE | S3: dSWE | T3: Melt
A4: Date | B4: DoY | C4: MJ/m2/d | I4: snow depth | K4: Precipitation | P4: g/cm3 | Q4: g/cm3 | R4: mm | S4: mm | T4: mm
H5: 801 | Q5: =Q2 -> 0.23 | R5: =H5*Q5 -> 184.23 | S5: 0 | T5: 0
A6: =Data!A6 -> 45658 | B6: 1 | C6: =ROUND(Data!BB6,2) -> 1.35 | D6: =ROUND(Data!P6,1) -> -6 | E6: =ROUND(Data!Y6,1) -> -9.3 | F6: =Data!BH6 -> 85.3 | G6: =Data!N6 -> 0 | H6: =Data!AY6 -> 772 | I6: =IF(H6>H5,ROUND((H6-H5)*I$1,1),0) -> 0 | K6: =I6 -> 0 | M6: =J6 -> 0 | N6: =K6 -> 0 | P6: =(R5+K6)/H6 -> 0.2386399 | Q6: =IF(P6>Q$1,Q$1,P6) -> 0.2386399 | R6: =Q6*H6 -> 184.23 | S6: =R6-R5 -> 0 | T6: =ROUND(K6-S6,1) -> 0
A7: =Data!A7 -> 45659 | B7: 2 | C7: =ROUND(Data!BB7,2) -> 1.17 | D7: =ROUND(Data!P7,1) -> -5.6 | E7: =ROUND(Data!Y7,1) -> -10 | F7: =Data!BH7 -> 84.6 | G7: =Data!N7 -> 0 | H7: =Data!AY7 -> 792 | I7: =IF(H7>H6,ROUND((H7-H6)*I$1,1),0) -> 2.6 | K7: =I7 -> 2.6 | M7: =J7+M6 -> 0 | N7: =K7+N6 -> 2.6 | P7: =ROUND((R6+K7)/H7,3) -> 0.236 | Q7: =IF(P7>Q$1,Q$1,P7) -> 0.236 | R7: =Q7*H7 -> 186.912 | S7: =R7-R6 -> 2.682 | T7: =ROUND(K7-S7,1) -> -0.1
A8: =Data!A8 -> 45660 | B8: 3 | C8: =ROUND(Data!BB8,2) -> 1.77 | D8: =ROUND(Data!P8,1) -> -3.2 | E8: =ROUND(Data!Y8,1) -> -10.7 | F8: =Data!BH8 -> 79.6 | G8: =Data!N8 -> 0 | H8: =Data!AY8 -> 792 | I8: =IF(H8>H7,ROUND((H8-H7)*I$1,1),0) -> 0 | K8: =I8 -> 0 | M8: =J8+M7 -> 0 | N8: =K8+N7 -> 2.6 | P8: =(R7+K8)/H8 -> 0.236 | Q8: =IF(P8>Q$1,Q$1,P8) -> 0.236 | R8: =Q8*H8 -> 186.912 | S8: =R8-R7 -> 0 | T8: =ROUND(K8-S8,1) -> 0
A9: =Data!A9 -> 45661 | B9: 4 | C9: =ROUND(Data!BB9,2) -> 1.68 | D9: =ROUND(Data!P9,1) -> -0.5 | E9: =ROUND(Data!Y9,1) -> -6.5 | F9: =Data!BH9 -> 80.6 | G9: =Data!N9 -> 0 | H9: =Data!AY9 -> 770 | I9: =IF(H9>H8,ROUND((H9-H8)*I$1,1),0) -> 0 | K9: =I9 -> 0 | M9: =J9+M8 -> 0 | N9: =K9+N8 -> 2.6 | P9: =(R8+K9)/H9 -> 0.24274286 | Q9: =IF(P9>Q$1,Q$1,P9) -> 0.24274286 | R9: =Q9*H9 -> 186.912 | S9: =R9-R8 -> 0 | T9: =ROUND(K9-S9,1) -> 0
A10: =Data!A10 -> 45662 | B10: 5 | C10: =ROUND(Data!BB10,2) -> 1.81 | D10: =ROUND(Data!P10,1) -> -1.1 | E10: =ROUND(Data!Y10,1) -> -5.5 | F10: =Data!BH10 -> 84.8 | G10: =Data!N10 -> 0 | H10: =Data!AY10 -> 739 | I10: =IF(H10>H9,ROUND((H10-H9)*I$1,1),0) -> 0 | K10: =I10 -> 0 | M10: =J10+M9 -> 0 | N10: =K10+N9 -> 2.6 | P10: =(R9+K10)/H10 -> 0.25292558 | Q10: =IF(P10>Q$1,Q$1,P10) -> 0.25292558 | R10: =Q10*H10 -> 186.912 | S10: =R10-R9 -> 0 | T10: =ROUND(K10-S10,1) -> 0
A11: =Data!A11 -> 45663 | B11: 6 | C11: =ROUND(Data!BB11,2) -> 1.4 | D11: =ROUND(Data!P11,1) -> -3.7 | E11: =ROUND(Data!Y11,1) -> -7.9 | F11: =Data!BH11 -> 88.5 | G11: =Data!N11 -> 0 | H11: =Data!AY11 -> 719 | I11: =IF(H11>H10,ROUND((H11-H10)*I$1,1),0) -> 0 | K11: =I11 -> 0 | M11: =J11+M10 -> 0 | N11: =K11+N10 -> 2.6 | P11: =(R10+K11)/H11 -> 0.25996106 | Q11: =IF(P11>Q$1,Q$1,P11) -> 0.25996106 | R11: =Q11*H11 -> 186.912 | S11: =R11-R10 -> 0 | T11: =ROUND(K11-S11,1) -> 0
A12: =Data!A12 -> 45664 | B12: 7 | C12: =ROUND(Data!BB12,2) -> 1.77 | D12: =ROUND(Data!P12,1) -> -4.6 | E12: =ROUND(Data!Y12,1) -> -10.6 | F12: =Data!BH12 -> 90 | G12: =Data!N12 -> 0 | H12: =Data!AY12 -> 729 | I12: =IF(H12>H11,ROUND((H12-H11)*I$1,1),0) -> 1.3 | K12: =I12 -> 1.3 | M12: =J12+M11 -> 0 | N12: =K12+N11 -> 3.9 | P12: =(R11+K12)/H12 -> 0.25817833 | Q12: =IF(P12>Q$1,Q$1,P12) -> 0.25817833 | R12: =Q12*H12 -> 188.212 | S12: =R12-R11 -> 1.3 | T12: =ROUND(K12-S12,1) -> 0
A13: =Data!A13 -> 45665 | B13: 8 | C13: =ROUND(Data!BB13,2) -> 1.21 | D13: =ROUND(Data!P13,1) -> -2.4 | E13: =ROUND(Data!Y13,1) -> -7.7 | F13: =Data!BH13 -> 92.1 | G13: =Data!N13 -> 0 | H13: =Data!AY13 -> 731 | I13: =IF(H13>H12,ROUND((H13-H12)*I$1,1),0) -> 0.3 | K13: =I13 -> 0.3 | M13: =J13+M12 -> 0 | N13: =K13+N12 -> 4.2 | P13: =(R12+K13)/H13 -> 0.25788235 | Q13: =IF(P13>Q$1,Q$1,P13) -> 0.25788235 | R13: =Q13*H13 -> 188.512 | S13: =R13-R12 -> 0.3 | T13: =ROUND(K13-S13,1) -> 0
A14: =Data!A14 -> 45666 | B14: 9 | C14: =ROUND(Data!BB14,2) -> 2.16 | D14: =ROUND(Data!P14,1) -> -0.7 | E14: =ROUND(Data!Y14,1) -> -11.7 | F14: =Data!BH14 -> 83.6 | G14: =Data!N14 -> 0 | H14: =Data!AY14 -> 710 | I14: =IF(H14>H13,ROUND((H14-H13)*I$1,1),0) -> 0 | K14: =I14 -> 0 | M14: =J14+M13 -> 0 | N14: =K14+N13 -> 4.2 | P14: =(R13+K14)/H14 -> 0.26550986 | Q14: =IF(P14>Q$1,Q$1,P14) -> 0.26550986 | R14: =Q14*H14 -> 188.512 | S14: =R14-R13 -> 0 | T14: =ROUND(K14-S14,1) -> 0
A15: =Data!A15 -> 45667 | B15: 10 | C15: =ROUND(Data!BB15,2) -> 1.03 | D15: =ROUND(Data!P15,1) -> -3.7 | E15: =ROUND(Data!Y15,1) -> -6.7 | F15: =Data!BH15 -> 92 | G15: =Data!N15 -> 0 | H15: =Data!AY15 -> 816 | I15: =IF(H15>H14,ROUND((H15-H14)*I$1,1),0) -> 13.8 | K15: =I15 -> 13.8 | M15: =J15+M14 -> 0 | N15: =K15+N14 -> 18 | P15: =(R14+K15)/H15 -> 0.24793137 | Q15: =IF(P15>Q$1,Q$1,P15) -> 0.24793137 | R15: =Q15*H15 -> 202.312 | S15: =R15-R14 -> 13.8 | T15: =ROUND(K15-S15,1) -> 0
A16: =Data!A16 -> 45668 | B16: 11 | C16: =ROUND(Data!BB16,2) -> 0.86 | D16: =ROUND(Data!P16,1) -> -3.9 | E16: =ROUND(Data!Y16,1) -> -5.5 | F16: =Data!BH16 -> 92.3 | G16: =Data!N16 -> 0 | H16: =Data!AY16 -> 803 | I16: =IF(H16>H15,ROUND((H16-H15)*I$1,1),0) -> 0 | K16: =I16 -> 0 | M16: =J16+M15 -> 0 | N16: =K16+N15 -> 18 | P16: =(R15+K16)/H16 -> 0.25194521 | Q16: =IF(P16>Q$1,Q$1,P16) -> 0.25194521 | R16: =Q16*H16 -> 202.312 | S16: =R16-R15 -> 0 | T16: =ROUND(K16-S16,1) -> 0
A17: =Data!A17 -> 45669 | B17: 12 | C17: =ROUND(Data!BB17,2) -> 1.07 | D17: =ROUND(Data!P17,1) -> -4.2 | E17: =ROUND(Data!Y17,1) -> -8.9 | F17: =Data!BH17 -> 88.5 | G17: =Data!N17 -> 0 | H17: =Data!AY17 -> 778 | I17: =IF(H17>H16,ROUND((H17-H16)*I$1,1),0) -> 0 | K17: =I17 -> 0 | M17: =J17+M16 -> 0 | N17: =K17+N16 -> 18 | P17: =(R16+K17)/H17 -> 0.26004113 | Q17: =IF(P17>Q$1,Q$1,P17) -> 0.26004113 | R17: =Q17*H17 -> 202.312 | S17: =R17-R16 -> 0 | T17: =ROUND(K17-S17,1) -> 0
A18: =Data!A18 -> 45670 | B18: 13 | C18: =ROUND(Data!BB18,2) -> 3.15 | D18: =ROUND(Data!P18,1) -> -1.4 | E18: =ROUND(Data!Y18,1) -> -14 | F18: =Data!BH18 -> 73.2 | G18: =Data!N18 -> 0 | H18: =Data!AY18 -> 767 | I18: =IF(H18>H17,ROUND((H18-H17)*I$1,1),0) -> 0 | K18: =I18 -> 0 | M18: =J18+M17 -> 0 | N18: =K18+N17 -> 18 | P18: =(R17+K18)/H18 -> 0.26377053 | Q18: =IF(P18>Q$1,Q$1,P18) -> 0.26377053 | R18: =Q18*H18 -> 202.312 | S18: =R18-R17 -> 0 | T18: =ROUND(K18-S18,1) -> 0
A19: =Data!A19 -> 45671 | B19: 14 | C19: =ROUND(Data!BB19,2) -> 2.45 | D19: =ROUND(Data!P19,1) -> 1.2 | E19: =ROUND(Data!Y19,1) -> -11.7 | F19: =Data!BH19 -> 74.3 | G19: =Data!N19 -> 0 | H19: =Data!AY19 -> 754 | I19: =IF(H19>H18,ROUND((H19-H18)*I$1,1),0) -> 0 | K19: =I19 -> 0 | M19: =J19+M18 -> 0 | N19: =K19+N18 -> 18 | P19: =(R18+K19)/H19 -> 0.2683183 | Q19: =IF(P19>Q$1,Q$1,P19) -> 0.2683183 | R19: =Q19*H19 -> 202.312 | S19: =R19-R18 -> 0 | T19: =ROUND(K19-S19,1) -> 0
... A131: =Data!A131 -> 45783 | B131: 126 | C131: =ROUND(Data!BB131,2) -> 0 | D131: =ROUND(Data!P131,1) -> 0 | E131: =ROUND(Data!Y131,1) -> 0 | F131: =Data!BH131 -> 0 | G131: =Data!N131 -> 0 | H131: =Data!AY131 -> 0 | I131: =IF(H131>H130,ROUND((H131-H130)*I$1,1),0) -> 0 | K131: =I131 -> 0 | M131: =J131+M130 -> 0 | N131: =K131+N130 -> 103.2 | P131: =(R130+K131)/H131 -> #DIV/0! | Q131: =IF(P131>Q$1,Q$1,P131) -> #DIV/0! | R131: =Q131*H131 -> #DIV/0! | S131: =R131-R130 -> #DIV/0! | T131: =ROUND(K131-S131,1) -> #DIV/0!
A132: =Data!A132 -> 45784 | B132: 127 | C132: =ROUND(Data!BB132,2) -> 0 | D132: =ROUND(Data!P132,1) -> 0 | E132: =ROUND(Data!Y132,1) -> 0 | F132: =Data!BH132 -> 0 | G132: =Data!N132 -> 0 | H132: =Data!AY132 -> 0 | I132: =IF(H132>H131,ROUND((H132-H131)*I$1,1),0) -> 0 | K132: =G132 -> 0 | M132: =J132+M131 -> 0 | N132: =K132+N131 -> 103.2 | P132: =(R131+K132)/H132 -> #DIV/0! | Q132: =IF(P132>Q$1,Q$1,P132) -> #DIV/0! | R132: =Q132*H132 -> #DIV/0! | S132: =R132-R131 -> #DIV/0! | T132: =ROUND(K132-S132,1) -> #DIV/0!
A133: =Data!A133 -> 45785 | B133: 128 | C133: =ROUND(Data!BB133,2) -> 0 | D133: =ROUND(Data!P133,1) -> 0 | E133: =ROUND(Data!Y133,1) -> 0 | F133: =Data!BH133 -> 0 | G133: =Data!N133 -> 0 | H133: =Data!AY133 -> 0 | I133: =IF(H133>H132,ROUND((H133-H132)*I$1,1),0) -> 0 | K133: =G133 -> 0 | M133: =J133+M132 -> 0 | N133: =K133+N132 -> 103.2 | P133: =(R132+K133)/H133 -> #DIV/0! | Q133: =IF(P133>Q$1,Q$1,P133) -> #DIV/0! | R133: =Q133*H133 -> #DIV/0! | S133: =R133-R132 -> #DIV/0! | T133: =ROUND(K133-S133,1) -> #DIV/0!
A134: =Data!A134 -> 45786 | B134: 129 | C134: =ROUND(Data!BB134,2) -> 0 | D134: =ROUND(Data!P134,1) -> 0 | E134: =ROUND(Data!Y134,1) -> 0 | F134: =Data!BH134 -> 0 | G134: =Data!N134 -> 0 | H134: =Data!AY134 -> 0 | I134: =IF(H134>H133,ROUND((H134-H133)*I$1,1),0) -> 0 | K134: =G134 -> 0 | M134: =J134+M133 -> 0 | N134: =K134+N133 -> 103.2 | P134: =(R133+K134)/H134 -> #DIV/0! | Q134: =IF(P134>Q$1,Q$1,P134) -> #DIV/0! | R134: =Q134*H134 -> #DIV/0! | S134: =R134-R133 -> #DIV/0! | T134: =ROUND(K134-S134,1) -> #DIV/0!
A135: =Data!A135 -> 45787 | B135: 130 | C135: =ROUND(Data!BB135,2) -> 0 | D135: =ROUND(Data!P135,1) -> 0 | E135: =ROUND(Data!Y135,1) -> 0 | F135: =Data!BH135 -> 0 | G135: =Data!N135 -> 0 | H135: =Data!AY135 -> 0 | I135: =IF(H135>H134,ROUND((H135-H134)*I$1,1),0) -> 0 | K135: =G135 -> 0 | M135: =J135+M134 -> 0 | N135: =K135+N134 -> 103.2 | P135: =(R134+K135)/H135 -> #DIV/0! | Q135: =IF(P135>Q$1,Q$1,P135) -> #DIV/0! | R135: =Q135*H135 -> #DIV/0! | S135: =R135-R134 -> #DIV/0! | T135: =ROUND(K135-S135,1) -> #DIV/0!
A136: =Data!A136 -> 45788 | B136: 131 | C136: =ROUND(Data!BB136,2) -> 0 | D136: =ROUND(Data!P136,1) -> 0 | E136: =ROUND(Data!Y136,1) -> 0 | F136: =Data!BH136 -> 0 | G136: =Data!N136 -> 0 | H136: =Data!AY136 -> 0 | I136: =IF(H136>H135,ROUND((H136-H135)*I$1,1),0) -> 0 | K136: =G136 -> 0 | M136: =J136+M135 -> 0 | N136: =K136+N135 -> 103.2 | P136: =(R135+K136)/H136 -> #DIV/0! | Q136: =IF(P136>Q$1,Q$1,P136) -> #DIV/0! | R136: =Q136*H136 -> #DIV/0! | S136: =R136-R135 -> #DIV/0! | T136: =ROUND(K136-S136,1) -> #DIV/0!
A137: =Data!A137 -> 45789 | B137: 132 | C137: =ROUND(Data!BB137,2) -> 0 | D137: =ROUND(Data!P137,1) -> 0 | E137: =ROUND(Data!Y137,1) -> 0 | F137: =Data!BH137 -> 0 | G137: =Data!N137 -> 0 | H137: =Data!AY137 -> 0 | I137: =IF(H137>H136,ROUND((H137-H136)*I$1,1),0) -> 0 | K137: =G137 -> 0 | M137: =J137+M136 -> 0 | N137: =K137+N136 -> 103.2 | P137: =(R136+K137)/H137 -> #DIV/0! | Q137: =IF(P137>Q$1,Q$1,P137) -> #DIV/0! | R137: =Q137*H137 -> #DIV/0! | S137: =R137-R136 -> #DIV/0! | T137: =ROUND(K137-S137,1) -> #DIV/0!
A138: =Data!A138 -> 45790 | B138: 133 | C138: =ROUND(Data!BB138,2) -> 0 | D138: =ROUND(Data!P138,1) -> 0 | E138: =ROUND(Data!Y138,1) -> 0 | F138: =Data!BH138 -> 0 | G138: =Data!N138 -> 0 | H138: =Data!AY138 -> 0 | I138: =IF(H138>H137,ROUND((H138-H137)*I$1,1),0) -> 0 | K138: =G138 -> 0 | M138: =J138+M137 -> 0 | N138: =K138+N137 -> 103.2 | P138: =(R137+K138)/H138 -> #DIV/0! | Q138: =IF(P138>Q$1,Q$1,P138) -> #DIV/0! | R138: =Q138*H138 -> #DIV/0! | S138: =R138-R137 -> #DIV/0! | T138: =ROUND(K138-S138,1) -> #DIV/0!
A139: =Data!A139 -> 45791 | B139: 134 | C139: =ROUND(Data!BB139,2) -> 0 | D139: =ROUND(Data!P139,1) -> 0 | E139: =ROUND(Data!Y139,1) -> 0 | F139: =Data!BH139 -> 0 | G139: =Data!N139 -> 0 | H139: =Data!AY139 -> 0 | I139: =IF(H139>H138,ROUND((H139-H138)*I$1,1),0) -> 0 | K139: =G139 -> 0 | M139: =J139+M138 -> 0 | N139: =K139+N138 -> 103.2 | P139: =(R138+K139)/H139 -> #DIV/0! | Q139: =IF(P139>Q$1,Q$1,P139) -> #DIV/0! | R139: =Q139*H139 -> #DIV/0! | S139: =R139-R138 -> #DIV/0! | T139: =ROUND(K139-S139,1) -> #DIV/0!
A140: =Data!A140 -> 45792 | B140: 135 | C140: =ROUND(Data!BB140,2) -> 0 | D140: =ROUND(Data!P140,1) -> 0 | E140: =ROUND(Data!Y140,1) -> 0 | F140: =Data!BH140 -> 0 | G140: =Data!N140 -> 0 | H140: =Data!AY140 -> 0 | I140: =IF(H140>H139,ROUND((H140-H139)*I$1,1),0) -> 0 | K140: =G140 -> 0 | M140: =J140+M139 -> 0 | N140: =K140+N139 -> 103.2 | P140: =(R139+K140)/H140 -> #DIV/0! | Q140: =IF(P140>Q$1,Q$1,P140) -> #DIV/0! | R140: =Q140*H140 -> #DIV/0! | S140: =R140-R139 -> #DIV/0! | T140: =ROUND(K140-S140,1) -> #DIV/0!
A141: =Data!A141 -> 45793 | B141: 136 | C141: =ROUND(Data!BB141,2) -> 0 | D141: =ROUND(Data!P141,1) -> 0 | E141: =ROUND(Data!Y141,1) -> 0 | F141: =Data!BH141 -> 0 | G141: =Data!N141 -> 0 | H141: =Data!AY141 -> 0 | I141: =IF(H141>H140,ROUND((H141-H140)*I$1,1),0) -> 0 | K141: =G141 -> 0 | M141: =J141+M140 -> 0 | N141: =K141+N140 -> 103.2 | P141: 1 | Q141: =IF(P141>Q$1,Q$1,P141) -> 0.4 | R141: =Q141*H141 -> 0 | S141: =R141-R140 -> #DIV/0! | T141: =ROUND(K141-S141,1) -> #DIV/0!
A142: =Data!A142 -> 45794 | B142: 137 | C142: =ROUND(Data!BB142,2) -> 0 | D142: =ROUND(Data!P142,1) -> 0 | E142: =ROUND(Data!Y142,1) -> 0 | F142: =Data!BH142 -> 0 | G142: =Data!N142 -> 0 | H142: =Data!AY142 -> 0 | I142: =IF(H142>H141,ROUND((H142-H141)*I$1,1),0) -> 0 | K142: =G142 -> 0 | M142: =J142+M141 -> 0 | N142: =K142+N141 -> 103.2
A143: =Data!A143 -> 45795 | B143: 138 | C143: =ROUND(Data!BB143,2) -> 0 | D143: =ROUND(Data!P143,1) -> 0 | E143: =ROUND(Data!Y143,1) -> 0 | F143: =Data!BH143 -> 0 | G143: =Data!N143 -> 0 | H143: =Data!AY143 -> 0 | I143: =IF(H143>H142,ROUND((H143-H142)*I$1,1),0) -> 0 | K143: =G143 -> 0 | M143: =J143+M142 -> 0 | N143: =K143+N142 -> 103.2
A144: =Data!A144 -> 45796 | B144: 139 | C144: =ROUND(Data!BB144,2) -> 0 | D144: =ROUND(Data!P144,1) -> 0 | E144: =ROUND(Data!Y144,1) -> 0 | F144: =Data!BH144 -> 0 | G144: =Data!N144 -> 0 | H144: =Data!AY144 -> 0 | I144: =IF(H144>H143,ROUND((H144-H143)*I$1,1),0) -> 0 | K144: =G144 -> 0 | M144: =J144+M143 -> 0 | N144: =K144+N143 -> 103.2
A145: =Data!A145 -> 45797 | B145: 140 | C145: =ROUND(Data!BB145,2) -> 0 | D145: =ROUND(Data!P145,1) -> 0 | E145: =ROUND(Data!Y145,1) -> 0 | F145: =Data!BH145 -> 0 | G145: =Data!N145 -> 0 | H145: =Data!AY145 -> 0 | I145: =IF(H145>H144,ROUND((H145-H144)*I$1,1),0) -> 0 | K145: =G145 -> 0 | M145: =J145+M144 -> 0 | N145: =K145+N144 -> 103.2
A146: =Data!A146 -> 45798 | B146: 141 | C146: =ROUND(Data!BB146,2) -> 0 | D146: =ROUND(Data!P146,1) -> 0 | E146: =ROUND(Data!Y146,1) -> 0 | F146: =Data!BH146 -> 0 | G146: =Data!N146 -> 0 | H146: =Data!AY146 -> 0 | I146: =IF(H146>H145,ROUND((H146-H145)*I$1,1),0) -> 0 | K146: =G146 -> 0 | M146: =J146+M145 -> 0 | N146: =K146+N145 -> 103.2
A147: =Data!A147 -> 45799 | B147: 142 | C147: =ROUND(Data!BB147,2) -> 0 | D147: =ROUND(Data!P147,1) -> 0 | E147: =ROUND(Data!Y147,1) -> 0 | F147: =Data!BH147 -> 0 | G147: =Data!N147 -> 0 | H147: =Data!AY147 -> 0 | I147: =IF(H147>H146,ROUND((H147-H146)*I$1,1),0) -> 0 | K147: =G147 -> 0 | M147: =J147+M146 -> 0 | N147: =K147+N146 -> 103.2
A148: =Data!A148 -> 45800 | B148: 143 | C148: =ROUND(Data!BB148,2) -> 0 | D148: =ROUND(Data!P148,1) -> 0 | E148: =ROUND(Data!Y148,1) -> 0 | F148: =Data!BH148 -> 0 | G148: =Data!N148 -> 0 | H148: =Data!AY148 -> 0 | I148: =IF(H148>H147,ROUND((H148-H147)*I$1,1),0) -> 0 | K148: =G148 -> 0 | M148: =J148+M147 -> 0 | N148: =K148+N147 -> 103.2
A149: =Data!A149 -> 45801 | B149: 144 | C149: =ROUND(Data!BB149,2) -> 0 | D149: =ROUND(Data!P149,1) -> 0 | E149: =ROUND(Data!Y149,1) -> 0 | F149: =Data!BH149 -> 0 | G149: =Data!N149 -> 0 | H149: =Data!AY149 -> 0 | I149: =IF(H149>H148,ROUND((H149-H148)*I$1,1),0) -> 0 | K149: =G149 -> 0 | M149: =J149+M148 -> 0 | N149: =K149+N148 -> 103.2
A150: =Data!A150 -> 45802 | B150: 145 | C150: =ROUND(Data!BB150,2) -> 0 | D150: =ROUND(Data!P150,1) -> 0 | E150: =ROUND(Data!Y150,1) -> 0 | F150: =Data!BH150 -> 0 | G150: =Data!N150 -> 0 | H150: =Data!AY150 -> 0 | I150: =IF(H150>H149,ROUND((H150-H149)*I$1,1),0) -> 0 | K150: =G150 -> 0 | M150: =J150+M149 -> 0 | N150: =K150+N149 -> 103.2
A151: =Data!A151 -> 45803 | B151: 146 | C151: =ROUND(Data!BB151,2) -> 0 | D151: =ROUND(Data!P151,1) -> 0 | E151: =ROUND(Data!Y151,1) -> 0 | F151: =Data!BH151 -> 0 | G151: =Data!N151 -> 0 | H151: =Data!AY151 -> 0 | I151: =IF(H151>H150,ROUND((H151-H150)*I$1,1),0) -> 0 | K151: =G151 -> 0 | M151: =J151+M150 -> 0 | N151: =K151+N150 -> 103.2
...

Sheet Data
A1: Sicamous base station 2025 | G1: Empty cell indicates no data | O1: From hourly | AY1: 3.24
A2: Last edit 19/04/25 | C2: Total | D2: Total | E2: Avg. | F2: Avg. | G2: Avg. | H2: Avg. | I2: Avg. | J2: Avg. | K2: Avg. | L2: Avg. | M2: Avg. | N2: Total | O2: Dist | P2: Max. | Q2: Max. | R2: Max. | S2: Max. | T2: Max. | U2: Max. | V2: Max. | W2: Max. | X2: Max. | Y2: Min. | Z2: Min. | AA2: Min. | AB2: Min. | AC2: Min. | AD2: Min. | AE2: Min. | AF2: Min. | AG2: Wind Rose: # Scans | BB2: Corrected from hourly | BF2: 0 | BG2: 0 | BH2: 0 | BI2: vpres | BM2: Wind Rose: | BV2: Summary | CV2: Midnight
C3: Solar | D3: Reflect | E3: Ta 6m | F3: RH | G3: Ta 3m | H3: Ta 1.5m | I3: Ta 0.25m | J3: Tsoil_Duff | K3: Tsoil_0.15 | L3: Tsoil_0.5 | M3: Wind | N3: Rain | P3: Ta 6m | Q3: RH | R3: Ta 3m | S3: Ta 1.5m | T3: Ta 0.25m | U3: Tsoil_Duff | V3: Tsoil_0.15 | W3: Tsoil_0.5 | X3: Wind | Y3: Ta 6m | Z3: RH | AA3: Ta 3m | AB3: Ta 1.5m | AC3: Ta 0.25m | AD3: Tsoil_Duff | AE3: Tsoil_0.15 | AF3: Tsoil_0.5 | AO3: Distance | AP3: SR50A | AQ3: Tlogger | AR3: Tlogger | AS3: Tpanel | AT3: Tlogger | AU3: Tpanel | AV3: BATT. | AW3: ID | AX3: Comments | AY3: Snow Depth | BA3: Solarmax | BB3: Solar | BC3: Reflect | BD3: Albedo | BG3: Adjusted | BI3: TXRHn | BJ3: vpdX | BV3: Solar | BW3: Relected | BX3: Ta6Ave | BY3: Ta3Ave | BZ3: Ta15Ave | CA3: Ta025Ave | CB3: TdufAve | CC3: Ts015Ave | CD3: Ts05Ave | CE3: RH6Ave | CF3: Ta6Max | CG3: Ta3Max | CH3: Ta15Max | CI3: Ta025Max | CJ3: TdufMax | CK3: Ts015Max | CL3: Ts05Max | CM3: RH6Max | CN3: Ta6Min | CO3: Ta3Min | CP3: Ta15Min | CQ3: Ta025Min | CR3: TdufMin | CS3: Ts015Min | CT3: Ts05Min | CU3: RH6Min | CV3: SnowD | CW3: Precipitation | CX3: Wind | CY3: WindX | CZ3: Vapres | DA3: vpdX | DB3: BatV
A4: Date | B4: DoY | C4: MJ/m2/d | D4: MJ/m2/d | E4: C | F4: % | G4: C | H4: C | I4: C | J4: C | K4: C | L4: C | M4: m/s | N4: mm | O4: m | P4: C | Q4: % | R4: C | S4: C | T4: C | U4: C | V4: C | W4: C | X4: m/s | Y4: C | Z4: % | AA4: C | AB4: C | AC4: C | AD4: C | AE4: C | AF4: C | AG4: N--NE | AH4: NE--E | AI4: E--SE | AJ4: SE--S | AK4: S--SW | AL4: SW--W | AM4: W--NW | AN4: NW--N | AO4: Cts | AP4: Quality | AQ4: Avg | AR4: Max | AS4: Max | AT4: Min | AU4: Min | AV4: (V) | AY4: mm | BA4: MJ/m2/d | BB4: MJ/m2/d | BC4: MJ/m2/d | BF4: RHMax | BG4: RHAvg | BH4: RHMin | BI4: kPa | BJ4: kPa | BL4: Scans | BM4: N--NE | BN4: NE--E | BO4: E--SE | BP4: SE--S | BQ4: S--SW | BR4: SW--W | BS4: W--NW | BT4: NW--N | BV4: MJ/m2/d | BW4: MJ/m2/d | BX4: C | BY4: C | BZ4: C | CA4: C | CB4: C | CC4: C | CD4: C | CE4: % | CF4: C | CG4: C | CH4: C | CI4: C | CJ4: C | CK4: C | CL4: C | CM4: % | CN4: C | CO4: C | CP4: C | CQ4: C | CR4: C | CS4: C | CT4: C | CU4: % | CV4: mm | CW4: mm/d | CX4: m/s | CY4: m/s | CZ4: kPa | DA4: kPa | DB4: V
A6: 45658 | B6: 1 | C6: 0.365 | D6: 1.351 | E6: -8.03 | F6: 90.9 | G6: -7.74 | I6: 0.859 | J6: 0.639 | K6: 1.248 | L6: 1.816 | M6: 0 | N6: 0 | O6: 2.468 | P6: -6.033 | Q6: 94.2 | R6: -5.344 | T6: 0.94 | U6: 0.717 | V6: 1.332 | W6: 1.906 | X6: 0 | Y6: -9.29 | Z6: 85.3 | AA6: -9.1 | AC6: 0.763 | AD6: 0.563 | AE6: 1.161 | AF6: 1.736 | AG6: 324 | AH6: 660 | AI6: 437 | AJ6: 54 | AK6: 281 | AL6: 527 | AM6: 386 | AN6: 128 | AO6: 2.511 | AP6: 205 | AQ6: -3.712 | AR6: -3.385 | AS6: -3.945 | AT6: 0.005 | AU6: -0.003 | AV6: 12.86 | AW6: 2876 | AY6: =(AY$1-O6)*1000 -> 772 | BA6: 4.59 | BB6: 1.35 | BC6: 1.24 | BD6: =BC6/BB6 -> 0.91851852 | BF6: =ROUND(Q6-BF$2,1) -> 94.2 | BG6: =ROUND(F6-BG$2,1) -> 90.9 | BH6: =ROUND(Z6-BH$2,1) -> 85.3 | BI6: =ROUND((0.6105*(EXP((17.273*P6)/(P6+237.3))))*BH6/100,3) -> 0.332 | BJ6: =ROUND(BI6/BH6*(100-BH6),3) -> 0.057 | BL6: =SUM(AG6:AN6) -> 2797 | BM6: =ROUND(AG6/$BL6,3) -> 0.116 | BN6: =ROUND(AH6/$BL6,3) -> 0.236 | BO6: =ROUND(AI6/$BL6,3) -> 0.156 | BP6: =ROUND(AJ6/$BL6,3) -> 0.019 | BQ6: =ROUND(AK6/$BL6,3) -> 0.1 | BR6: =ROUND(AL6/$BL6,3) -> 0.188 | BS6: =ROUND(AM6/$BL6,3) -> 0.138 | BT6: =ROUND(AN6/$BL6,3) -> 0.046 | BV6: =BB6 -> 1.35 | BW6: =BC6 -> 1.24 | BX6: =ROUND(E6,1) -> -8 | BY6: =ROUND(G6,1) -> -7.7 | BZ6: NA | CA6: =ROUND(I6,1) -> 0.9 | CB6: =ROUND(J6,1) -> 0.6 | CC6: =ROUND(K6,1) -> 1.2 | CD6: =ROUND(L6,1) -> 1.8 | CE6: =ROUND(BG6,1) -> 90.9 | CF6: =ROUND(P6,1) -> -6 | CG6: =ROUND(R6,1) -> -5.3 | CH6: NA | CI6: =ROUND(T6,1) -> 0.9 | CJ6: =ROUND(U6,1) -> 0.7 | CK6: =ROUND(V6,1) -> 1.3 | CL6: =ROUND(W6,1) -> 1.9 | CM6: =ROUND(BF6,1) -> 94.2 | CN6: =ROUND(Y6,1) -> -9.3 | CO6: =ROUND(AA6,1) -> -9.1 | CP6: NA | CQ6: =ROUND(AC6,1) -> 0.8 | CR6: =ROUND(AD6,1) -> 0.6 | CS6: =ROUND(AE6,1) -> 1.2 | CT6: =ROUND(AF6,1) -> 1.7 | CU6: =ROUND(BH6,1) -> 85.3 | CV6: =AY6 -> 772 | CW6: =ROUND(PPTest!K6,1) -> 0 | CX6: =ROUND(M6,2) -> 0 | CY6: =ROUND(X6,2) -> 0 | CZ6: =BI6 -> 0.332 | DA6: =BJ6 -> 0.057 | DB6: =AV6 -> 12.86
A7: =A6+1 -> 45659 | B7: 2 | C7: 0.311 | D7: 1.168 | E7: -7.914 | F7: 90.6 | G7: -7.682 | I7: 0.85 | J7: 0.629 | K7: 1.234 | L7: 1.802 | M7: 0 | N7: 0 | O7: 2.448 | P7: -5.625 | Q7: 93.5 | R7: -5.119 | T7: 0.932 | U7: 0.714 | V7: 1.308 | W7: 1.894 | X7: 0 | Y7: -9.97 | Z7: 84.6 | AA7: -9.83 | AC7: 0.773 | AD7: 0.556 | AE7: 1.154 | AF7: 1.73 | AG7: 763 | AH7: 834 | AI7: 609 | AJ7: 132 | AK7: 175 | AL7: 144 | AM7: 68 | AN7: 99 | AO7: 2.48 | AP7: 272 | AQ7: -3.921 | AR7: -3.665 | AS7: -4.225 | AT7: 0.004 | AU7: -0.003 | AV7: 12.85 | AW7: 2876 | AY7: =(AY$1-O7)*1000 -> 792 | BA7: 4.63 | BB7: 1.17 | BC7: 1.07 | BD7: =BC7/BB7 -> 0.91452991 | BF7: =ROUND(Q7-BF$2,1) -> 93.5 | BG7: =ROUND(F7-BG$2,1) -> 90.6 | BH7: =ROUND(Z7-BH$2,1) -> 84.6 | BI7: =ROUND((0.6105*(EXP((17.273*P7)/(P7+237.3))))*BH7/100,3) -> 0.34 | BJ7: =ROUND(BI7/BH7*(100-BH7),3) -> 0.062 | BL7: =SUM(AG7:AN7) -> 2824 | BM7: =ROUND(AG7/$BL7,3) -> 0.27 | BN7: =ROUND(AH7/$BL7,3) -> 0.295 | BO7: =ROUND(AI7/$BL7,3) -> 0.216 | BP7: =ROUND(AJ7/$BL7,3) -> 0.047 | BQ7: =ROUND(AK7/$BL7,3) -> 0.062 | BR7: =ROUND(AL7/$BL7,3) -> 0.051 | BS7: =ROUND(AM7/$BL7,3) -> 0.024 | BT7: =ROUND(AN7/$BL7,3) -> 0.035 | BV7: =BB7 -> 1.17 | BW7: =BC7 -> 1.07 | BX7: =ROUND(E7,1) -> -7.9 | BY7: =ROUND(G7,1) -> -7.7 | BZ7: NA | CA7: =ROUND(I7,1) -> 0.9 | CB7: =ROUND(J7,1) -> 0.6 | CC7: =ROUND(K7,1) -> 1.2 | CD7: =ROUND(L7,1) -> 1.8 | CE7: =ROUND(BG7,1) -> 90.6 | CF7: =ROUND(P7,1) -> -5.6 | CG7: =ROUND(R7,1) -> -5.1 | CH7: NA | CI7: =ROUND(T7,1) -> 0.9 | CJ7: =ROUND(U7,1) -> 0.7 | CK7: =ROUND(V7,1) -> 1.3 | CL7: =ROUND(W7,1) -> 1.9 | CM7: =ROUND(BF7,1) -> 93.5 | CN7: =ROUND(Y7,1) -> -10 | CO7: =ROUND(AA7,1) -> -9.8 | CP7: NA | CQ7: =ROUND(AC7,1) -> 0.8 | CR7: =ROUND(AD7,1) -> 0.6 | CS7: =ROUND(AE7,1) -> 1.2 | CT7: =ROUND(AF7,1) -> 1.7 | CU7: =ROUND(BH7,1) -> 84.6 | CV7: =AY7 -> 792 | CW7: =ROUND(PPTest!K7,1) -> 2.6 | CX7: =ROUND(M7,2) -> 0 | CY7: =ROUND(X7,2) -> 0 | CZ7: =BI7 -> 0.34 | DA7: =BJ7 -> 0.062 | DB7: =AV7 -> 12.85
A8: =A7+1 -> 45660 | B8: 3 | C8: 0.522 | D8: 1.768 | E8: -6.298 | F8: 90.4 | G8: -6.215 | I8: 0.847 | J8: 0.624 | K8: 1.227 | L8: 1.796 | M8: 0 | N8: 0 | O8: 2.448 | P8: -3.247 | Q8: 94.4 | R8: -2.753 | T8: 0.932 | U8: 0.714 | V8: 1.312 | W8: 1.886 | X8: 0 | Y8: -10.72 | Z8: 79.62 | AA8: -11.64 | AC8: 0.775 | AD8: 0.545 | AE8: 1.154 | AF8: 1.721 | AG8: 1547 | AH8: 594 | AI8: 356 | AJ8: 175 | AK8: 29 | AL8: 21 | AM8: 29 | AN8: 106 | AO8: 2.473 | AP8: 325 | AQ8: -3.758 | AR8: -3.45 | AS8: -4.202 | AT8: 0.005 | AU8: -0.004 | AV8: 12.84 | AW8: 2876 | AY8: =(AY$1-O8)*1000 -> 792 | BA8: 4.67 | BB8: 1.77 | BC8: 1.62 | BD8: =BC8/BB8 -> 0.91525424 | BF8: =ROUND(Q8-BF$2,1) -> 94.4 | BG8: =ROUND(F8-BG$2,1) -> 90.4 | BH8: =ROUND(Z8-BH$2,1) -> 79.6 | BI8: =ROUND((0.6105*(EXP((17.273*P8)/(P8+237.3))))*BH8/100,3) -> 0.382 | BJ8: =ROUND(BI8/BH8*(100-BH8),3) -> 0.098 | BL8: =SUM(AG8:AN8) -> 2857 | BM8: =ROUND(AG8/$BL8,3) -> 0.541 | BN8: =ROUND(AH8/$BL8,3) -> 0.208 | BO8: =ROUND(AI8/$BL8,3) -> 0.125 | BP8: =ROUND(AJ8/$BL8,3) -> 0.061 | BQ8: =ROUND(AK8/$BL8,3) -> 0.01 | BR8: =ROUND(AL8/$BL8,3) -> 0.007 | BS8: =ROUND(AM8/$BL8,3) -> 0.01 | BT8: =ROUND(AN8/$BL8,3) -> 0.037 | BV8: =BB8 -> 1.77 | BW8: =BC8 -> 1.62 | BX8: =ROUND(E8,1) -> -6.3 | BY8: =ROUND(G8,1) -> -6.2 | BZ8: NA | CA8: =ROUND(I8,1) -> 0.8 | CB8: =ROUND(J8,1) -> 0.6 | CC8: =ROUND(K8,1) -> 1.2 | CD8: =ROUND(L8,1) -> 1.8 | CE8: =ROUND(BG8,1) -> 90.4 | CF8: =ROUND(P8,1) -> -3.2 | CG8: =ROUND(R8,1) -> -2.8 | CH8: NA | CI8: =ROUND(T8,1) -> 0.9 | CJ8: =ROUND(U8,1) -> 0.7 | CK8: =ROUND(V8,1) -> 1.3 | CL8: =ROUND(W8,1) -> 1.9 | CM8: =ROUND(BF8,1) -> 94.4 | CN8: =ROUND(Y8,1) -> -10.7 | CO8: =ROUND(AA8,1) -> -11.6 | CP8: NA | CQ8: =ROUND(AC8,1) -> 0.8 | CR8: =ROUND(AD8,1) -> 0.5 | CS8: =ROUND(AE8,1) -> 1.2 | CT8: =ROUND(AF8,1) -> 1.7 | CU8: =ROUND(BH8,1) -> 79.6 | CV8: =AY8 -> 792 | CW8: =ROUND(PPTest!K8,1) -> 0 | CX8: =ROUND(M8,2) -> 0 | CY8: =ROUND(X8,2) -> 0 | CZ8: =BI8 -> 0.382 | DA8: =BJ8 -> 0.098 | DB8: =AV8 -> 12.84
A9: =A8+1 -> 45661 | B9: 4 | C9: 0.514 | D9: 1.688 | E9: -4.187 | F9: 91.1 | G9: -4.063 | I9: 0.847 | J9: 0.621 | K9: 1.225 | L9: 1.792 | M9: 0 | N9: 0 | O9: 2.47 | P9: -0.462 | Q9: 95.8 | R9: 0.596 | T9: 0.92 | U9: 0.69 | V9: 1.314 | W9: 1.875 | X9: 0 | Y9: -6.508 | Z9: 80.6 | AA9: -6.504 | AC9: 0.766 | AD9: 0.541 | AE9: 1.145 | AF9: 1.717 | AG9: 1536 | AH9: 268 | AI9: 266 | AJ9: 160 | AK9: 186 | AL9: 200 | AM9: 102 | AN9: 134 | AO9: 2.491 | AP9: 216 | AQ9: -3.131 | AR9: -2.42 | AS9: -3.536 | AT9: 0.004 | AU9: -0.003 | AV9: 12.84 | AW9: 2876 | AY9: =(AY$1-O9)*1000 -> 770 | BA9: 4.72 | BB9: 1.68 | BC9: 1.55 | BD9: =BC9/BB9 -> 0.92261905 | BF9: =ROUND(Q9-BF$2,1) -> 95.8 | BG9: =ROUND(F9-BG$2,1) -> 91.1 | BH9: =ROUND(Z9-BH$2,1) -> 80.6 | BI9: =ROUND((0.6105*(EXP((17.273*P9)/(P9+237.3))))*BH9/100,3) -> 0.476 | BJ9: =ROUND(BI9/BH9*(100-BH9),3) -> 0.115 | BL9: =SUM(AG9:AN9) -> 2852 | BM9: =ROUND(AG9/$BL9,3) -> 0.539 | BN9: =ROUND(AH9/$BL9,3) -> 0.094 | BO9: =ROUND(AI9/$BL9,3) -> 0.093 | BP9: =ROUND(AJ9/$BL9,3) -> 0.056 | BQ9: =ROUND(AK9/$BL9,3) -> 0.065 | BR9: =ROUND(AL9/$BL9,3) -> 0.07 | BS9: =ROUND(AM9/$BL9,3) -> 0.036 | BT9: =ROUND(AN9/$BL9,3) -> 0.047 | BV9: =BB9 -> 1.68 | BW9: =BC9 -> 1.55 | BX9: =ROUND(E9,1) -> -4.2 | BY9: =ROUND(G9,1) -> -4.1 | BZ9: NA | CA9: =ROUND(I9,1) -> 0.8 | CB9: =ROUND(J9,1) -> 0.6 | CC9: =ROUND(K9,1) -> 1.2 | CD9: =ROUND(L9,1) -> 1.8 | CE9: =ROUND(BG9,1) -> 91.1 | CF9: =ROUND(P9,1) -> -0.5 | CG9: =ROUND(R9,1) -> 0.6 | CH9: NA | CI9: =ROUND(T9,1) -> 0.9 | CJ9: =ROUND(U9,1) -> 0.7 | CK9: =ROUND(V9,1) -> 1.3 | CL9: =ROUND(W9,1) -> 1.9 | CM9: =ROUND(BF9,1) -> 95.8 | CN9: =ROUND(Y9,1) -> -6.5 | CO9: =ROUND(AA9,1) -> -6.5 | CP9: NA | CQ9: =ROUND(AC9,1) -> 0.8 | CR9: =ROUND(AD9,1) -> 0.5 | CS9: =ROUND(AE9,1) -> 1.1 | CT9: =ROUND(AF9,1) -> 1.7 | CU9: =ROUND(BH9,1) -> 80.6 | CV9: =AY9 -> 770 | CW9: =ROUND(PPTest!K9,1) -> 0 | CX9: =ROUND(M9,2) -> 0 | CY9: =ROUND(X9,2) -> 0 | CZ9: =BI9 -> 0.476 | DA9: =BJ9 -> 0.115 | DB9: =AV9 -> 12.84
A10: =A9+1 -> 45662 | B10: 5 | C10: 0.634 | D10: 1.813 | E10: -3.955 | F10: 93.3 | G10: -3.695 | I10: 0.842 | J10: 0.617 | K10: 1.221 | L10: 1.788 | M10: 0 | N10: 0 | O10: 2.501 | P10: -1.141 | Q10: 96.1 | R10: 1.036 | T10: 0.911 | U10: 0.708 | V10: 1.303 | W10: 1.859 | X10: 0 | Y10: -5.489 | Z10: 84.8 | AA10: -5.336 | AC10: 0.769 | AD10: 0.552 | AE10: 1.132 | AF10: 1.708 | AG10: 369 | AH10: 509 | AI10: 368 | AJ10: 146 | AK10: 543 | AL10: 482 | AM10: 176 | AN10: 171 | AO10: 2.526 | AP10: 209 | AQ10: -2.692 | AR10: -2.056 | AS10: -3.15 | AT10: 0.004 | AU10: -0.003 | AV10: 12.96 | AW10: 2876 | AY10: =(AY$1-O10)*1000 -> 739 | BA10: 4.76 | BB10: 1.81 | BC10: 1.66 | BD10: =BC10/BB10 -> 0.91712707 | BF10: =ROUND(Q10-BF$2,1) -> 96.1 | BG10: =ROUND(F10-BG$2,1) -> 93.3 | BH10: =ROUND(Z10-BH$2,1) -> 84.8 | BI10: =ROUND((0.6105*(EXP((17.273*P10)/(P10+237.3))))*BH10/100,3) -> 0.476 | BJ10: =ROUND(BI10/BH10*(100-BH10),3) -> 0.085 | BL10: =SUM(AG10:AN10) -> 2764 | BM10: =ROUND(AG10/$BL10,3) -> 0.134 | BN10: =ROUND(AH10/$BL10,3) -> 0.184 | BO10: =ROUND(AI10/$BL10,3) -> 0.133 | BP10: =ROUND(AJ10/$BL10,3) -> 0.053 | BQ10: =ROUND(AK10/$BL10,3) -> 0.196 | BR10: =ROUND(AL10/$BL10,3) -> 0.174 | BS10: =ROUND(AM10/$BL10,3) -> 0.064 | BT10: =ROUND(AN10/$BL10,3) -> 0.062 | BV10: =BB10 -> 1.81 | BW10: =BC10 -> 1.66 | BX10: =ROUND(E10,1) -> -4 | BY10: =ROUND(G10,1) -> -3.7 | BZ10: NA | CA10: =ROUND(I10,1) -> 0.8 | CB10: =ROUND(J10,1) -> 0.6 | CC10: =ROUND(K10,1) -> 1.2 | CD10: =ROUND(L10,1) -> 1.8 | CE10: =ROUND(BG10,1) -> 93.3 | CF10: =ROUND(P10,1) -> -1.1 | CG10: =ROUND(R10,1) -> 1 | CH10: NA | CI10: =ROUND(T10,1) -> 0.9 | CJ10: =ROUND(U10,1) -> 0.7 | CK10: =ROUND(V10,1) -> 1.3 | CL10: =ROUND(W10,1) -> 1.9 | CM10: =ROUND(BF10,1) -> 96.1 | CN10: =ROUND(Y10,1) -> -5.5 | CO10: =ROUND(AA10,1) -> -5.3 | CP10: NA | CQ10: =ROUND(AC10,1) -> 0.8 | CR10: =ROUND(AD10,1) -> 0.6 | CS10: =ROUND(AE10,1) -> 1.1 | CT10: =ROUND(AF10,1) -> 1.7 | CU10: =ROUND(BH10,1) -> 84.8 | CV10: =AY10 -> 739 | CW10: =ROUND(PPTest!K10,1) -> 0 | CX10: =ROUND(M10,2) -> 0 | CY10: =ROUND(X10,2) -> 0 | CZ10: =BI10 -> 0.476 | DA10: =BJ10 -> 0.085 | DB10: =AV10 -> 12.96
A11: =A10+1 -> 45663 | B11: 6 | C11: 0.371 | D11: 1.403 | E11: -5.161 | F11: 93.8 | G11: -4.862 | I11: 0.833 | J11: 0.612 | K11: 1.208 | L11: 1.777 | M11: 0 | N11: 0 | O11: 2.521 | P11: -3.655 | Q11: 96.3 | R11: -3.136 | T11: 0.928 | U11: 0.687 | V11: 1.279 | W11: 1.856 | X11: 0.527 | Y11: -7.867 | Z11: 88.5 | AA11: -7.419 | AC11: 0.757 | AD11: 0.537 | AE11: 1.127 | AF11: 1.696 | AG11: 266 | AH11: 310 | AI11: 595 | AJ11: 247 | AK11: 399 | AL11: 400 | AM11: 244 | AN11: 337 | AO11: 2.558 | AP11: 221 | AQ11: -2.885 | AR11: -2.463 | AS11: -3.407 | AT11: 0.004 | AU11: -0.003 | AV11: 12.84 | AW11: 2876 | AY11: =(AY$1-O11)*1000 -> 719 | BA11: 4.82 | BB11: 1.4 | BC11: 1.29 | BD11: =BC11/BB11 -> 0.92142857 | BF11: =ROUND(Q11-BF$2,1) -> 96.3 | BG11: =ROUND(F11-BG$2,1) -> 93.8 | BH11: =ROUND(Z11-BH$2,1) -> 88.5 | BI11: =ROUND((0.6105*(EXP((17.273*P11)/(P11+237.3))))*BH11/100,3) -> 0.412 | BJ11: =ROUND(BI11/BH11*(100-BH11),3) -> 0.054 | BL11: =SUM(AG11:AN11) -> 2798 | BM11: =ROUND(AG11/$BL11,3) -> 0.095 | BN11: =ROUND(AH11/$BL11,3) -> 0.111 | BO11: =ROUND(AI11/$BL11,3) -> 0.213 | BP11: =ROUND(AJ11/$BL11,3) -> 0.088 | BQ11: =ROUND(AK11/$BL11,3) -> 0.143 | BR11: =ROUND(AL11/$BL11,3) -> 0.143 | BS11: =ROUND(AM11/$BL11,3) -> 0.087 | BT11: =ROUND(AN11/$BL11,3) -> 0.12 | BV11: =BB11 -> 1.4 | BW11: =BC11 -> 1.29 | BX11: =ROUND(E11,1) -> -5.2 | BY11: =ROUND(G11,1) -> -4.9 | BZ11: NA | CA11: =ROUND(I11,1) -> 0.8 | CB11: =ROUND(J11,1) -> 0.6 | CC11: =ROUND(K11,1) -> 1.2 | CD11: =ROUND(L11,1) -> 1.8 | CE11: =ROUND(BG11,1) -> 93.8 | CF11: =ROUND(P11,1) -> -3.7 | CG11: =ROUND(R11,1) -> -3.1 | CH11: NA | CI11: =ROUND(T11,1) -> 0.9 | CJ11: =ROUND(U11,1) -> 0.7 | CK11: =ROUND(V11,1) -> 1.3 | CL11: =ROUND(W11,1) -> 1.9 | CM11: =ROUND(BF11,1) -> 96.3 | CN11: =ROUND(Y11,1) -> -7.9 | CO11: =ROUND(AA11,1) -> -7.4 | CP11: NA | CQ11: =ROUND(AC11,1) -> 0.8 | CR11: =ROUND(AD11,1) -> 0.5 | CS11: =ROUND(AE11,1) -> 1.1 | CT11: =ROUND(AF11,1) -> 1.7 | CU11: =ROUND(BH11,1) -> 88.5 | CV11: =AY11 -> 719 | CW11: =ROUND(PPTest!K11,1) -> 0 | CX11: =ROUND(M11,2) -> 0 | CY11: =ROUND(X11,2) -> 0.53 | CZ11: =BI11 -> 0.412 | DA11: =BJ11 -> 0.054 | DB11: =AV11 -> 12.84
A12: =A11+1 -> 45664 | B12: 7 | C12: 0.678 | D12: 1.774 | E12: -7.464 | F12: 93 | G12: -7.126 | I12: 0.829 | J12: 0.611 | K12: 1.198 | L12: 1.767 | M12: 0 | N12: 0 | O12: 2.511 | P12: -4.606 | Q12: 94.8 | R12: -4.45 | T12: 0.915 | U12: 0.696 | V12: 1.277 | W12: 1.84 | X12: 0 | Y12: -10.58 | Z12: 90 | AA12: -10.37 | AC12: 0.752 | AD12: 0.537 | AE12: 1.122 | AF12: 1.675 | AG12: 361 | AH12: 663 | AI12: 669 | AJ12: 206 | AK12: 303 | AL12: 314 | AM12: 162 | AN12: 188 | AO12: 2.542 | AP12: 234 | AQ12: -4.007 | AR12: -3.407 | AS12: -4.699 | AT12: 0.005 | AU12: -0.003 | AV12: 12.83 | AW12: 2876 | AY12: =(AY$1-O12)*1000 -> 729 | BA12: 4.87 | BB12: 1.77 | BC12: 1.63 | BD12: =BC12/BB12 -> 0.92090395 | BF12: =ROUND(Q12-BF$2,1) -> 94.8 | BG12: =ROUND(F12-BG$2,1) -> 93 | BH12: =ROUND(Z12-BH$2,1) -> 90 | BI12: =ROUND((0.6105*(EXP((17.273*P12)/(P12+237.3))))*BH12/100,3) -> 0.39 | BJ12: =ROUND(BI12/BH12*(100-BH12),3) -> 0.043 | BL12: =SUM(AG12:AN12) -> 2866 | BM12: =ROUND(AG12/$BL12,3) -> 0.126 | BN12: =ROUND(AH12/$BL12,3) -> 0.231 | BO12: =ROUND(AI12/$BL12,3) -> 0.233 | BP12: =ROUND(AJ12/$BL12,3) -> 0.072 | BQ12: =ROUND(AK12/$BL12,3) -> 0.106 | BR12: =ROUND(AL12/$BL12,3) -> 0.11 | BS12: =ROUND(AM12/$BL12,3) -> 0.057 | BT12: =ROUND(AN12/$BL12,3) -> 0.066 | BV12: =BB12 -> 1.77 | BW12: =BC12 -> 1.63 | BX12: =ROUND(E12,1) -> -7.5 | BY12: =ROUND(G12,1) -> -7.1 | BZ12: NA | CA12: =ROUND(I12,1) -> 0.8 | CB12: =ROUND(J12,1) -> 0.6 | CC12: =ROUND(K12,1) -> 1.2 | CD12: =ROUND(L12,1) -> 1.8 | CE12: =ROUND(BG12,1) -> 93 | CF12: =ROUND(P12,1) -> -4.6 | CG12: =ROUND(R12,1) -> -4.5 | CH12: NA | CI12: =ROUND(T12,1) -> 0.9 | CJ12: =ROUND(U12,1) -> 0.7 | CK12: =ROUND(V12,1) -> 1.3 | CL12: =ROUND(W12,1) -> 1.8 | CM12: =ROUND(BF12,1) -> 94.8 | CN12: =ROUND(Y12,1) -> -10.6 | CO12: =ROUND(AA12,1) -> -10.4 | CP12: NA | CQ12: =ROUND(AC12,1) -> 0.8 | CR12: =ROUND(AD12,1) -> 0.5 | CS12: =ROUND(AE12,1) -> 1.1 | CT12: =ROUND(AF12,1) -> 1.7 | CU12: =ROUND(BH12,1) -> 90 | CV12: =AY12 -> 729 | CW12: =ROUND(PPTest!K12,1) -> 1.3 | CX12: =ROUND(M12,2) -> 0 | CY12: =ROUND(X12,2) -> 0 | CZ12: =BI12 -> 0.39 | DA12: =BJ12 -> 0.043 | DB12: =AV12 -> 12.83
A13: =A12+1 -> 45665 | B13: 8 | C13: 0.308 | D13: 1.213 | E13: -4.818 | F13: 94.4 | G13: -4.649 | I13: 0.825 | J13: 0.606 | K13: 1.194 | L13: 1.764 | M13: 0 | N13: 0 | O13: 2.509 | P13: -2.364 | Q13: 95.9 | R13: -2.18 | T13: 0.9 | U13: 0.69 | V13: 1.273 | W13: 1.85 | X13: 0 | Y13: -7.731 | Z13: 92.1 | AA13: -8.37 | AC13: 0.751 | AD13: 0.534 | AE13: 1.118 | AF13: 1.693 | AG13: 187 | AH13: 406 | AI13: 417 | AJ13: 293 | AK13: 427 | AL13: 472 | AM13: 330 | AN13: 314 | AO13: 2.545 | AP13: 222 | AQ13: -3.388 | AR13: -2.506 | AS13: -4.051 | AT13: 0.004 | AU13: -0.003 | AV13: 12.83 | AW13: 2876 | AY13: =(AY$1-O13)*1000 -> 731 | BA13: 4.93 | BB13: 1.21 | BC13: 1.11 | BD13: =BC13/BB13 -> 0.91735537 | BF13: =ROUND(Q13-BF$2,1) -> 95.9 | BG13: =ROUND(F13-BG$2,1) -> 94.4 | BH13: =ROUND(Z13-BH$2,1) -> 92.1 | BI13: =ROUND((0.6105*(EXP((17.273*P13)/(P13+237.3))))*BH13/100,3) -> 0.473 | BJ13: =ROUND(BI13/BH13*(100-BH13),3) -> 0.041 | BL13: =SUM(AG13:AN13) -> 2846 | BM13: =ROUND(AG13/$BL13,3) -> 0.066 | BN13: =ROUND(AH13/$BL13,3) -> 0.143 | BO13: =ROUND(AI13/$BL13,3) -> 0.147 | BP13: =ROUND(AJ13/$BL13,3) -> 0.103 | BQ13: =ROUND(AK13/$BL13,3) -> 0.15 | BR13: =ROUND(AL13/$BL13,3) -> 0.166 | BS13: =ROUND(AM13/$BL13,3) -> 0.116 | BT13: =ROUND(AN13/$BL13,3) -> 0.11 | BV13: =BB13 -> 1.21 | BW13: =BC13 -> 1.11 | BX13: =ROUND(E13,1) -> -4.8 | BY13: =ROUND(G13,1) -> -4.6 | BZ13: NA | CA13: =ROUND(I13,1) -> 0.8 | CB13: =ROUND(J13,1) -> 0.6 | CC13: =ROUND(K13,1) -> 1.2 | CD13: =ROUND(L13,1) -> 1.8 | CE13: =ROUND(BG13,1) -> 94.4 | CF13: =ROUND(P13,1) -> -2.4 | CG13: =ROUND(R13,1) -> -2.2 | CH13: NA | CI13: =ROUND(T13,1) -> 0.9 | CJ13: =ROUND(U13,1) -> 0.7 | CK13: =ROUND(V13,1) -> 1.3 | CL13: =ROUND(W13,1) -> 1.9 | CM13: =ROUND(BF13,1) -> 95.9 | CN13: =ROUND(Y13,1) -> -7.7 | CO13: =ROUND(AA13,1) -> -8.4 | CP13: NA | CQ13: =ROUND(AC13,1) -> 0.8 | CR13: =ROUND(AD13,1) -> 0.5 | CS13: =ROUND(AE13,1) -> 1.1 | CT13: =ROUND(AF13,1) -> 1.7 | CU13: =ROUND(BH13,1) -> 92.1 | CV13: =AY13 -> 731 | CW13: =ROUND(PPTest!K13,1) -> 0.3 | CX13: =ROUND(M13,2) -> 0 | CY13: =ROUND(X13,2) -> 0 | CZ13: =BI13 -> 0.473 | DA13: =BJ13 -> 0.041 | DB13: =AV13 -> 12.83
A14: =A13+1 -> 45666 | B14: 9 | C14: 0.891 | D14: 2.162 | E14: -6.361 | F14: 91.5 | G14: -6.347 | I14: 0.824 | J14: 0.608 | K14: 1.19 | L14: 1.761 | M14: 0 | N14: 0 | O14: 2.53 | P14: -0.734 | Q14: 95.4 | R14: -1.021 | T14: 0.906 | U14: 0.696 | V14: 1.273 | W14: 1.848 | X14: 0.5 | Y14: -11.67 | Z14: 83.6 | AA14: -12.43 | AC14: 0.744 | AD14: 0.528 | AE14: 1.109 | AF14: 1.683 | AG14: 258 | AH14: 905 | AI14: 877 | AJ14: 105 | AK14: 233 | AL14: 275 | AM14: 141 | AN14: 76 | AO14: 0 | AP14: 0 | AQ14: -4 | AR14: -3.021 | AS14: -5.07 | AT14: 0.005 | AU14: -0.003 | AV14: 13.06 | AW14: 2876 | AY14: =(AY$1-O14)*1000 -> 710 | BA14: 4.99 | BB14: 2.16 | BC14: 1.99 | BD14: =BC14/BB14 -> 0.9212963 | BF14: =ROUND(Q14-BF$2,1) -> 95.4 | BG14: =ROUND(F14-BG$2,1) -> 91.5 | BH14: =ROUND(Z14-BH$2,1) -> 83.6 | BI14: =ROUND((0.6105*(EXP((17.273*P14)/(P14+237.3))))*BH14/100,3) -> 0.484 | BJ14: =ROUND(BI14/BH14*(100-BH14),3) -> 0.095 | BL14: =SUM(AG14:AN14) -> 2870 | BM14: =ROUND(AG14/$BL14,3) -> 0.09 | BN14: =ROUND(AH14/$BL14,3) -> 0.315 | BO14: =ROUND(AI14/$BL14,3) -> 0.306 | BP14: =ROUND(AJ14/$BL14,3) -> 0.037 | BQ14: =ROUND(AK14/$BL14,3) -> 0.081 | BR14: =ROUND(AL14/$BL14,3) -> 0.096 | BS14: =ROUND(AM14/$BL14,3) -> 0.049 | BT14: =ROUND(AN14/$BL14,3) -> 0.026 | BV14: =BB14 -> 2.16 | BW14: =BC14 -> 1.99 | BX14: =ROUND(E14,1) -> -6.4 | BY14: =ROUND(G14,1) -> -6.3 | BZ14: NA | CA14: =ROUND(I14,1) -> 0.8 | CB14: =ROUND(J14,1) -> 0.6 | CC14: =ROUND(K14,1) -> 1.2 | CD14: =ROUND(L14,1) -> 1.8 | CE14: =ROUND(BG14,1) -> 91.5 | CF14: =ROUND(P14,1) -> -0.7 | CG14: =ROUND(R14,1) -> -1 | CH14: NA | CI14: =ROUND(T14,1) -> 0.9 | CJ14: =ROUND(U14,1) -> 0.7 | CK14: =ROUND(V14,1) -> 1.3 | CL14: =ROUND(W14,1) -> 1.8 | CM14: =ROUND(BF14,1) -> 95.4 | CN14: =ROUND(Y14,1) -> -11.7 | CO14: =ROUND(AA14,1) -> -12.4 | CP14: NA | CQ14: =ROUND(AC14,1) -> 0.7 | CR14: =ROUND(AD14,1) -> 0.5 | CS14: =ROUND(AE14,1) -> 1.1 | CT14: =ROUND(AF14,1) -> 1.7 | CU14: =ROUND(BH14,1) -> 83.6 | CV14: =AY14 -> 710 | CW14: =ROUND(PPTest!K14,1) -> 0 | CX14: =ROUND(M14,2) -> 0 | CY14: =ROUND(X14,2) -> 0.5 | CZ14: =BI14 -> 0.484 | DA14: =BJ14 -> 0.095 | DB14: =AV14 -> 13.06
A15: =A14+1 -> 45667 | B15: 10 | C15: 0.262 | D15: 1.027 | E15: -4.967 | F15: 94.3 | G15: -4.587 | I15: 0.813 | J15: 0.596 | K15: 1.177 | L15: 1.749 | M15: 0.003 | N15: 0 | O15: 2.424 | P15: -3.723 | Q15: 96.1 | R15: -3.184 | T15: 0.882 | U15: 0.677 | V15: 1.259 | W15: 1.815 | X15: 0.58 | Y15: -6.712 | Z15: 92 | AA15: -6.274 | AC15: 0.721 | AD15: 0.521 | AE15: 1.095 | AF15: 1.666 | AG15: 53 | AH15: 53 | AI15: 43 | AJ15: 28 | AK15: 172 | AL15: 2048 | AM15: 381 | AN15: 53 | AO15: 2.442 | AP15: 276 | AQ15: -3.465 | AR15: -3.021 | AS15: -3.988 | AT15: 0.005 | AU15: -0.004 | AV15: 12.83 | AW15: 2876 | AY15: =(AY$1-O15)*1000 -> 816 | BA15: 5.06 | BB15: 1.03 | BC15: 0.94 | BD15: =BC15/BB15 -> 0.91262136 | BF15: =ROUND(Q15-BF$2,1) -> 96.1 | BG15: =ROUND(F15-BG$2,1) -> 94.3 | BH15: =ROUND(Z15-BH$2,1) -> 92 | BI15: =ROUND((0.6105*(EXP((17.273*P15)/(P15+237.3))))*BH15/100,3) -> 0.426 | BJ15: =ROUND(BI15/BH15*(100-BH15),3) -> 0.037 | BL15: =SUM(AG15:AN15) -> 2831 | BM15: =ROUND(AG15/$BL15,3) -> 0.019 | BN15: =ROUND(AH15/$BL15,3) -> 0.019 | BO15: =ROUND(AI15/$BL15,3) -> 0.015 | BP15: =ROUND(AJ15/$BL15,3) -> 0.01 | BQ15: =ROUND(AK15/$BL15,3) -> 0.061 | BR15: =ROUND(AL15/$BL15,3) -> 0.723 | BS15: =ROUND(AM15/$BL15,3) -> 0.135 | BT15: =ROUND(AN15/$BL15,3) -> 0.019 | BV15: =BB15 -> 1.03 | BW15: =BC15 -> 0.94 | BX15: =ROUND(E15,1) -> -5 | BY15: =ROUND(G15,1) -> -4.6 | BZ15: NA | CA15: =ROUND(I15,1) -> 0.8 | CB15: =ROUND(J15,1) -> 0.6 | CC15: =ROUND(K15,1) -> 1.2 | CD15: =ROUND(L15,1) -> 1.7 | CE15: =ROUND(BG15,1) -> 94.3 | CF15: =ROUND(P15,1) -> -3.7 | CG15: =ROUND(R15,1) -> -3.2 | CH15: NA | CI15: =ROUND(T15,1) -> 0.9 | CJ15: =ROUND(U15,1) -> 0.7 | CK15: =ROUND(V15,1) -> 1.3 | CL15: =ROUND(W15,1) -> 1.8 | CM15: =ROUND(BF15,1) -> 96.1 | CN15: =ROUND(Y15,1) -> -6.7 | CO15: =ROUND(AA15,1) -> -6.3 | CP15: NA | CQ15: =ROUND(AC15,1) -> 0.7 | CR15: =ROUND(AD15,1) -> 0.5 | CS15: =ROUND(AE15,1) -> 1.1 | CT15: =ROUND(AF15,1) -> 1.7 | CU15: =ROUND(BH15,1) -> 92 | CV15: =AY15 -> 816 | CW15: =ROUND(PPTest!K15,1) -> 13.8 | CX15: =ROUND(M15,2) -> 0 | CY15: =ROUND(X15,2) -> 0.58 | CZ15: =BI15 -> 0.426 | DA15: =BJ15 -> 0.037 | DB15: =AV15 -> 12.83
A16: =A15+1 -> 45668 | B16: 11 | C16: 0.225 | D16: 0.861 | E16: -4.432 | F16: 94.3 | G16: -4.09 | I16: 0.808 | J16: 0.591 | K16: 1.174 | L16: 1.746 | M16: 0.004 | N16: 0 | O16: 2.437 | P16: -3.859 | Q16: 95.2 | R16: -3.181 | T16: 0.887 | U16: 0.671 | V16: 1.246 | W16: 1.818 | X16: 0.58 | Y16: -5.489 | Z16: 92.3 | AA16: -5.226 | AC16: 0.726 | AD16: 0.51 | AE16: 1.089 | AF16: 1.668 | AG16: 14 | AH16: 13 | AI16: 14 | AJ16: 50 | AK16: 241 | AL16: 1768 | AM16: 276 | AN16: 59 | AO16: 2.462 | AP16: 195 | AQ16: -2.904 | AR16: -2.677 | AS16: -3.107 | AT16: 0.005 | AU16: -0.003 | AV16: 12.82 | AW16: 2876 | AY16: =(AY$1-O16)*1000 -> 803 | BA16: 5.13 | BB16: 0.86 | BC16: 0.79 | BD16: =BC16/BB16 -> 0.91860465 | BF16: =ROUND(Q16-BF$2,1) -> 95.2 | BG16: =ROUND(F16-BG$2,1) -> 94.3 | BH16: =ROUND(Z16-BH$2,1) -> 92.3 | BI16: =ROUND((0.6105*(EXP((17.273*P16)/(P16+237.3))))*BH16/100,3) -> 0.424 | BJ16: =ROUND(BI16/BH16*(100-BH16),3) -> 0.035 | BL16: =SUM(AG16:AN16) -> 2435 | BM16: =ROUND(AG16/$BL16,3) -> 0.006 | BN16: =ROUND(AH16/$BL16,3) -> 0.005 | BO16: =ROUND(AI16/$BL16,3) -> 0.006 | BP16: =ROUND(AJ16/$BL16,3) -> 0.021 | BQ16: =ROUND(AK16/$BL16,3) -> 0.099 | BR16: =ROUND(AL16/$BL16,3) -> 0.726 | BS16: =ROUND(AM16/$BL16,3) -> 0.113 | BT16: =ROUND(AN16/$BL16,3) -> 0.024 | BV16: =BB16 -> 0.86 | BW16: =BC16 -> 0.79 | BX16: =ROUND(E16,1) -> -4.4 | BY16: =ROUND(G16,1) -> -4.1 | BZ16: NA | CA16: =ROUND(I16,1) -> 0.8 | CB16: =ROUND(J16,1) -> 0.6 | CC16: =ROUND(K16,1) -> 1.2 | CD16: =ROUND(L16,1) -> 1.7 | CE16: =ROUND(BG16,1) -> 94.3 | CF16: =ROUND(P16,1) -> -3.9 | CG16: =ROUND(R16,1) -> -3.2 | CH16: NA | CI16: =ROUND(T16,1) -> 0.9 | CJ16: =ROUND(U16,1) -> 0.7 | CK16: =ROUND(V16,1) -> 1.2 | CL16: =ROUND(W16,1) -> 1.8 | CM16: =ROUND(BF16,1) -> 95.2 | CN16: =ROUND(Y16,1) -> -5.5 | CO16: =ROUND(AA16,1) -> -5.2 | CP16: NA | CQ16: =ROUND(AC16,1) -> 0.7 | CR16: =ROUND(AD16,1) -> 0.5 | CS16: =ROUND(AE16,1) -> 1.1 | CT16: =ROUND(AF16,1) -> 1.7 | CU16: =ROUND(BH16,1) -> 92.3 | CV16: =AY16 -> 803 | CW16: =ROUND(PPTest!K16,1) -> 0 | CX16: =ROUND(M16,2) -> 0 | CY16: =ROUND(X16,2) -> 0.58 | CZ16: =BI16 -> 0.424 | DA16: =BJ16 -> 0.035 | DB16: =AV16 -> 12.82
A17: =A16+1 -> 45669 | B17: 12 | C17: 0.283 | D17: 1.071 | E17: -5.536 | F17: 93.3 | G17: -5.294 | I17: 0.805 | J17: 0.589 | K17: 1.168 | L17: 1.739 | M17: 0 | N17: 0 | O17: 2.462 | P17: -4.198 | Q17: 95 | R17: -3.973 | T17: 0.886 | U17: 0.67 | V17: 1.237 | W17: 1.814 | X17: 0 | Y17: -8.89 | Z17: 88.5 | AA17: -9.61 | AC17: 0.718 | AD17: 0.517 | AE17: 1.097 | AF17: 1.667 | AG17: 13 | AH17: 9 | AI17: 6 | AJ17: 21 | AK17: 133 | AL17: 2338 | AM17: 73 | AN17: 23 | AO17: 2.503 | AP17: 195 | AQ17: -2.844 | AR17: -2.677 | AS17: -2.978 | AT17: 0.004 | AU17: -0.004 | AV17: 12.82 | AW17: 2876 | AY17: =(AY$1-O17)*1000 -> 778 | BA17: 5.2 | BB17: 1.07 | BC17: 0.98 | BD17: =BC17/BB17 -> 0.91588785 | BF17: =ROUND(Q17-BF$2,1) -> 95 | BG17: =ROUND(F17-BG$2,1) -> 93.3 | BH17: =ROUND(Z17-BH$2,1) -> 88.5 | BI17: =ROUND((0.6105*(EXP((17.273*P17)/(P17+237.3))))*BH17/100,3) -> 0.396 | BJ17: =ROUND(BI17/BH17*(100-BH17),3) -> 0.051 | BL17: =SUM(AG17:AN17) -> 2616 | BM17: =ROUND(AG17/$BL17,3) -> 0.005 | BN17: =ROUND(AH17/$BL17,3) -> 0.003 | BO17: =ROUND(AI17/$BL17,3) -> 0.002 | BP17: =ROUND(AJ17/$BL17,3) -> 0.008 | BQ17: =ROUND(AK17/$BL17,3) -> 0.051 | BR17: =ROUND(AL17/$BL17,3) -> 0.894 | BS17: =ROUND(AM17/$BL17,3) -> 0.028 | BT17: =ROUND(AN17/$BL17,3) -> 0.009 | BV17: =BB17 -> 1.07 | BW17: =BC17 -> 0.98 | BX17: =ROUND(E17,1) -> -5.5 | BY17: =ROUND(G17,1) -> -5.3 | BZ17: NA | CA17: =ROUND(I17,1) -> 0.8 | CB17: =ROUND(J17,1) -> 0.6 | CC17: =ROUND(K17,1) -> 1.2 | CD17: =ROUND(L17,1) -> 1.7 | CE17: =ROUND(BG17,1) -> 93.3 | CF17: =ROUND(P17,1) -> -4.2 | CG17: =ROUND(R17,1) -> -4 | CH17: NA | CI17: =ROUND(T17,1) -> 0.9 | CJ17: =ROUND(U17,1) -> 0.7 | CK17: =ROUND(V17,1) -> 1.2 | CL17: =ROUND(W17,1) -> 1.8 | CM17: =ROUND(BF17,1) -> 95 | CN17: =ROUND(Y17,1) -> -8.9 | CO17: =ROUND(AA17,1) -> -9.6 | CP17: NA | CQ17: =ROUND(AC17,1) -> 0.7 | CR17: =ROUND(AD17,1) -> 0.5 | CS17: =ROUND(AE17,1) -> 1.1 | CT17: =ROUND(AF17,1) -> 1.7 | CU17: =ROUND(BH17,1) -> 88.5 | CV17: =AY17 -> 778 | CW17: =ROUND(PPTest!K17,1) -> 0 | CX17: =ROUND(M17,2) -> 0 | CY17: =ROUND(X17,2) -> 0 | CZ17: =BI17 -> 0.396 | DA17: =BJ17 -> 0.051 | DB17: =AV17 -> 12.82
A18: =A17+1 -> 45670 | B18: 13 | C18: 2.553 | D18: 2.195 | E18: -10.07 | F18: 88.1 | G18: -10.15 | I18: 0.809 | J18: 0.597 | K18: 1.169 | L18: 1.74 | M18: 0 | N18: 0 | O18: 2.473 | P18: -1.413 | Q18: 92.7 | R18: 1.581 | T18: 0.884 | U18: 0.67 | V18: 1.259 | W18: 1.819 | X18: 0 | Y18: -13.98 | Z18: 73.23 | AA18: -14.27 | AC18: 0.729 | AD18: 0.521 | AE18: 1.085 | AF18: 1.667 | AG18: 51 | AH18: 228 | AI18: 176 | AJ18: 81 | AK18: 123 | AL18: 1420 | AM18: 58 | AN18: 28 | AO18: 2.525 | AP18: 183 | AQ18: -3.278 | AR18: -2.549 | AS18: -3.816 | AT18: 0.005 | AU18: -0.003 | AV18: 13.16 | AW18: 2876 | AY18: =(AY$1-O18)*1000 -> 767 | BA18: 5.27 | BB18: 3.15 | BC18: 2.02 | BD18: =BC18/BB18 -> 0.64126984 | BF18: =ROUND(Q18-BF$2,1) -> 92.7 | BG18: =ROUND(F18-BG$2,1) -> 88.1 | BH18: =ROUND(Z18-BH$2,1) -> 73.2 | BI18: =ROUND((0.6105*(EXP((17.273*P18)/(P18+237.3))))*BH18/100,3) -> 0.403 | BJ18: =ROUND(BI18/BH18*(100-BH18),3) -> 0.148 | BL18: =SUM(AG18:AN18) -> 2165 | BM18: =ROUND(AG18/$BL18,3) -> 0.024 | BN18: =ROUND(AH18/$BL18,3) -> 0.105 | BO18: =ROUND(AI18/$BL18,3) -> 0.081 | BP18: =ROUND(AJ18/$BL18,3) -> 0.037 | BQ18: =ROUND(AK18/$BL18,3) -> 0.057 | BR18: =ROUND(AL18/$BL18,3) -> 0.656 | BS18: =ROUND(AM18/$BL18,3) -> 0.027 | BT18: =ROUND(AN18/$BL18,3) -> 0.013 | BV18: =BB18 -> 3.15 | BW18: =BC18 -> 2.02 | BX18: =ROUND(E18,1) -> -10.1 | BY18: =ROUND(G18,1) -> -10.2 | BZ18: NA | CA18: =ROUND(I18,1) -> 0.8 | CB18: =ROUND(J18,1) -> 0.6 | CC18: =ROUND(K18,1) -> 1.2 | CD18: =ROUND(L18,1) -> 1.7 | CE18: =ROUND(BG18,1) -> 88.1 | CF18: =ROUND(P18,1) -> -1.4 | CG18: =ROUND(R18,1) -> 1.6 | CH18: NA | CI18: =ROUND(T18,1) -> 0.9 | CJ18: =ROUND(U18,1) -> 0.7 | CK18: =ROUND(V18,1) -> 1.3 | CL18: =ROUND(W18,1) -> 1.8 | CM18: =ROUND(BF18,1) -> 92.7 | CN18: =ROUND(Y18,1) -> -14 | CO18: =ROUND(AA18,1) -> -14.3 | CP18: NA | CQ18: =ROUND(AC18,1) -> 0.7 | CR18: =ROUND(AD18,1) -> 0.5 | CS18: =ROUND(AE18,1) -> 1.1 | CT18: =ROUND(AF18,1) -> 1.7 | CU18: =ROUND(BH18,1) -> 73.2 | CV18: =AY18 -> 767 | CW18: =ROUND(PPTest!K18,1) -> 0 | CX18: =ROUND(M18,2) -> 0 | CY18: =ROUND(X18,2) -> 0 | CZ18: =BI18 -> 0.403 | DA18: =BJ18 -> 0.148 | DB18: =AV18 -> 13.16
... A62: =A61+1 -> 45714 | B62: 57 | C62: 8.3 | D62: 5.687 | E62: -1.65 | F62: 81.2 | G62: -1.422 | I62: 0.675 | J62: 0.197 | K62: 0.804 | L62: 1.457 | M62: 0.013 | N62: 0.254 | O62: 2.247 | P62: 4.414 | Q62: 96.3 | R62: 7.266 | T62: 0.755 | U62: 0.28 | V62: 0.889 | W62: 1.536 | X62: 3.834 | Y62: -8.08 | Z62: 51.21 | AA62: -8.42 | AC62: 0.59 | AD62: 0.116 | AE62: 0.712 | AF62: 1.381 | AG62: 371 | AH62: 779 | AI62: 656 | AJ62: 263 | AK62: 209 | AL62: 225 | AM62: 157 | AN62: 201 | AO62: 2.247 | AP62: 214 | AQ62: -0.393 | AR62: -0.287 | AS62: -0.5 | AT62: 0.005 | AU62: -0.003 | AV62: 13.15 | AW62: 2876 | AY62: =(AY$1-O62)*1000 -> 993 | BA62: 12.27 | BB62: 8.3 | BC62: 5.22 | BD62: =BC62/BB62 -> 0.62891566 | BF62: =ROUND(Q62-BF$2,1) -> 96.3 | BG62: =ROUND(F62-BG$2,1) -> 81.2 | BH62: =ROUND(Z62-BH$2,1) -> 51.2 | BI62: =ROUND((0.6105*(EXP((17.273*P62)/(P62+237.3))))*BH62/100,3) -> 0.428 | BJ62: =ROUND(BI62/BH62*(100-BH62),3) -> 0.408 | BL62: =SUM(AG62:AN62) -> 2861 | BM62: =ROUND(AG62/$BL62,3) -> 0.13 | BN62: =ROUND(AH62/$BL62,3) -> 0.272 | BO62: =ROUND(AI62/$BL62,3) -> 0.229 | BP62: =ROUND(AJ62/$BL62,3) -> 0.092 | BQ62: =ROUND(AK62/$BL62,3) -> 0.073 | BR62: =ROUND(AL62/$BL62,3) -> 0.079 | BS62: =ROUND(AM62/$BL62,3) -> 0.055 | BT62: =ROUND(AN62/$BL62,3) -> 0.07 | BV62: =BB62 -> 8.3 | BW62: =BC62 -> 5.22 | BX62: =ROUND(E62,1) -> -1.7 | BY62: =ROUND(G62,1) -> -1.4 | BZ62: NA | CA62: =ROUND(I62,1) -> 0.7 | CB62: =ROUND(J62,1) -> 0.2 | CC62: =ROUND(K62,1) -> 0.8 | CD62: =ROUND(L62,1) -> 1.5 | CE62: =ROUND(BG62,1) -> 81.2 | CF62: =ROUND(P62,1) -> 4.4 | CG62: =ROUND(R62,1) -> 7.3 | CH62: NA | CI62: =ROUND(T62,1) -> 0.8 | CJ62: =ROUND(U62,1) -> 0.3 | CK62: =ROUND(V62,1) -> 0.9 | CL62: =ROUND(W62,1) -> 1.5 | CM62: =ROUND(BF62,1) -> 96.3 | CN62: =ROUND(Y62,1) -> -8.1 | CO62: =ROUND(AA62,1) -> -8.4 | CP62: NA | CQ62: =ROUND(AC62,1) -> 0.6 | CR62: =ROUND(AD62,1) -> 0.1 | CS62: =ROUND(AE62,1) -> 0.7 | CT62: =ROUND(AF62,1) -> 1.4 | CU62: =ROUND(BH62,1) -> 51.2 | CV62: =AY62 -> 993 | CW62: =ROUND(PPTest!K62,1) -> 0 | CX62: =ROUND(M62,2) -> 0.01 | CY62: =ROUND(X62,2) -> 3.83 | CZ62: =BI62 -> 0.428 | DA62: =BJ62 -> 0.408 | DB62: =AV62 -> 13.15
A63: =A62+1 -> 45715 | B63: 58 | BA63: 12.51 | BD63: =BC63/BB63 -> #DIV/0! | BF63: =ROUND(Q63-BF$2,1) -> 0 | BG63: =ROUND(F63-BG$2,1) -> 0 | BH63: =ROUND(Z63-BH$2,1) -> 0 | BI63: =ROUND((0.6105*(EXP((17.273*P63)/(P63+237.3))))*BH63/100,3) -> 0 | BJ63: =ROUND(BI63/BH63*(100-BH63),3) -> #DIV/0! | BL63: =SUM(AG63:AN63) -> 0 | BM63: =ROUND(AG63/$BL63,3) -> #DIV/0! | BN63: =ROUND(AH63/$BL63,3) -> #DIV/0! | BO63: =ROUND(AI63/$BL63,3) -> #DIV/0! | BP63: =ROUND(AJ63/$BL63,3) -> #DIV/0! | BQ63: =ROUND(AK63/$BL63,3) -> #DIV/0! | BR63: =ROUND(AL63/$BL63,3) -> #DIV/0! | BS63: =ROUND(AM63/$BL63,3) -> #DIV/0! | BT63: =ROUND(AN63/$BL63,3) -> #DIV/0! | BV63: =BB63 -> 0 | BW63: =BC63 -> 0 | BX63: =ROUND(E63,1) -> 0 | BY63: =ROUND(G63,1) -> 0 | BZ63: NA | CA63: =ROUND(I63,1) -> 0 | CB63: =ROUND(J63,1) -> 0 | CC63: =ROUND(K63,1) -> 0 | CD63: =ROUND(L63,1) -> 0 | CE63: =ROUND(BG63,1) -> 0 | CF63: =ROUND(P63,1) -> 0 | CG63: =ROUND(R63,1) -> 0 | CH63: NA | CI63: =ROUND(T63,1) -> 0 | CJ63: =ROUND(U63,1) -> 0 | CK63: =ROUND(V63,1) -> 0 | CL63: =ROUND(W63,1) -> 0 | CM63: =ROUND(BF63,1) -> 0 | CN63: =ROUND(Y63,1) -> 0 | CO63: =ROUND(AA63,1) -> 0 | CP63: NA | CQ63: =ROUND(AC63,1) -> 0 | CR63: =ROUND(AD63,1) -> 0 | CS63: =ROUND(AE63,1) -> 0 | CT63: =ROUND(AF63,1) -> 0 | CU63: =ROUND(BH63,1) -> 0 | CV63: =AY63 -> 0 | CW63: =ROUND(PPTest!K63,1) -> 0 | CX63: =ROUND(M63,2) -> 0 | CY63: =ROUND(X63,2) -> 0 | CZ63: =BI63 -> 0 | DA63: =BJ63 -> #DIV/0! | DB63: =AV63 -> 0
A64: =A63+1 -> 45716 | B64: 59 | BA64: 12.75 | BD64: =BC64/BB64 -> #DIV/0! | BF64: =ROUND(Q64-BF$2,1) -> 0 | BG64: =ROUND(F64-BG$2,1) -> 0 | BH64: =ROUND(Z64-BH$2,1) -> 0 | BI64: =ROUND((0.6105*(EXP((17.273*P64)/(P64+237.3))))*BH64/100,3) -> 0 | BJ64: =ROUND(BI64/BH64*(100-BH64),3) -> #DIV/0! | BL64: =SUM(AG64:AN64) -> 0 | BM64: =ROUND(AG64/$BL64,3) -> #DIV/0! | BN64: =ROUND(AH64/$BL64,3) -> #DIV/0! | BO64: =ROUND(AI64/$BL64,3) -> #DIV/0! | BP64: =ROUND(AJ64/$BL64,3) -> #DIV/0! | BQ64: =ROUND(AK64/$BL64,3) -> #DIV/0! | BR64: =ROUND(AL64/$BL64,3) -> #DIV/0! | BS64: =ROUND(AM64/$BL64,3) -> #DIV/0! | BT64: =ROUND(AN64/$BL64,3) -> #DIV/0! | BV64: =BB64 -> 0 | BW64: =BC64 -> 0 | BX64: =ROUND(E64,1) -> 0 | BY64: =ROUND(G64,1) -> 0 | BZ64: NA | CA64: =ROUND(I64,1) -> 0 | CB64: =ROUND(J64,1) -> 0 | CC64: =ROUND(K64,1) -> 0 | CD64: =ROUND(L64,1) -> 0 | CE64: =ROUND(BG64,1) -> 0 | CF64: =ROUND(P64,1) -> 0 | CG64: =ROUND(R64,1) -> 0 | CH64: NA | CI64: =ROUND(T64,1) -> 0 | CJ64: =ROUND(U64,1) -> 0 | CK64: =ROUND(V64,1) -> 0 | CL64: =ROUND(W64,1) -> 0 | CM64: =ROUND(BF64,1) -> 0 | CN64: =ROUND(Y64,1) -> 0 | CO64: =ROUND(AA64,1) -> 0 | CP64: NA | CQ64: =ROUND(AC64,1) -> 0 | CR64: =ROUND(AD64,1) -> 0 | CS64: =ROUND(AE64,1) -> 0 | CT64: =ROUND(AF64,1) -> 0 | CU64: =ROUND(BH64,1) -> 0 | CV64: =AY64 -> 0 | CW64: =ROUND(PPTest!K64,1) -> 0 | CX64: =ROUND(M64,2) -> 0 | CY64: =ROUND(X64,2) -> 0 | CZ64: =BI64 -> 0 | DA64: =BJ64 -> #DIV/0! | DB64: =AV64 -> 0
A65: =A64+1 -> 45717 | B65: 60 | BA65: 12.98 | BD65: =BC65/BB65 -> #DIV/0! | BF65: =ROUND(Q65-BF$2,1) -> 0 | BG65: =ROUND(F65-BG$2,1) -> 0 | BH65: =ROUND(Z65-BH$2,1) -> 0 | BI65: =ROUND((0.6105*(EXP((17.273*P65)/(P65+237.3))))*BH65/100,3) -> 0 | BJ65: =ROUND(BI65/BH65*(100-BH65),3) -> #DIV/0! | BL65: =SUM(AG65:AN65) -> 0 | BM65: =ROUND(AG65/$BL65,3) -> #DIV/0! | BN65: =ROUND(AH65/$BL65,3) -> #DIV/0! | BO65: =ROUND(AI65/$BL65,3) -> #DIV/0! | BP65: =ROUND(AJ65/$BL65,3) -> #DIV/0! | BQ65: =ROUND(AK65/$BL65,3) -> #DIV/0! | BR65: =ROUND(AL65/$BL65,3) -> #DIV/0! | BS65: =ROUND(AM65/$BL65,3) -> #DIV/0! | BT65: =ROUND(AN65/$BL65,3) -> #DIV/0! | BV65: =BB65 -> 0 | BW65: =BC65 -> 0 | BX65: =ROUND(E65,1) -> 0 | BY65: =ROUND(G65,1) -> 0 | BZ65: NA | CA65: =ROUND(I65,1) -> 0 | CB65: =ROUND(J65,1) -> 0 | CC65: =ROUND(K65,1) -> 0 | CD65: =ROUND(L65,1) -> 0 | CE65: =ROUND(BG65,1) -> 0 | CF65: =ROUND(P65,1) -> 0 | CG65: =ROUND(R65,1) -> 0 | CH65: NA | CI65: =ROUND(T65,1) -> 0 | CJ65: =ROUND(U65,1) -> 0 | CK65: =ROUND(V65,1) -> 0 | CL65: =ROUND(W65,1) -> 0 | CM65: =ROUND(BF65,1) -> 0 | CN65: =ROUND(Y65,1) -> 0 | CO65: =ROUND(AA65,1) -> 0 | CP65: NA | CQ65: =ROUND(AC65,1) -> 0 | CR65: =ROUND(AD65,1) -> 0 | CS65: =ROUND(AE65,1) -> 0 | CT65: =ROUND(AF65,1) -> 0 | CU65: =ROUND(BH65,1) -> 0 | CV65: =AY65 -> 0 | CW65: =ROUND(PPTest!K65,1) -> 0 | CX65: =ROUND(M65,2) -> 0 | CY65: =ROUND(X65,2) -> 0 | CZ65: =BI65 -> 0 | DA65: =BJ65 -> #DIV/0! | DB65: =AV65 -> 0
A66: =A65+1 -> 45718 | B66: 61 | BA66: 13.23 | BD66: =BC66/BB66 -> #DIV/0! | BF66: =ROUND(Q66-BF$2,1) -> 0 | BG66: =ROUND(F66-BG$2,1) -> 0 | BH66: =ROUND(Z66-BH$2,1) -> 0 | BI66: =ROUND((0.6105*(EXP((17.273*P66)/(P66+237.3))))*BH66/100,3) -> 0 | BJ66: =ROUND(BI66/BH66*(100-BH66),3) -> #DIV/0! | BL66: =SUM(AG66:AN66) -> 0 | BM66: =ROUND(AG66/$BL66,3) -> #DIV/0! | BN66: =ROUND(AH66/$BL66,3) -> #DIV/0! | BO66: =ROUND(AI66/$BL66,3) -> #DIV/0! | BP66: =ROUND(AJ66/$BL66,3) -> #DIV/0! | BQ66: =ROUND(AK66/$BL66,3) -> #DIV/0! | BR66: =ROUND(AL66/$BL66,3) -> #DIV/0! | BS66: =ROUND(AM66/$BL66,3) -> #DIV/0! | BT66: =ROUND(AN66/$BL66,3) -> #DIV/0! | BV66: =BB66 -> 0 | BW66: =BC66 -> 0 | BX66: =ROUND(E66,1) -> 0 | BY66: =ROUND(G66,1) -> 0 | BZ66: NA | CA66: =ROUND(I66,1) -> 0 | CB66: =ROUND(J66,1) -> 0 | CC66: =ROUND(K66,1) -> 0 | CD66: =ROUND(L66,1) -> 0 | CE66: =ROUND(BG66,1) -> 0 | CF66: =ROUND(P66,1) -> 0 | CG66: =ROUND(R66,1) -> 0 | CH66: NA | CI66: =ROUND(T66,1) -> 0 | CJ66: =ROUND(U66,1) -> 0 | CK66: =ROUND(V66,1) -> 0 | CL66: =ROUND(W66,1) -> 0 | CM66: =ROUND(BF66,1) -> 0 | CN66: =ROUND(Y66,1) -> 0 | CO66: =ROUND(AA66,1) -> 0 | CP66: NA | CQ66: =ROUND(AC66,1) -> 0 | CR66: =ROUND(AD66,1) -> 0 | CS66: =ROUND(AE66,1) -> 0 | CT66: =ROUND(AF66,1) -> 0 | CU66: =ROUND(BH66,1) -> 0 | CV66: =AY66 -> 0 | CW66: =ROUND(PPTest!K66,1) -> 0 | CX66: =ROUND(M66,2) -> 0 | CY66: =ROUND(X66,2) -> 0 | CZ66: =BI66 -> 0 | DA66: =BJ66 -> #DIV/0! | DB66: =AV66 -> 0
A67: =A66+1 -> 45719 | B67: 62 | BA67: 13.47 | BD67: =BC67/BB67 -> #DIV/0! | BF67: =ROUND(Q67-BF$2,1) -> 0 | BG67: =ROUND(F67-BG$2,1) -> 0 | BH67: =ROUND(Z67-BH$2,1) -> 0 | BI67: =ROUND((0.6105*(EXP((17.273*P67)/(P67+237.3))))*BH67/100,3) -> 0 | BJ67: =ROUND(BI67/BH67*(100-BH67),3) -> #DIV/0! | BL67: =SUM(AG67:AN67) -> 0 | BM67: =ROUND(AG67/$BL67,3) -> #DIV/0! | BN67: =ROUND(AH67/$BL67,3) -> #DIV/0! | BO67: =ROUND(AI67/$BL67,3) -> #DIV/0! | BP67: =ROUND(AJ67/$BL67,3) -> #DIV/0! | BQ67: =ROUND(AK67/$BL67,3) -> #DIV/0! | BR67: =ROUND(AL67/$BL67,3) -> #DIV/0! | BS67: =ROUND(AM67/$BL67,3) -> #DIV/0! | BT67: =ROUND(AN67/$BL67,3) -> #DIV/0! | BV67: =BB67 -> 0 | BW67: =BC67 -> 0 | BX67: =ROUND(E67,1) -> 0 | BY67: =ROUND(G67,1) -> 0 | BZ67: NA | CA67: =ROUND(I67,1) -> 0 | CB67: =ROUND(J67,1) -> 0 | CC67: =ROUND(K67,1) -> 0 | CD67: =ROUND(L67,1) -> 0 | CE67: =ROUND(BG67,1) -> 0 | CF67: =ROUND(P67,1) -> 0 | CG67: =ROUND(R67,1) -> 0 | CH67: NA | CI67: =ROUND(T67,1) -> 0 | CJ67: =ROUND(U67,1) -> 0 | CK67: =ROUND(V67,1) -> 0 | CL67: =ROUND(W67,1) -> 0 | CM67: =ROUND(BF67,1) -> 0 | CN67: =ROUND(Y67,1) -> 0 | CO67: =ROUND(AA67,1) -> 0 | CP67: NA | CQ67: =ROUND(AC67,1) -> 0 | CR67: =ROUND(AD67,1) -> 0 | CS67: =ROUND(AE67,1) -> 0 | CT67: =ROUND(AF67,1) -> 0 | CU67: =ROUND(BH67,1) -> 0 | CV67: =AY67 -> 0 | CW67: =ROUND(PPTest!K67,1) -> 0 | CX67: =ROUND(M67,2) -> 0 | CY67: =ROUND(X67,2) -> 0 | CZ67: =BI67 -> 0 | DA67: =BJ67 -> #DIV/0! | DB67: =AV67 -> 0
A68: =A67+1 -> 45720 | B68: 63 | BA68: 13.71 | BD68: =BC68/BB68 -> #DIV/0! | BF68: =ROUND(Q68-BF$2,1) -> 0 | BG68: =ROUND(F68-BG$2,1) -> 0 | BH68: =ROUND(Z68-BH$2,1) -> 0 | BI68: =ROUND((0.6105*(EXP((17.273*P68)/(P68+237.3))))*BH68/100,3) -> 0 | BJ68: =ROUND(BI68/BH68*(100-BH68),3) -> #DIV/0! | BL68: =SUM(AG68:AN68) -> 0 | BM68: =ROUND(AG68/$BL68,3) -> #DIV/0! | BN68: =ROUND(AH68/$BL68,3) -> #DIV/0! | BO68: =ROUND(AI68/$BL68,3) -> #DIV/0! | BP68: =ROUND(AJ68/$BL68,3) -> #DIV/0! | BQ68: =ROUND(AK68/$BL68,3) -> #DIV/0! | BR68: =ROUND(AL68/$BL68,3) -> #DIV/0! | BS68: =ROUND(AM68/$BL68,3) -> #DIV/0! | BT68: =ROUND(AN68/$BL68,3) -> #DIV/0! | BV68: =BB68 -> 0 | BW68: =BC68 -> 0 | BX68: =ROUND(E68,1) -> 0 | BY68: =ROUND(G68,1) -> 0 | BZ68: NA | CA68: =ROUND(I68,1) -> 0 | CB68: =ROUND(J68,1) -> 0 | CC68: =ROUND(K68,1) -> 0 | CD68: =ROUND(L68,1) -> 0 | CE68: =ROUND(BG68,1) -> 0 | CF68: =ROUND(P68,1) -> 0 | CG68: =ROUND(R68,1) -> 0 | CH68: NA | CI68: =ROUND(T68,1) -> 0 | CJ68: =ROUND(U68,1) -> 0 | CK68: =ROUND(V68,1) -> 0 | CL68: =ROUND(W68,1) -> 0 | CM68: =ROUND(BF68,1) -> 0 | CN68: =ROUND(Y68,1) -> 0 | CO68: =ROUND(AA68,1) -> 0 | CP68: NA | CQ68: =ROUND(AC68,1) -> 0 | CR68: =ROUND(AD68,1) -> 0 | CS68: =ROUND(AE68,1) -> 0 | CT68: =ROUND(AF68,1) -> 0 | CU68: =ROUND(BH68,1) -> 0 | CV68: =AY68 -> 0 | CW68: =ROUND(PPTest!K68,1) -> 0 | CX68: =ROUND(M68,2) -> 0 | CY68: =ROUND(X68,2) -> 0 | CZ68: =BI68 -> 0 | DA68: =BJ68 -> #DIV/0! | DB68: =AV68 -> 0
