Workbook

Sheet Meta
A1: Meta data for Sicamous base station
A2: Last edit 11/04/25
B3: CR10 data logger and storage module
A5: Solar W/m2
B6: LiCor silicon Pyranometer at 6 m
B7: Kmax from 10 min simulation
A8: PAR mol/m2/d
B9: LiCor PAR sensor 6 m above surface. Calibration drift problem
A10: Tair C
B11: HMP35C in RMYoung pie plate sheild at 6 m
B12: Thermocouples referenced to thermistor on panel at 3 m, 1.5 m and 0.25 m
A13: RH %
B14: HMP35C in RMYoung pie plate sheild at 6 m
B15: Corrected RH based on Rhmax=100. Calculated vpres (kPa)
A16: Soil temperature C
B17: Thermocouples referenced to thermistor on panel at 0.15 m and 0.5 m depths
A18: Precipitation mm
B19: Sierra Misco tipping bucket 1 mm/tip
A20: Snow depth m, mm
B21: CSI UDG01
A22: Wind m/s
B23: MetOne anemometer at 6 m
A24: Wind direction degrees
B25: MetOne Wind vane at 6 m
A27: PPT= snow+rain
B28: Snow = Daily increase in pack depth and assumed compacted density of 0.13 Mg/m3
B29: Rain = Rain gauge.
C30: If there is a snow pack then review tiping bucket data to determine if likely snow melt rather than rain, i.e., tipping when above zero and low humidity and sunny.
C31: Also sum tipping bucket over days to see if simialr total to water equivalent of snow fal from depth change.
C32: April-May, Dec used Sicamous Fire Weather Station rainfall adjusted by *1.05
A33: Vapour pressure kPa
B34: Calculated from the daily maximum temperature and mininimum relative humdity: esat(Tmax)*RHmin/100
A35: Maximum vapour presure deficit
B36: Calculated from the daily maximum temperature and mininimum relative humdity: esat(Tmax)*(1-RHmin/100)

Sheet PPTest
A1: Precipitation | I1: 0.13 | K1: Rain | P1: Max density | Q1: 0.4
A2: =Data!A2 -> Last edit 18/04/25 | K2: SnowDepthChange | P2: Start Density | Q2: 0.334
C3: Total | K3: FWS* | L3: 1.05
C4: Solar | D4: Tmax | E4: Tmin | F4: Rhmin | G4: Rain | H4: SnowD | I4: Precip.from | J4: FWS | M4: FWS | N4: Sicamous | P4: density | R4: SWE | S4: dSWE | T4: Melt
A5: Date | B5: DoY | C5: MJ/m2/d | I5: snow depth | K5: Precipitation | P5: g/cm3 | R5: mm | S5: mm | T5: mm
H6: =Data!BE6 -> 583 | Q6: =Q2 -> 0.334 | R6: =H6*Q$2 -> 194.722 | S6: 0 | T6: 0
A7: 38718 | B7: 1 | C7: =ROUND(Data!BI7,2) -> 1.46 | D7: =ROUND(Data!O7,1) -> -0.2 | E7: =ROUND(Data!AA7,1) -> -8.5 | F7: =Data!BN7 -> 71.8 | G7: =Data!N7 -> 0 | H7: =Data!BE7 -> 605 | I7: =IF(H7>H6,ROUND((H7-H6)*I$1,1),0) -> 2.9 | J7: =Data!BR7 -> 0 | K7: =I7 -> 2.9 | M7: =J7 -> 0 | N7: =K7 -> 2.9 | P7: =(R6+K7)/H7 -> 0.32664793 | Q7: =IF(P7>Q$1,Q$1,P7) -> 0.32664793 | R7: =Q7*H7 -> 197.622 | S7: =R7-R6 -> 2.9 | T7: =K7-S7 -> -5.7731597e-15
A8: =A7+1 -> 38719 | B8: 2 | C8: =ROUND(Data!BI8,2) -> 3.17 | D8: =ROUND(Data!O8,1) -> 1.1 | E8: =ROUND(Data!AA8,1) -> -3.9 | F8: =Data!BN8 -> 61.1 | G8: =Data!N8 -> 0 | H8: =Data!BE8 -> 586 | I8: =IF(H8>H7,ROUND((H8-H7)*I$1,1),0) -> 0 | J8: =Data!BR8 -> 0 | K8: =I8 -> 0 | M8: =J8+M7 -> 0 | N8: =K8+N7 -> 2.9 | P8: =(R7+K8)/H8 -> 0.33723891 | Q8: =IF(P8>Q$1,Q$1,P8) -> 0.33723891 | R8: =Q8*H8 -> 197.622 | S8: =R8-R7 -> 0 | T8: =K8-S8 -> 0
A9: =A8+1 -> 38720 | B9: 3 | C9: =ROUND(Data!BI9,2) -> 1.82 | D9: =ROUND(Data!O9,1) -> -1.1 | E9: =ROUND(Data!AA9,1) -> -5.4 | F9: =Data!BN9 -> 62.8 | G9: =Data!N9 -> 0 | H9: =Data!BE9 -> 675 | I9: =IF(H9>H8,ROUND((H9-H8)*I$1,1),0) -> 11.6 | J9: =Data!BR9 -> 0 | K9: =I9 -> 11.6 | M9: =J9+M8 -> 0 | N9: =K9+N8 -> 14.5 | P9: =(R8+K9)/H9 -> 0.30995852 | Q9: =IF(P9>Q$1,Q$1,P9) -> 0.30995852 | R9: =Q9*H9 -> 209.222 | S9: =R9-R8 -> 11.6 | T9: =K9-S9 -> 3.375078e-14
A10: =A9+1 -> 38721 | B10: 4 | C10: =ROUND(Data!BI10,2) -> 2.73 | D10: =ROUND(Data!O10,1) -> 0.3 | E10: =ROUND(Data!AA10,1) -> -5.9 | F10: =Data!BN10 -> 65.6 | G10: =Data!N10 -> 0 | H10: =Data!BE10 -> 661 | I10: =IF(H10>H9,ROUND((H10-H9)*I$1,1),0) -> 0 | J10: =Data!BR10 -> 0 | K10: =I10 -> 0 | M10: =J10+M9 -> 0 | N10: =K10+N9 -> 14.5 | P10: =(R9+K10)/H10 -> 0.31652345 | Q10: =IF(P10>Q$1,Q$1,P10) -> 0.31652345 | R10: =Q10*H10 -> 209.222 | S10: =R10-R9 -> 0 | T10: =K10-S10 -> 0
A11: =A10+1 -> 38722 | B11: 5 | C11: =ROUND(Data!BI11,2) -> 0.64 | D11: =ROUND(Data!O11,1) -> 1.3 | E11: =ROUND(Data!AA11,1) -> -2.9 | F11: =Data!BN11 -> 67 | G11: =Data!N11 -> 0 | H11: =Data!BE11 -> 644 | I11: =IF(H11>H10,ROUND((H11-H10)*I$1,1),0) -> 0 | J11: =Data!BR11 -> 0 | K11: =I11 -> 0 | M11: =J11+M10 -> 0 | N11: =K11+N10 -> 14.5 | P11: =(R10+K11)/H11 -> 0.32487888 | Q11: =IF(P11>Q$1,Q$1,P11) -> 0.32487888 | R11: =Q11*H11 -> 209.222 | S11: =R11-R10 -> 0 | T11: =K11-S11 -> 0
A12: =A11+1 -> 38723 | B12: 6 | C12: =ROUND(Data!BI12,2) -> 1.52 | D12: =ROUND(Data!O12,1) -> 1.9 | E12: =ROUND(Data!AA12,1) -> -1.8 | F12: =Data!BN12 -> 89.1 | G12: =Data!N12 -> 0 | H12: =Data!BE12 -> 645 | I12: =IF(H12>H11,ROUND((H12-H11)*I$1,1),0) -> 0.1 | J12: =Data!BR12 -> 0 | K12: =I12 -> 0.1 | M12: =J12+M11 -> 0 | N12: =K12+N11 -> 14.6 | P12: =(R11+K12)/H12 -> 0.32453023 | Q12: =IF(P12>Q$1,Q$1,P12) -> 0.32453023 | R12: =Q12*H12 -> 209.322 | S12: =R12-R11 -> 0.1 | T12: =K12-S12 -> 5.689893e-15
A13: =A12+1 -> 38724 | B13: 7 | C13: =ROUND(Data!BI13,2) -> 2.25 | D13: =ROUND(Data!O13,1) -> -0.1 | E13: =ROUND(Data!AA13,1) -> -6.5 | F13: =Data!BN13 -> 91 | G13: =Data!N13 -> 0 | H13: =Data!BE13 -> 667 | I13: =IF(H13>H12,ROUND((H13-H12)*I$1,1),0) -> 2.9 | J13: =Data!BR13 -> 0 | K13: =I13 -> 2.9 | M13: =J13+M12 -> 0 | N13: =K13+N12 -> 17.5 | P13: =(R12+K13)/H13 -> 0.31817391 | Q13: =IF(P13>Q$1,Q$1,P13) -> 0.31817391 | R13: =Q13*H13 -> 212.222 | S13: =R13-R12 -> 2.9 | T13: =K13-S13 -> -5.7731597e-15
A14: =A13+1 -> 38725 | B14: 8 | C14: =ROUND(Data!BI14,2) -> 0.55 | D14: =ROUND(Data!O14,1) -> -1 | E14: =ROUND(Data!AA14,1) -> -4.3 | F14: =Data!BN14 -> 76.4 | G14: =Data!N14 -> 0 | H14: =Data!BE14 -> 680 | I14: =IF(H14>H13,ROUND((H14-H13)*I$1,1),0) -> 1.7 | J14: =Data!BR14 -> 0 | K14: =I14 -> 1.7 | M14: =J14+M13 -> 0 | N14: =K14+N13 -> 19.2 | P14: =(R13+K14)/H14 -> 0.31459118 | Q14: =IF(P14>Q$1,Q$1,P14) -> 0.31459118 | R14: =Q14*H14 -> 213.922 | S14: =R14-R13 -> 1.7 | T14: =K14-S14 -> 1.1324275e-14
A15: =A14+1 -> 38726 | B15: 9 | C15: =ROUND(Data!BI15,2) -> 0.15 | D15: =ROUND(Data!O15,1) -> -1.5 | E15: =ROUND(Data!AA15,1) -> -3.8 | F15: =Data!BN15 -> 81.5 | G15: =Data!N15 -> 0 | H15: =Data!BE15 -> 793 | I15: =IF(H15>H14,ROUND((H15-H14)*I$1,1),0) -> 14.7 | J15: =Data!BR15 -> 0 | K15: =I15 -> 14.7 | M15: =J15+M14 -> 0 | N15: =K15+N14 -> 33.9 | P15: =(R14+K15)/H15 -> 0.28830013 | Q15: =IF(P15>Q$1,Q$1,P15) -> 0.28830013 | R15: =Q15*H15 -> 228.622 | S15: =R15-R14 -> 14.7 | T15: =K15-S15 -> 0
A16: =A15+1 -> 38727 | B16: 10 | C16: =ROUND(Data!BI16,2) -> 0.2 | D16: =ROUND(Data!O16,1) -> -0.1 | E16: =ROUND(Data!AA16,1) -> -4.2 | F16: =Data!BN16 -> 82.1 | G16: =Data!N16 -> 0 | H16: =Data!BE16 -> 879 | I16: =IF(H16>H15,ROUND((H16-H15)*I$1,1),0) -> 11.2 | J16: =Data!BR16 -> 0 | K16: =I16 -> 11.2 | M16: =J16+M15 -> 0 | N16: =K16+N15 -> 45.1 | P16: =(R15+K16)/H16 -> 0.27283504 | Q16: =IF(P16>Q$1,Q$1,P16) -> 0.27283504 | R16: =Q16*H16 -> 239.822 | S16: =R16-R15 -> 11.2 | T16: =K16-S16 -> 3.907985e-14
A17: =A16+1 -> 38728 | B17: 11 | C17: =ROUND(Data!BI17,2) -> 0.56 | D17: =ROUND(Data!O17,1) -> -1.7 | E17: =ROUND(Data!AA17,1) -> -4 | F17: =Data!BN17 -> 80.9 | G17: =Data!N17 -> 0 | H17: =Data!BE17 -> 920 | I17: =IF(H17>H16,ROUND((H17-H16)*I$1,1),0) -> 5.3 | J17: =Data!BR17 -> 0 | K17: =I17 -> 5.3 | M17: =J17+M16 -> 0 | N17: =K17+N16 -> 50.4 | P17: =(R16+K17)/H17 -> 0.26643696 | Q17: =IF(P17>Q$1,Q$1,P17) -> 0.26643696 | R17: =Q17*H17 -> 245.122 | S17: =R17-R16 -> 5.3 | T17: =K17-S17 -> -3.9968029e-14
A18: =A17+1 -> 38729 | B18: 12 | C18: =ROUND(Data!BI18,2) -> 0.52 | D18: =ROUND(Data!O18,1) -> -2.8 | E18: =ROUND(Data!AA18,1) -> -4.2 | F18: =Data!BN18 -> 84.8 | G18: =Data!N18 -> 0 | H18: =Data!BE18 -> 991 | I18: =IF(H18>H17,ROUND((H18-H17)*I$1,1),0) -> 9.2 | J18: =Data!BR18 -> 0 | K18: =I18 -> 9.2 | M18: =J18+M17 -> 0 | N18: =K18+N17 -> 59.6 | P18: =(R17+K18)/H18 -> 0.25663169 | Q18: =IF(P18>Q$1,Q$1,P18) -> 0.25663169 | R18: =Q18*H18 -> 254.322 | S18: =R18-R17 -> 9.2 | T18: =K18-S18 -> -1.7763568e-14
A19: =A18+1 -> 38730 | B19: 13 | C19: =ROUND(Data!BI19,2) -> 0.63 | D19: =ROUND(Data!O19,1) -> 0.4 | E19: =ROUND(Data!AA19,1) -> -3.6 | F19: =Data!BN19 -> 87.5 | G19: =Data!N19 -> 0 | H19: =Data!BE19 -> 929 | I19: =IF(H19>H18,ROUND((H19-H18)*I$1,1),0) -> 0 | J19: =Data!BR19 -> 0 | K19: =I19 -> 0 | M19: =J19+M18 -> 0 | N19: =K19+N18 -> 59.6 | P19: =(R18+K19)/H19 -> 0.27375888 | Q19: =IF(P19>Q$1,Q$1,P19) -> 0.27375888 | R19: =Q19*H19 -> 254.322 | S19: =R19-R18 -> 0 | T19: =K19-S19 -> 0
... A99: =A98+1 -> 38810 | B99: 93 | C99: =ROUND(Data!BI99,2) -> 11.01 | D99: =ROUND(Data!O99,1) -> 6.1 | E99: =ROUND(Data!AA99,1) -> -8.6 | F99: =Data!BN99 -> 30.8 | G99: =Data!N99 -> 0 | H99: =Data!BE99 -> 1181 | I99: =IF(H99>H98,ROUND((H99-H98)*I$1,1),0) -> 0 | J99: =Data!BR99 -> 0 | K99: =I99 -> 0 | M99: =J99+M98 -> 36.4 | N99: =K99+N98 -> 258.4 | P99: =(R98+K99)/H99 -> 0.38367655 | Q99: =IF(P99>Q$1,Q$1,P99) -> 0.38367655 | R99: =Q99*H99 -> 453.122 | S99: =R99-R98 -> 0 | T99: =K99-S99 -> 0
A100: =A99+1 -> 38811 | B100: 94 | C100: =ROUND(Data!BI100,2) -> 5.59 | D100: =ROUND(Data!O100,1) -> 2.8 | E100: =ROUND(Data!AA100,1) -> -1.1 | F100: =Data!BN100 -> 86.1 | G100: =Data!N100 -> 1 | H100: =Data!BE100 -> 1162 | I100: =IF(H100>H99,ROUND((H100-H99)*I$1,1),0) -> 0 | J100: =Data!BR100 -> 4.4 | K100: =ROUND(J100*L$3,1) -> 4.6 | M100: =J100+M99 -> 40.8 | N100: =K100+N99 -> 263 | P100: =(R99+K100)/H100 -> 0.39390878 | Q100: =IF(P100>Q$1,Q$1,P100) -> 0.39390878 | R100: =Q100*H100 -> 457.722 | S100: =R100-R99 -> 4.6 | T100: =K100-S100 -> -2.3092639e-14
A101: =A100+1 -> 38812 | B101: 95 | C101: =ROUND(Data!BI101,2) -> 19.05 | D101: =ROUND(Data!O101,1) -> 10.1 | E101: =ROUND(Data!AA101,1) -> -4 | F101: =Data!BN101 -> 44.8 | G101: =Data!N101 -> 0 | H101: =Data!BE101 -> 1100 | I101: =IF(H101>H100,ROUND((H101-H100)*I$1,1),0) -> 0 | J101: =Data!BR101 -> 0.2 | K101: =ROUND(J101*L$3,1) -> 0.2 | M101: =J101+M100 -> 41 | N101: =K101+N100 -> 263.2 | P101: =(R100+K101)/H101 -> 0.41629273 | Q101: =IF(P101>Q$1,Q$1,P101) -> 0.4 | R101: =Q101*H101 -> 440 | S101: =R101-R100 -> -17.722 | T101: =K101-S101 -> 17.922
A102: =A101+1 -> 38813 | B102: 96 | C102: =ROUND(Data!BI102,2) -> 12.29 | D102: =ROUND(Data!O102,1) -> 9.2 | E102: =ROUND(Data!AA102,1) -> -3 | F102: =Data!BN102 -> 49.3 | G102: =Data!N102 -> 1 | H102: =Data!BE102 -> 1079 | I102: =IF(H102>H101,ROUND((H102-H101)*I$1,1),0) -> 0 | J102: =Data!BR102 -> 3.4 | K102: =ROUND(J102*L$3,1) -> 3.6 | M102: =J102+M101 -> 44.4 | N102: =K102+N101 -> 266.8 | P102: =(R101+K102)/H102 -> 0.41112141 | Q102: =IF(P102>Q$1,Q$1,P102) -> 0.4 | R102: =Q102*H102 -> 431.6 | S102: =R102-R101 -> -8.4 | T102: =K102-S102 -> 12
A103: =A102+1 -> 38814 | B103: 97 | C103: =ROUND(Data!BI103,2) -> 16.41 | D103: =ROUND(Data!O103,1) -> 8.9 | E103: =ROUND(Data!AA103,1) -> -4.7 | F103: =Data!BN103 -> 41.3 | G103: =Data!N103 -> 0 | H103: =Data!BE103 -> 1052 | I103: =IF(H103>H102,ROUND((H103-H102)*I$1,1),0) -> 0 | J103: =Data!BR103 -> 0 | K103: =ROUND(J103*L$3,1) -> 0 | M103: =J103+M102 -> 44.4 | N103: =K103+N102 -> 266.8 | P103: =(R102+K103)/H103 -> 0.41026616 | Q103: =IF(P103>Q$1,Q$1,P103) -> 0.4 | R103: =Q103*H103 -> 420.8 | S103: =R103-R102 -> -10.8 | T103: =K103-S103 -> 10.8
A104: =A103+1 -> 38815 | B104: 98 | C104: =ROUND(Data!BI104,2) -> 8.39 | D104: =ROUND(Data!O104,1) -> 7.3 | E104: =ROUND(Data!AA104,1) -> 0 | F104: =Data!BN104 -> 51.8 | G104: =Data!N104 -> 0 | H104: =Data!BE104 -> 1020 | I104: =IF(H104>H103,ROUND((H104-H103)*I$1,1),0) -> 0 | J104: =Data!BR104 -> 1 | K104: =ROUND(J104*L$3,1) -> 1.1 | M104: =J104+M103 -> 45.4 | N104: =K104+N103 -> 267.9 | P104: =(R103+K104)/H104 -> 0.41362745 | Q104: =IF(P104>Q$1,Q$1,P104) -> 0.4 | R104: =Q104*H104 -> 408 | S104: =R104-R103 -> -12.8 | T104: =K104-S104 -> 13.9
A105: =A104+1 -> 38816 | B105: 99 | C105: =ROUND(Data!BI105,2) -> 15 | D105: =ROUND(Data!O105,1) -> 7.7 | E105: =ROUND(Data!AA105,1) -> -0.4 | F105: =Data!BN105 -> 52.6 | G105: =Data!N105 -> 0 | H105: =Data!BE105 -> 990 | I105: =IF(H105>H104,ROUND((H105-H104)*I$1,1),0) -> 0 | J105: =Data!BR105 -> 1.2 | K105: =ROUND(J105*L$3,1) -> 1.3 | M105: =J105+M104 -> 46.6 | N105: =K105+N104 -> 269.2 | P105: =(R104+K105)/H105 -> 0.41343434 | Q105: =IF(P105>Q$1,Q$1,P105) -> 0.4 | R105: =Q105*H105 -> 396 | S105: =R105-R104 -> -12 | T105: =K105-S105 -> 13.3
A106: =A105+1 -> 38817 | B106: 100 | C106: =ROUND(Data!BI106,2) -> 11.4 | D106: =ROUND(Data!O106,1) -> 5.2 | E106: =ROUND(Data!AA106,1) -> -2.9 | F106: =Data!BN106 -> 59.3 | G106: =Data!N106 -> 1 | H106: =Data!BE106 -> 976 | I106: =IF(H106>H105,ROUND((H106-H105)*I$1,1),0) -> 0 | J106: =Data!BR106 -> 3 | K106: =ROUND(J106*L$3,1) -> 3.2 | M106: =J106+M105 -> 49.6 | N106: =K106+N105 -> 272.4 | P106: =(R105+K106)/H106 -> 0.40901639 | Q106: =IF(P106>Q$1,Q$1,P106) -> 0.4 | R106: =Q106*H106 -> 390.4 | S106: =R106-R105 -> -5.6 | T106: =K106-S106 -> 8.8
A107: =A106+1 -> 38818 | B107: 101 | C107: =ROUND(Data!BI107,2) -> 8.06 | D107: =ROUND(Data!O107,1) -> 4.9 | E107: =ROUND(Data!AA107,1) -> -2.8 | F107: =Data!BN107 -> 73.3 | G107: =Data!N107 -> 1 | H107: =Data!BE107 -> 977 | I107: =IF(H107>H106,ROUND((H107-H106)*I$1,1),0) -> 0.1 | J107: =Data!BR107 -> 1.2 | K107: =ROUND(J107*L$3,1) -> 1.3 | M107: =J107+M106 -> 50.8 | N107: =K107+N106 -> 273.7 | P107: =(R106+K107)/H107 -> 0.40092119 | Q107: =IF(P107>Q$1,Q$1,P107) -> 0.4 | R107: =Q107*H107 -> 390.8 | S107: =R107-R106 -> 0.4 | T107: =K107-S107 -> 0.9
A108: =A107+1 -> 38819 | B108: 102 | C108: =ROUND(Data!BI108,2) -> 10.28 | D108: =ROUND(Data!O108,1) -> 4.5 | E108: =ROUND(Data!AA108,1) -> -3.1 | F108: =Data!BN108 -> 66.5 | G108: =Data!N108 -> 0 | H108: =Data!BE108 -> 974 | I108: =IF(H108>H107,ROUND((H108-H107)*I$1,1),0) -> 0 | J108: =Data!BR108 -> 1.2 | K108: =ROUND(J108*L$3,1) -> 1.3 | M108: =J108+M107 -> 52 | N108: =K108+N107 -> 275 | P108: =(R107+K108)/H108 -> 0.40256674 | Q108: =IF(P108>Q$1,Q$1,P108) -> 0.4 | R108: =Q108*H108 -> 389.6 | S108: =R108-R107 -> -1.2 | T108: =K108-S108 -> 2.5
A109: =A108+1 -> 38820 | B109: 103 | C109: =ROUND(Data!BI109,2) -> 7.91 | D109: =ROUND(Data!O109,1) -> 1.5 | E109: =ROUND(Data!AA109,1) -> -3.6 | F109: =Data!BN109 -> 61.1 | G109: =Data!N109 -> 0 | H109: =Data!BE109 -> 1090 | I109: =IF(H109>H108,ROUND((H109-H108)*I$1,1),0) -> 15.1 | J109: =Data!BR109 -> 7.4 | K109: =I109 -> 15.1 | M109: =J109+M108 -> 59.4 | N109: =K109+N108 -> 290.1 | P109: =(R108+K109)/H109 -> 0.3712844 | Q109: =IF(P109>Q$1,Q$1,P109) -> 0.3712844 | R109: =Q109*H109 -> 404.7 | S109: =R109-R108 -> 15.1 | T109: =K109-S109 -> -2.3092639e-14
A110: =A109+1 -> 38821 | B110: 104 | C110: =ROUND(Data!BI110,2) -> 7.35 | D110: =ROUND(Data!O110,1) -> 4.3 | E110: =ROUND(Data!AA110,1) -> -4.8 | F110: =Data!BN110 -> 71.1 | G110: =Data!N110 -> 3 | H110: =Data!BE110 -> 1046 | I110: =IF(H110>H109,ROUND((H110-H109)*I$1,1),0) -> 0 | J110: =Data!BR110 -> 0.6 | K110: =I110 -> 0 | M110: =J110+M109 -> 60 | N110: =K110+N109 -> 290.1 | P110: =(R109+K110)/H110 -> 0.38690249 | Q110: =IF(P110>Q$1,Q$1,P110) -> 0.38690249 | R110: =Q110*H110 -> 404.7 | S110: =R110-R109 -> 0 | T110: =K110-S110 -> 0
A111: =A110+1 -> 38822 | B111: 105 | C111: =ROUND(Data!BI111,2) -> 15.28 | D111: =ROUND(Data!O111,1) -> 1.4 | E111: =ROUND(Data!AA111,1) -> -8.7 | F111: =Data!BN111 -> 46.8 | G111: =Data!N111 -> 0 | H111: =Data!BE111 -> 1167 | I111: =IF(H111>H110,ROUND((H111-H110)*I$1,1),0) -> 15.7 | J111: =Data!BR111 -> 0 | K111: =I111 -> 15.7 | M111: =J111+M110 -> 60 | N111: =K111+N110 -> 305.8 | P111: =(R110+K111)/H111 -> 0.36023993 | Q111: =IF(P111>Q$1,Q$1,P111) -> 0.36023993 | R111: =Q111*H111 -> 420.4 | S111: =R111-R110 -> 15.7 | T111: =K111-S111 -> 0
A112: =A111+1 -> 38823 | B112: 106 | C112: =ROUND(Data!BI112,2) -> 10.79 | D112: =ROUND(Data!O112,1) -> 0.6 | E112: =ROUND(Data!AA112,1) -> -12.5 | F112: =Data!BN112 -> 52.3 | G112: =Data!N112 -> 0 | H112: =Data!BE112 -> 1102 | I112: =IF(H112>H111,ROUND((H112-H111)*I$1,1),0) -> 0 | J112: =Data!BR112 -> 7.6 | K112: =I112 -> 0 | M112: =J112+M111 -> 67.6 | N112: =K112+N111 -> 305.8 | P112: =(R111+K112)/H112 -> 0.3814882 | Q112: =IF(P112>Q$1,Q$1,P112) -> 0.3814882 | R112: =Q112*H112 -> 420.4 | S112: =R112-R111 -> 0 | T112: =K112-S112 -> 0
A113: =A112+1 -> 38824 | B113: 107 | C113: =ROUND(Data!BI113,2) -> 20.56 | D113: =ROUND(Data!O113,1) -> 3 | E113: =ROUND(Data!AA113,1) -> -14.6 | F113: =Data!BN113 -> 42.2 | G113: =Data!N113 -> 0 | H113: =Data!BE113 -> 1042 | I113: =IF(H113>H112,ROUND((H113-H112)*I$1,1),0) -> 0 | J113: =Data!BR113 -> 0 | K113: =I113 -> 0 | M113: =J113+M112 -> 67.6 | N113: =K113+N112 -> 305.8 | P113: =(R112+K113)/H113 -> 0.40345489 | Q113: =IF(P113>Q$1,Q$1,P113) -> 0.4 | R113: =Q113*H113 -> 416.8 | S113: =R113-R112 -> -3.6 | T113: =K113-S113 -> 3.6
A114: =A113+1 -> 38825 | B114: 108 | C114: =ROUND(Data!BI114,2) -> 23.01 | D114: =ROUND(Data!O114,1) -> 6.7 | E114: =ROUND(Data!AA114,1) -> -13 | F114: =Data!BN114 -> 32.1 | G114: =Data!N114 -> 0 | H114: =Data!BE114 -> 1015 | I114: =IF(H114>H113,ROUND((H114-H113)*I$1,1),0) -> 0 | J114: =Data!BR114 -> 0 | K114: =I114 -> 0 | M114: =J114+M113 -> 67.6 | N114: =K114+N113 -> 305.8 | P114: =(R113+K114)/H114 -> 0.41064039 | Q114: =IF(P114>Q$1,Q$1,P114) -> 0.4 | R114: =Q114*H114 -> 406 | S114: =R114-R113 -> -10.8 | T114: =K114-S114 -> 10.8
A115: =A114+1 -> 38826 | B115: 109 | C115: =ROUND(Data!BI115,2) -> 22.24 | D115: =ROUND(Data!O115,1) -> 10.2 | E115: =ROUND(Data!AA115,1) -> -3.3 | F115: =Data!BN115 -> 29.2 | G115: =Data!N115 -> 0 | H115: =Data!BE115 -> 992 | I115: =IF(H115>H114,ROUND((H115-H114)*I$1,1),0) -> 0 | J115: =Data!BR115 -> 0 | K115: =I115 -> 0 | M115: =J115+M114 -> 67.6 | N115: =K115+N114 -> 305.8 | P115: =(R114+K115)/H115 -> 0.40927419 | Q115: =IF(P115>Q$1,Q$1,P115) -> 0.4 | R115: =Q115*H115 -> 396.8 | S115: =R115-R114 -> -9.2 | T115: =K115-S115 -> 9.2
A116: =A115+1 -> 38827 | B116: 110 | C116: =ROUND(Data!BI116,2) -> 20.17 | D116: =ROUND(Data!O116,1) -> 11.9 | E116: =ROUND(Data!AA116,1) -> 0.3 | F116: =Data!BN116 -> 35.2 | G116: =Data!N116 -> 0 | H116: =Data!BE116 -> 955 | I116: =IF(H116>H115,ROUND((H116-H115)*I$1,1),0) -> 0 | J116: =Data!BR116 -> 0 | K116: =I116 -> 0 | M116: =J116+M115 -> 67.6 | N116: =K116+N115 -> 305.8 | P116: =(R115+K116)/H116 -> 0.41549738 | Q116: =IF(P116>Q$1,Q$1,P116) -> 0.4 | R116: =Q116*H116 -> 382 | S116: =R116-R115 -> -14.8 | T116: =K116-S116 -> 14.8
A117: =A116+1 -> 38828 | B117: 111 | C117: =ROUND(Data!BI117,2) -> 3.42 | D117: =ROUND(Data!O117,1) -> 8.7 | E117: =ROUND(Data!AA117,1) -> -3.8 | F117: =Data!BN117 -> 45.6 | G117: =Data!N117 -> 11 | H117: =Data!BE117 -> 1010 | I117: =IF(H117>H116,ROUND((H117-H116)*I$1,1),0) -> 7.2 | J117: =Data!BR117 -> 18.8 | K117: =I117 -> 7.2 | M117: =J117+M116 -> 86.4 | N117: =K117+N116 -> 313 | P117: =(R116+K117)/H117 -> 0.38534653 | Q117: =IF(P117>Q$1,Q$1,P117) -> 0.38534653 | R117: =Q117*H117 -> 389.2 | S117: =R117-R116 -> 7.2 | T117: =K117-S117 -> 1.1546319e-14
A118: =A117+1 -> 38829 | B118: 112 | C118: =ROUND(Data!BI118,2) -> 15.87 | D118: =ROUND(Data!O118,1) -> 3.3 | E118: =ROUND(Data!AA118,1) -> -7.5 | F118: =Data!BN118 -> 50.3 | G118: =Data!N118 -> 3 | H118: =Data!BE118 -> 1000 | I118: =IF(H118>H117,ROUND((H118-H117)*I$1,1),0) -> 0 | J118: =Data!BR118 -> 1.6 | K118: =I118 -> 0 | M118: =J118+M117 -> 88 | N118: =K118+N117 -> 313 | P118: =(R117+K118)/H118 -> 0.3892 | Q118: =IF(P118>Q$1,Q$1,P118) -> 0.3892 | R118: =Q118*H118 -> 389.2 | S118: =R118-R117 -> 0 | T118: =K118-S118 -> 0
A119: =A118+1 -> 38830 | B119: 113 | C119: =ROUND(Data!BI119,2) -> 26.61 | D119: =ROUND(Data!O119,1) -> 10 | E119: =ROUND(Data!AA119,1) -> -9.8 | F119: =Data!BN119 -> 23.7 | G119: =Data!N119 -> 0 | H119: =Data!BE119 -> 919 | I119: =IF(H119>H118,ROUND((H119-H118)*I$1,1),0) -> 0 | J119: =Data!BR119 -> 0 | K119: =I119 -> 0 | M119: =J119+M118 -> 88 | N119: =K119+N118 -> 313 | P119: =(R118+K119)/H119 -> 0.42350381 | Q119: =IF(P119>Q$1,Q$1,P119) -> 0.4 | R119: =Q119*H119 -> 367.6 | S119: =R119-R118 -> -21.6 | T119: =K119-S119 -> 21.6
...

Sheet Data
A1: Sicamous base station 2006 | E1: RH, Solar and PAR new calibrations added col BL onwards | M1: Removed -6999 indicating bad data | BE1: 3496 | BH1: =2.02 -> 2.02 | BI1: Recalibrated 30/07/07 | BL1: Rh_adjustment, 2/08/07) | BM1: 1.59
A2: Last edit 18/04/25 | E2: PAR 5 to 10% low | J2: Empty cell indicates no data | BE2: 3510 | BI2: 0.98 | BJ2: 1.1 | BL2: 111 | BM2: -76.7 | BT2: Summary
C3: Total | D3: Total | E3: Avg. | F3: Avg. | G3: Avg. | H3: Avg. | I3: Avg. | J3: Avg. | K3: Avg. | L3: Avg. | M3: Avg. | N3: Total | O3: Max. | P3: Time | Q3: Max. | R3: Time | S3: Max. | T3: Max. | U3: Max. | V3: Max. | W3: Max. | X3: Max. | Y3: Max. | Z3: Time | AA3: Min. | AB3: Time | AC3: Min. | AD3: Time | AE3: Min. | AF3: Min. | AG3: Min. | AH3: Min. | AI3: Min. | AJ3: Min. | AK3: Wind Rose: | BI3: Revised | BL3: 99 | BM3: 0.88 | BP3: Used Rhcor | CT3: Midnight
C4: Solar | D4: PAR | E4: Ta 6m | F4: RH | G4: Ta 3m | H4: Ta 1.5m | I4: Ta 0.25m | J4: Tsoil_Duff | K4: Tsoil_0.15 | L4: Tsoil_0.5 | M4: Wind | N4: Rain | O4: Ta 6m | P4: Ta 6m | Q4: RH | R4: RH | S4: Ta 3m | T4: Ta 1.5m | U4: Ta 0.25m | V4: Tsoil_Duff | W4: Tsoil_0.15 | X4: Tsoil_0.5 | Y4: Wind | Z4: Max_Wind | AA4: Ta 6m | AB4: Ta 6m | AC4: RH | AD4: RH | AE4: Ta 3m | AF4: Ta 1.5m | AG4: Ta 0.25m | AH4: Tsoil_Duff | AI4: Tsoil_0.15 | AJ4: Tsoil_0.5 | AS4: Distance | AT4: Distance | AV4: Tlogger | AW4: Tpanel | AX4: Tlogger | AY4: Tpanel | AZ4: Tlogger | BA4: Tpanel | BB4: BATT. | BC4: ID | BD4: Comments | BE4: Snow Depth | BG4: Solarmax | BH4: PARmax | BI4: Solar | BJ4: PAR | BM4: -7 | BO4: Vapres | BP4: VPDx | BR4: FWS | BT4: Solar | BU4: PAR | BV4: Ta6Ave | BW4: Ta3Ave | BX4: Ta15Ave | BY4: Ta025Ave | BZ4: TdufAve | CA4: Ts015Ave | CB4: Ts05Ave | CC4: RH6Ave | CD4: Ta6Max | CE4: Ta3Max | CF4: Ta15Max | CG4: Ta025Max | CH4: TdufMax | CI4: Ts015Max | CJ4: Ts05Max | CK4: RH6Max | CL4: Ta6Min | CM4: Ta3Min | CN4: Ta15Min | CO4: Ta025Min | CP4: TdufMin | CQ4: Ts015Min | CR4: Ts05Min | CS4: RH6Min | CT4: SnowD | CU4: Precipitation | CV4: Wind | CW4: WindX | CX4: Vapres | CY4: vpdX | CZ4: BatV
A5: Date | B5: Doy | C5: MJ/m2/d | D5: mol/m2/d | E5: C | F5: % | G5: C | H5: C | I5: C | J5: C | K5: C | L5: C | M5: m/s | N5: mm | O5: C | P5: PST | Q5: % | R5: PST | S5: C | T5: C | U5: C | V5: C | W5: C | X5: C | Y5: m/s | Z5: PST | AA5: C | AB5: PST | AC5: % | AD5: PST | AE5: C | AF5: C | AG5: C | AH5: C | AI5: C | AJ5: C | AK5: N--NE | AL5: NE--E | AM5: E--SE | AN5: SE--S | AO5: S--SW | AP5: SW--W | AQ5: W--NW | AR5: NW--N | AS5: Max | AT5: Min | AU5: Avg | AV5: Avg | AW5: Avg | AX5: Max | AY5: Max | AZ5: Min | BA5: Min | BB5: (V) | BG5: MJ/m2/d | BH5: mol/m2/d | BL5: RHMax | BM5: RHAvg | BN5: RHMin | BO5: kPa | BP5: kPa | BT5: MJ/m2/d | BU5: mol/m2/d | BV5: C | BW5: C | BX5: C | BY5: C | BZ5: C | CA5: C | CB5: C | CC5: % | CD5: C | CE5: C | CF5: C | CG5: C | CH5: C | CI5: C | CJ5: C | CK5: % | CL5: C | CM5: C | CN5: C | CO5: C | CP5: C | CQ5: C | CR5: C | CS5: % | CT5: mm | CU5: mm/d | CV5: m/s | CW5: m/s | CX5: kPa | CY5: kPa | CZ5: V
BE6: 583
A7: 38718 | B7: 1 | C7: 1.487 | D7: 3.172 | E7: -2.786 | F7: 101.6 | G7: -3.491 | H7: -3.775 | I7: -0.051 | J7: -0.449 | K7: -0.158 | L7: 0.806 | M7: 1.615 | N7: 0 | O7: -0.229 | P7: 1151 | Q7: 110.5 | R7: 326 | S7: 0.397 | T7: 0.369 | U7: 0.244 | V7: -0.252 | W7: 0.097 | X7: 1.054 | Y7: 4.65 | Z7: 2212 | AA7: -8.49 | AB7: 813 | AC7: 89.6 | AD7: 1629 | AE7: -10.26 | AF7: -11.66 | AG7: -0.276 | AH7: -0.701 | AI7: -0.383 | AJ7: 0.587 | AK7: 0.174 | AL7: 0.279 | AM7: 0.21 | AN7: 0.102 | AO7: 0.072 | AP7: 0.049 | AQ7: 0.036 | AR7: 0.078 | AS7: 2911 | AT7: 2901 | AU7: 2905 | AV7: -4.543 | AW7: -4.599 | AX7: -1.911 | AY7: -1.853 | AZ7: -10.36 | BA7: -10.7 | BB7: 13.03 | BC7: 2876 | BE7: =BE$2-AU7 -> 605 | BG7: 4.59 | BH7: =BG7*$BH$1 -> 9.2718 | BI7: =ROUND(C7*BI$2,2) -> 1.46 | BJ7: =ROUND(D7*BJ$2,2) -> 3.49 | BL7: =ROUND(IF(Q7>BL$2,100,IF(Q7>BL$3,BM$1*Q7+BM$2, Q7*BM$3+BM$4)),1) -> 99 | BM7: =ROUND(IF(F7>BL$2,100, IF(F7>BL$3,BM$1*F7+BM$2, F7*BM$3+BM$4)),1) -> 84.8 | BN7: =ROUND(IF(AC7>BL$2,100,IF(AC7>BL$3,BM$1*AC7+BM$2, AC7*BM$3+BM$4)),1) -> 71.8 | BO7: =ROUND((0.6105*(EXP((17.273*O7)/(O7+237.3))))*BN7/100,3) -> 0.431 | BP7: =ROUND((100-BN7)*BO7/BN7,3) -> 0.169 | BT7: =BI7 -> 1.46 | BU7: =BJ7 -> 3.49 | BV7: =ROUND(E7,1) -> -2.8 | BW7: =ROUND(G7,1) -> -3.5 | BX7: =ROUND(H7,1) -> -3.8 | BY7: =ROUND(I7,1) -> -0.1 | BZ7: =ROUND(J7,1) -> -0.4 | CA7: =ROUND(K7,1) -> -0.2 | CB7: =ROUND(L7,1) -> 0.8 | CC7: =ROUND(BM7,1) -> 84.8 | CD7: =ROUND(O7,1) -> -0.2 | CE7: =ROUND(S7,1) -> 0.4 | CF7: =ROUND(T7,1) -> 0.4 | CG7: =ROUND(U7,1) -> 0.2 | CH7: =ROUND(V7,1) -> -0.3 | CI7: =ROUND(W7,1) -> 0.1 | CJ7: =ROUND(X7,1) -> 1.1 | CK7: =ROUND(BL7,1) -> 99 | CL7: =ROUND(AA7,1) -> -8.5 | CM7: =ROUND(AE7,1) -> -10.3 | CN7: =ROUND(AF7,1) -> -11.7 | CO7: =ROUND(AG7,1) -> -0.3 | CP7: =ROUND(AH7,1) -> -0.7 | CQ7: =ROUND(AI7,1) -> -0.4 | CR7: =ROUND(AJ7,1) -> 0.6 | CS7: =ROUND(BN7,1) -> 71.8 | CT7: =BE7 -> 605 | CU7: =PPTest!K7 -> 2.9 | CV7: =ROUND(M7,2) -> 1.62 | CW7: =ROUND(Y7,2) -> 4.65 | CX7: =BO7 -> 0.431 | CY7: =BP7 -> 0.169 | CZ7: =BB7 -> 13.03
A8: =A7+1 -> 38719 | B8: 2 | C8: 3.239 | D8: 6.016 | E8: -1.613 | F8: 97.1 | G8: -2.173 | H8: -2.357 | I8: -0.049 | J8: -0.439 | K8: -0.172 | L8: 0.802 | M8: 1.315 | N8: 0 | O8: 1.079 | P8: 1217 | Q8: 110 | R8: 2254 | S8: 3.066 | T8: 3.527 | U8: 0.23 | V8: -0.178 | W8: 0.071 | X8: 1.049 | Y8: 4.65 | Z8: 229 | AA8: -3.864 | AB8: 845 | AC8: 77.4 | AD8: 1216 | AE8: -5.8 | AF8: -6.711 | AG8: -0.285 | AH8: -0.699 | AI8: -0.391 | AJ8: 0.584 | AK8: 0.14 | AL8: 0.272 | AM8: 0.197 | AN8: 0.097 | AO8: 0.087 | AP8: 0.094 | AQ8: 0.053 | AR8: 0.06 | AS8: 2929 | AT8: 2920 | AU8: 2924 | AV8: -2.957 | AW8: -3.026 | AX8: -0.304 | AY8: 0.28 | AZ8: -5.566 | BA8: -5.912 | BB8: 13.01 | BC8: 2876 | BE8: =BE$2-AU8 -> 586 | BG8: 4.63 | BH8: =BG8*$BH$1 -> 9.3526 | BI8: =ROUND(C8*BI$2,2) -> 3.17 | BJ8: =ROUND(D8*BJ$2,2) -> 6.62 | BL8: =ROUND(IF(Q8>BL$2,100,IF(Q8>BL$3,BM$1*Q8+BM$2, Q8*BM$3+BM$4)),1) -> 98.2 | BM8: =ROUND(IF(F8>BL$2,100, IF(F8>BL$3,BM$1*F8+BM$2, F8*BM$3+BM$4)),1) -> 78.4 | BN8: =ROUND(IF(AC8>BL$2,100,IF(AC8>BL$3,BM$1*AC8+BM$2, AC8*BM$3+BM$4)),1) -> 61.1 | BO8: =ROUND((0.6105*(EXP((17.273*O8)/(O8+237.3))))*BN8/100,3) -> 0.403 | BP8: =ROUND((100-BN8)*BO8/BN8,3) -> 0.257 | BT8: =BI8 -> 3.17 | BU8: =BJ8 -> 6.62 | BV8: =ROUND(E8,1) -> -1.6 | BW8: =ROUND(G8,1) -> -2.2 | BX8: =ROUND(H8,1) -> -2.4 | BY8: =ROUND(I8,1) -> 0 | BZ8: =ROUND(J8,1) -> -0.4 | CA8: =ROUND(K8,1) -> -0.2 | CB8: =ROUND(L8,1) -> 0.8 | CC8: =ROUND(BM8,1) -> 78.4 | CD8: =ROUND(O8,1) -> 1.1 | CE8: =ROUND(S8,1) -> 3.1 | CF8: =ROUND(T8,1) -> 3.5 | CG8: =ROUND(U8,1) -> 0.2 | CH8: =ROUND(V8,1) -> -0.2 | CI8: =ROUND(W8,1) -> 0.1 | CJ8: =ROUND(X8,1) -> 1 | CK8: =ROUND(BL8,1) -> 98.2 | CL8: =ROUND(AA8,1) -> -3.9 | CM8: =ROUND(AE8,1) -> -5.8 | CN8: =ROUND(AF8,1) -> -6.7 | CO8: =ROUND(AG8,1) -> -0.3 | CP8: =ROUND(AH8,1) -> -0.7 | CQ8: =ROUND(AI8,1) -> -0.4 | CR8: =ROUND(AJ8,1) -> 0.6 | CS8: =ROUND(BN8,1) -> 61.1 | CT8: =BE8 -> 586 | CU8: =PPTest!K8 -> 0 | CV8: =ROUND(M8,2) -> 1.32 | CW8: =ROUND(Y8,2) -> 4.65 | CX8: =BO8 -> 0.403 | CY8: =BP8 -> 0.257 | CZ8: =BB8 -> 13.01
A9: =A8+1 -> 38720 | B9: 3 | C9: 1.853 | D9: 2.304 | E9: -3.32 | F9: 103.8 | G9: -3.726 | H9: -3.799 | I9: -0.052 | J9: -0.478 | K9: -0.201 | L9: 0.774 | M9: 1.204 | N9: 0 | O9: -1.052 | P9: 1249 | Q9: 111 | R9: 416 | S9: 0.09 | T9: 0.284 | U9: 0.071 | V9: -0.359 | W9: -0.088 | X9: 0.876 | Y9: 3.187 | Z9: 1849 | AA9: -5.446 | AB9: 1658 | AC9: 79.3 | AD9: 1320 | AE9: -7 | AF9: -7.76 | AG9: -0.436 | AH9: -0.868 | AI9: -0.55 | AJ9: 0.426 | AK9: 0.083 | AL9: 0.104 | AM9: 0.115 | AN9: 0.074 | AO9: 0.147 | AP9: 0.261 | AQ9: 0.122 | AR9: 0.094 | AS9: 2836 | AT9: 2835 | AU9: 2835 | AV9: -3.914 | AW9: -3.977 | AX9: -1.911 | AY9: -1.64 | AZ9: -6.389 | BA9: -6.723 | BB9: 13.11 | BC9: 2876 | BE9: =BE$2-AU9 -> 675 | BG9: 4.67 | BH9: =BG9*$BH$1 -> 9.4334 | BI9: =ROUND(C9*BI$2,2) -> 1.82 | BJ9: =ROUND(D9*BJ$2,2) -> 2.53 | BL9: =ROUND(IF(Q9>BL$2,100,IF(Q9>BL$3,BM$1*Q9+BM$2, Q9*BM$3+BM$4)),1) -> 99.8 | BM9: =ROUND(IF(F9>BL$2,100, IF(F9>BL$3,BM$1*F9+BM$2, F9*BM$3+BM$4)),1) -> 88.3 | BN9: =ROUND(IF(AC9>BL$2,100,IF(AC9>BL$3,BM$1*AC9+BM$2, AC9*BM$3+BM$4)),1) -> 62.8 | BO9: =ROUND((0.6105*(EXP((17.273*O9)/(O9+237.3))))*BN9/100,3) -> 0.355 | BP9: =ROUND((100-BN9)*BO9/BN9,3) -> 0.21 | BT9: =BI9 -> 1.82 | BU9: =BJ9 -> 2.53 | BV9: =ROUND(E9,1) -> -3.3 | BW9: =ROUND(G9,1) -> -3.7 | BX9: =ROUND(H9,1) -> -3.8 | BY9: =ROUND(I9,1) -> -0.1 | BZ9: =ROUND(J9,1) -> -0.5 | CA9: =ROUND(K9,1) -> -0.2 | CB9: =ROUND(L9,1) -> 0.8 | CC9: =ROUND(BM9,1) -> 88.3 | CD9: =ROUND(O9,1) -> -1.1 | CE9: =ROUND(S9,1) -> 0.1 | CF9: =ROUND(T9,1) -> 0.3 | CG9: =ROUND(U9,1) -> 0.1 | CH9: =ROUND(V9,1) -> -0.4 | CI9: =ROUND(W9,1) -> -0.1 | CJ9: =ROUND(X9,1) -> 0.9 | CK9: =ROUND(BL9,1) -> 99.8 | CL9: =ROUND(AA9,1) -> -5.4 | CM9: =ROUND(AE9,1) -> -7 | CN9: =ROUND(AF9,1) -> -7.8 | CO9: =ROUND(AG9,1) -> -0.4 | CP9: =ROUND(AH9,1) -> -0.9 | CQ9: =ROUND(AI9,1) -> -0.6 | CR9: =ROUND(AJ9,1) -> 0.4 | CS9: =ROUND(BN9,1) -> 62.8 | CT9: =BE9 -> 675 | CU9: =PPTest!K9 -> 11.6 | CV9: =ROUND(M9,2) -> 1.2 | CW9: =ROUND(Y9,2) -> 3.19 | CX9: =BO9 -> 0.355 | CY9: =BP9 -> 0.21 | CZ9: =BB9 -> 13.11
A10: =A9+1 -> 38721 | B10: 4 | C10: 2.784 | D10: 3.342 | E10: -2.952 | F10: 99.2 | G10: -3.539 | H10: -3.74 | I10: -0.047 | J10: -0.529 | K10: -0.207 | L10: 0.777 | M10: 1.429 | N10: 0 | O10: 0.347 | P10: 1326 | Q10: 110.6 | R10: 506 | S10: 1.591 | T10: 1.483 | U10: 0.19 | V10: -0.322 | W10: 0.019 | X10: 0.995 | Y10: 4.53 | Z10: 2240 | AA10: -5.863 | AB10: 559 | AC10: 82.5 | AD10: 1251 | AE10: -8.25 | AF10: -9.32 | AG10: -0.386 | AH10: -0.85 | AI10: -0.522 | AJ10: 0.465 | AK10: 0.104 | AL10: 0.105 | AM10: 0.111 | AN10: 0.097 | AO10: 0.212 | AP10: 0.212 | AQ10: 0.093 | AR10: 0.066 | AS10: 2854 | AT10: 2844 | AU10: 2849 | AV10: -4.405 | AW10: -4.455 | AX10: -1.292 | AY10: -0.925 | AZ10: -7.07 | BA10: -7.48 | BB10: 13.1 | BC10: 2876 | BE10: =BE$2-AU10 -> 661 | BG10: 4.72 | BH10: =BG10*$BH$1 -> 9.5344 | BI10: =ROUND(C10*BI$2,2) -> 2.73 | BJ10: =ROUND(D10*BJ$2,2) -> 3.68 | BL10: =ROUND(IF(Q10>BL$2,100,IF(Q10>BL$3,BM$1*Q10+BM$2, Q10*BM$3+BM$4)),1) -> 99.2 | BM10: =ROUND(IF(F10>BL$2,100, IF(F10>BL$3,BM$1*F10+BM$2, F10*BM$3+BM$4)),1) -> 81 | BN10: =ROUND(IF(AC10>BL$2,100,IF(AC10>BL$3,BM$1*AC10+BM$2, AC10*BM$3+BM$4)),1) -> 65.6 | BO10: =ROUND((0.6105*(EXP((17.273*O10)/(O10+237.3))))*BN10/100,3) -> 0.411 | BP10: =ROUND((100-BN10)*BO10/BN10,3) -> 0.216 | BT10: =BI10 -> 2.73 | BU10: =BJ10 -> 3.68 | BV10: =ROUND(E10,1) -> -3 | BW10: =ROUND(G10,1) -> -3.5 | BX10: =ROUND(H10,1) -> -3.7 | BY10: =ROUND(I10,1) -> 0 | BZ10: =ROUND(J10,1) -> -0.5 | CA10: =ROUND(K10,1) -> -0.2 | CB10: =ROUND(L10,1) -> 0.8 | CC10: =ROUND(BM10,1) -> 81 | CD10: =ROUND(O10,1) -> 0.3 | CE10: =ROUND(S10,1) -> 1.6 | CF10: =ROUND(T10,1) -> 1.5 | CG10: =ROUND(U10,1) -> 0.2 | CH10: =ROUND(V10,1) -> -0.3 | CI10: =ROUND(W10,1) -> 0 | CJ10: =ROUND(X10,1) -> 1 | CK10: =ROUND(BL10,1) -> 99.2 | CL10: =ROUND(AA10,1) -> -5.9 | CM10: =ROUND(AE10,1) -> -8.3 | CN10: =ROUND(AF10,1) -> -9.3 | CO10: =ROUND(AG10,1) -> -0.4 | CP10: =ROUND(AH10,1) -> -0.9 | CQ10: =ROUND(AI10,1) -> -0.5 | CR10: =ROUND(AJ10,1) -> 0.5 | CS10: =ROUND(BN10,1) -> 65.6 | CT10: =BE10 -> 661 | CU10: =PPTest!K10 -> 0 | CV10: =ROUND(M10,2) -> 1.43 | CW10: =ROUND(Y10,2) -> 4.53 | CX10: =BO10 -> 0.411 | CY10: =BP10 -> 0.216 | CZ10: =BB10 -> 13.1
A11: =A10+1 -> 38722 | B11: 5 | C11: 0.655 | D11: 1.219 | E11: -0.771 | F11: 99.1 | G11: -1.235 | H11: -1.322 | I11: -0.014 | J11: -0.427 | K11: -0.163 | L11: 0.823 | M11: 1.827 | N11: 0 | O11: 1.334 | P11: 1447 | Q11: 110.5 | R11: 2344 | S11: 1.017 | T11: 0.989 | U11: 0.077 | V11: -0.331 | W11: -0.093 | X11: 0.882 | Y11: 5.488 | Z11: 807 | AA11: -2.931 | AB11: 10 | AC11: 84.1 | AD11: 635 | AE11: -3.468 | AF11: -3.547 | AG11: -0.141 | AH11: -0.523 | AI11: -0.214 | AJ11: 0.769 | AK11: 0.165 | AL11: 0.128 | AM11: 0.083 | AN11: 0.048 | AO11: 0.095 | AP11: 0.184 | AQ11: 0.152 | AR11: 0.144 | AS11: 2870 | AT11: 2862 | AU11: 2866 | AV11: -1.68 | AW11: -1.69 | AX11: -0.243 | AY11: -0.176 | AZ11: -3.439 | BA11: -3.51 | BB11: 12.7 | BC11: 2876 | BE11: =BE$2-AU11 -> 644 | BG11: 4.76 | BH11: =BG11*$BH$1 -> 9.6152 | BI11: =ROUND(C11*BI$2,2) -> 0.64 | BJ11: =ROUND(D11*BJ$2,2) -> 1.34 | BL11: =ROUND(IF(Q11>BL$2,100,IF(Q11>BL$3,BM$1*Q11+BM$2, Q11*BM$3+BM$4)),1) -> 99 | BM11: =ROUND(IF(F11>BL$2,100, IF(F11>BL$3,BM$1*F11+BM$2, F11*BM$3+BM$4)),1) -> 80.9 | BN11: =ROUND(IF(AC11>BL$2,100,IF(AC11>BL$3,BM$1*AC11+BM$2, AC11*BM$3+BM$4)),1) -> 67 | BO11: =ROUND((0.6105*(EXP((17.273*O11)/(O11+237.3))))*BN11/100,3) -> 0.451 | BP11: =ROUND((100-BN11)*BO11/BN11,3) -> 0.222 | BT11: =BI11 -> 0.64 | BU11: =BJ11 -> 1.34 | BV11: =ROUND(E11,1) -> -0.8 | BW11: =ROUND(G11,1) -> -1.2 | BX11: =ROUND(H11,1) -> -1.3 | BY11: =ROUND(I11,1) -> 0 | BZ11: =ROUND(J11,1) -> -0.4 | CA11: =ROUND(K11,1) -> -0.2 | CB11: =ROUND(L11,1) -> 0.8 | CC11: =ROUND(BM11,1) -> 80.9 | CD11: =ROUND(O11,1) -> 1.3 | CE11: =ROUND(S11,1) -> 1 | CF11: =ROUND(T11,1) -> 1 | CG11: =ROUND(U11,1) -> 0.1 | CH11: =ROUND(V11,1) -> -0.3 | CI11: =ROUND(W11,1) -> -0.1 | CJ11: =ROUND(X11,1) -> 0.9 | CK11: =ROUND(BL11,1) -> 99 | CL11: =ROUND(AA11,1) -> -2.9 | CM11: =ROUND(AE11,1) -> -3.5 | CN11: =ROUND(AF11,1) -> -3.5 | CO11: =ROUND(AG11,1) -> -0.1 | CP11: =ROUND(AH11,1) -> -0.5 | CQ11: =ROUND(AI11,1) -> -0.2 | CR11: =ROUND(AJ11,1) -> 0.8 | CS11: =ROUND(BN11,1) -> 67 | CT11: =BE11 -> 644 | CU11: =PPTest!K11 -> 0 | CV11: =ROUND(M11,2) -> 1.83 | CW11: =ROUND(Y11,2) -> 5.49 | CX11: =BO11 -> 0.451 | CY11: =BP11 -> 0.222 | CZ11: =BB11 -> 12.7
A12: =A11+1 -> 38723 | B12: 6 | C12: 1.552 | D12: 2.814 | E12: 0.365 | F12: 108.5 | G12: -0.042 | H12: -0.092 | I12: 0.09 | J12: -0.295 | K12: -0.116 | L12: 0.842 | M12: 1.392 | N12: 0 | O12: 1.87 | P12: 1105 | Q12: 111 | R12: 324 | S12: 2.144 | T12: 2.245 | U12: 0.167 | V12: -0.206 | W12: -0.031 | X12: 0.933 | Y12: 4.277 | Z12: 1627 | AA12: -1.781 | AB12: 315 | AC12: 104.3 | AD12: 1638 | AE12: -2.241 | AF12: -2.218 | AG12: -0.014 | AH12: -0.406 | AI12: -0.196 | AJ12: 0.779 | AK12: 0.055 | AL12: 0.069 | AM12: 0.044 | AN12: 0.062 | AO12: 0.175 | AP12: 0.292 | AQ12: 0.222 | AR12: 0.082 | AS12: 2868 | AT12: 2862 | AU12: 2865 | AV12: -0.214 | AW12: -0.231 | AX12: 1.074 | AY12: 1.172 | AZ12: -1.642 | BA12: -1.557 | BB12: 12.8 | BC12: 2876 | BE12: =BE$2-AU12 -> 645 | BG12: 4.82 | BH12: =BG12*$BH$1 -> 9.7364 | BI12: =ROUND(C12*BI$2,2) -> 1.52 | BJ12: =ROUND(D12*BJ$2,2) -> 3.1 | BL12: =ROUND(IF(Q12>BL$2,100,IF(Q12>BL$3,BM$1*Q12+BM$2, Q12*BM$3+BM$4)),1) -> 99.8 | BM12: =ROUND(IF(F12>BL$2,100, IF(F12>BL$3,BM$1*F12+BM$2, F12*BM$3+BM$4)),1) -> 95.8 | BN12: =ROUND(IF(AC12>BL$2,100,IF(AC12>BL$3,BM$1*AC12+BM$2, AC12*BM$3+BM$4)),1) -> 89.1 | BO12: =ROUND((0.6105*(EXP((17.273*O12)/(O12+237.3))))*BN12/100,3) -> 0.623 | BP12: =ROUND((100-BN12)*BO12/BN12,3) -> 0.076 | BT12: =BI12 -> 1.52 | BU12: =BJ12 -> 3.1 | BV12: =ROUND(E12,1) -> 0.4 | BW12: =ROUND(G12,1) -> 0 | BX12: =ROUND(H12,1) -> -0.1 | BY12: =ROUND(I12,1) -> 0.1 | BZ12: =ROUND(J12,1) -> -0.3 | CA12: =ROUND(K12,1) -> -0.1 | CB12: =ROUND(L12,1) -> 0.8 | CC12: =ROUND(BM12,1) -> 95.8 | CD12: =ROUND(O12,1) -> 1.9 | CE12: =ROUND(S12,1) -> 2.1 | CF12: =ROUND(T12,1) -> 2.2 | CG12: =ROUND(U12,1) -> 0.2 | CH12: =ROUND(V12,1) -> -0.2 | CI12: =ROUND(W12,1) -> 0 | CJ12: =ROUND(X12,1) -> 0.9 | CK12: =ROUND(BL12,1) -> 99.8 | CL12: =ROUND(AA12,1) -> -1.8 | CM12: =ROUND(AE12,1) -> -2.2 | CN12: =ROUND(AF12,1) -> -2.2 | CO12: =ROUND(AG12,1) -> 0 | CP12: =ROUND(AH12,1) -> -0.4 | CQ12: =ROUND(AI12,1) -> -0.2 | CR12: =ROUND(AJ12,1) -> 0.8 | CS12: =ROUND(BN12,1) -> 89.1 | CT12: =BE12 -> 645 | CU12: =PPTest!K12 -> 0.1 | CV12: =ROUND(M12,2) -> 1.39 | CW12: =ROUND(Y12,2) -> 4.28 | CX12: =BO12 -> 0.623 | CY12: =BP12 -> 0.076 | CZ12: =BB12 -> 12.8
A13: =A12+1 -> 38724 | B13: 7 | C13: 2.295 | D13: 3.38 | E13: -2.588 | F13: 110.1 | G13: -3.247 | H13: -3.427 | I13: 0.066 | J13: -0.372 | K13: -0.17 | L13: 0.784 | M13: 0.747 | N13: 0 | O13: -0.056 | P13: 2 | Q13: 111.2 | R13: 702 | S13: -0.49 | T13: -0.456 | U13: 0.34 | V13: -0.132 | W13: 0.067 | X13: 1.02 | Y13: 2.322 | Z13: 1513 | AA13: -6.528 | AB13: 901 | AC13: 105.5 | AD13: 957 | AE13: -8.66 | AF13: -10.2 | AG13: -0.231 | AH13: -0.674 | AI13: -0.436 | AJ13: 0.529 | AK13: 0.071 | AL13: 0.303 | AM13: 0.256 | AN13: 0.058 | AO13: 0.137 | AP13: 0.114 | AQ13: 0.04 | AR13: 0.02 | AS13: 2844 | AT13: 2841 | AU13: 2843 | AV13: -3.38 | AW13: -3.498 | AX13: -0.325 | AY13: -0.455 | AZ13: -8.53 | BA13: -9 | BB13: 13.02 | BC13: 2876 | BE13: =BE$2-AU13 -> 667 | BG13: 4.87 | BH13: =BG13*$BH$1 -> 9.8374 | BI13: =ROUND(C13*BI$2,2) -> 2.25 | BJ13: =ROUND(D13*BJ$2,2) -> 3.72 | BL13: =ROUND(IF(Q13>BL$2,100,IF(Q13>BL$3,BM$1*Q13+BM$2, Q13*BM$3+BM$4)),1) -> 100 | BM13: =ROUND(IF(F13>BL$2,100, IF(F13>BL$3,BM$1*F13+BM$2, F13*BM$3+BM$4)),1) -> 98.4 | BN13: =ROUND(IF(AC13>BL$2,100,IF(AC13>BL$3,BM$1*AC13+BM$2, AC13*BM$3+BM$4)),1) -> 91 | BO13: =ROUND((0.6105*(EXP((17.273*O13)/(O13+237.3))))*BN13/100,3) -> 0.553 | BP13: =ROUND((100-BN13)*BO13/BN13,3) -> 0.055 | BT13: =BI13 -> 2.25 | BU13: =BJ13 -> 3.72 | BV13: =ROUND(E13,1) -> -2.6 | BW13: =ROUND(G13,1) -> -3.2 | BX13: =ROUND(H13,1) -> -3.4 | BY13: =ROUND(I13,1) -> 0.1 | BZ13: =ROUND(J13,1) -> -0.4 | CA13: =ROUND(K13,1) -> -0.2 | CB13: =ROUND(L13,1) -> 0.8 | CC13: =ROUND(BM13,1) -> 98.4 | CD13: =ROUND(O13,1) -> -0.1 | CE13: =ROUND(S13,1) -> -0.5 | CF13: =ROUND(T13,1) -> -0.5 | CG13: =ROUND(U13,1) -> 0.3 | CH13: =ROUND(V13,1) -> -0.1 | CI13: =ROUND(W13,1) -> 0.1 | CJ13: =ROUND(X13,1) -> 1 | CK13: =ROUND(BL13,1) -> 100 | CL13: =ROUND(AA13,1) -> -6.5 | CM13: =ROUND(AE13,1) -> -8.7 | CN13: =ROUND(AF13,1) -> -10.2 | CO13: =ROUND(AG13,1) -> -0.2 | CP13: =ROUND(AH13,1) -> -0.7 | CQ13: =ROUND(AI13,1) -> -0.4 | CR13: =ROUND(AJ13,1) -> 0.5 | CS13: =ROUND(BN13,1) -> 91 | CT13: =BE13 -> 667 | CU13: =PPTest!K13 -> 2.9 | CV13: =ROUND(M13,2) -> 0.75 | CW13: =ROUND(Y13,2) -> 2.32 | CX13: =BO13 -> 0.553 | CY13: =BP13 -> 0.055 | CZ13: =BB13 -> 13.02
A14: =A13+1 -> 38725 | B14: 8 | C14: 0.564 | D14: 0.987 | E14: -3.071 | F14: 105.8 | G14: -3.489 | H14: -3.512 | I14: 0.131 | J14: -0.43 | K14: -0.168 | L14: 0.794 | M14: 1.387 | N14: 0 | O14: -1.036 | P14: 1340 | Q14: 111.1 | R14: 7 | S14: 0.08 | T14: 0.488 | U14: 0.265 | V14: -0.27 | W14: -0.043 | X14: 0.921 | Y14: 4.996 | Z14: 2249 | AA14: -4.344 | AB14: 1741 | AC14: 94.8 | AD14: 1341 | AE14: -5.748 | AF14: -6.544 | AG14: -0.058 | AH14: -0.6 | AI14: -0.322 | AJ14: 0.643 | AK14: 0.022 | AL14: 0.026 | AM14: 0.058 | AN14: 0.064 | AO14: 0.24 | AP14: 0.422 | AQ14: 0.145 | AR14: 0.024 | AS14: 2831 | AT14: 2830 | AU14: 2830 | AV14: -3.512 | AW14: -3.584 | AX14: -1.683 | AY14: -1.417 | AZ14: -5.524 | BA14: -5.73 | BB14: 13.01 | BC14: 2876 | BE14: =BE$2-AU14 -> 680 | BG14: 4.93 | BH14: =BG14*$BH$1 -> 9.9586 | BI14: =ROUND(C14*BI$2,2) -> 0.55 | BJ14: =ROUND(D14*BJ$2,2) -> 1.09 | BL14: =ROUND(IF(Q14>BL$2,100,IF(Q14>BL$3,BM$1*Q14+BM$2, Q14*BM$3+BM$4)),1) -> 100 | BM14: =ROUND(IF(F14>BL$2,100, IF(F14>BL$3,BM$1*F14+BM$2, F14*BM$3+BM$4)),1) -> 91.5 | BN14: =ROUND(IF(AC14>BL$2,100,IF(AC14>BL$3,BM$1*AC14+BM$2, AC14*BM$3+BM$4)),1) -> 76.4 | BO14: =ROUND((0.6105*(EXP((17.273*O14)/(O14+237.3))))*BN14/100,3) -> 0.432 | BP14: =ROUND((100-BN14)*BO14/BN14,3) -> 0.133 | BT14: =BI14 -> 0.55 | BU14: =BJ14 -> 1.09 | BV14: =ROUND(E14,1) -> -3.1 | BW14: =ROUND(G14,1) -> -3.5 | BX14: =ROUND(H14,1) -> -3.5 | BY14: =ROUND(I14,1) -> 0.1 | BZ14: =ROUND(J14,1) -> -0.4 | CA14: =ROUND(K14,1) -> -0.2 | CB14: =ROUND(L14,1) -> 0.8 | CC14: =ROUND(BM14,1) -> 91.5 | CD14: =ROUND(O14,1) -> -1 | CE14: =ROUND(S14,1) -> 0.1 | CF14: =ROUND(T14,1) -> 0.5 | CG14: =ROUND(U14,1) -> 0.3 | CH14: =ROUND(V14,1) -> -0.3 | CI14: =ROUND(W14,1) -> 0 | CJ14: =ROUND(X14,1) -> 0.9 | CK14: =ROUND(BL14,1) -> 100 | CL14: =ROUND(AA14,1) -> -4.3 | CM14: =ROUND(AE14,1) -> -5.7 | CN14: =ROUND(AF14,1) -> -6.5 | CO14: =ROUND(AG14,1) -> -0.1 | CP14: =ROUND(AH14,1) -> -0.6 | CQ14: =ROUND(AI14,1) -> -0.3 | CR14: =ROUND(AJ14,1) -> 0.6 | CS14: =ROUND(BN14,1) -> 76.4 | CT14: =BE14 -> 680 | CU14: =PPTest!K14 -> 1.7 | CV14: =ROUND(M14,2) -> 1.39 | CW14: =ROUND(Y14,2) -> 5 | CX14: =BO14 -> 0.432 | CY14: =BP14 -> 0.133 | CZ14: =BB14 -> 13.01
A15: =A14+1 -> 38726 | B15: 9 | C15: 0.156 | D15: 0.258 | E15: -2.615 | F15: 107.3 | G15: -3.029 | H15: -3.076 | I15: 0.097 | J15: -0.469 | K15: -0.174 | L15: 0.801 | M15: 1.484 | N15: 0 | O15: -1.45 | P15: 906 | Q15: 111.1 | R15: 2055 | S15: -1.623 | T15: -1.634 | U15: 0.17 | V15: -0.398 | W15: -0.117 | X15: 0.859 | Y15: 5.408 | Z15: 442 | AA15: -3.77 | AB15: 39 | AC15: 99.5 | AD15: 9 | AE15: -4.355 | AF15: -4.875 | AG15: -0.031 | AH15: -0.584 | AI15: -0.3 | AJ15: 0.687 | AK15: 0.061 | AL15: 0.039 | AM15: 0.065 | AN15: 0.062 | AO15: 0.174 | AP15: 0.238 | AQ15: 0.237 | AR15: 0.124 | AS15: 2726 | AT15: 2710 | AU15: 2717 | AV15: -3.242 | AW15: -3.273 | AX15: -2.325 | AY15: -2.355 | AZ15: -4.225 | BA15: -4.229 | BB15: 12.65 | BC15: 2876 | BE15: =BE$2-AU15 -> 793 | BG15: 4.99 | BH15: =BG15*$BH$1 -> 10.0798 | BI15: =ROUND(C15*BI$2,2) -> 0.15 | BJ15: =ROUND(D15*BJ$2,2) -> 0.28 | BL15: =ROUND(IF(Q15>BL$2,100,IF(Q15>BL$3,BM$1*Q15+BM$2, Q15*BM$3+BM$4)),1) -> 100 | BM15: =ROUND(IF(F15>BL$2,100, IF(F15>BL$3,BM$1*F15+BM$2, F15*BM$3+BM$4)),1) -> 93.9 | BN15: =ROUND(IF(AC15>BL$2,100,IF(AC15>BL$3,BM$1*AC15+BM$2, AC15*BM$3+BM$4)),1) -> 81.5 | BO15: =ROUND((0.6105*(EXP((17.273*O15)/(O15+237.3))))*BN15/100,3) -> 0.447 | BP15: =ROUND((100-BN15)*BO15/BN15,3) -> 0.101 | BT15: =BI15 -> 0.15 | BU15: =BJ15 -> 0.28 | BV15: =ROUND(E15,1) -> -2.6 | BW15: =ROUND(G15,1) -> -3 | BX15: =ROUND(H15,1) -> -3.1 | BY15: =ROUND(I15,1) -> 0.1 | BZ15: =ROUND(J15,1) -> -0.5 | CA15: =ROUND(K15,1) -> -0.2 | CB15: =ROUND(L15,1) -> 0.8 | CC15: =ROUND(BM15,1) -> 93.9 | CD15: =ROUND(O15,1) -> -1.5 | CE15: =ROUND(S15,1) -> -1.6 | CF15: =ROUND(T15,1) -> -1.6 | CG15: =ROUND(U15,1) -> 0.2 | CH15: =ROUND(V15,1) -> -0.4 | CI15: =ROUND(W15,1) -> -0.1 | CJ15: =ROUND(X15,1) -> 0.9 | CK15: =ROUND(BL15,1) -> 100 | CL15: =ROUND(AA15,1) -> -3.8 | CM15: =ROUND(AE15,1) -> -4.4 | CN15: =ROUND(AF15,1) -> -4.9 | CO15: =ROUND(AG15,1) -> 0 | CP15: =ROUND(AH15,1) -> -0.6 | CQ15: =ROUND(AI15,1) -> -0.3 | CR15: =ROUND(AJ15,1) -> 0.7 | CS15: =ROUND(BN15,1) -> 81.5 | CT15: =BE15 -> 793 | CU15: =PPTest!K15 -> 14.7 | CV15: =ROUND(M15,2) -> 1.48 | CW15: =ROUND(Y15,2) -> 5.41 | CX15: =BO15 -> 0.447 | CY15: =BP15 -> 0.101 | CZ15: =BB15 -> 12.65
A16: =A15+1 -> 38727 | B16: 10 | C16: 0.201 | D16: 0.396 | E16: -1.888 | F16: 108.5 | G16: -2.305 | H16: -2.422 | I16: 0.131 | J16: -0.403 | K16: -0.169 | L16: 0.802 | M16: 1.614 | N16: 0 | O16: -0.072 | P16: 1017 | Q16: 111 | R16: 538 | S16: -0.074 | T16: -0.292 | U16: 0.22 | V16: -0.315 | W16: -0.098 | X16: 0.876 | Y16: 6.113 | Z16: 1205 | AA16: -4.248 | AB16: 2316 | AC16: 99.9 | AD16: 1707 | AE16: -4.99 | AF16: -5.381 | AG16: 0.021 | AH16: -0.509 | AI16: -0.282 | AJ16: 0.687 | AK16: 0.219 | AL16: 0.102 | AM16: 0.067 | AN16: 0.047 | AO16: 0.178 | AP16: 0.239 | AQ16: 0.102 | AR16: 0.046 | AS16: 2632 | AT16: 2631 | AU16: 2631 | AV16: -2.36 | AW16: -2.46 | AX16: -0.842 | AY16: -0.816 | AZ16: -4.601 | BA16: -4.749 | BB16: 12.59 | BC16: 2876 | BE16: =BE$2-AU16 -> 879 | BG16: 5.06 | BH16: =BG16*$BH$1 -> 10.2212 | BI16: =ROUND(C16*BI$2,2) -> 0.2 | BJ16: =ROUND(D16*BJ$2,2) -> 0.44 | BL16: =ROUND(IF(Q16>BL$2,100,IF(Q16>BL$3,BM$1*Q16+BM$2, Q16*BM$3+BM$4)),1) -> 99.8 | BM16: =ROUND(IF(F16>BL$2,100, IF(F16>BL$3,BM$1*F16+BM$2, F16*BM$3+BM$4)),1) -> 95.8 | BN16: =ROUND(IF(AC16>BL$2,100,IF(AC16>BL$3,BM$1*AC16+BM$2, AC16*BM$3+BM$4)),1) -> 82.1 | BO16: =ROUND((0.6105*(EXP((17.273*O16)/(O16+237.3))))*BN16/100,3) -> 0.499 | BP16: =ROUND((100-BN16)*BO16/BN16,3) -> 0.109 | BT16: =BI16 -> 0.2 | BU16: =BJ16 -> 0.44 | BV16: =ROUND(E16,1) -> -1.9 | BW16: =ROUND(G16,1) -> -2.3 | BX16: =ROUND(H16,1) -> -2.4 | BY16: =ROUND(I16,1) -> 0.1 | BZ16: =ROUND(J16,1) -> -0.4 | CA16: =ROUND(K16,1) -> -0.2 | CB16: =ROUND(L16,1) -> 0.8 | CC16: =ROUND(BM16,1) -> 95.8 | CD16: =ROUND(O16,1) -> -0.1 | CE16: =ROUND(S16,1) -> -0.1 | CF16: =ROUND(T16,1) -> -0.3 | CG16: =ROUND(U16,1) -> 0.2 | CH16: =ROUND(V16,1) -> -0.3 | CI16: =ROUND(W16,1) -> -0.1 | CJ16: =ROUND(X16,1) -> 0.9 | CK16: =ROUND(BL16,1) -> 99.8 | CL16: =ROUND(AA16,1) -> -4.2 | CM16: =ROUND(AE16,1) -> -5 | CN16: =ROUND(AF16,1) -> -5.4 | CO16: =ROUND(AG16,1) -> 0 | CP16: =ROUND(AH16,1) -> -0.5 | CQ16: =ROUND(AI16,1) -> -0.3 | CR16: =ROUND(AJ16,1) -> 0.7 | CS16: =ROUND(BN16,1) -> 82.1 | CT16: =BE16 -> 879 | CU16: =PPTest!K16 -> 11.2 | CV16: =ROUND(M16,2) -> 1.61 | CW16: =ROUND(Y16,2) -> 6.11 | CX16: =BO16 -> 0.499 | CY16: =BP16 -> 0.109 | CZ16: =BB16 -> 12.59
A17: =A16+1 -> 38728 | B17: 11 | C17: 0.572 | D17: 0.916 | E17: -3.181 | F17: 108 | G17: -3.508 | H17: -3.543 | I17: 0.147 | J17: -0.426 | K17: -0.167 | L17: 0.799 | M17: 1.956 | N17: 0 | O17: -1.731 | P17: 1220 | Q17: 111.1 | R17: 549 | S17: -0.859 | T17: -0.721 | U17: 0.21 | V17: -0.363 | W17: -0.105 | X17: 0.848 | Y17: 5.089 | Z17: 1235 | AA17: -3.986 | AB17: 454 | AC17: 99.1 | AD17: 1222 | AE17: -4.48 | AF17: -4.764 | AG17: 0.092 | AH17: -0.484 | AI17: -0.211 | AJ17: 0.756 | AK17: 0.028 | AL17: 0.117 | AM17: 0.051 | AN17: 0.013 | AO17: 0.228 | AP17: 0.459 | AQ17: 0.092 | AR17: 0.01 | AS17: 6999 | AT17: 6999 | AU17: 6999 | AV17: -3.384 | AW17: -3.444 | AX17: -2.511 | AY17: -2.494 | AZ17: -4.601 | BA17: -4.681 | BB17: 12.93 | BC17: 2876 | BE17: 920 | BG17: 5.13 | BH17: =BG17*$BH$1 -> 10.3626 | BI17: =ROUND(C17*BI$2,2) -> 0.56 | BJ17: =ROUND(D17*BJ$2,2) -> 1.01 | BL17: =ROUND(IF(Q17>BL$2,100,IF(Q17>BL$3,BM$1*Q17+BM$2, Q17*BM$3+BM$4)),1) -> 100 | BM17: =ROUND(IF(F17>BL$2,100, IF(F17>BL$3,BM$1*F17+BM$2, F17*BM$3+BM$4)),1) -> 95 | BN17: =ROUND(IF(AC17>BL$2,100,IF(AC17>BL$3,BM$1*AC17+BM$2, AC17*BM$3+BM$4)),1) -> 80.9 | BO17: =ROUND((0.6105*(EXP((17.273*O17)/(O17+237.3))))*BN17/100,3) -> 0.435 | BP17: =ROUND((100-BN17)*BO17/BN17,3) -> 0.103 | BT17: =BI17 -> 0.56 | BU17: =BJ17 -> 1.01 | BV17: =ROUND(E17,1) -> -3.2 | BW17: =ROUND(G17,1) -> -3.5 | BX17: =ROUND(H17,1) -> -3.5 | BY17: =ROUND(I17,1) -> 0.1 | BZ17: =ROUND(J17,1) -> -0.4 | CA17: =ROUND(K17,1) -> -0.2 | CB17: =ROUND(L17,1) -> 0.8 | CC17: =ROUND(BM17,1) -> 95 | CD17: =ROUND(O17,1) -> -1.7 | CE17: =ROUND(S17,1) -> -0.9 | CF17: =ROUND(T17,1) -> -0.7 | CG17: =ROUND(U17,1) -> 0.2 | CH17: =ROUND(V17,1) -> -0.4 | CI17: =ROUND(W17,1) -> -0.1 | CJ17: =ROUND(X17,1) -> 0.8 | CK17: =ROUND(BL17,1) -> 100 | CL17: =ROUND(AA17,1) -> -4 | CM17: =ROUND(AE17,1) -> -4.5 | CN17: =ROUND(AF17,1) -> -4.8 | CO17: =ROUND(AG17,1) -> 0.1 | CP17: =ROUND(AH17,1) -> -0.5 | CQ17: =ROUND(AI17,1) -> -0.2 | CR17: =ROUND(AJ17,1) -> 0.8 | CS17: =ROUND(BN17,1) -> 80.9 | CT17: =BE17 -> 920 | CU17: =PPTest!K17 -> 5.3 | CV17: =ROUND(M17,2) -> 1.96 | CW17: =ROUND(Y17,2) -> 5.09 | CX17: =BO17 -> 0.435 | CY17: =BP17 -> 0.103 | CZ17: =BB17 -> 12.93
A18: =A17+1 -> 38729 | B18: 12 | C18: 0.534 | D18: 0.88 | E18: -3.847 | F18: 108.3 | G18: -3.973 | H18: -4.061 | I18: 0.142 | J18: -0.472 | K18: -0.186 | L18: 0.787 | M18: 0.487 | N18: 0 | O18: -2.781 | P18: 1103 | Q18: 110.4 | R18: 426 | S18: -2.173 | T18: -2.546 | U18: 0.213 | V18: -0.417 | W18: -0.137 | X18: 0.837 | Y18: 2.508 | Z18: 12 | AA18: -4.241 | AB18: 1855 | AC18: 101.6 | AD18: 1432 | AE18: -4.715 | AF18: -5.093 | AG18: 0.065 | AH18: -0.532 | AI18: -0.245 | AJ18: 0.732 | AK18: 0.072 | AL18: 0.073 | AM18: 0.072 | AN18: 0.057 | AO18: 0.207 | AP18: 0.304 | AQ18: 0.125 | AR18: 0.091 | AS18: 6999 | AT18: 2519 | AU18: =AT18 -> 2519 | AV18: -3.755 | AW18: -3.861 | AX18: -3.047 | AY18: -3.052 | AZ18: -4.205 | BA18: -4.295 | BB18: 12.9 | BC18: 2876 | BE18: =BE$2-AU18 -> 991 | BG18: 5.2 | BH18: =BG18*$BH$1 -> 10.504 | BI18: =ROUND(C18*BI$2,2) -> 0.52 | BJ18: =ROUND(D18*BJ$2,2) -> 0.97 | BL18: =ROUND(IF(Q18>BL$2,100,IF(Q18>BL$3,BM$1*Q18+BM$2, Q18*BM$3+BM$4)),1) -> 98.8 | BM18: =ROUND(IF(F18>BL$2,100, IF(F18>BL$3,BM$1*F18+BM$2, F18*BM$3+BM$4)),1) -> 95.5 | BN18: =ROUND(IF(AC18>BL$2,100,IF(AC18>BL$3,BM$1*AC18+BM$2, AC18*BM$3+BM$4)),1) -> 84.8 | BO18: =ROUND((0.6105*(EXP((17.273*O18)/(O18+237.3))))*BN18/100,3) -> 0.422 | BP18: =ROUND((100-BN18)*BO18/BN18,3) -> 0.076 | BT18: =BI18 -> 0.52 | BU18: =BJ18 -> 0.97 | BV18: =ROUND(E18,1) -> -3.8 | BW18: =ROUND(G18,1) -> -4 | BX18: =ROUND(H18,1) -> -4.1 | BY18: =ROUND(I18,1) -> 0.1 | BZ18: =ROUND(J18,1) -> -0.5 | CA18: =ROUND(K18,1) -> -0.2 | CB18: =ROUND(L18,1) -> 0.8 | CC18: =ROUND(BM18,1) -> 95.5 | CD18: =ROUND(O18,1) -> -2.8 | CE18: =ROUND(S18,1) -> -2.2 | CF18: =ROUND(T18,1) -> -2.5 | CG18: =ROUND(U18,1) -> 0.2 | CH18: =ROUND(V18,1) -> -0.4 | CI18: =ROUND(W18,1) -> -0.1 | CJ18: =ROUND(X18,1) -> 0.8 | CK18: =ROUND(BL18,1) -> 98.8 | CL18: =ROUND(AA18,1) -> -4.2 | CM18: =ROUND(AE18,1) -> -4.7 | CN18: =ROUND(AF18,1) -> -5.1 | CO18: =ROUND(AG18,1) -> 0.1 | CP18: =ROUND(AH18,1) -> -0.5 | CQ18: =ROUND(AI18,1) -> -0.2 | CR18: =ROUND(AJ18,1) -> 0.7 | CS18: =ROUND(BN18,1) -> 84.8 | CT18: =BE18 -> 991 | CU18: =PPTest!K18 -> 9.2 | CV18: =ROUND(M18,2) -> 0.49 | CW18: =ROUND(Y18,2) -> 2.51 | CX18: =BO18 -> 0.422 | CY18: =BP18 -> 0.076 | CZ18: =BB18 -> 12.9
A19: =A18+1 -> 38730 | B19: 13 | C19: 0.639 | D19: 1.054 | E19: -1.579 | F19: 109.3 | G19: -1.702 | H19: -1.799 | I19: 0.174 | J19: -0.409 | K19: -0.158 | L19: 0.813 | M19: 0.899 | N19: 0 | O19: 0.419 | P19: 1339 | Q19: 111 | R19: 2208 | S19: 0.648 | T19: 0.671 | U19: 0.234 | V19: -0.344 | W19: -0.097 | X19: 0.869 | Y19: 3.652 | Z19: 1353 | AA19: -3.639 | AB19: 1 | AC19: 103.3 | AD19: 1338 | AE19: -3.781 | AF19: -3.793 | AG19: 0.042 | AH19: -0.51 | AI19: -0.205 | AJ19: 0.774 | AK19: 0.08 | AL19: 0.052 | AM19: 0.053 | AN19: 0.065 | AO19: 0.16 | AP19: 0.271 | AQ19: 0.197 | AR19: 0.122 | AS19: 2583 | AT19: 2580 | AU19: 2581 | AV19: -2.089 | AW19: -2.074 | AX19: -0.718 | AY19: -0.686 | AZ19: -4.059 | BA19: -4.079 | BB19: 12.93 | BC19: 2876 | BE19: =BE$2-AU19 -> 929 | BG19: 5.27 | BH19: =BG19*$BH$1 -> 10.6454 | BI19: =ROUND(C19*BI$2,2) -> 0.63 | BJ19: =ROUND(D19*BJ$2,2) -> 1.16 | BL19: =ROUND(IF(Q19>BL$2,100,IF(Q19>BL$3,BM$1*Q19+BM$2, Q19*BM$3+BM$4)),1) -> 99.8 | BM19: =ROUND(IF(F19>BL$2,100, IF(F19>BL$3,BM$1*F19+BM$2, F19*BM$3+BM$4)),1) -> 97.1 | BN19: =ROUND(IF(AC19>BL$2,100,IF(AC19>BL$3,BM$1*AC19+BM$2, AC19*BM$3+BM$4)),1) -> 87.5 | BO19: =ROUND((0.6105*(EXP((17.273*O19)/(O19+237.3))))*BN19/100,3) -> 0.551 | BP19: =ROUND((100-BN19)*BO19/BN19,3) -> 0.079 | BT19: =BI19 -> 0.63 | BU19: =BJ19 -> 1.16 | BV19: =ROUND(E19,1) -> -1.6 | BW19: =ROUND(G19,1) -> -1.7 | BX19: =ROUND(H19,1) -> -1.8 | BY19: =ROUND(I19,1) -> 0.2 | BZ19: =ROUND(J19,1) -> -0.4 | CA19: =ROUND(K19,1) -> -0.2 | CB19: =ROUND(L19,1) -> 0.8 | CC19: =ROUND(BM19,1) -> 97.1 | CD19: =ROUND(O19,1) -> 0.4 | CE19: =ROUND(S19,1) -> 0.6 | CF19: =ROUND(T19,1) -> 0.7 | CG19: =ROUND(U19,1) -> 0.2 | CH19: =ROUND(V19,1) -> -0.3 | CI19: =ROUND(W19,1) -> -0.1 | CJ19: =ROUND(X19,1) -> 0.9 | CK19: =ROUND(BL19,1) -> 99.8 | CL19: =ROUND(AA19,1) -> -3.6 | CM19: =ROUND(AE19,1) -> -3.8 | CN19: =ROUND(AF19,1) -> -3.8 | CO19: =ROUND(AG19,1) -> 0 | CP19: =ROUND(AH19,1) -> -0.5 | CQ19: =ROUND(AI19,1) -> -0.2 | CR19: =ROUND(AJ19,1) -> 0.8 | CS19: =ROUND(BN19,1) -> 87.5 | CT19: =BE19 -> 929 | CU19: =PPTest!K19 -> 0 | CV19: =ROUND(M19,2) -> 0.9 | CW19: =ROUND(Y19,2) -> 3.65 | CX19: =BO19 -> 0.551 | CY19: =BP19 -> 0.079 | CZ19: =BB19 -> 12.93
A20: =A19+1 -> 38731 | B20: 14 | C20: 1.044 | D20: 1.381 | E20: -2.777 | F20: 110 | G20: -3.249 | H20: -3.444 | I20: 0.18 | J20: -0.395 | K20: -0.169 | L20: 0.785 | M20: 0.931 | N20: 0 | O20: -1.371 | P20: 135 | Q20: 111.2 | R20: 2327 | S20: -1.169 | T20: -1.202 | U20: 0.274 | V20: -0.325 | W20: -0.089 | X20: 0.852 | Y20: 3.267 | Z20: 149 | AA20: -4.514 | AB20: 828 | AC20: 105.3 | AD20: 1154 | AE20: -6.183 | AF20: -7.54 | AG20: 0.058 | AH20: -0.505 | AI20: -0.272 | AJ20: 0.682 | AK20: 0.049 | AL20: 0.102 | AM20: 0.083 | AN20: 0.05 | AO20: 0.222 | AP20: 0.358 | AQ20: 0.107 | AR20: 0.028 | AS20: 2615 | AT20: 2614 | AU20: 2614 | AV20: -2.69 | AW20: -2.81 | AX20: -1.58 | AY20: -1.641 | AZ20: -4.184 | BA20: -4.408 | BB20: 13.01 | BC20: 2876 | BE20: =BE$2-AU20 -> 896 | BG20: 5.36 | BH20: =BG20*$BH$1 -> 10.8272 | BI20: =ROUND(C20*BI$2,2) -> 1.02 | BJ20: =ROUND(D20*BJ$2,2) -> 1.52 | BL20: =ROUND(IF(Q20>BL$2,100,IF(Q20>BL$3,BM$1*Q20+BM$2, Q20*BM$3+BM$4)),1) -> 100 | BM20: =ROUND(IF(F20>BL$2,100, IF(F20>BL$3,BM$1*F20+BM$2, F20*BM$3+BM$4)),1) -> 98.2 | BN20: =ROUND(IF(AC20>BL$2,100,IF(AC20>BL$3,BM$1*AC20+BM$2, AC20*BM$3+BM$4)),1) -> 90.7 | BO20: =ROUND((0.6105*(EXP((17.273*O20)/(O20+237.3))))*BN20/100,3) -> 0.501 | BP20: =ROUND((100-BN20)*BO20/BN20,3) -> 0.051 | BT20: =BI20 -> 1.02 | BU20: =BJ20 -> 1.52 | BV20: =ROUND(E20,1) -> -2.8 | BW20: =ROUND(G20,1) -> -3.2 | BX20: =ROUND(H20,1) -> -3.4 | BY20: =ROUND(I20,1) -> 0.2 | BZ20: =ROUND(J20,1) -> -0.4 | CA20: =ROUND(K20,1) -> -0.2 | CB20: =ROUND(L20,1) -> 0.8 | CC20: =ROUND(BM20,1) -> 98.2 | CD20: =ROUND(O20,1) -> -1.4 | CE20: =ROUND(S20,1) -> -1.2 | CF20: =ROUND(T20,1) -> -1.2 | CG20: =ROUND(U20,1) -> 0.3 | CH20: =ROUND(V20,1) -> -0.3 | CI20: =ROUND(W20,1) -> -0.1 | CJ20: =ROUND(X20,1) -> 0.9 | CK20: =ROUND(BL20,1) -> 100 | CL20: =ROUND(AA20,1) -> -4.5 | CM20: =ROUND(AE20,1) -> -6.2 | CN20: =ROUND(AF20,1) -> -7.5 | CO20: =ROUND(AG20,1) -> 0.1 | CP20: =ROUND(AH20,1) -> -0.5 | CQ20: =ROUND(AI20,1) -> -0.3 | CR20: =ROUND(AJ20,1) -> 0.7 | CS20: =ROUND(BN20,1) -> 90.7 | CT20: =BE20 -> 896 | CU20: =PPTest!K20 -> 0 | CV20: =ROUND(M20,2) -> 0.93 | CW20: =ROUND(Y20,2) -> 3.27 | CX20: =BO20 -> 0.501 | CY20: =BP20 -> 0.051 | CZ20: =BB20 -> 13.01
A21: =A20+1 -> 38732 | B21: 15 | C21: 0.779 | D21: 1.079 | E21: -7.21 | F21: 109 | G21: -7.76 | H21: -7.94 | I21: 0.105 | J21: -0.563 | K21: -0.223 | L21: 0.74 | M21: 1.657 | N21: 0 | O21: -4.137 | P21: 1 | Q21: 110.6 | R21: 34 | S21: -4.51 | T21: -4.384 | U21: 0.179 | V21: -0.408 | W21: -0.156 | X21: 0.803 | Y21: 3.479 | Z21: 1251 | AA21: -14 | AB21: 2359 | AC21: 106.4 | AD21: 2354 | AE21: -16.09 | AF21: -17.33 | AG21: -0.122 | AH21: -0.907 | AI21: -0.429 | AJ21: 0.57 | AK21: 0.017 | AL21: 0.173 | AM21: 0.101 | AN21: 0.007 | AO21: 0.163 | AP21: 0.435 | AQ21: 0.097 | AR21: 0.007 | AS21: 6999 | AT21: 2574 | AU21: =AT21 -> 2574 | AV21: -5.706 | AW21: -5.951 | AX21: -3.481 | AY21: -3.631 | AZ21: -9.14 | BA21: -10.11 | BB21: 12.97 | BC21: 2876 | BE21: =BE$2-AU21 -> 936 | BG21: 5.44 | BH21: =BG21*$BH$1 -> 10.9888 | BI21: =ROUND(C21*BI$2,2) -> 0.76 | BJ21: =ROUND(D21*BJ$2,2) -> 1.19 | BL21: =ROUND(IF(Q21>BL$2,100,IF(Q21>BL$3,BM$1*Q21+BM$2, Q21*BM$3+BM$4)),1) -> 99.2 | BM21: =ROUND(IF(F21>BL$2,100, IF(F21>BL$3,BM$1*F21+BM$2, F21*BM$3+BM$4)),1) -> 96.6 | BN21: =ROUND(IF(AC21>BL$2,100,IF(AC21>BL$3,BM$1*AC21+BM$2, AC21*BM$3+BM$4)),1) -> 92.5 | BO21: =ROUND((0.6105*(EXP((17.273*O21)/(O21+237.3))))*BN21/100,3) -> 0.416 | BP21: =ROUND((100-BN21)*BO21/BN21,3) -> 0.034 | BT21: =BI21 -> 0.76 | BU21: =BJ21 -> 1.19 | BV21: =ROUND(E21,1) -> -7.2 | BW21: =ROUND(G21,1) -> -7.8 | BX21: =ROUND(H21,1) -> -7.9 | BY21: =ROUND(I21,1) -> 0.1 | BZ21: =ROUND(J21,1) -> -0.6 | CA21: =ROUND(K21,1) -> -0.2 | CB21: =ROUND(L21,1) -> 0.7 | CC21: =ROUND(BM21,1) -> 96.6 | CD21: =ROUND(O21,1) -> -4.1 | CE21: =ROUND(S21,1) -> -4.5 | CF21: =ROUND(T21,1) -> -4.4 | CG21: =ROUND(U21,1) -> 0.2 | CH21: =ROUND(V21,1) -> -0.4 | CI21: =ROUND(W21,1) -> -0.2 | CJ21: =ROUND(X21,1) -> 0.8 | CK21: =ROUND(BL21,1) -> 99.2 | CL21: =ROUND(AA21,1) -> -14 | CM21: =ROUND(AE21,1) -> -16.1 | CN21: =ROUND(AF21,1) -> -17.3 | CO21: =ROUND(AG21,1) -> -0.1 | CP21: =ROUND(AH21,1) -> -0.9 | CQ21: =ROUND(AI21,1) -> -0.4 | CR21: =ROUND(AJ21,1) -> 0.6 | CS21: =ROUND(BN21,1) -> 92.5 | CT21: =BE21 -> 936 | CU21: =PPTest!K21 -> 5.2 | CV21: =ROUND(M21,2) -> 1.66 | CW21: =ROUND(Y21,2) -> 3.48 | CX21: =BO21 -> 0.416 | CY21: =BP21 -> 0.034 | CZ21: =BB21 -> 12.97
A22: =A21+1 -> 38733 | B22: 16 | C22: 0.909 | D22: 1.297 | E22: -6.868 | F22: 108.2 | G22: -6.895 | H22: -6.988 | I22: 0.088 | J22: -0.695 | K22: -0.232 | L22: 0.77 | M22: 1.478 | N22: 0 | O22: -4.616 | P22: 2359 | Q22: 109.4 | R22: 216 | S22: -4.138 | T22: -4.138 | U22: 0.187 | V22: -0.633 | W22: -0.137 | X22: 0.835 | Y22: 4.53 | Z22: 2248 | AA22: -14.09 | AB22: 5 | AC22: 105.9 | AD22: 1718 | AE22: -15.9 | AF22: -16.43 | AG22: -0.124 | AH22: -0.885 | AI22: -0.407 | AJ22: 0.581 | AK22: 0.065 | AL22: 0.083 | AM22: 0.099 | AN22: 0.116 | AO22: 0.204 | AP22: 0.199 | AQ22: 0.147 | AR22: 0.087 | AS22: 2541 | AT22: 2539 | AU22: 2539 | AV22: -6.606 | AW22: -6.664 | AX22: -4.894 | AY22: -4.944 | AZ22: -10.29 | BA22: -10.73 | BB22: 13.03 | BC22: 2876 | BE22: =BE$2-AU22 -> 971 | BG22: 5.53 | BH22: =BG22*$BH$1 -> 11.1706 | BI22: =ROUND(C22*BI$2,2) -> 0.89 | BJ22: =ROUND(D22*BJ$2,2) -> 1.43 | BL22: =ROUND(IF(Q22>BL$2,100,IF(Q22>BL$3,BM$1*Q22+BM$2, Q22*BM$3+BM$4)),1) -> 97.2 | BM22: =ROUND(IF(F22>BL$2,100, IF(F22>BL$3,BM$1*F22+BM$2, F22*BM$3+BM$4)),1) -> 95.3 | BN22: =ROUND(IF(AC22>BL$2,100,IF(AC22>BL$3,BM$1*AC22+BM$2, AC22*BM$3+BM$4)),1) -> 91.7 | BO22: =ROUND((0.6105*(EXP((17.273*O22)/(O22+237.3))))*BN22/100,3) -> 0.397 | BP22: =ROUND((100-BN22)*BO22/BN22,3) -> 0.036 | BT22: =BI22 -> 0.89 | BU22: =BJ22 -> 1.43 | BV22: =ROUND(E22,1) -> -6.9 | BW22: =ROUND(G22,1) -> -6.9 | BX22: =ROUND(H22,1) -> -7 | BY22: =ROUND(I22,1) -> 0.1 | BZ22: =ROUND(J22,1) -> -0.7 | CA22: =ROUND(K22,1) -> -0.2 | CB22: =ROUND(L22,1) -> 0.8 | CC22: =ROUND(BM22,1) -> 95.3 | CD22: =ROUND(O22,1) -> -4.6 | CE22: =ROUND(S22,1) -> -4.1 | CF22: =ROUND(T22,1) -> -4.1 | CG22: =ROUND(U22,1) -> 0.2 | CH22: =ROUND(V22,1) -> -0.6 | CI22: =ROUND(W22,1) -> -0.1 | CJ22: =ROUND(X22,1) -> 0.8 | CK22: =ROUND(BL22,1) -> 97.2 | CL22: =ROUND(AA22,1) -> -14.1 | CM22: =ROUND(AE22,1) -> -15.9 | CN22: =ROUND(AF22,1) -> -16.4 | CO22: =ROUND(AG22,1) -> -0.1 | CP22: =ROUND(AH22,1) -> -0.9 | CQ22: =ROUND(AI22,1) -> -0.4 | CR22: =ROUND(AJ22,1) -> 0.6 | CS22: =ROUND(BN22,1) -> 91.7 | CT22: =BE22 -> 971 | CU22: =PPTest!K22 -> 4.6 | CV22: =ROUND(M22,2) -> 1.48 | CW22: =ROUND(Y22,2) -> 4.53 | CX22: =BO22 -> 0.397 | CY22: =BP22 -> 0.036 | CZ22: =BB22 -> 13.03
