Workbook

Sheet Meta
A1: Meta data for Sicamous base station | N1: March - May Sicamous and MoTI
A2: Last edit 12/04/25
B3: Replaced 21X with CR10 data logger and storage module 1 September 2000
B4: Gap filling of temperature and humidity using relationships between Sicamous Creek and Sicamous FWS and Malakwa MoTI stations
A5: Solar W/m2
B6: LiCor silicon Pyranometer at 6 m
B7: Kmax from 10 min simulation
A8: PAR mol/m2/d
B9: LiCor PAR sensor 6 m above surface. Calibration drift problem | I9: 6 m air Temperature
A10: Tair C | H10: 1 Jan to 29 Feb, June 1-6
B11: HMP35C in RMYoung pie plate sheild at 6 m | I11: Tave C = MoTI* 0.77 - 6.2
B12: Thermocouples referenced to thermistor on panel at 3 m, 1.5 m and 0.25 m | I12: Tmax C = MoTI*0.69 - 5.3
I13: Tmin C = 2*Tave - Tmax This is used because the Tmin relationship was weak and gives some minimums that appear too low.
H14: 7 Jun to 18 Sept
A15: RH % | I15: Tave C = FWS* 0.82 - 1.1
B16: HMP35C in RMYoung pie plate sheild at 6 m | I16: Tmax C = FWS*0.92 - 0.52
B17: Corrected RH based on Rhmax=100. Calculated vpres (kPa) | I17: Tmin C = FWS*0.61 - 1.82
D18: 7 Jun to 18 Sept | F18: Rhmincor % = FWS*0.85 - 2.6
A20: Soil temperature C
B21: Thermocouples referenced to thermistor on panel at 0.15 m and 0.5 m depths
A22: Precipitation mm
B23: Sierra Misco tipping bucket not working
C24: Estimate from Sicamous FWS and MoTi Malakwa
A25: Snow depth m, mm
B26: CSI UDG01
A27: Wind m/s
B28: MetOne anemometer at 6 m
A29: Wind direction degrees
B30: MetOne Wind vane at 6 m
A32: PPT= snow+rain
B33: Snow = Daily increase in pack depth and assumed compacted density of 0.13 Mg/m3
B34: Rain = Rain gauge.
C35: If there is a snow pack then review tiping bucket data to determine if likely snow melt rather than rain, i.e., tipping when above zero and low humidity and sunny.
C36: Also sum tipping bucket over days to see if simialr total to water equivalent of snow fal from depth change.
C37: Sicamous Fire Weather Station rainfall adjusted by *1.05 | H37: MoTI Malakwa adjusted by *1.4*1.05
A38: Vapour pressure kPa
B39: 1 Jan to 29 Feb, June 1-6: Esat at minimum air temperature
B40: Calculated from the daily maximum temperature and mininimum relative humdity: esat(Tmax)*RHmin/100
A41: Maximum vapour presure deficit
B42: 1 Jan to 29 Feb, June 1-6: vpd kPa = esat(Tmax)-esat(Tmin)
...

Sheet PPTest
A1: Precipitation | I1: 0.13 | K1: Rain | L1: Malakwa*1.4*1.05 | P1: Max density | Q1: 0.4
A2: =Data!A2 -> Last edit 21/04/25 | K2: SnowDepthChange | P2: Start Density | Q2: 0.23
C3: Total | K3: FWS* | L3: 1.05
C4: Solar | D4: Tmax | E4: Tmin | F4: Rhmin | G4: Rain | H4: SnowD | I4: Precip.from | J4: FWS | M4: FWS | N4: Sicamous | P4: density | R4: SWE | S4: dSWE | T4: Melt
A5: Date | B5: DoY | C5: MJ/m2/d | I5: snow depth | K5: Precipitation | P5: g/cm3 | R5: mm | S5: mm | T5: mm
H6: 650 | Q6: =Q2 -> 0.23 | R6: =H6*Q$2 -> 149.5 | S6: 0 | T6: 0
A7: 36526 | B7: 1 | C7: =ROUND(Data!BO7,2) -> 0 | D7: =ROUND(Data!R7,1) -> -6.8 | E7: =ROUND(Data!AF7,1) -> -11.4 | F7: =Data!BT7 -> 0 | G7: =Data!Q7 -> 0 | H7: =Data!BF7 -> 0 | I7: =IF(H7>H6,ROUND((H7-H6)*I$1,1),0) -> 0 | J7: =Data!BX7 -> 12.32 | K7: =J7*L$3 -> 12.936 | M7: =J7 -> 12.32 | N7: =K7 -> 12.936 | R7: =R6+K7 -> 162.436 | S7: =R7-R6 -> 12.936 | T7: =K7-S7 -> 0
A8: =A7+1 -> 36527 | B8: 2 | C8: =ROUND(Data!BO8,2) -> 0 | D8: =ROUND(Data!R8,1) -> -5 | E8: =ROUND(Data!AF8,1) -> -10.2 | F8: =Data!BT8 -> 0 | G8: =Data!Q8 -> 0 | H8: =Data!BF8 -> 0 | I8: =IF(H8>H7,ROUND((H8-H7)*I$1,1),0) -> 0 | J8: =Data!BX8 -> 4.06 | K8: =J8*L$3 -> 4.263 | M8: =J8+M7 -> 16.38 | N8: =K8+N7 -> 17.199 | R8: =R7+K8 -> 166.699 | S8: =R8-R7 -> 4.263 | T8: =K8-S8 -> 0
A9: =A8+1 -> 36528 | B9: 3 | C9: =ROUND(Data!BO9,2) -> 0 | D9: =ROUND(Data!R9,1) -> -5.4 | E9: =ROUND(Data!AF9,1) -> -9.4 | F9: =Data!BT9 -> 0 | G9: =Data!Q9 -> 0 | H9: =Data!BF9 -> 0 | I9: =IF(H9>H8,ROUND((H9-H8)*I$1,1),0) -> 0 | J9: =Data!BX9 -> 4.62 | K9: =J9*L$3 -> 4.851 | M9: =J9+M8 -> 21 | N9: =K9+N8 -> 22.05 | R9: =R8+K9 -> 171.55 | S9: =R9-R8 -> 4.851 | T9: =K9-S9 -> 0
A10: =A9+1 -> 36529 | B10: 4 | C10: =ROUND(Data!BO10,2) -> 0 | D10: =ROUND(Data!R10,1) -> -5.2 | E10: =ROUND(Data!AF10,1) -> -8.8 | F10: =Data!BT10 -> 0 | G10: =Data!Q10 -> 0 | H10: =Data!BF10 -> 0 | I10: =IF(H10>H9,ROUND((H10-H9)*I$1,1),0) -> 0 | J10: =Data!BX10 -> 6.16 | K10: =J10*L$3 -> 6.468 | M10: =J10+M9 -> 27.16 | N10: =K10+N9 -> 28.518 | R10: =R9+K10 -> 178.018 | S10: =R10-R9 -> 6.468 | T10: =K10-S10 -> 7.9936058e-15
A11: =A10+1 -> 36530 | B11: 5 | C11: =ROUND(Data!BO11,2) -> 0 | D11: =ROUND(Data!R11,1) -> -5 | E11: =ROUND(Data!AF11,1) -> -9.4 | F11: =Data!BT11 -> 0 | G11: =Data!Q11 -> 0 | H11: =Data!BF11 -> 0 | I11: =IF(H11>H10,ROUND((H11-H10)*I$1,1),0) -> 0 | J11: =Data!BX11 -> 0.98 | K11: =J11*L$3 -> 1.029 | M11: =J11+M10 -> 28.14 | N11: =K11+N10 -> 29.547 | R11: =R10+K11 -> 179.047 | S11: =R11-R10 -> 1.029 | T11: =K11-S11 -> 3.5527137e-15
A12: =A11+1 -> 36531 | B12: 6 | C12: =ROUND(Data!BO12,2) -> 0 | D12: =ROUND(Data!R12,1) -> -5.8 | E12: =ROUND(Data!AF12,1) -> -9.2 | F12: =Data!BT12 -> 0 | G12: =Data!Q12 -> 0 | H12: =Data!BF12 -> 0 | I12: =IF(H12>H11,ROUND((H12-H11)*I$1,1),0) -> 0 | J12: =Data!BX12 -> 21.56 | K12: =J12*L$3 -> 22.638 | M12: =J12+M11 -> 49.7 | N12: =K12+N11 -> 52.185 | R12: =R11+K12 -> 201.685 | S12: =R12-R11 -> 22.638 | T12: =K12-S12 -> 0
A13: =A12+1 -> 36532 | B13: 7 | C13: =ROUND(Data!BO13,2) -> 0 | D13: =ROUND(Data!R13,1) -> -4.8 | E13: =ROUND(Data!AF13,1) -> -8.8 | F13: =Data!BT13 -> 0 | G13: =Data!Q13 -> 0 | H13: =Data!BF13 -> 0 | I13: =IF(H13>H12,ROUND((H13-H12)*I$1,1),0) -> 0 | J13: =Data!BX13 -> 0 | K13: =J13*L$3 -> 0 | M13: =J13+M12 -> 49.7 | N13: =K13+N12 -> 52.185 | R13: =R12+K13 -> 201.685 | S13: =R13-R12 -> 0 | T13: =K13-S13 -> 0
A14: =A13+1 -> 36533 | B14: 8 | C14: =ROUND(Data!BO14,2) -> 0 | D14: =ROUND(Data!R14,1) -> -5.2 | E14: =ROUND(Data!AF14,1) -> -7.6 | F14: =Data!BT14 -> 0 | G14: =Data!Q14 -> 0 | H14: =Data!BF14 -> 0 | I14: =IF(H14>H13,ROUND((H14-H13)*I$1,1),0) -> 0 | J14: =Data!BX14 -> 21 | K14: =J14*L$3 -> 22.05 | M14: =J14+M13 -> 70.7 | N14: =K14+N13 -> 74.235 | R14: =R13+K14 -> 223.735 | S14: =R14-R13 -> 22.05 | T14: =K14-S14 -> 0
A15: =A14+1 -> 36534 | B15: 9 | C15: =ROUND(Data!BO15,2) -> 0 | D15: =ROUND(Data!R15,1) -> -4.8 | E15: =ROUND(Data!AF15,1) -> -9 | F15: =Data!BT15 -> 0 | G15: =Data!Q15 -> 0 | H15: =Data!BF15 -> 0 | I15: =IF(H15>H14,ROUND((H15-H14)*I$1,1),0) -> 0 | J15: =Data!BX15 -> 6.72 | K15: =J15*L$3 -> 7.056 | M15: =J15+M14 -> 77.42 | N15: =K15+N14 -> 81.291 | R15: =R14+K15 -> 230.791 | S15: =R15-R14 -> 7.056 | T15: =K15-S15 -> -1.1546319e-14
A16: =A15+1 -> 36535 | B16: 10 | C16: =ROUND(Data!BO16,2) -> 0 | D16: =ROUND(Data!R16,1) -> -5.6 | E16: =ROUND(Data!AF16,1) -> -14.4 | F16: =Data!BT16 -> 0 | G16: =Data!Q16 -> 0 | H16: =Data!BF16 -> 0 | I16: =IF(H16>H15,ROUND((H16-H15)*I$1,1),0) -> 0 | J16: =Data!BX16 -> 0.7 | K16: =J16*L$3 -> 0.735 | M16: =J16+M15 -> 78.12 | N16: =K16+N15 -> 82.026 | R16: =R15+K16 -> 231.526 | S16: =R16-R15 -> 0.735 | T16: =K16-S16 -> -1.3655743e-14
A17: =A16+1 -> 36536 | B17: 11 | C17: =ROUND(Data!BO17,2) -> 0 | D17: =ROUND(Data!R17,1) -> -7.2 | E17: =ROUND(Data!AF17,1) -> -14.8 | F17: =Data!BT17 -> 0 | G17: =Data!Q17 -> 0 | H17: =Data!BF17 -> 0 | I17: =IF(H17>H16,ROUND((H17-H16)*I$1,1),0) -> 0 | J17: =Data!BX17 -> 1.68 | K17: =J17*L$3 -> 1.764 | M17: =J17+M16 -> 79.8 | N17: =K17+N16 -> 83.79 | R17: =R16+K17 -> 233.29 | S17: =R17-R16 -> 1.764 | T17: =K17-S17 -> -9.7699626e-15
A18: =A17+1 -> 36537 | B18: 12 | C18: =ROUND(Data!BO18,2) -> 0 | D18: =ROUND(Data!R18,1) -> -6.3 | E18: =ROUND(Data!AF18,1) -> -13.9 | F18: =Data!BT18 -> 0 | G18: =Data!Q18 -> 0 | H18: =Data!BF18 -> 0 | I18: =IF(H18>H17,ROUND((H18-H17)*I$1,1),0) -> 0 | J18: =Data!BX18 -> 3.92 | K18: =J18*L$3 -> 4.116 | M18: =J18+M17 -> 83.72 | N18: =K18+N17 -> 87.906 | R18: =R17+K18 -> 237.406 | S18: =R18-R17 -> 4.116 | T18: =K18-S18 -> -1.2434498e-14
A19: =A18+1 -> 36538 | B19: 13 | C19: =ROUND(Data!BO19,2) -> 0 | D19: =ROUND(Data!R19,1) -> -5.4 | E19: =ROUND(Data!AF19,1) -> -14.2 | F19: =Data!BT19 -> 0 | G19: =Data!Q19 -> 0 | H19: =Data!BF19 -> 0 | I19: =IF(H19>H18,ROUND((H19-H18)*I$1,1),0) -> 0 | J19: =Data!BX19 -> 0 | K19: =J19*L$3 -> 0 | M19: =J19+M18 -> 83.72 | N19: =K19+N18 -> 87.906 | R19: =R18+K19 -> 237.406 | S19: =R19-R18 -> 0 | T19: =K19-S19 -> 0
... A67: =A66+1 -> 36586 | B67: 61 | C67: =ROUND(Data!BO67,2) -> 0 | D67: =ROUND(Data!R67,1) -> -0.7 | E67: =ROUND(Data!AF67,1) -> -6.5 | F67: =Data!BT67 -> 0 | G67: =Data!Q67 -> 0 | H67: =Data!BF67 -> 0 | I67: =IF(H67>H66,ROUND((H67-H66)*I$1,1),0) -> 0 | J67: =Data!BX67 -> 4.76 | K67: =J67*L$3 -> 4.998 | M67: =J67+M66 -> 198.94 | N67: =K67+N66 -> 208.887 | R67: =R66+K67 -> 358.387 | S67: =R67-R66 -> 4.998 | T67: =K67-S67 -> 9.7699626e-15
A68: =A67+1 -> 36587 | B68: 62 | C68: =ROUND(Data!BO68,2) -> 0.51 | D68: =ROUND(Data!R68,1) -> -0.4 | E68: =ROUND(Data!AF68,1) -> -6.1 | F68: =Data!BT68 -> 79.7 | G68: =Data!Q68 -> 0 | H68: =Data!BF68 -> 1250 | I68: 0 | J68: =Data!BX68 -> 5.18 | K68: =J68*L$3 -> 5.439 | M68: =J68+M67 -> 204.12 | N68: =K68+N67 -> 214.326 | P68: =(R67+K68)/H68 -> 0.2910608 | Q68: =IF(P68>Q$1,Q$1,P68) -> 0.2910608 | R68: =Q68*H68 -> 363.826 | S68: =R68-R67 -> 5.439 | T68: =K68-S68 -> -2.1316282e-14
A69: =A68+1 -> 36588 | B69: 63 | C69: =ROUND(Data!BO69,2) -> 1.06 | D69: =ROUND(Data!R69,1) -> -0.3 | E69: =ROUND(Data!AF69,1) -> -7 | F69: =Data!BT69 -> 75 | G69: =Data!Q69 -> 0 | H69: =Data!BF69 -> 1293 | I69: =IF(H69>H68,ROUND((H69-H68)*I$1,1),0) -> 5.6 | J69: =Data!BX69 -> 7.98 | K69: =I69 -> 5.6 | M69: =J69+M68 -> 212.1 | N69: =K69+N68 -> 219.926 | P69: =(R68+K69)/H69 -> 0.2857123 | Q69: =IF(P69>Q$1,Q$1,P69) -> 0.2857123 | R69: =Q69*H69 -> 369.426 | S69: =R69-R68 -> 5.6 | T69: =K69-S69 -> -7.9936058e-14
A70: =A69+1 -> 36589 | B70: 64 | C70: =ROUND(Data!BO70,2) -> 1.15 | D70: =ROUND(Data!R70,1) -> -1.2 | E70: =ROUND(Data!AF70,1) -> -7.4 | F70: =Data!BT70 -> 82 | G70: =Data!Q70 -> 0 | H70: =Data!BF70 -> 1318 | I70: =IF(H70>H69,ROUND((H70-H69)*I$1,1),0) -> 3.3 | J70: =Data!BX70 -> 9.24 | K70: =I70 -> 3.3 | M70: =J70+M69 -> 221.34 | N70: =K70+N69 -> 223.226 | P70: =(R69+K70)/H70 -> 0.28279666 | Q70: =IF(P70>Q$1,Q$1,P70) -> 0.28279666 | R70: =Q70*H70 -> 372.726 | S70: =R70-R69 -> 3.3 | T70: =K70-S70 -> -1.1546319e-14
A71: =A70+1 -> 36590 | B71: 65 | C71: =ROUND(Data!BO71,2) -> 2.33 | D71: =ROUND(Data!R71,1) -> -1.6 | E71: =ROUND(Data!AF71,1) -> -12.5 | F71: =Data!BT71 -> 60 | G71: =Data!Q71 -> 0 | H71: =Data!BF71 -> 1288 | I71: =IF(H71>H70,ROUND((H71-H70)*I$1,1),0) -> 0 | J71: =Data!BX71 -> 0 | K71: =I71 -> 0 | M71: =J71+M70 -> 221.34 | N71: =K71+N70 -> 223.226 | P71: =(R70+K71)/H71 -> 0.28938354 | Q71: =IF(P71>Q$1,Q$1,P71) -> 0.28938354 | R71: =Q71*H71 -> 372.726 | S71: =R71-R70 -> 0 | T71: =K71-S71 -> 0
A72: =A71+1 -> 36591 | B72: 66 | C72: =ROUND(Data!BO72,2) -> 1.38 | D72: =ROUND(Data!R72,1) -> -4.3 | E72: =ROUND(Data!AF72,1) -> -16.1 | F72: =Data!BT72 -> 83.1 | G72: =Data!Q72 -> 0 | H72: =Data!BF72 -> 1304 | I72: =IF(H72>H71,ROUND((H72-H71)*I$1,1),0) -> 2.1 | J72: =Data!BX72 -> 2.38 | K72: =I72 -> 2.1 | M72: =J72+M71 -> 223.72 | N72: =K72+N71 -> 225.326 | P72: =(R71+K72)/H72 -> 0.28744325 | Q72: =IF(P72>Q$1,Q$1,P72) -> 0.28744325 | R72: =Q72*H72 -> 374.826 | S72: =R72-R71 -> 2.1 | T72: =K72-S72 -> -2.264855e-14
A73: =A72+1 -> 36592 | B73: 67 | C73: =ROUND(Data!BO73,2) -> 8.24 | D73: =ROUND(Data!R73,1) -> 0.1 | E73: =ROUND(Data!AF73,1) -> -18.9 | F73: =Data!BT73 -> 32.7 | G73: =Data!Q73 -> 0 | H73: =Data!BF73 -> 1278 | I73: =IF(H73>H72,ROUND((H73-H72)*I$1,1),0) -> 0 | J73: =Data!BX73 -> 0.28 | K73: =I73 -> 0 | M73: =J73+M72 -> 224 | N73: =K73+N72 -> 225.326 | P73: =(R72+K73)/H73 -> 0.29329108 | Q73: =IF(P73>Q$1,Q$1,P73) -> 0.29329108 | R73: =Q73*H73 -> 374.826 | S73: =R73-R72 -> 0 | T73: =K73-S73 -> 0
A74: =A73+1 -> 36593 | B74: 68 | C74: =ROUND(Data!BO74,2) -> 11.82 | D74: =ROUND(Data!R74,1) -> 3.4 | E74: =ROUND(Data!AF74,1) -> -11.2 | F74: =Data!BT74 -> 37.2 | G74: =Data!Q74 -> 0 | H74: =Data!BF74 -> 1254 | I74: =IF(H74>H73,ROUND((H74-H73)*I$1,1),0) -> 0 | J74: =Data!BX74 -> 0 | K74: =I74 -> 0 | M74: =J74+M73 -> 224 | N74: =K74+N73 -> 225.326 | P74: =(R73+K74)/H74 -> 0.29890431 | Q74: =IF(P74>Q$1,Q$1,P74) -> 0.29890431 | R74: =Q74*H74 -> 374.826 | S74: =R74-R73 -> 0 | T74: =K74-S74 -> 0
A75: =A74+1 -> 36594 | B75: 69 | C75: =ROUND(Data!BO75,2) -> 4.44 | D75: =ROUND(Data!R75,1) -> 0.9 | E75: =ROUND(Data!AF75,1) -> -3 | F75: =Data!BT75 -> 69 | G75: =Data!Q75 -> 0 | H75: =Data!BF75 -> 1253 | I75: =IF(H75>H74,ROUND((H75-H74)*I$1,1),0) -> 0 | J75: =Data!BX75 -> 0.84 | K75: =I75 -> 0 | M75: =J75+M74 -> 224.84 | N75: =K75+N74 -> 225.326 | P75: =(R74+K75)/H75 -> 0.29914286 | Q75: =IF(P75>Q$1,Q$1,P75) -> 0.29914286 | R75: =Q75*H75 -> 374.826 | S75: =R75-R74 -> 0 | T75: =K75-S75 -> 0
A76: =A75+1 -> 36595 | B76: 70 | C76: =ROUND(Data!BO76,2) -> 10.16 | D76: =ROUND(Data!R76,1) -> 3.2 | E76: =ROUND(Data!AF76,1) -> -3.9 | F76: =Data!BT76 -> 52.3 | G76: =Data!Q76 -> 0 | H76: =Data!BF76 -> 1244 | I76: =IF(H76>H75,ROUND((H76-H75)*I$1,1),0) -> 0 | J76: =Data!BX76 -> 0.42 | K76: =I76 -> 0 | M76: =J76+M75 -> 225.26 | N76: =K76+N75 -> 225.326 | P76: =(R75+K76)/H76 -> 0.30130707 | Q76: =IF(P76>Q$1,Q$1,P76) -> 0.30130707 | R76: =Q76*H76 -> 374.826 | S76: =R76-R75 -> 0 | T76: =K76-S76 -> 0
A77: =A76+1 -> 36596 | B77: 71 | C77: =ROUND(Data!BO77,2) -> 9.51 | D77: =ROUND(Data!R77,1) -> 0.8 | E77: =ROUND(Data!AF77,1) -> -3.9 | F77: =Data!BT77 -> 46.6 | G77: =Data!Q77 -> 0 | H77: =Data!BF77 -> 1240 | I77: =IF(H77>H76,ROUND((H77-H76)*I$1,1),0) -> 0 | J77: =Data!BX77 -> 1.96 | K77: =I77 -> 0 | M77: =J77+M76 -> 227.22 | N77: =K77+N76 -> 225.326 | P77: =(R76+K77)/H77 -> 0.30227903 | Q77: =IF(P77>Q$1,Q$1,P77) -> 0.30227903 | R77: =Q77*H77 -> 374.826 | S77: =R77-R76 -> 0 | T77: =K77-S77 -> 0
A78: =A77+1 -> 36597 | B78: 72 | C78: =ROUND(Data!BO78,2) -> 9.42 | D78: =ROUND(Data!R78,1) -> 0.8 | E78: =ROUND(Data!AF78,1) -> -9.7 | F78: =Data!BT78 -> 49.1 | G78: =Data!Q78 -> 0 | H78: =Data!BF78 -> 1233 | I78: =IF(H78>H77,ROUND((H78-H77)*I$1,1),0) -> 0 | J78: =Data!BX78 -> 0 | K78: =I78 -> 0 | M78: =J78+M77 -> 227.22 | N78: =K78+N77 -> 225.326 | P78: =(R77+K78)/H78 -> 0.30399513 | Q78: =IF(P78>Q$1,Q$1,P78) -> 0.30399513 | R78: =Q78*H78 -> 374.826 | S78: =R78-R77 -> 0 | T78: =K78-S78 -> 0
A79: =A78+1 -> 36598 | B79: 73 | C79: =ROUND(Data!BO79,2) -> 11.04 | D79: =ROUND(Data!R79,1) -> 3.3 | E79: =ROUND(Data!AF79,1) -> -5.7 | F79: =Data!BT79 -> 45.4 | G79: =Data!Q79 -> 0 | H79: =Data!BF79 -> 1208 | I79: =IF(H79>H78,ROUND((H79-H78)*I$1,1),0) -> 0 | J79: =Data!BX79 -> 0 | K79: =I79 -> 0 | M79: =J79+M78 -> 227.22 | N79: =K79+N78 -> 225.326 | P79: =(R78+K79)/H79 -> 0.31028642 | Q79: =IF(P79>Q$1,Q$1,P79) -> 0.31028642 | R79: =Q79*H79 -> 374.826 | S79: =R79-R78 -> 0 | T79: =K79-S79 -> 0
A80: =A79+1 -> 36599 | B80: 74 | C80: =ROUND(Data!BO80,2) -> 2.68 | D80: =ROUND(Data!R80,1) -> -1.6 | E80: =ROUND(Data!AF80,1) -> -4.6 | F80: =Data!BT80 -> 90.9 | G80: =Data!Q80 -> 0 | H80: =Data!BF80 -> 1348 | I80: =IF(H80>H79,ROUND((H80-H79)*I$1,1),0) -> 18.2 | J80: =Data!BX80 -> 16.8 | K80: =I80 -> 18.2 | M80: =J80+M79 -> 244.02 | N80: =K80+N79 -> 243.526 | P80: =(R79+K80)/H80 -> 0.29156231 | Q80: =IF(P80>Q$1,Q$1,P80) -> 0.29156231 | R80: =Q80*H80 -> 393.026 | S80: =R80-R79 -> 18.2 | T80: =K80-S80 -> 0
... A110: =A109+1 -> 36629 | B110: 104 | C110: =ROUND(Data!BO110,2) -> 5.17 | D110: =ROUND(Data!R110,1) -> 3.7 | E110: =ROUND(Data!AF110,1) -> -4.9 | F110: =Data!BT110 -> 80.6 | G110: =Data!Q110 -> 0 | H110: =Data!BF110 -> 1169 | I110: =IF(H110>H109,ROUND((H110-H109)*I$1,1),0) -> 8.3 | J110: =Data!BX110 -> 13.16 | K110: =I110 -> 8.3 | M110: =J110+M109 -> 318.78 | N110: =K110+N109 -> 293.126 | P110: =(R109+K110)/H110 -> 0.37863644 | Q110: =IF(P110>Q$1,Q$1,P110) -> 0.37863644 | R110: =Q110*H110 -> 442.626 | S110: =R110-R109 -> 8.3 | T110: =K110-S110 -> 0
A111: =A110+1 -> 36630 | B111: 105 | C111: =ROUND(Data!BO111,2) -> 2.01 | D111: =ROUND(Data!R111,1) -> 0.6 | E111: =ROUND(Data!AF111,1) -> -5.7 | F111: =Data!BT111 -> 92 | G111: =Data!Q111 -> 0 | H111: =Data!BF111 -> 1169 | I111: =IF(H111>H110,ROUND((H111-H110)*I$1,1),0) -> 0 | J111: =Data!BX111 -> 4.9 | K111: =J111*L$3 -> 5.145 | M111: =J111+M110 -> 323.68 | N111: =K111+N110 -> 298.271 | P111: =(R110+K111)/H111 -> 0.38303764 | Q111: =IF(P111>Q$1,Q$1,P111) -> 0.38303764 | R111: =Q111*H111 -> 447.771 | S111: =R111-R110 -> 5.145 | T111: =K111-S111 -> 1.8651747e-14
A112: =A111+1 -> 36631 | B112: 106 | C112: =ROUND(Data!BO112,2) -> 15.04 | D112: =ROUND(Data!R112,1) -> 4.2 | E112: =ROUND(Data!AF112,1) -> -3 | F112: =Data!BT112 -> 59.2 | G112: =Data!Q112 -> 0 | H112: =Data!BF112 -> 1138 | I112: =IF(H112>H111,ROUND((H112-H111)*I$1,1),0) -> 0 | J112: =Data!BX112 -> 4.48 | K112: =J112*L$3 -> 4.704 | M112: =J112+M111 -> 328.16 | N112: =K112+N111 -> 302.975 | P112: =(R111+K112)/H112 -> 0.39760545 | Q112: =IF(P112>Q$1,Q$1,P112) -> 0.39760545 | R112: =Q112*H112 -> 452.475 | S112: =R112-R111 -> 4.704 | T112: =K112-S112 -> 4.8849813e-14
A113: =A112+1 -> 36632 | B113: 107 | C113: =ROUND(Data!BO113,2) -> 13.27 | D113: =ROUND(Data!R113,1) -> 5.5 | E113: =ROUND(Data!AF113,1) -> -6.5 | F113: =Data!BT113 -> 54.9 | G113: =Data!Q113 -> 0 | H113: =Data!BF113 -> 1154 | I113: =IF(H113>H112,ROUND((H113-H112)*I$1,1),0) -> 2.1 | J113: =Data!BX113 -> 0 | K113: =I113 -> 2.1 | M113: =J113+M112 -> 328.16 | N113: =K113+N112 -> 305.075 | P113: =(R112+K113)/H113 -> 0.39391248 | Q113: =IF(P113>Q$1,Q$1,P113) -> 0.39391248 | R113: =Q113*H113 -> 454.575 | S113: =R113-R112 -> 2.1 | T113: =K113-S113 -> -2.264855e-14
A114: =A113+1 -> 36633 | B114: 108 | C114: =ROUND(Data!BO114,2) -> 25.37 | D114: =ROUND(Data!R114,1) -> 7.7 | E114: =ROUND(Data!AF114,1) -> -6.1 | F114: =Data!BT114 -> 24.5 | G114: =Data!Q114 -> 0 | H114: =Data!BF114 -> 1109 | I114: =IF(H114>H113,ROUND((H114-H113)*I$1,1),0) -> 0 | J114: =Data!BX114 -> 0 | K114: =I114 -> 0 | M114: =J114+M113 -> 328.16 | N114: =K114+N113 -> 305.075 | P114: =(R113+K114)/H114 -> 0.4098963 | Q114: =IF(P114>Q$1,Q$1,P114) -> 0.4 | R114: =Q114*H114 -> 443.6 | S114: =R114-R113 -> -10.975 | T114: =K114-S114 -> 10.975
A115: =A114+1 -> 36634 | B115: 109 | C115: =ROUND(Data!BO115,2) -> 24.65 | D115: =ROUND(Data!R115,1) -> 12.2 | E115: =ROUND(Data!AF115,1) -> -7.2 | F115: =Data!BT115 -> 17.5 | G115: =Data!Q115 -> 0 | H115: =Data!BF115 -> 1061 | I115: =IF(H115>H114,ROUND((H115-H114)*I$1,1),0) -> 0 | J115: =Data!BX115 -> 0 | K115: =I115 -> 0 | M115: =J115+M114 -> 328.16 | N115: =K115+N114 -> 305.075 | P115: =(R114+K115)/H115 -> 0.41809614 | Q115: =IF(P115>Q$1,Q$1,P115) -> 0.4 | R115: =Q115*H115 -> 424.4 | S115: =R115-R114 -> -19.2 | T115: =K115-S115 -> 19.2
A116: =A115+1 -> 36635 | B116: 110 | C116: =ROUND(Data!BO116,2) -> 25.74 | D116: =ROUND(Data!R116,1) -> 12.7 | E116: =ROUND(Data!AF116,1) -> -5.2 | F116: =Data!BT116 -> 24 | G116: =Data!Q116 -> 0 | H116: =Data!BF116 -> 1023 | I116: =IF(H116>H115,ROUND((H116-H115)*I$1,1),0) -> 0 | J116: =Data!BX116 -> 0 | K116: =I116 -> 0 | M116: =J116+M115 -> 328.16 | N116: =K116+N115 -> 305.075 | P116: =(R115+K116)/H116 -> 0.41485826 | Q116: =IF(P116>Q$1,Q$1,P116) -> 0.4 | R116: =Q116*H116 -> 409.2 | S116: =R116-R115 -> -15.2 | T116: =K116-S116 -> 15.2
...

Sheet Data
A1: Sicamous Creek 2000 Daily data | D1: No data for day 1 to 61, day 153-161. | J1: RH, Solar and PAR new calibrations added col BL onwards | P1: Windrose data invalid September-December | BF1: 3493 | BN1: =2.02 -> 2.02 | BO1: Recalibrated 30/07/07 | BR1: Rh_adjustment, 2/08/07) | BS1: 1.59 | BV1: UseRHcor
A2: Last edit 21/04/25 | C2: Rainfall - no data | F2: Removed -6999 indicating bad data | I2: Empty cell indicates no data | L2: Wind corrected for scan time of 30 sec 2 Mar to 31 May while programmed for a multiplier for 10 secs. Mean windspeed missing day 262 onward | BO2: 0.98 | BP2: 1.1 | BR2: 110 | BS2: -75.7 | BX2: 1.4 | BZ2: 1.4 | CB2: Summary
C3: TOTAL | D3: MEAN | E3: MEAN | F3: MEAN | G3: MEAN | H3: MEAN | I3: MEAN | J3: MEAN | K3: MEAN | L3: MEAN | M3: MEAN | N3: MEAN | O3: MEAN | P3: MEAN | Q3: TOTAL | R3: MAX. | S3: TIME | T3: MAX | U3: TIME | V3: MAX | W3: MAX | X3: MAX | Y3: MAX | Z3: MAX | AA3: MAX | AB3: MAX | AC3: MAX | AD3: MAX | AE3: TIME | AF3: MIN | AG3: TIME | AH3: MIN | AI3: TIME | AJ3: MIN | AK3: MIN | AL3: MIN | AM3: MIN | AN3: MIN | AO3: MIN | AP3: MIN | AQ3: MIN | AR3: Wind Rose: | BO3: Revised | BR3: 99 | BS3: 0.88 | BU3: esTn | BV3: esTx-esTn | DB3: Midnight | DK3: FWS | DQ3: MoTI Malakwa
C4: SOLAR | D4: PAR | E4: Ta 6m | F4: RH | G4: Ta 3m | H4: Ta 1.5m | I4: Ta 0.25m | J4: Tstem | K4: Tstem | L4: Tsoil | M4: Tsoil | N4: Tsoil | O4: SHORT | P4: WIND | Q4: RAIN | R4: Ta 6m | S4: tA 6m | T4: RH | U4: RH | V4: Ta 3m | W4: Ta 1.5m | X4: Ta 0.25m | Y4: Tstem | Z4: Tstem | AA4: Tsoil | AB4: Tsoil | AC4: Tsoil | AD4: WIND SPD | AE4: MAX U | AF4: Ta 6m | AG4: tA 6m | AH4: RH | AI4: RH | AJ4: Ta 3m | AK4: Ta 1.5m | AL4: Ta 0.25m | AM4: Tstem | AN4: Tstem | AO4: Tsoil | AP4: Tsoil | AQ4: Tsoil | AZ4: DAILY AVG | BA4: DISTANCE | BB4: BATT. | BC4: Identity | BD4: Distance | BE4: Distance | BF4: Snow depth | BG4: AVG | BH4: Max | BI4: Max | BJ4: Min | BK4: Min | BM4: Solarmax | BN4: PARmax | BO4: Solar | BP4: PAR | BQ4: =MAX(BR7:BR372) -> 100 | BS4: -6 | BU4: Vpres | BV4: VPD | BX4: UPC to FWS | BZ4: Malakwa | CB4: Solar | CC4: PAR | CD4: Ta6Ave | CE4: Ta3Ave | CF4: Ta15Ave | CG4: Ta025Ave | CH4: TdufAve | CI4: Ts015Ave | CJ4: Ts05Ave | CK4: RH6Ave | CL4: Ta6Max | CM4: Ta3Max | CN4: Ta15Max | CO4: Ta025Max | CP4: TdufMax | CQ4: Ts015Max | CR4: Ts05Max | CS4: RH6Max | CT4: Ta6Min | CU4: Ta3Min | CV4: Ta15Min | CW4: Ta025Min | CX4: TdufMin | CY4: Ts015Min | CZ4: Ts05Min | DA4: RH6Min | DB4: SnowD | DC4: Precipitation | DD4: Wind | DE4: WindX | DF4: Vapres | DG4: vpdX | DH4: BatV | DK4: C | DL4: C | DM4: C | DN4: % | DO4: % | DQ4: C | DR4: C | DS4: C
A5: Date | B5: DofY | C5: MJ/m2/d | D5: mol/m2/d | E5: C | F5: % | G5: C | H5: C | I5: C | J5: WEST | K5: EAST | L5: duff | M5: 15cm | N5: 50cm | O5: (mV) | P5: (m/s) | Q5: mm | R5: C | T5: % | V5: C | W5: C | X5: C | Y5: WEST | Z5: EAST | AA5: duff | AB5: 15cm | AC5: 50cm | AD5: m/s | AE5: m/s | AF5: C | AG5: C | AH5: % | AJ5: C | AK5: C | AL5: C | AM5: WEST | AN5: EAST | AO5: duff | AP5: 15cm | AQ5: 50cm | AR5: N--NE | AS5: NE--E | AT5: E--SE | AU5: SE--S | AV5: S--SW | AW5: SW--W | AX5: W--NW | AY5: NW--N | AZ5: PANEL T | BA5: (mm) | BB5: (V) | BD5: Max | BE5: Min | BF5: mm | BG5: Logger | BH5: Logger | BI5: PANEL T | BJ5: Logger | BK5: PANEL T | BM5: MJ/m2/d | BN5: mol/m2/d | BR5: RHMax | BS5: RHAvg | BT5: RHMin | BU5: kPa | BV5: kPa | BX5: FWS | CB5: MJ/m2/d | CC5: mol/m2/d | CD5: C | CE5: C | CF5: C | CG5: C | CH5: C | CI5: C | CJ5: C | CK5: % | CL5: C | CM5: C | CN5: C | CO5: C | CP5: C | CQ5: C | CR5: C | CS5: % | CT5: C | CU5: C | CV5: C | CW5: C | CX5: C | CY5: C | CZ5: C | DA5: % | DB5: mm | DC5: mm/d | DD5: m/s | DE5: m/s | DF5: kPa | DG5: kPa | DH5: V | DK5: Tav | DL5: Tmax | DM5: Tmin | DN5: Rhav | DO5: Rhmin | DQ5: Tav | DR5: Tmax | DS5: Tmin
A7: 36526 | B7: 1 | E7: =ROUND(0.77*DQ7-6.2,1) -> -9.1 | R7: =ROUND(DR7*0.69-5.3,1) -> -6.8 | AF7: =ROUND(2*E7-R7,1) -> -11.4 | BM7: 4.59 | BN7: =BM7*$BN$1 -> 9.2718 | BU7: =ROUND((0.6105*(EXP((17.273*AF7)/(AF7+237.3)))),3) -> 0.255 | BV7: =ROUND((0.6105*(EXP((17.273*R7)/(R7+237.3))))-BU7,3) -> 0.112 | BX7: =BZ7*BZ$2 -> 12.32 | BY7: 8.32 | BZ7: 8.8 | CB7: NA | CC7: NA | CD7: =ROUND(E7,1) -> -9.1 | CE7: NA | CF7: NA | CG7: NA | CH7: NA | CI7: NA | CJ7: NA | CK7: NA | CL7: =ROUND(R7,1) -> -6.8 | CM7: NA | CN7: NA | CO7: NA | CP7: NA | CQ7: NA | CR7: NA | CS7: NA | CT7: =ROUND(AF7,1) -> -11.4 | CU7: NA | CV7: NA | CW7: NA | CX7: NA | CY7: NA | CZ7: NA | DA7: NA | DB7: NA | DC7: =ROUND(PPTest!K7,1) -> 12.9 | DD7: NA | DE7: NA | DF7: =BU7 -> 0.255 | DG7: =BV7 -> 0.112 | DH7: NA | DQ7: -3.8 | DR7: -2.2 | DS7: -5.4
A8: =A7+1 -> 36527 | B8: 2 | E8: =ROUND(0.77*DQ8-6.2,1) -> -7.6 | R8: =ROUND(DR8*0.69-5.3,1) -> -5 | AF8: =ROUND(2*E8-R8,1) -> -10.2 | BM8: 4.63 | BN8: =BM8*$BN$1 -> 9.3526 | BU8: =ROUND((0.6105*(EXP((17.273*AF8)/(AF8+237.3)))),3) -> 0.281 | BV8: =ROUND((0.6105*(EXP((17.273*R8)/(R8+237.3))))-BU8,3) -> 0.14 | BX8: =BZ8*BZ$2 -> 4.06 | BY8: 4.03 | BZ8: 2.9 | CB8: NA | CC8: NA | CD8: =ROUND(E8,1) -> -7.6 | CE8: NA | CF8: NA | CG8: NA | CH8: NA | CI8: NA | CJ8: NA | CK8: NA | CL8: =ROUND(R8,1) -> -5 | CM8: NA | CN8: NA | CO8: NA | CP8: NA | CQ8: NA | CR8: NA | CS8: NA | CT8: =ROUND(AF8,1) -> -10.2 | CU8: NA | CV8: NA | CW8: NA | CX8: NA | CY8: NA | CZ8: NA | DA8: NA | DB8: NA | DC8: =ROUND(PPTest!K8,1) -> 4.3 | DD8: NA | DE8: NA | DF8: =BU8 -> 0.281 | DG8: =BV8 -> 0.14 | DH8: NA | DQ8: -1.8 | DR8: 0.5 | DS8: -4
A9: =A8+1 -> 36528 | B9: 3 | E9: =ROUND(0.77*DQ9-6.2,1) -> -7.4 | R9: =ROUND(DR9*0.69-5.3,1) -> -5.4 | AF9: =ROUND(2*E9-R9,1) -> -9.4 | BM9: 4.67 | BN9: =BM9*$BN$1 -> 9.4334 | BU9: =ROUND((0.6105*(EXP((17.273*AF9)/(AF9+237.3)))),3) -> 0.299 | BV9: =ROUND((0.6105*(EXP((17.273*R9)/(R9+237.3))))-BU9,3) -> 0.109 | BX9: =BZ9*BZ$2 -> 4.62 | BY9: 7.93 | BZ9: 3.3 | CB9: NA | CC9: NA | CD9: =ROUND(E9,1) -> -7.4 | CE9: NA | CF9: NA | CG9: NA | CH9: NA | CI9: NA | CJ9: NA | CK9: NA | CL9: =ROUND(R9,1) -> -5.4 | CM9: NA | CN9: NA | CO9: NA | CP9: NA | CQ9: NA | CR9: NA | CS9: NA | CT9: =ROUND(AF9,1) -> -9.4 | CU9: NA | CV9: NA | CW9: NA | CX9: NA | CY9: NA | CZ9: NA | DA9: NA | DB9: NA | DC9: =ROUND(PPTest!K9,1) -> 4.9 | DD9: NA | DE9: NA | DF9: =BU9 -> 0.299 | DG9: =BV9 -> 0.109 | DH9: NA | DQ9: -1.6 | DR9: -0.1 | DS9: -3.1
A10: =A9+1 -> 36529 | B10: 4 | E10: =ROUND(0.77*DQ10-6.2,1) -> -7 | R10: =ROUND(DR10*0.69-5.3,1) -> -5.2 | AF10: =ROUND(2*E10-R10,1) -> -8.8 | BM10: 4.72 | BN10: =BM10*$BN$1 -> 9.5344 | BU10: =ROUND((0.6105*(EXP((17.273*AF10)/(AF10+237.3)))),3) -> 0.314 | BV10: =ROUND((0.6105*(EXP((17.273*R10)/(R10+237.3))))-BU10,3) -> 0.101 | BX10: =BZ10*BZ$2 -> 6.16 | BY10: 0 | BZ10: 4.4 | CB10: NA | CC10: NA | CD10: =ROUND(E10,1) -> -7 | CE10: NA | CF10: NA | CG10: NA | CH10: NA | CI10: NA | CJ10: NA | CK10: NA | CL10: =ROUND(R10,1) -> -5.2 | CM10: NA | CN10: NA | CO10: NA | CP10: NA | CQ10: NA | CR10: NA | CS10: NA | CT10: =ROUND(AF10,1) -> -8.8 | CU10: NA | CV10: NA | CW10: NA | CX10: NA | CY10: NA | CZ10: NA | DA10: NA | DB10: NA | DC10: =ROUND(PPTest!K10,1) -> 6.5 | DD10: NA | DE10: NA | DF10: =BU10 -> 0.314 | DG10: =BV10 -> 0.101 | DH10: NA | DQ10: -1.1 | DR10: 0.1 | DS10: -2.2
A11: =A10+1 -> 36530 | B11: 5 | E11: =ROUND(0.77*DQ11-6.2,1) -> -7.2 | R11: =ROUND(DR11*0.69-5.3,1) -> -5 | AF11: =ROUND(2*E11-R11,1) -> -9.4 | BM11: 4.76 | BN11: =BM11*$BN$1 -> 9.6152 | BU11: =ROUND((0.6105*(EXP((17.273*AF11)/(AF11+237.3)))),3) -> 0.299 | BV11: =ROUND((0.6105*(EXP((17.273*R11)/(R11+237.3))))-BU11,3) -> 0.122 | BX11: =BZ11*BZ$2 -> 0.98 | BY11: 0 | BZ11: 0.7 | CB11: NA | CC11: NA | CD11: =ROUND(E11,1) -> -7.2 | CE11: NA | CF11: NA | CG11: NA | CH11: NA | CI11: NA | CJ11: NA | CK11: NA | CL11: =ROUND(R11,1) -> -5 | CM11: NA | CN11: NA | CO11: NA | CP11: NA | CQ11: NA | CR11: NA | CS11: NA | CT11: =ROUND(AF11,1) -> -9.4 | CU11: NA | CV11: NA | CW11: NA | CX11: NA | CY11: NA | CZ11: NA | DA11: NA | DB11: NA | DC11: =ROUND(PPTest!K11,1) -> 1 | DD11: NA | DE11: NA | DF11: =BU11 -> 0.299 | DG11: =BV11 -> 0.122 | DH11: NA | DQ11: -1.3 | DR11: 0.4 | DS11: -2.9
A12: =A11+1 -> 36531 | B12: 6 | E12: =ROUND(0.77*DQ12-6.2,1) -> -7.5 | R12: =ROUND(DR12*0.69-5.3,1) -> -5.8 | AF12: =ROUND(2*E12-R12,1) -> -9.2 | BM12: 4.82 | BN12: =BM12*$BN$1 -> 9.7364 | BU12: =ROUND((0.6105*(EXP((17.273*AF12)/(AF12+237.3)))),3) -> 0.304 | BV12: =ROUND((0.6105*(EXP((17.273*R12)/(R12+237.3))))-BU12,3) -> 0.092 | BX12: =BZ12*BZ$2 -> 21.56 | BY12: 0 | BZ12: 15.4 | CB12: NA | CC12: NA | CD12: =ROUND(E12,1) -> -7.5 | CE12: NA | CF12: NA | CG12: NA | CH12: NA | CI12: NA | CJ12: NA | CK12: NA | CL12: =ROUND(R12,1) -> -5.8 | CM12: NA | CN12: NA | CO12: NA | CP12: NA | CQ12: NA | CR12: NA | CS12: NA | CT12: =ROUND(AF12,1) -> -9.2 | CU12: NA | CV12: NA | CW12: NA | CX12: NA | CY12: NA | CZ12: NA | DA12: NA | DB12: NA | DC12: =ROUND(PPTest!K12,1) -> 22.6 | DD12: NA | DE12: NA | DF12: =BU12 -> 0.304 | DG12: =BV12 -> 0.092 | DH12: NA | DQ12: -1.7 | DR12: -0.7 | DS12: -2.6
A13: =A12+1 -> 36532 | B13: 7 | E13: =ROUND(0.77*DQ13-6.2,1) -> -6.8 | R13: =ROUND(DR13*0.69-5.3,1) -> -4.8 | AF13: =ROUND(2*E13-R13,1) -> -8.8 | BM13: 4.87 | BN13: =BM13*$BN$1 -> 9.8374 | BU13: =ROUND((0.6105*(EXP((17.273*AF13)/(AF13+237.3)))),3) -> 0.314 | BV13: =ROUND((0.6105*(EXP((17.273*R13)/(R13+237.3))))-BU13,3) -> 0.113 | BX13: =BZ13*BZ$2 -> 0 | BY13: 4.29 | BZ13: 0 | CB13: NA | CC13: NA | CD13: =ROUND(E13,1) -> -6.8 | CE13: NA | CF13: NA | CG13: NA | CH13: NA | CI13: NA | CJ13: NA | CK13: NA | CL13: =ROUND(R13,1) -> -4.8 | CM13: NA | CN13: NA | CO13: NA | CP13: NA | CQ13: NA | CR13: NA | CS13: NA | CT13: =ROUND(AF13,1) -> -8.8 | CU13: NA | CV13: NA | CW13: NA | CX13: NA | CY13: NA | CZ13: NA | DA13: NA | DB13: NA | DC13: =ROUND(PPTest!K13,1) -> 0 | DD13: NA | DE13: NA | DF13: =BU13 -> 0.314 | DG13: =BV13 -> 0.113 | DH13: NA | DQ13: -0.8 | DR13: 0.7 | DS13: -2.3
A14: =A13+1 -> 36533 | B14: 8 | E14: =ROUND(0.77*DQ14-6.2,1) -> -6.4 | R14: =ROUND(DR14*0.69-5.3,1) -> -5.2 | AF14: =ROUND(2*E14-R14,1) -> -7.6 | BM14: 4.93 | BN14: =BM14*$BN$1 -> 9.9586 | BU14: =ROUND((0.6105*(EXP((17.273*AF14)/(AF14+237.3)))),3) -> 0.345 | BV14: =ROUND((0.6105*(EXP((17.273*R14)/(R14+237.3))))-BU14,3) -> 0.07 | BX14: =BZ14*BZ$2 -> 21 | BY14: 2.73 | BZ14: 15 | CB14: NA | CC14: NA | CD14: =ROUND(E14,1) -> -6.4 | CE14: NA | CF14: NA | CG14: NA | CH14: NA | CI14: NA | CJ14: NA | CK14: NA | CL14: =ROUND(R14,1) -> -5.2 | CM14: NA | CN14: NA | CO14: NA | CP14: NA | CQ14: NA | CR14: NA | CS14: NA | CT14: =ROUND(AF14,1) -> -7.6 | CU14: NA | CV14: NA | CW14: NA | CX14: NA | CY14: NA | CZ14: NA | DA14: NA | DB14: NA | DC14: =ROUND(PPTest!K14,1) -> 22.1 | DD14: NA | DE14: NA | DF14: =BU14 -> 0.345 | DG14: =BV14 -> 0.07 | DH14: NA | DQ14: -0.3 | DR14: 0.1 | DS14: -0.6
A15: =A14+1 -> 36534 | B15: 9 | E15: =ROUND(0.77*DQ15-6.2,1) -> -6.9 | R15: =ROUND(DR15*0.69-5.3,1) -> -4.8 | AF15: =ROUND(2*E15-R15,1) -> -9 | BM15: 4.99 | BN15: =BM15*$BN$1 -> 10.0798 | BU15: =ROUND((0.6105*(EXP((17.273*AF15)/(AF15+237.3)))),3) -> 0.309 | BV15: =ROUND((0.6105*(EXP((17.273*R15)/(R15+237.3))))-BU15,3) -> 0.118 | BX15: =BZ15*BZ$2 -> 6.72 | BY15: 0 | BZ15: 4.8 | CB15: NA | CC15: NA | CD15: =ROUND(E15,1) -> -6.9 | CE15: NA | CF15: NA | CG15: NA | CH15: NA | CI15: NA | CJ15: NA | CK15: NA | CL15: =ROUND(R15,1) -> -4.8 | CM15: NA | CN15: NA | CO15: NA | CP15: NA | CQ15: NA | CR15: NA | CS15: NA | CT15: =ROUND(AF15,1) -> -9 | CU15: NA | CV15: NA | CW15: NA | CX15: NA | CY15: NA | CZ15: NA | DA15: NA | DB15: NA | DC15: =ROUND(PPTest!K15,1) -> 7.1 | DD15: NA | DE15: NA | DF15: =BU15 -> 0.309 | DG15: =BV15 -> 0.118 | DH15: NA | DQ15: -0.9 | DR15: 0.7 | DS15: -2.4
A16: =A15+1 -> 36535 | B16: 10 | E16: =ROUND(0.77*DQ16-6.2,1) -> -10 | R16: =ROUND(DR16*0.69-5.3,1) -> -5.6 | AF16: =ROUND(2*E16-R16,1) -> -14.4 | BM16: 5.06 | BN16: =BM16*$BN$1 -> 10.2212 | BU16: =ROUND((0.6105*(EXP((17.273*AF16)/(AF16+237.3)))),3) -> 0.2 | BV16: =ROUND((0.6105*(EXP((17.273*R16)/(R16+237.3))))-BU16,3) -> 0.202 | BX16: =BZ16*BZ$2 -> 0.7 | BY16: 0 | BZ16: 0.5 | CB16: NA | CC16: NA | CD16: =ROUND(E16,1) -> -10 | CE16: NA | CF16: NA | CG16: NA | CH16: NA | CI16: NA | CJ16: NA | CK16: NA | CL16: =ROUND(R16,1) -> -5.6 | CM16: NA | CN16: NA | CO16: NA | CP16: NA | CQ16: NA | CR16: NA | CS16: NA | CT16: =ROUND(AF16,1) -> -14.4 | CU16: NA | CV16: NA | CW16: NA | CX16: NA | CY16: NA | CZ16: NA | DA16: NA | DB16: NA | DC16: =ROUND(PPTest!K16,1) -> 0.7 | DD16: NA | DE16: NA | DF16: =BU16 -> 0.2 | DG16: =BV16 -> 0.202 | DH16: NA | DQ16: -4.9 | DR16: -0.5 | DS16: -9.2
A17: =A16+1 -> 36536 | B17: 11 | E17: =ROUND(0.77*DQ17-6.2,1) -> -11 | R17: =ROUND(DR17*0.69-5.3,1) -> -7.2 | AF17: =ROUND(2*E17-R17,1) -> -14.8 | BM17: 5.13 | BN17: =BM17*$BN$1 -> 10.3626 | BU17: =ROUND((0.6105*(EXP((17.273*AF17)/(AF17+237.3)))),3) -> 0.194 | BV17: =ROUND((0.6105*(EXP((17.273*R17)/(R17+237.3))))-BU17,3) -> 0.162 | BX17: =BZ17*BZ$2 -> 1.68 | BY17: 1.43 | BZ17: 1.2 | CB17: NA | CC17: NA | CD17: =ROUND(E17,1) -> -11 | CE17: NA | CF17: NA | CG17: NA | CH17: NA | CI17: NA | CJ17: NA | CK17: NA | CL17: =ROUND(R17,1) -> -7.2 | CM17: NA | CN17: NA | CO17: NA | CP17: NA | CQ17: NA | CR17: NA | CS17: NA | CT17: =ROUND(AF17,1) -> -14.8 | CU17: NA | CV17: NA | CW17: NA | CX17: NA | CY17: NA | CZ17: NA | DA17: NA | DB17: NA | DC17: =ROUND(PPTest!K17,1) -> 1.8 | DD17: NA | DE17: NA | DF17: =BU17 -> 0.194 | DG17: =BV17 -> 0.162 | DH17: NA | DQ17: -6.2 | DR17: -2.8 | DS17: -9.5
A18: =A17+1 -> 36537 | B18: 12 | E18: =ROUND(0.77*DQ18-6.2,1) -> -10.1 | R18: =ROUND(DR18*0.69-5.3,1) -> -6.3 | AF18: =ROUND(2*E18-R18,1) -> -13.9 | BM18: 5.2 | BN18: =BM18*$BN$1 -> 10.504 | BU18: =ROUND((0.6105*(EXP((17.273*AF18)/(AF18+237.3)))),3) -> 0.208 | BV18: =ROUND((0.6105*(EXP((17.273*R18)/(R18+237.3))))-BU18,3) -> 0.173 | BX18: =BZ18*BZ$2 -> 3.92 | BY18: 3.38 | BZ18: 2.8 | CB18: NA | CC18: NA | CD18: =ROUND(E18,1) -> -10.1 | CE18: NA | CF18: NA | CG18: NA | CH18: NA | CI18: NA | CJ18: NA | CK18: NA | CL18: =ROUND(R18,1) -> -6.3 | CM18: NA | CN18: NA | CO18: NA | CP18: NA | CQ18: NA | CR18: NA | CS18: NA | CT18: =ROUND(AF18,1) -> -13.9 | CU18: NA | CV18: NA | CW18: NA | CX18: NA | CY18: NA | CZ18: NA | DA18: NA | DB18: NA | DC18: =ROUND(PPTest!K18,1) -> 4.1 | DD18: NA | DE18: NA | DF18: =BU18 -> 0.208 | DG18: =BV18 -> 0.173 | DH18: NA | DQ18: -5 | DR18: -1.4 | DS18: -8.5
A19: =A18+1 -> 36538 | B19: 13 | E19: =ROUND(0.77*DQ19-6.2,1) -> -9.8 | R19: =ROUND(DR19*0.69-5.3,1) -> -5.4 | AF19: =ROUND(2*E19-R19,1) -> -14.2 | BM19: 5.27 | BN19: =BM19*$BN$1 -> 10.6454 | BU19: =ROUND((0.6105*(EXP((17.273*AF19)/(AF19+237.3)))),3) -> 0.203 | BV19: =ROUND((0.6105*(EXP((17.273*R19)/(R19+237.3))))-BU19,3) -> 0.205 | BX19: =BZ19*BZ$2 -> 0 | BY19: 3.25 | BZ19: 0 | CB19: NA | CC19: NA | CD19: =ROUND(E19,1) -> -9.8 | CE19: NA | CF19: NA | CG19: NA | CH19: NA | CI19: NA | CJ19: NA | CK19: NA | CL19: =ROUND(R19,1) -> -5.4 | CM19: NA | CN19: NA | CO19: NA | CP19: NA | CQ19: NA | CR19: NA | CS19: NA | CT19: =ROUND(AF19,1) -> -14.2 | CU19: NA | CV19: NA | CW19: NA | CX19: NA | CY19: NA | CZ19: NA | DA19: NA | DB19: NA | DC19: =ROUND(PPTest!K19,1) -> 0 | DD19: NA | DE19: NA | DF19: =BU19 -> 0.203 | DG19: =BV19 -> 0.205 | DH19: NA | DQ19: -4.7 | DR19: -0.2 | DS19: -9.1
... A67: =A66+1 -> 36586 | B67: 61 | E67: =ROUND(0.77*DQ67-6.2,1) -> -3.6 | R67: =ROUND(DR67*0.69-5.3,1) -> -0.7 | AF67: =ROUND(2*E67-R67,1) -> -6.5 | BM67: 13.23 | BN67: =BM67*$BN$1 -> 26.7246 | BU67: =ROUND((0.6105*(EXP((17.273*AF67)/(AF67+237.3)))),3) -> 0.375 | BV67: =ROUND((0.6105*(EXP((17.273*R67)/(R67+237.3))))-BU67,3) -> 0.205 | BX67: =BZ67*BZ$2 -> 4.76 | BY67: 0 | BZ67: 3.4 | CB67: NA | CC67: NA | CD67: =ROUND(E67,1) -> -3.6 | CE67: NA | CF67: NA | CG67: NA | CH67: NA | CI67: NA | CJ67: NA | CK67: NA | CL67: =ROUND(R67,1) -> -0.7 | CM67: NA | CN67: NA | CO67: NA | CP67: NA | CQ67: NA | CR67: NA | CS67: NA | CT67: =ROUND(AF67,1) -> -6.5 | CU67: NA | CV67: NA | CW67: NA | CX67: NA | CY67: NA | CZ67: NA | DA67: NA | DB67: NA | DC67: =ROUND(PPTest!K67,1) -> 5 | DD67: NA | DE67: NA | DF67: =BU67 -> 0.375 | DG67: =BV67 -> 0.205 | DH67: NA | DQ67: 3.4 | DR67: 6.6 | DS67: 0.2
A68: =A67+1 -> 36587 | B68: 62 | C68: 0.517 | D68: 0.757 | E68: -1.68 | F68: 105.2 | I68: -0.093 | J68: -2.096 | K68: -0.891 | L68: -0.122 | M68: 0.293 | N68: 0.911 | O68: 0 | P68: 1.1246667 | R68: -0.373 | S68: 1622 | T68: 107.9 | U68: 1537 | X68: -0.024 | Y68: -1.91 | Z68: -0.277 | AA68: -0.058 | AB68: 0.356 | AC68: 0.978 | AD68: 3.888 | AE68: 1841 | AF68: -6.113 | AG68: 0 | AH68: 97.4 | AI68: 2053 | AL68: -0.131 | AM68: -2.764 | AN68: -3.052 | AO68: -0.16 | AP68: 0.256 | AQ68: 0.872 | AR68: 0.025 | AS68: 0.064 | AT68: 0.105 | AU68: 0.089 | AV68: 0.22 | AW68: 0.356 | AX68: 0.097 | AY68: 0.043 | AZ68: -1.416 | BA68: 2288 | BF68: 1250 | BM68: 13.47 | BN68: =BM68*$BN$1 -> 27.2094 | BO68: =ROUND(C68*BO$2,2) -> 0.51 | BP68: =ROUND(D68*BP$2,2) -> 0.83 | BR68: =ROUND(IF(T68>BR$2,100,IF(T68>BR$3,BS$1*T68+BS$2, T68*BS$3+BS$4)),1) -> 95.9 | BS68: =ROUND(IF(F68>BR$2,100, IF(F68>BR$3,BS$1*F68+BS$2, F68*BS$3+BS$4)),1) -> 91.6 | BT68: =ROUND(IF(AH68>BR$2,100,IF(AH68>BR$3,BS$1*AH68+BS$2, AH68*BS$3+BS$4)),1) -> 79.7 | BU68: =ROUND(0.6105*(EXP((17.273*R68)/(R68+237.3)))*BT68/100, 3) -> 0.474 | BV68: =ROUND((100-BT68)*BU68/BT68,3) -> 0.121 | BX68: =BZ68*BZ$2 -> 5.18 | BY68: 0 | BZ68: 3.7 | CB68: =BO68 -> 0.51 | CC68: =BP68 -> 0.83 | CD68: =ROUND(E68,1) -> -1.7 | CE68: NA | CF68: NA | CG68: =ROUND(I68,1) -> -0.1 | CH68: =ROUND(L68,1) -> -0.1 | CI68: =ROUND(M68,1) -> 0.3 | CJ68: =ROUND(N68,1) -> 0.9 | CK68: =ROUND(BS68,1) -> 91.6 | CL68: =ROUND(R68,1) -> -0.4 | CM68: NA | CN68: NA | CO68: =ROUND(X68,1) -> 0 | CP68: =ROUND(AA68,1) -> -0.1 | CQ68: =ROUND(AB68,1) -> 0.4 | CR68: =ROUND(AC68,1) -> 1 | CS68: =ROUND(BR68,1) -> 95.9 | CT68: =ROUND(AF68,1) -> -6.1 | CU68: NA | CV68: NA | CW68: =ROUND(AL68,1) -> -0.1 | CX68: =ROUND(AO68,1) -> -0.2 | CY68: =ROUND(AP68,1) -> 0.3 | CZ68: =ROUND(AQ68,1) -> 0.9 | DA68: =ROUND(BT68,1) -> 79.7 | DB68: =BF68 -> 1250 | DC68: =ROUND(PPTest!K68,1) -> 5.4 | DD68: =ROUND(P68,2) -> 1.12 | DE68: =ROUND(AD68,2) -> 3.89 | DF68: =BU68 -> 0.474 | DG68: =BV68 -> 0.121 | DH68: NA | DQ68: 2.4 | DR68: 4.4 | DS68: 0.4
A69: =A68+1 -> 36588 | B69: 63 | C69: 1.08 | D69: 1.686 | E69: -2.067 | F69: 102.2 | I69: -0.143 | J69: -3.401 | K69: -2.837 | L69: -0.157 | M69: 0.251 | N69: 0.861 | O69: 0 | P69: 1.4796667 | R69: -0.296 | S69: 1359 | T69: 108.9 | U69: 2344 | X69: -0.083 | Y69: -2.407 | Z69: -0.693 | AA69: -0.112 | AB69: 0.313 | AC69: 0.942 | AD69: 5.408 | AE69: 655 | AF69: -6.954 | AG69: 47 | AH69: 92 | AI69: 748 | AL69: -0.222 | AM69: -5.051 | AN69: -7.67 | AO69: -0.208 | AP69: 0.184 | AQ69: 0.794 | AR69: 0.03 | AS69: 0.065 | AT69: 0.08 | AU69: 0.087 | AV69: 0.194 | AW69: 0.326 | AX69: 0.172 | AY69: 0.047 | AZ69: -3.495 | BA69: 2200 | BB69: 13.06 | BC69: 2786 | BF69: =$BF$1-BA69 -> 1293 | BM69: 13.71 | BN69: =BM69*$BN$1 -> 27.6942 | BO69: =ROUND(C69*BO$2,2) -> 1.06 | BP69: =ROUND(D69*BP$2,2) -> 1.85 | BR69: =ROUND(IF(T69>BR$2,100,IF(T69>BR$3,BS$1*T69+BS$2, T69*BS$3+BS$4)),1) -> 97.5 | BS69: =ROUND(IF(F69>BR$2,100, IF(F69>BR$3,BS$1*F69+BS$2, F69*BS$3+BS$4)),1) -> 86.8 | BT69: =ROUND(IF(AH69>BR$2,100,IF(AH69>BR$3,BS$1*AH69+BS$2, AH69*BS$3+BS$4)),1) -> 75 | BU69: =ROUND(0.6105*(EXP((17.273*R69)/(R69+237.3)))*BT69/100, 3) -> 0.448 | BV69: =ROUND((100-BT69)*BU69/BT69,3) -> 0.149 | BX69: =BZ69*BZ$2 -> 7.98 | BY69: 0 | BZ69: 5.7 | CB69: =BO69 -> 1.06 | CC69: =BP69 -> 1.85 | CD69: =ROUND(E69,1) -> -2.1 | CE69: NA | CF69: NA | CG69: =ROUND(I69,1) -> -0.1 | CH69: =ROUND(L69,1) -> -0.2 | CI69: =ROUND(M69,1) -> 0.3 | CJ69: =ROUND(N69,1) -> 0.9 | CK69: =ROUND(BS69,1) -> 86.8 | CL69: =ROUND(R69,1) -> -0.3 | CM69: NA | CN69: NA | CO69: =ROUND(X69,1) -> -0.1 | CP69: =ROUND(AA69,1) -> -0.1 | CQ69: =ROUND(AB69,1) -> 0.3 | CR69: =ROUND(AC69,1) -> 0.9 | CS69: =ROUND(BR69,1) -> 97.5 | CT69: =ROUND(AF69,1) -> -7 | CU69: NA | CV69: NA | CW69: =ROUND(AL69,1) -> -0.2 | CX69: =ROUND(AO69,1) -> -0.2 | CY69: =ROUND(AP69,1) -> 0.2 | CZ69: =ROUND(AQ69,1) -> 0.8 | DA69: =ROUND(BT69,1) -> 75 | DB69: =BF69 -> 1293 | DC69: =ROUND(PPTest!K69,1) -> 5.6 | DD69: =ROUND(P69,2) -> 1.48 | DE69: =ROUND(AD69,2) -> 5.41 | DF69: =BU69 -> 0.448 | DG69: =BV69 -> 0.149 | DH69: =BB69 -> 13.06 | DQ69: 1.5 | DR69: 3.1 | DS69: -0.2
A70: =A69+1 -> 36589 | B70: 64 | C70: 1.173 | D70: 1.784 | E70: -3.019 | F70: 106.4 | I70: -0.098 | J70: -2.705 | K70: -2.738 | L70: -0.147 | M70: 0.261 | N70: 0.872 | O70: 0 | P70: 1.2806667 | R70: -1.237 | S70: 1035 | T70: 109.1 | U70: 536 | X70: -0.064 | Y70: -2.394 | Z70: -1.46 | AA70: -0.108 | AB70: 0.303 | AC70: 0.929 | AD70: 3.4613333 | AE70: 1305 | AF70: -7.35 | AG70: 0 | AH70: 99.2 | AI70: 1251 | AL70: -0.137 | AM70: -3.817 | AN70: -7.39 | AO70: -0.172 | AP70: 0.228 | AQ70: 0.834 | AR70: 0.024 | AS70: 0.006 | AT70: 0.019 | AU70: 0.042 | AV70: 0.274 | AW70: 0.486 | AX70: 0.126 | AY70: 0.023 | AZ70: -2.544 | BA70: 2175 | BB70: 10.45 | BC70: 2786 | BF70: =$BF$1-BA70 -> 1318 | BM70: 13.95 | BN70: =BM70*$BN$1 -> 28.179 | BO70: =ROUND(C70*BO$2,2) -> 1.15 | BP70: =ROUND(D70*BP$2,2) -> 1.96 | BR70: =ROUND(IF(T70>BR$2,100,IF(T70>BR$3,BS$1*T70+BS$2, T70*BS$3+BS$4)),1) -> 97.8 | BS70: =ROUND(IF(F70>BR$2,100, IF(F70>BR$3,BS$1*F70+BS$2, F70*BS$3+BS$4)),1) -> 93.5 | BT70: =ROUND(IF(AH70>BR$2,100,IF(AH70>BR$3,BS$1*AH70+BS$2, AH70*BS$3+BS$4)),1) -> 82 | BU70: =ROUND(0.6105*(EXP((17.273*R70)/(R70+237.3)))*BT70/100, 3) -> 0.457 | BV70: =ROUND((100-BT70)*BU70/BT70,3) -> 0.1 | BX70: =BZ70*BZ$2 -> 9.24 | BY70: 3.12 | BZ70: 6.6 | CB70: =BO70 -> 1.15 | CC70: =BP70 -> 1.96 | CD70: =ROUND(E70,1) -> -3 | CE70: NA | CF70: NA | CG70: =ROUND(I70,1) -> -0.1 | CH70: =ROUND(L70,1) -> -0.1 | CI70: =ROUND(M70,1) -> 0.3 | CJ70: =ROUND(N70,1) -> 0.9 | CK70: =ROUND(BS70,1) -> 93.5 | CL70: =ROUND(R70,1) -> -1.2 | CM70: NA | CN70: NA | CO70: =ROUND(X70,1) -> -0.1 | CP70: =ROUND(AA70,1) -> -0.1 | CQ70: =ROUND(AB70,1) -> 0.3 | CR70: =ROUND(AC70,1) -> 0.9 | CS70: =ROUND(BR70,1) -> 97.8 | CT70: =ROUND(AF70,1) -> -7.4 | CU70: NA | CV70: NA | CW70: =ROUND(AL70,1) -> -0.1 | CX70: =ROUND(AO70,1) -> -0.2 | CY70: =ROUND(AP70,1) -> 0.2 | CZ70: =ROUND(AQ70,1) -> 0.8 | DA70: =ROUND(BT70,1) -> 82 | DB70: =BF70 -> 1318 | DC70: =ROUND(PPTest!K70,1) -> 3.3 | DD70: =ROUND(P70,2) -> 1.28 | DE70: =ROUND(AD70,2) -> 3.46 | DF70: =BU70 -> 0.457 | DG70: =BV70 -> 0.1 | DH70: =BB70 -> 10.45 | DQ70: 2 | DR70: 4.2 | DS70: -0.2
A71: =A70+1 -> 36590 | B71: 65 | C71: 2.378 | D71: 3.02 | E71: -6.585 | F71: 102.3 | I71: -0.127 | J71: -5.55 | K71: -6.291 | L71: -0.153 | M71: 0.253 | N71: 0.86 | O71: 0 | P71: 1.1933333 | R71: -1.617 | S71: 1112 | T71: 108.2 | U71: 217 | X71: -0.078 | Y71: -3.826 | Z71: -1.143 | AA71: -0.072 | AB71: 0.345 | AC71: 0.967 | AD71: 3.3013333 | AE71: 1455 | AF71: -12.54 | AG71: 553 | AH71: 75 | AI71: 1110 | AL71: -0.203 | AM71: -7.41 | AN71: -13.56 | AO71: -0.251 | AP71: 0.109 | AQ71: 0.697 | AR71: 0.061 | AS71: 0.29 | AT71: 0.26 | AU71: 0.042 | AV71: 0.096 | AW71: 0.183 | AX71: 0.021 | AY71: 0.048 | AZ71: -6.571 | BA71: 2205 | BB71: 13.17 | BC71: 2786 | BF71: =$BF$1-BA71 -> 1288 | BM71: 14.21 | BN71: =BM71*$BN$1 -> 28.7042 | BO71: =ROUND(C71*BO$2,2) -> 2.33 | BP71: =ROUND(D71*BP$2,2) -> 3.32 | BR71: =ROUND(IF(T71>BR$2,100,IF(T71>BR$3,BS$1*T71+BS$2, T71*BS$3+BS$4)),1) -> 96.3 | BS71: =ROUND(IF(F71>BR$2,100, IF(F71>BR$3,BS$1*F71+BS$2, F71*BS$3+BS$4)),1) -> 87 | BT71: =ROUND(IF(AH71>BR$2,100,IF(AH71>BR$3,BS$1*AH71+BS$2, AH71*BS$3+BS$4)),1) -> 60 | BU71: =ROUND(0.6105*(EXP((17.273*R71)/(R71+237.3)))*BT71/100, 3) -> 0.325 | BV71: =ROUND((100-BT71)*BU71/BT71,3) -> 0.217 | BX71: =BZ71*BZ$2 -> 0 | BY71: 0 | BZ71: 0 | CB71: =BO71 -> 2.33 | CC71: =BP71 -> 3.32 | CD71: =ROUND(E71,1) -> -6.6 | CE71: NA | CF71: NA | CG71: =ROUND(I71,1) -> -0.1 | CH71: =ROUND(L71,1) -> -0.2 | CI71: =ROUND(M71,1) -> 0.3 | CJ71: =ROUND(N71,1) -> 0.9 | CK71: =ROUND(BS71,1) -> 87 | CL71: =ROUND(R71,1) -> -1.6 | CM71: NA | CN71: NA | CO71: =ROUND(X71,1) -> -0.1 | CP71: =ROUND(AA71,1) -> -0.1 | CQ71: =ROUND(AB71,1) -> 0.3 | CR71: =ROUND(AC71,1) -> 1 | CS71: =ROUND(BR71,1) -> 96.3 | CT71: =ROUND(AF71,1) -> -12.5 | CU71: NA | CV71: NA | CW71: =ROUND(AL71,1) -> -0.2 | CX71: =ROUND(AO71,1) -> -0.3 | CY71: =ROUND(AP71,1) -> 0.1 | CZ71: =ROUND(AQ71,1) -> 0.7 | DA71: =ROUND(BT71,1) -> 60 | DB71: =BF71 -> 1288 | DC71: =ROUND(PPTest!K71,1) -> 0 | DD71: =ROUND(P71,2) -> 1.19 | DE71: =ROUND(AD71,2) -> 3.3 | DF71: =BU71 -> 0.325 | DG71: =BV71 -> 0.217 | DH71: =BB71 -> 13.17 | DQ71: 3.1 | DR71: 7 | DS71: -0.9
A72: =A71+1 -> 36591 | B72: 66 | C72: 1.412 | D72: 2.235 | E72: -6.98 | F72: 105.1 | I72: -0.106 | J72: -5.37 | K72: -6.715 | L72: -0.147 | M72: 0.261 | N72: 0.868 | O72: 0 | P72: 1.3643333 | R72: -4.31 | S72: 1424 | T72: 107.6 | U72: 238 | X72: -0.045 | Y72: -4.719 | Z72: -2.825 | AA72: -0.063 | AB72: 0.357 | AC72: 0.978 | AD72: 3.3813333 | AE72: 1300 | AF72: -16.05 | AG72: 2355 | AH72: 99.9 | AI72: 1149 | AL72: -0.178 | AM72: -10.23 | AN72: -17.51 | AO72: -0.201 | AP72: 0.196 | AQ72: 0.8 | AR72: 0.026 | AS72: 0.116 | AT72: 0.157 | AU72: 0.014 | AV72: 0.108 | AW72: 0.458 | AX72: 0.107 | AY72: 0.014 | AZ72: -5.774 | BA72: 2189 | BB72: 13.18 | BC72: 2786 | BF72: =$BF$1-BA72 -> 1304 | BM72: 14.45 | BN72: =BM72*$BN$1 -> 29.189 | BO72: =ROUND(C72*BO$2,2) -> 1.38 | BP72: =ROUND(D72*BP$2,2) -> 2.46 | BR72: =ROUND(IF(T72>BR$2,100,IF(T72>BR$3,BS$1*T72+BS$2, T72*BS$3+BS$4)),1) -> 95.4 | BS72: =ROUND(IF(F72>BR$2,100, IF(F72>BR$3,BS$1*F72+BS$2, F72*BS$3+BS$4)),1) -> 91.4 | BT72: =ROUND(IF(AH72>BR$2,100,IF(AH72>BR$3,BS$1*AH72+BS$2, AH72*BS$3+BS$4)),1) -> 83.1 | BU72: =ROUND(0.6105*(EXP((17.273*R72)/(R72+237.3)))*BT72/100, 3) -> 0.369 | BV72: =ROUND((100-BT72)*BU72/BT72,3) -> 0.075 | BX72: =BZ72*BZ$2 -> 2.38 | BY72: 3.38 | BZ72: 1.7 | CB72: =BO72 -> 1.38 | CC72: =BP72 -> 2.46 | CD72: =ROUND(E72,1) -> -7 | CE72: NA | CF72: NA | CG72: =ROUND(I72,1) -> -0.1 | CH72: =ROUND(L72,1) -> -0.1 | CI72: =ROUND(M72,1) -> 0.3 | CJ72: =ROUND(N72,1) -> 0.9 | CK72: =ROUND(BS72,1) -> 91.4 | CL72: =ROUND(R72,1) -> -4.3 | CM72: NA | CN72: NA | CO72: =ROUND(X72,1) -> 0 | CP72: =ROUND(AA72,1) -> -0.1 | CQ72: =ROUND(AB72,1) -> 0.4 | CR72: =ROUND(AC72,1) -> 1 | CS72: =ROUND(BR72,1) -> 95.4 | CT72: =ROUND(AF72,1) -> -16.1 | CU72: NA | CV72: NA | CW72: =ROUND(AL72,1) -> -0.2 | CX72: =ROUND(AO72,1) -> -0.2 | CY72: =ROUND(AP72,1) -> 0.2 | CZ72: =ROUND(AQ72,1) -> 0.8 | DA72: =ROUND(BT72,1) -> 83.1 | DB72: =BF72 -> 1304 | DC72: =ROUND(PPTest!K72,1) -> 2.1 | DD72: =ROUND(P72,2) -> 1.36 | DE72: =ROUND(AD72,2) -> 3.38 | DF72: =BU72 -> 0.369 | DG72: =BV72 -> 0.075 | DH72: =BB72 -> 13.18 | DQ72: 0.2 | DR72: 1.9 | DS72: -1.5
A73: =A72+1 -> 36592 | B73: 67 | C73: 8.41 | D73: 11.86 | E73: -8.88 | F73: 87.5 | I73: -0.293 | J73: -8.11 | K73: -8.38 | L73: -0.162 | M73: 0.237 | N73: 0.838 | O73: 0 | P73: 1.593 | R73: 0.094 | S73: 1308 | T73: 106.4 | U73: 2339 | X73: -0.152 | Y73: -4.689 | Z73: -0.278 | AA73: -0.082 | AB73: 0.333 | AC73: 0.945 | AD73: 4.3413333 | AE73: 1118 | AF73: -18.85 | AG73: 610 | AH73: 43.95 | AI73: 1309 | AL73: -0.574 | AM73: -12.43 | AN73: -20.09 | AO73: -0.261 | AP73: 0.065 | AQ73: 0.649 | AR73: 0.055 | AS73: 0.268 | AT73: 0.43 | AU73: 0.076 | AV73: 0.077 | AW73: 0.06 | AX73: 0.014 | AY73: 0.02 | AZ73: -10.95 | BA73: 2215 | BB73: 13.19 | BC73: 2786 | BF73: =$BF$1-BA73 -> 1278 | BM73: 14.7 | BN73: =BM73*$BN$1 -> 29.694 | BO73: =ROUND(C73*BO$2,2) -> 8.24 | BP73: =ROUND(D73*BP$2,2) -> 13.05 | BR73: =ROUND(IF(T73>BR$2,100,IF(T73>BR$3,BS$1*T73+BS$2, T73*BS$3+BS$4)),1) -> 93.5 | BS73: =ROUND(IF(F73>BR$2,100, IF(F73>BR$3,BS$1*F73+BS$2, F73*BS$3+BS$4)),1) -> 71 | BT73: =ROUND(IF(AH73>BR$2,100,IF(AH73>BR$3,BS$1*AH73+BS$2, AH73*BS$3+BS$4)),1) -> 32.7 | BU73: =ROUND(0.6105*(EXP((17.273*R73)/(R73+237.3)))*BT73/100, 3) -> 0.201 | BV73: =ROUND((100-BT73)*BU73/BT73,3) -> 0.414 | BX73: =BZ73*BZ$2 -> 0.28 | BY73: 0 | BZ73: 0.2 | CB73: =BO73 -> 8.24 | CC73: =BP73 -> 13.05 | CD73: =ROUND(E73,1) -> -8.9 | CE73: NA | CF73: NA | CG73: =ROUND(I73,1) -> -0.3 | CH73: =ROUND(L73,1) -> -0.2 | CI73: =ROUND(M73,1) -> 0.2 | CJ73: =ROUND(N73,1) -> 0.8 | CK73: =ROUND(BS73,1) -> 71 | CL73: =ROUND(R73,1) -> 0.1 | CM73: NA | CN73: NA | CO73: =ROUND(X73,1) -> -0.2 | CP73: =ROUND(AA73,1) -> -0.1 | CQ73: =ROUND(AB73,1) -> 0.3 | CR73: =ROUND(AC73,1) -> 0.9 | CS73: =ROUND(BR73,1) -> 93.5 | CT73: =ROUND(AF73,1) -> -18.9 | CU73: NA | CV73: NA | CW73: =ROUND(AL73,1) -> -0.6 | CX73: =ROUND(AO73,1) -> -0.3 | CY73: =ROUND(AP73,1) -> 0.1 | CZ73: =ROUND(AQ73,1) -> 0.6 | DA73: =ROUND(BT73,1) -> 32.7 | DB73: =BF73 -> 1278 | DC73: =ROUND(PPTest!K73,1) -> 0 | DD73: =ROUND(P73,2) -> 1.59 | DE73: =ROUND(AD73,2) -> 4.34 | DF73: =BU73 -> 0.201 | DG73: =BV73 -> 0.414 | DH73: =BB73 -> 13.19 | DQ73: 1.6 | DR73: 6.3 | DS73: -3.2
A74: =A73+1 -> 36593 | B74: 68 | C74: 12.06 | D74: 20.81 | E74: -3.353 | F74: 84.3 | I74: -0.283 | J74: -5.01 | K74: -4.206 | L74: -0.15 | M74: 0.25 | N74: 0.846 | O74: 0 | P74: 1.5543333 | R74: 3.386 | S74: 1445 | T74: 105 | U74: 537 | X74: -0.121 | Y74: -2.799 | Z74: 1.712 | AA74: -0.084 | AB74: 0.333 | AC74: 0.94 | AD74: 5.2746667 | AE74: 1201 | AF74: -11.16 | AG74: 32 | AH74: 49.08 | AI74: 1402 | AL74: -0.468 | AM74: -7.64 | AN74: -12.34 | AO74: -0.231 | AP74: 0.13 | AQ74: 0.715 | AR74: 0.072 | AS74: 0.277 | AT74: 0.378 | AU74: 0.108 | AV74: 0.054 | AW74: 0.055 | AX74: 0.028 | AY74: 0.029 | AZ74: -5.64 | BA74: 2239 | BB74: 13.21 | BC74: 2786 | BF74: =$BF$1-BA74 -> 1254 | BM74: 14.96 | BN74: =BM74*$BN$1 -> 30.2192 | BO74: =ROUND(C74*BO$2,2) -> 11.82 | BP74: =ROUND(D74*BP$2,2) -> 22.89 | BR74: =ROUND(IF(T74>BR$2,100,IF(T74>BR$3,BS$1*T74+BS$2, T74*BS$3+BS$4)),1) -> 91.3 | BS74: =ROUND(IF(F74>BR$2,100, IF(F74>BR$3,BS$1*F74+BS$2, F74*BS$3+BS$4)),1) -> 68.2 | BT74: =ROUND(IF(AH74>BR$2,100,IF(AH74>BR$3,BS$1*AH74+BS$2, AH74*BS$3+BS$4)),1) -> 37.2 | BU74: =ROUND(0.6105*(EXP((17.273*R74)/(R74+237.3)))*BT74/100, 3) -> 0.29 | BV74: =ROUND((100-BT74)*BU74/BT74,3) -> 0.49 | BX74: =BZ74*BZ$2 -> 0 | BY74: 0 | BZ74: 0 | CB74: =BO74 -> 11.82 | CC74: =BP74 -> 22.89 | CD74: =ROUND(E74,1) -> -3.4 | CE74: NA | CF74: NA | CG74: =ROUND(I74,1) -> -0.3 | CH74: =ROUND(L74,1) -> -0.2 | CI74: =ROUND(M74,1) -> 0.3 | CJ74: =ROUND(N74,1) -> 0.8 | CK74: =ROUND(BS74,1) -> 68.2 | CL74: =ROUND(R74,1) -> 3.4 | CM74: NA | CN74: NA | CO74: =ROUND(X74,1) -> -0.1 | CP74: =ROUND(AA74,1) -> -0.1 | CQ74: =ROUND(AB74,1) -> 0.3 | CR74: =ROUND(AC74,1) -> 0.9 | CS74: =ROUND(BR74,1) -> 91.3 | CT74: =ROUND(AF74,1) -> -11.2 | CU74: NA | CV74: NA | CW74: =ROUND(AL74,1) -> -0.5 | CX74: =ROUND(AO74,1) -> -0.2 | CY74: =ROUND(AP74,1) -> 0.1 | CZ74: =ROUND(AQ74,1) -> 0.7 | DA74: =ROUND(BT74,1) -> 37.2 | DB74: =BF74 -> 1254 | DC74: =ROUND(PPTest!K74,1) -> 0 | DD74: =ROUND(P74,2) -> 1.55 | DE74: =ROUND(AD74,2) -> 5.27 | DF74: =BU74 -> 0.29 | DG74: =BV74 -> 0.49 | DH74: =BB74 -> 13.21 | DQ74: 3.1 | DR74: 10.5 | DS74: -4.3
A75: =A74+1 -> 36594 | B75: 69 | C75: 4.533 | D75: 7.91 | E75: -1.47 | F75: 103.5 | I75: -0.085 | J75: -2.602 | K75: -0.552 | L75: -0.139 | M75: 0.267 | N75: 0.862 | O75: 0 | P75: 1.3613333 | R75: 0.882 | S75: 1520 | T75: 109.3 | U75: 2033 | X75: 0 | Y75: -2 | Z75: -0.176 | AA75: -0.086 | AB75: 0.32 | AC75: 0.918 | AD75: 4.1013333 | AE75: 1339 | AF75: -2.977 | AG75: 600 | AH75: 85.2 | AI75: 1549 | AL75: -0.164 | AM75: -3.102 | AN75: -0.924 | AO75: -0.181 | AP75: 0.206 | AQ75: 0.797 | AR75: 0.036 | AS75: 0.141 | AT75: 0.103 | AU75: 0.02 | AV75: 0.122 | AW75: 0.41 | AX75: 0.149 | AY75: 0.017 | AZ75: -2.05 | BA75: 2240 | BB75: 13.21 | BC75: 2786 | BF75: =$BF$1-BA75 -> 1253 | BM75: 15.22 | BN75: =BM75*$BN$1 -> 30.7444 | BO75: =ROUND(C75*BO$2,2) -> 4.44 | BP75: =ROUND(D75*BP$2,2) -> 8.7 | BR75: =ROUND(IF(T75>BR$2,100,IF(T75>BR$3,BS$1*T75+BS$2, T75*BS$3+BS$4)),1) -> 98.1 | BS75: =ROUND(IF(F75>BR$2,100, IF(F75>BR$3,BS$1*F75+BS$2, F75*BS$3+BS$4)),1) -> 88.9 | BT75: =ROUND(IF(AH75>BR$2,100,IF(AH75>BR$3,BS$1*AH75+BS$2, AH75*BS$3+BS$4)),1) -> 69 | BU75: =ROUND(0.6105*(EXP((17.273*R75)/(R75+237.3)))*BT75/100, 3) -> 0.449 | BV75: =ROUND((100-BT75)*BU75/BT75,3) -> 0.202 | BX75: =BZ75*BZ$2 -> 0.84 | BY75: 1.6 | BZ75: 0.6 | CB75: =BO75 -> 4.44 | CC75: =BP75 -> 8.7 | CD75: =ROUND(E75,1) -> -1.5 | CE75: NA | CF75: NA | CG75: =ROUND(I75,1) -> -0.1 | CH75: =ROUND(L75,1) -> -0.1 | CI75: =ROUND(M75,1) -> 0.3 | CJ75: =ROUND(N75,1) -> 0.9 | CK75: =ROUND(BS75,1) -> 88.9 | CL75: =ROUND(R75,1) -> 0.9 | CM75: NA | CN75: NA | CO75: =ROUND(X75,1) -> 0 | CP75: =ROUND(AA75,1) -> -0.1 | CQ75: =ROUND(AB75,1) -> 0.3 | CR75: =ROUND(AC75,1) -> 0.9 | CS75: =ROUND(BR75,1) -> 98.1 | CT75: =ROUND(AF75,1) -> -3 | CU75: NA | CV75: NA | CW75: =ROUND(AL75,1) -> -0.2 | CX75: =ROUND(AO75,1) -> -0.2 | CY75: =ROUND(AP75,1) -> 0.2 | CZ75: =ROUND(AQ75,1) -> 0.8 | DA75: =ROUND(BT75,1) -> 69 | DB75: =BF75 -> 1253 | DC75: =ROUND(PPTest!K75,1) -> 0 | DD75: =ROUND(P75,2) -> 1.36 | DE75: =ROUND(AD75,2) -> 4.1 | DF75: =BU75 -> 0.449 | DG75: =BV75 -> 0.202 | DH75: =BB75 -> 13.21 | DQ75: 3.8 | DR75: 7.7 | DS75: -0.2
A76: =A75+1 -> 36595 | B76: 70 | C76: 10.37 | D76: 18.17 | E76: -0.808 | F76: 93 | I76: -0.075 | J76: -2.368 | K76: -0.663 | L76: -0.136 | M76: 0.271 | N76: 0.864 | O76: 0 | P76: 1.4576667 | R76: 3.206 | S76: 1412 | T76: 108.6 | U76: 628 | X76: -0.007 | Y76: -1.702 | Z76: 0.96 | AA76: -0.08 | AB76: 0.339 | AC76: 0.934 | AD76: 5.328 | AE76: 1139 | AF76: -3.915 | AG76: 651 | AH76: 66.24 | AI76: 1304 | AL76: -0.212 | AM76: -3.119 | AN76: -2.092 | AO76: -0.221 | AP76: 0.16 | AQ76: 0.741 | AR76: 0.07 | AS76: 0.104 | AT76: 0.102 | AU76: 0.088 | AV76: 0.179 | AW76: 0.305 | AX76: 0.105 | AY76: 0.047 | AZ76: -2.13 | BA76: 2249 | BB76: 13.19 | BC76: 2786 | BF76: =$BF$1-BA76 -> 1244 | BM76: 15.48 | BN76: =BM76*$BN$1 -> 31.2696 | BO76: =ROUND(C76*BO$2,2) -> 10.16 | BP76: =ROUND(D76*BP$2,2) -> 19.99 | BR76: =ROUND(IF(T76>BR$2,100,IF(T76>BR$3,BS$1*T76+BS$2, T76*BS$3+BS$4)),1) -> 97 | BS76: =ROUND(IF(F76>BR$2,100, IF(F76>BR$3,BS$1*F76+BS$2, F76*BS$3+BS$4)),1) -> 75.8 | BT76: =ROUND(IF(AH76>BR$2,100,IF(AH76>BR$3,BS$1*AH76+BS$2, AH76*BS$3+BS$4)),1) -> 52.3 | BU76: =ROUND(0.6105*(EXP((17.273*R76)/(R76+237.3)))*BT76/100, 3) -> 0.402 | BV76: =ROUND((100-BT76)*BU76/BT76,3) -> 0.367 | BX76: =BZ76*BZ$2 -> 0.42 | BY76: 0 | BZ76: 0.3 | CB76: =BO76 -> 10.16 | CC76: =BP76 -> 19.99 | CD76: =ROUND(E76,1) -> -0.8 | CE76: NA | CF76: NA | CG76: =ROUND(I76,1) -> -0.1 | CH76: =ROUND(L76,1) -> -0.1 | CI76: =ROUND(M76,1) -> 0.3 | CJ76: =ROUND(N76,1) -> 0.9 | CK76: =ROUND(BS76,1) -> 75.8 | CL76: =ROUND(R76,1) -> 3.2 | CM76: NA | CN76: NA | CO76: =ROUND(X76,1) -> 0 | CP76: =ROUND(AA76,1) -> -0.1 | CQ76: =ROUND(AB76,1) -> 0.3 | CR76: =ROUND(AC76,1) -> 0.9 | CS76: =ROUND(BR76,1) -> 97 | CT76: =ROUND(AF76,1) -> -3.9 | CU76: NA | CV76: NA | CW76: =ROUND(AL76,1) -> -0.2 | CX76: =ROUND(AO76,1) -> -0.2 | CY76: =ROUND(AP76,1) -> 0.2 | CZ76: =ROUND(AQ76,1) -> 0.7 | DA76: =ROUND(BT76,1) -> 52.3 | DB76: =BF76 -> 1244 | DC76: =ROUND(PPTest!K76,1) -> 0 | DD76: =ROUND(P76,2) -> 1.46 | DE76: =ROUND(AD76,2) -> 5.33 | DF76: =BU76 -> 0.402 | DG76: =BV76 -> 0.367 | DH76: =BB76 -> 13.19 | DQ76: 5 | DR76: 10 | DS76: 0
A77: =A76+1 -> 36596 | B77: 71 | C77: 9.7 | D77: 16.1 | E77: -1.636 | F77: 86.8 | I77: -0.078 | J77: -2.775 | K77: -0.494 | L77: -0.141 | M77: 0.264 | N77: 0.856 | O77: 0 | P77: 2.4606667 | R77: 0.831 | S77: 1428 | T77: 107.6 | U77: 404 | X77: -0.03 | Y77: -2.351 | Z77: -0.139 | AA77: -0.108 | AB77: 0.307 | AC77: 0.903 | AD77: 7.088 | AE77: 1331 | AF77: -3.863 | AG77: 2359 | AH77: 59.8 | AI77: 1456 | AL77: -0.142 | AM77: -3.636 | AN77: -0.814 | AO77: -0.174 | AP77: 0.213 | AQ77: 0.798 | AR77: 0.017 | AS77: 0.04 | AT77: 0.048 | AU77: 0.03 | AV77: 0.225 | AW77: 0.542 | AX77: 0.074 | AY77: 0.024 | AZ77: -2.686 | BA77: 2253 | BB77: 13.21 | BC77: 2786 | BF77: =$BF$1-BA77 -> 1240 | BM77: 15.73 | BN77: =BM77*$BN$1 -> 31.7746 | BO77: =ROUND(C77*BO$2,2) -> 9.51 | BP77: =ROUND(D77*BP$2,2) -> 17.71 | BR77: =ROUND(IF(T77>BR$2,100,IF(T77>BR$3,BS$1*T77+BS$2, T77*BS$3+BS$4)),1) -> 95.4 | BS77: =ROUND(IF(F77>BR$2,100, IF(F77>BR$3,BS$1*F77+BS$2, F77*BS$3+BS$4)),1) -> 70.4 | BT77: =ROUND(IF(AH77>BR$2,100,IF(AH77>BR$3,BS$1*AH77+BS$2, AH77*BS$3+BS$4)),1) -> 46.6 | BU77: =ROUND(0.6105*(EXP((17.273*R77)/(R77+237.3)))*BT77/100, 3) -> 0.302 | BV77: =ROUND((100-BT77)*BU77/BT77,3) -> 0.346 | BX77: =BZ77*BZ$2 -> 1.96 | BY77: 0 | BZ77: 1.4 | CB77: =BO77 -> 9.51 | CC77: =BP77 -> 17.71 | CD77: =ROUND(E77,1) -> -1.6 | CE77: NA | CF77: NA | CG77: =ROUND(I77,1) -> -0.1 | CH77: =ROUND(L77,1) -> -0.1 | CI77: =ROUND(M77,1) -> 0.3 | CJ77: =ROUND(N77,1) -> 0.9 | CK77: =ROUND(BS77,1) -> 70.4 | CL77: =ROUND(R77,1) -> 0.8 | CM77: NA | CN77: NA | CO77: =ROUND(X77,1) -> 0 | CP77: =ROUND(AA77,1) -> -0.1 | CQ77: =ROUND(AB77,1) -> 0.3 | CR77: =ROUND(AC77,1) -> 0.9 | CS77: =ROUND(BR77,1) -> 95.4 | CT77: =ROUND(AF77,1) -> -3.9 | CU77: NA | CV77: NA | CW77: =ROUND(AL77,1) -> -0.1 | CX77: =ROUND(AO77,1) -> -0.2 | CY77: =ROUND(AP77,1) -> 0.2 | CZ77: =ROUND(AQ77,1) -> 0.8 | DA77: =ROUND(BT77,1) -> 46.6 | DB77: =BF77 -> 1240 | DC77: =ROUND(PPTest!K77,1) -> 0 | DD77: =ROUND(P77,2) -> 2.46 | DE77: =ROUND(AD77,2) -> 7.09 | DF77: =BU77 -> 0.302 | DG77: =BV77 -> 0.346 | DH77: =BB77 -> 13.21 | DQ77: 6.2 | DR77: 12.1 | DS77: 0.3
A78: =A77+1 -> 36597 | B78: 72 | C78: 9.61 | D78: 16.57 | E78: -3.776 | F78: 87.4 | I78: -0.075 | J78: -4.488 | K78: -2.295 | L78: -0.143 | M78: 0.262 | N78: 0.852 | O78: 0 | P78: 1.4673333 | R78: 0.789 | S78: 1519 | T78: 106.9 | U78: 413 | X78: -0.006 | Y78: -3.388 | Z78: -0.241 | AA78: -0.078 | AB78: 0.34 | AC78: 0.948 | AD78: 4.208 | AE78: 1047 | AF78: -9.68 | AG78: 424 | AH78: 62.65 | AI78: 1555 | AL78: -0.158 | AM78: -6.244 | AN78: -9.43 | AO78: -0.216 | AP78: 0.159 | AQ78: 0.737 | AR78: 0.022 | AS78: 0.172 | AT78: 0.151 | AU78: 0.039 | AV78: 0.119 | AW78: 0.348 | AX78: 0.112 | AY78: 0.037 | AZ78: -4.636 | BA78: 2260 | BB78: 13.23 | BC78: 2786 | BF78: =$BF$1-BA78 -> 1233 | BM78: 15.98 | BN78: =BM78*$BN$1 -> 32.2796 | BO78: =ROUND(C78*BO$2,2) -> 9.42 | BP78: =ROUND(D78*BP$2,2) -> 18.23 | BR78: =ROUND(IF(T78>BR$2,100,IF(T78>BR$3,BS$1*T78+BS$2, T78*BS$3+BS$4)),1) -> 94.3 | BS78: =ROUND(IF(F78>BR$2,100, IF(F78>BR$3,BS$1*F78+BS$2, F78*BS$3+BS$4)),1) -> 70.9 | BT78: =ROUND(IF(AH78>BR$2,100,IF(AH78>BR$3,BS$1*AH78+BS$2, AH78*BS$3+BS$4)),1) -> 49.1 | BU78: =ROUND(0.6105*(EXP((17.273*R78)/(R78+237.3)))*BT78/100, 3) -> 0.317 | BV78: =ROUND((100-BT78)*BU78/BT78,3) -> 0.329 | BX78: =BZ78*BZ$2 -> 0 | BY78: 0 | BZ78: 0 | CB78: =BO78 -> 9.42 | CC78: =BP78 -> 18.23 | CD78: =ROUND(E78,1) -> -3.8 | CE78: NA | CF78: NA | CG78: =ROUND(I78,1) -> -0.1 | CH78: =ROUND(L78,1) -> -0.1 | CI78: =ROUND(M78,1) -> 0.3 | CJ78: =ROUND(N78,1) -> 0.9 | CK78: =ROUND(BS78,1) -> 70.9 | CL78: =ROUND(R78,1) -> 0.8 | CM78: NA | CN78: NA | CO78: =ROUND(X78,1) -> 0 | CP78: =ROUND(AA78,1) -> -0.1 | CQ78: =ROUND(AB78,1) -> 0.3 | CR78: =ROUND(AC78,1) -> 0.9 | CS78: =ROUND(BR78,1) -> 94.3 | CT78: =ROUND(AF78,1) -> -9.7 | CU78: NA | CV78: NA | CW78: =ROUND(AL78,1) -> -0.2 | CX78: =ROUND(AO78,1) -> -0.2 | CY78: =ROUND(AP78,1) -> 0.2 | CZ78: =ROUND(AQ78,1) -> 0.7 | DA78: =ROUND(BT78,1) -> 49.1 | DB78: =BF78 -> 1233 | DC78: =ROUND(PPTest!K78,1) -> 0 | DD78: =ROUND(P78,2) -> 1.47 | DE78: =ROUND(AD78,2) -> 4.21 | DF78: =BU78 -> 0.317 | DG78: =BV78 -> 0.329 | DH78: =BB78 -> 13.23 | DQ78: 5 | DR78: 11.9 | DS78: -1.9
